[2025-06-22 00:26:01,550] [INFO] uvicorn.error: Shutting down
[2025-06-22 00:26:01,652] [INFO] uvicorn.error: Waiting for application shutdown.
[2025-06-22 00:26:01,652] [INFO] uvicorn.error: Application shutdown complete.
[2025-06-22 00:26:01,653] [INFO] uvicorn.error: Finished server process [10840]
[2025-06-22 00:26:03,953] [INFO] uvicorn.error: Started server process [7528]
[2025-06-22 00:26:03,953] [INFO] uvicorn.error: Waiting for application startup.
[2025-06-22 00:26:03,954] [INFO] uvicorn.error: Application startup complete.
[2025-06-22 00:26:18,056] [INFO] uvicorn.error: Shutting down
[2025-06-22 00:26:18,167] [INFO] uvicorn.error: Waiting for application shutdown.
[2025-06-22 00:26:18,168] [INFO] uvicorn.error: Application shutdown complete.
[2025-06-22 00:26:18,168] [INFO] uvicorn.error: Finished server process [7528]
[2025-06-22 00:26:20,213] [INFO] uvicorn.error: Started server process [272]
[2025-06-22 00:26:20,214] [INFO] uvicorn.error: Waiting for application startup.
[2025-06-22 00:26:20,214] [INFO] uvicorn.error: Application startup complete.
[2025-06-22 00:26:38,963] [INFO] uvicorn.error: Shutting down
[2025-06-22 00:26:39,075] [INFO] uvicorn.error: Waiting for application shutdown.
[2025-06-22 00:26:39,076] [INFO] uvicorn.error: Application shutdown complete.
[2025-06-22 00:26:39,077] [INFO] uvicorn.error: Finished server process [272]
[2025-06-22 00:36:45,413] [INFO] uvicorn.error: Started server process [12084]
[2025-06-22 00:36:45,413] [INFO] uvicorn.error: Waiting for application startup.
[2025-06-22 00:36:45,414] [INFO] uvicorn.error: Application startup complete.
[2025-06-22 00:37:37,941] [INFO] uvicorn.error: Shutting down
[2025-06-22 00:37:38,057] [INFO] uvicorn.error: Waiting for application shutdown.
[2025-06-22 00:37:38,057] [INFO] uvicorn.error: Application shutdown complete.
[2025-06-22 00:37:38,058] [INFO] uvicorn.error: Finished server process [12084]
[2025-06-22 00:37:40,179] [INFO] uvicorn.error: Started server process [7660]
[2025-06-22 00:37:40,180] [INFO] uvicorn.error: Waiting for application startup.
[2025-06-22 00:37:40,181] [INFO] uvicorn.error: Application startup complete.
[2025-06-22 00:39:57,836] [INFO] uvicorn.error: Shutting down
[2025-06-22 00:39:57,951] [INFO] uvicorn.error: Waiting for application shutdown.
[2025-06-22 00:39:57,951] [INFO] uvicorn.error: Application shutdown complete.
[2025-06-22 00:39:57,952] [INFO] uvicorn.error: Finished server process [7660]
[2025-06-22 00:40:00,260] [INFO] uvicorn.error: Started server process [13632]
[2025-06-22 00:40:00,260] [INFO] uvicorn.error: Waiting for application startup.
[2025-06-22 00:40:00,261] [INFO] uvicorn.error: Application startup complete.
[2025-06-22 00:43:28,992] [INFO] uvicorn.error: Shutting down
[2025-06-22 00:43:29,107] [INFO] uvicorn.error: Waiting for application shutdown.
[2025-06-22 00:43:29,107] [INFO] uvicorn.error: Application shutdown complete.
[2025-06-22 00:43:29,108] [INFO] uvicorn.error: Finished server process [13632]
[2025-06-22 00:43:31,263] [INFO] uvicorn.error: Started server process [10500]
[2025-06-22 00:43:31,263] [INFO] uvicorn.error: Waiting for application startup.
[2025-06-22 00:43:31,264] [INFO] uvicorn.error: Application startup complete.
[2025-06-22 00:45:12,562] [INFO] app.routes.user: Creating user tes22t Employee ID: 4 
[2025-06-22 00:45:12,894] [ERROR] uvicorn.error: Exception in ASGI application
Traceback (most recent call last):
  File "C:\Users\pc\AppData\Local\Programs\Python\Python313\Lib\site-packages\uvicorn\protocols\http\h11_impl.py", line 403, in run_asgi
    result = await app(  # type: ignore[func-returns-value]
             ^^^^^^^^^^^^^^^^^^^^^^^^^^^^^^^^^^^^^^^^^^^^^^
        self.scope, self.receive, self.send
        ^^^^^^^^^^^^^^^^^^^^^^^^^^^^^^^^^^^
    )
    ^
  File "C:\Users\pc\AppData\Local\Programs\Python\Python313\Lib\site-packages\uvicorn\middleware\proxy_headers.py", line 60, in __call__
    return await self.app(scope, receive, send)
           ^^^^^^^^^^^^^^^^^^^^^^^^^^^^^^^^^^^^
  File "C:\Users\pc\AppData\Local\Programs\Python\Python313\Lib\site-packages\fastapi\applications.py", line 1054, in __call__
    await super().__call__(scope, receive, send)
  File "C:\Users\pc\AppData\Local\Programs\Python\Python313\Lib\site-packages\starlette\applications.py", line 112, in __call__
    await self.middleware_stack(scope, receive, send)
  File "C:\Users\pc\AppData\Local\Programs\Python\Python313\Lib\site-packages\starlette\middleware\errors.py", line 187, in __call__
    raise exc
  File "C:\Users\pc\AppData\Local\Programs\Python\Python313\Lib\site-packages\starlette\middleware\errors.py", line 165, in __call__
    await self.app(scope, receive, _send)
  File "C:\Users\pc\AppData\Local\Programs\Python\Python313\Lib\site-packages\starlette\middleware\cors.py", line 93, in __call__
    await self.simple_response(scope, receive, send, request_headers=headers)
  File "C:\Users\pc\AppData\Local\Programs\Python\Python313\Lib\site-packages\starlette\middleware\cors.py", line 144, in simple_response
    await self.app(scope, receive, send)
  File "C:\Users\pc\AppData\Local\Programs\Python\Python313\Lib\site-packages\starlette\middleware\exceptions.py", line 62, in __call__
    await wrap_app_handling_exceptions(self.app, conn)(scope, receive, send)
  File "C:\Users\pc\AppData\Local\Programs\Python\Python313\Lib\site-packages\starlette\_exception_handler.py", line 53, in wrapped_app
    raise exc
  File "C:\Users\pc\AppData\Local\Programs\Python\Python313\Lib\site-packages\starlette\_exception_handler.py", line 42, in wrapped_app
    await app(scope, receive, sender)
  File "C:\Users\pc\AppData\Local\Programs\Python\Python313\Lib\site-packages\starlette\routing.py", line 714, in __call__
    await self.middleware_stack(scope, receive, send)
  File "C:\Users\pc\AppData\Local\Programs\Python\Python313\Lib\site-packages\starlette\routing.py", line 734, in app
    await route.handle(scope, receive, send)
  File "C:\Users\pc\AppData\Local\Programs\Python\Python313\Lib\site-packages\starlette\routing.py", line 288, in handle
    await self.app(scope, receive, send)
  File "C:\Users\pc\AppData\Local\Programs\Python\Python313\Lib\site-packages\starlette\routing.py", line 76, in app
    await wrap_app_handling_exceptions(app, request)(scope, receive, send)
  File "C:\Users\pc\AppData\Local\Programs\Python\Python313\Lib\site-packages\starlette\_exception_handler.py", line 53, in wrapped_app
    raise exc
  File "C:\Users\pc\AppData\Local\Programs\Python\Python313\Lib\site-packages\starlette\_exception_handler.py", line 42, in wrapped_app
    await app(scope, receive, sender)
  File "C:\Users\pc\AppData\Local\Programs\Python\Python313\Lib\site-packages\starlette\routing.py", line 73, in app
    response = await f(request)
               ^^^^^^^^^^^^^^^^
  File "C:\Users\pc\AppData\Local\Programs\Python\Python313\Lib\site-packages\fastapi\routing.py", line 327, in app
    content = await serialize_response(
              ^^^^^^^^^^^^^^^^^^^^^^^^^
    ...<9 lines>...
    )
    ^
  File "C:\Users\pc\AppData\Local\Programs\Python\Python313\Lib\site-packages\fastapi\routing.py", line 176, in serialize_response
    raise ResponseValidationError(
        errors=_normalize_errors(errors), body=response_content
    )
fastapi.exceptions.ResponseValidationError: 1 validation errors:
  {'type': 'missing', 'loc': ('response', 'employee_name'), 'msg': 'Field required', 'input': <app.models.user.User object at 0x0000024BB2E959D0>}

[2025-06-22 00:47:06,026] [INFO] uvicorn.error: Shutting down
[2025-06-22 00:47:06,127] [INFO] uvicorn.error: Waiting for application shutdown.
[2025-06-22 00:47:06,128] [INFO] uvicorn.error: Application shutdown complete.
[2025-06-22 00:47:06,128] [INFO] uvicorn.error: Finished server process [10500]
[2025-06-22 00:47:08,370] [INFO] uvicorn.error: Started server process [13900]
[2025-06-22 00:47:08,370] [INFO] uvicorn.error: Waiting for application startup.
[2025-06-22 00:47:08,371] [INFO] uvicorn.error: Application startup complete.
[2025-06-22 00:47:47,469] [INFO] uvicorn.error: Shutting down
[2025-06-22 00:47:47,570] [INFO] uvicorn.error: Waiting for application shutdown.
[2025-06-22 00:47:47,571] [INFO] uvicorn.error: Application shutdown complete.
[2025-06-22 00:47:47,571] [INFO] uvicorn.error: Finished server process [13900]
[2025-06-22 00:47:49,955] [INFO] uvicorn.error: Started server process [656]
[2025-06-22 00:47:49,955] [INFO] uvicorn.error: Waiting for application startup.
[2025-06-22 00:47:49,956] [INFO] uvicorn.error: Application startup complete.
[2025-06-22 00:48:02,468] [INFO] uvicorn.error: Shutting down
[2025-06-22 00:48:02,570] [INFO] uvicorn.error: Waiting for application shutdown.
[2025-06-22 00:48:02,571] [INFO] uvicorn.error: Application shutdown complete.
[2025-06-22 00:48:02,571] [INFO] uvicorn.error: Finished server process [656]
[2025-06-22 00:48:04,715] [INFO] uvicorn.error: Started server process [7992]
[2025-06-22 00:48:04,716] [INFO] uvicorn.error: Waiting for application startup.
[2025-06-22 00:48:04,716] [INFO] uvicorn.error: Application startup complete.
[2025-06-22 00:48:09,494] [INFO] uvicorn.error: Shutting down
[2025-06-22 00:48:09,597] [INFO] uvicorn.error: Waiting for application shutdown.
[2025-06-22 00:48:09,598] [INFO] uvicorn.error: Application shutdown complete.
[2025-06-22 00:48:09,598] [INFO] uvicorn.error: Finished server process [7992]
[2025-06-22 00:48:11,586] [INFO] uvicorn.error: Started server process [13612]
[2025-06-22 00:48:11,586] [INFO] uvicorn.error: Waiting for application startup.
[2025-06-22 00:48:11,587] [INFO] uvicorn.error: Application startup complete.
[2025-06-22 00:48:21,383] [INFO] uvicorn.error: Shutting down
[2025-06-22 00:48:21,486] [INFO] uvicorn.error: Waiting for application shutdown.
[2025-06-22 00:48:21,486] [INFO] uvicorn.error: Application shutdown complete.
[2025-06-22 00:48:21,486] [INFO] uvicorn.error: Finished server process [13612]
[2025-06-22 00:48:23,807] [INFO] uvicorn.error: Started server process [6084]
[2025-06-22 00:48:23,808] [INFO] uvicorn.error: Waiting for application startup.
[2025-06-22 00:48:23,808] [INFO] uvicorn.error: Application startup complete.
[2025-06-22 00:48:51,740] [INFO] app.routes.user: Creating user tes2222t Employee ID: 5 
[2025-06-22 00:48:52,093] [ERROR] uvicorn.error: Exception in ASGI application
Traceback (most recent call last):
  File "C:\Users\pc\AppData\Local\Programs\Python\Python313\Lib\site-packages\uvicorn\protocols\http\h11_impl.py", line 403, in run_asgi
    result = await app(  # type: ignore[func-returns-value]
             ^^^^^^^^^^^^^^^^^^^^^^^^^^^^^^^^^^^^^^^^^^^^^^
        self.scope, self.receive, self.send
        ^^^^^^^^^^^^^^^^^^^^^^^^^^^^^^^^^^^
    )
    ^
  File "C:\Users\pc\AppData\Local\Programs\Python\Python313\Lib\site-packages\uvicorn\middleware\proxy_headers.py", line 60, in __call__
    return await self.app(scope, receive, send)
           ^^^^^^^^^^^^^^^^^^^^^^^^^^^^^^^^^^^^
  File "C:\Users\pc\AppData\Local\Programs\Python\Python313\Lib\site-packages\fastapi\applications.py", line 1054, in __call__
    await super().__call__(scope, receive, send)
  File "C:\Users\pc\AppData\Local\Programs\Python\Python313\Lib\site-packages\starlette\applications.py", line 112, in __call__
    await self.middleware_stack(scope, receive, send)
  File "C:\Users\pc\AppData\Local\Programs\Python\Python313\Lib\site-packages\starlette\middleware\errors.py", line 187, in __call__
    raise exc
  File "C:\Users\pc\AppData\Local\Programs\Python\Python313\Lib\site-packages\starlette\middleware\errors.py", line 165, in __call__
    await self.app(scope, receive, _send)
  File "C:\Users\pc\AppData\Local\Programs\Python\Python313\Lib\site-packages\starlette\middleware\cors.py", line 93, in __call__
    await self.simple_response(scope, receive, send, request_headers=headers)
  File "C:\Users\pc\AppData\Local\Programs\Python\Python313\Lib\site-packages\starlette\middleware\cors.py", line 144, in simple_response
    await self.app(scope, receive, send)
  File "C:\Users\pc\AppData\Local\Programs\Python\Python313\Lib\site-packages\starlette\middleware\exceptions.py", line 62, in __call__
    await wrap_app_handling_exceptions(self.app, conn)(scope, receive, send)
  File "C:\Users\pc\AppData\Local\Programs\Python\Python313\Lib\site-packages\starlette\_exception_handler.py", line 53, in wrapped_app
    raise exc
  File "C:\Users\pc\AppData\Local\Programs\Python\Python313\Lib\site-packages\starlette\_exception_handler.py", line 42, in wrapped_app
    await app(scope, receive, sender)
  File "C:\Users\pc\AppData\Local\Programs\Python\Python313\Lib\site-packages\starlette\routing.py", line 714, in __call__
    await self.middleware_stack(scope, receive, send)
  File "C:\Users\pc\AppData\Local\Programs\Python\Python313\Lib\site-packages\starlette\routing.py", line 734, in app
    await route.handle(scope, receive, send)
  File "C:\Users\pc\AppData\Local\Programs\Python\Python313\Lib\site-packages\starlette\routing.py", line 288, in handle
    await self.app(scope, receive, send)
  File "C:\Users\pc\AppData\Local\Programs\Python\Python313\Lib\site-packages\starlette\routing.py", line 76, in app
    await wrap_app_handling_exceptions(app, request)(scope, receive, send)
  File "C:\Users\pc\AppData\Local\Programs\Python\Python313\Lib\site-packages\starlette\_exception_handler.py", line 53, in wrapped_app
    raise exc
  File "C:\Users\pc\AppData\Local\Programs\Python\Python313\Lib\site-packages\starlette\_exception_handler.py", line 42, in wrapped_app
    await app(scope, receive, sender)
  File "C:\Users\pc\AppData\Local\Programs\Python\Python313\Lib\site-packages\starlette\routing.py", line 73, in app
    response = await f(request)
               ^^^^^^^^^^^^^^^^
  File "C:\Users\pc\AppData\Local\Programs\Python\Python313\Lib\site-packages\fastapi\routing.py", line 327, in app
    content = await serialize_response(
              ^^^^^^^^^^^^^^^^^^^^^^^^^
    ...<9 lines>...
    )
    ^
  File "C:\Users\pc\AppData\Local\Programs\Python\Python313\Lib\site-packages\fastapi\routing.py", line 176, in serialize_response
    raise ResponseValidationError(
        errors=_normalize_errors(errors), body=response_content
    )
fastapi.exceptions.ResponseValidationError: 1 validation errors:
  {'type': 'missing', 'loc': ('response', 'employee_name'), 'msg': 'Field required', 'input': <app.models.user.User object at 0x000002352D103250>}

[2025-06-22 00:49:12,849] [INFO] uvicorn.error: Shutting down
[2025-06-22 00:49:12,951] [INFO] uvicorn.error: Waiting for application shutdown.
[2025-06-22 00:49:12,952] [INFO] uvicorn.error: Application shutdown complete.
[2025-06-22 00:49:12,952] [INFO] uvicorn.error: Finished server process [6084]
[2025-06-22 00:49:15,179] [INFO] uvicorn.error: Started server process [12980]
[2025-06-22 00:49:15,180] [INFO] uvicorn.error: Waiting for application startup.
[2025-06-22 00:49:15,180] [INFO] uvicorn.error: Application startup complete.
[2025-06-22 00:49:50,827] [INFO] uvicorn.error: Shutting down
[2025-06-22 00:49:50,940] [INFO] uvicorn.error: Waiting for application shutdown.
[2025-06-22 00:49:50,941] [INFO] uvicorn.error: Application shutdown complete.
[2025-06-22 00:49:50,942] [INFO] uvicorn.error: Finished server process [12980]
[2025-06-22 00:49:53,014] [INFO] uvicorn.error: Started server process [10404]
[2025-06-22 00:49:53,014] [INFO] uvicorn.error: Waiting for application startup.
[2025-06-22 00:49:53,015] [INFO] uvicorn.error: Application startup complete.
[2025-06-22 00:50:06,178] [INFO] app.routes.user: Creating user tes222222t Employee ID: 5 
[2025-06-22 00:50:06,502] [ERROR] uvicorn.error: Exception in ASGI application
Traceback (most recent call last):
  File "C:\Users\pc\AppData\Local\Programs\Python\Python313\Lib\site-packages\uvicorn\protocols\http\h11_impl.py", line 403, in run_asgi
    result = await app(  # type: ignore[func-returns-value]
             ^^^^^^^^^^^^^^^^^^^^^^^^^^^^^^^^^^^^^^^^^^^^^^
        self.scope, self.receive, self.send
        ^^^^^^^^^^^^^^^^^^^^^^^^^^^^^^^^^^^
    )
    ^
  File "C:\Users\pc\AppData\Local\Programs\Python\Python313\Lib\site-packages\uvicorn\middleware\proxy_headers.py", line 60, in __call__
    return await self.app(scope, receive, send)
           ^^^^^^^^^^^^^^^^^^^^^^^^^^^^^^^^^^^^
  File "C:\Users\pc\AppData\Local\Programs\Python\Python313\Lib\site-packages\fastapi\applications.py", line 1054, in __call__
    await super().__call__(scope, receive, send)
  File "C:\Users\pc\AppData\Local\Programs\Python\Python313\Lib\site-packages\starlette\applications.py", line 112, in __call__
    await self.middleware_stack(scope, receive, send)
  File "C:\Users\pc\AppData\Local\Programs\Python\Python313\Lib\site-packages\starlette\middleware\errors.py", line 187, in __call__
    raise exc
  File "C:\Users\pc\AppData\Local\Programs\Python\Python313\Lib\site-packages\starlette\middleware\errors.py", line 165, in __call__
    await self.app(scope, receive, _send)
  File "C:\Users\pc\AppData\Local\Programs\Python\Python313\Lib\site-packages\starlette\middleware\cors.py", line 93, in __call__
    await self.simple_response(scope, receive, send, request_headers=headers)
  File "C:\Users\pc\AppData\Local\Programs\Python\Python313\Lib\site-packages\starlette\middleware\cors.py", line 144, in simple_response
    await self.app(scope, receive, send)
  File "C:\Users\pc\AppData\Local\Programs\Python\Python313\Lib\site-packages\starlette\middleware\exceptions.py", line 62, in __call__
    await wrap_app_handling_exceptions(self.app, conn)(scope, receive, send)
  File "C:\Users\pc\AppData\Local\Programs\Python\Python313\Lib\site-packages\starlette\_exception_handler.py", line 53, in wrapped_app
    raise exc
  File "C:\Users\pc\AppData\Local\Programs\Python\Python313\Lib\site-packages\starlette\_exception_handler.py", line 42, in wrapped_app
    await app(scope, receive, sender)
  File "C:\Users\pc\AppData\Local\Programs\Python\Python313\Lib\site-packages\starlette\routing.py", line 714, in __call__
    await self.middleware_stack(scope, receive, send)
  File "C:\Users\pc\AppData\Local\Programs\Python\Python313\Lib\site-packages\starlette\routing.py", line 734, in app
    await route.handle(scope, receive, send)
  File "C:\Users\pc\AppData\Local\Programs\Python\Python313\Lib\site-packages\starlette\routing.py", line 288, in handle
    await self.app(scope, receive, send)
  File "C:\Users\pc\AppData\Local\Programs\Python\Python313\Lib\site-packages\starlette\routing.py", line 76, in app
    await wrap_app_handling_exceptions(app, request)(scope, receive, send)
  File "C:\Users\pc\AppData\Local\Programs\Python\Python313\Lib\site-packages\starlette\_exception_handler.py", line 53, in wrapped_app
    raise exc
  File "C:\Users\pc\AppData\Local\Programs\Python\Python313\Lib\site-packages\starlette\_exception_handler.py", line 42, in wrapped_app
    await app(scope, receive, sender)
  File "C:\Users\pc\AppData\Local\Programs\Python\Python313\Lib\site-packages\starlette\routing.py", line 73, in app
    response = await f(request)
               ^^^^^^^^^^^^^^^^
  File "C:\Users\pc\AppData\Local\Programs\Python\Python313\Lib\site-packages\fastapi\routing.py", line 327, in app
    content = await serialize_response(
              ^^^^^^^^^^^^^^^^^^^^^^^^^
    ...<9 lines>...
    )
    ^
  File "C:\Users\pc\AppData\Local\Programs\Python\Python313\Lib\site-packages\fastapi\routing.py", line 176, in serialize_response
    raise ResponseValidationError(
        errors=_normalize_errors(errors), body=response_content
    )
fastapi.exceptions.ResponseValidationError: 1 validation errors:
  {'type': 'missing', 'loc': ('response', 'employee_name'), 'msg': 'Field required', 'input': <app.models.user.User object at 0x000002B4402BF250>}

[2025-06-22 00:50:22,263] [INFO] uvicorn.error: Shutting down
[2025-06-22 00:50:22,377] [INFO] uvicorn.error: Waiting for application shutdown.
[2025-06-22 00:50:22,378] [INFO] uvicorn.error: Application shutdown complete.
[2025-06-22 00:50:22,378] [INFO] uvicorn.error: Finished server process [10404]
[2025-06-22 00:51:10,545] [INFO] uvicorn.error: Started server process [7644]
[2025-06-22 00:51:10,545] [INFO] uvicorn.error: Waiting for application startup.
[2025-06-22 00:51:10,546] [INFO] uvicorn.error: Application startup complete.
[2025-06-22 00:52:29,118] [INFO] uvicorn.error: Shutting down
[2025-06-22 00:52:29,220] [INFO] uvicorn.error: Waiting for application shutdown.
[2025-06-22 00:52:29,220] [INFO] uvicorn.error: Application shutdown complete.
[2025-06-22 00:52:29,221] [INFO] uvicorn.error: Finished server process [7644]
[2025-06-22 00:52:31,281] [INFO] uvicorn.error: Started server process [4696]
[2025-06-22 00:52:31,281] [INFO] uvicorn.error: Waiting for application startup.
[2025-06-22 00:52:31,282] [INFO] uvicorn.error: Application startup complete.
[2025-06-22 00:52:43,090] [INFO] app.routes.user: Creating user tes211222ww22t Employee ID: 5 
[2025-06-22 00:55:53,317] [INFO] uvicorn.error: Shutting down
[2025-06-22 00:55:53,434] [INFO] uvicorn.error: Waiting for application shutdown.
[2025-06-22 00:55:53,435] [INFO] uvicorn.error: Application shutdown complete.
[2025-06-22 00:55:53,435] [INFO] uvicorn.error: Finished server process [4696]
[2025-06-22 00:55:55,575] [INFO] uvicorn.error: Started server process [2116]
[2025-06-22 00:55:55,575] [INFO] uvicorn.error: Waiting for application startup.
[2025-06-22 00:55:55,576] [INFO] uvicorn.error: Application startup complete.
[2025-06-22 00:56:03,494] [INFO] uvicorn.error: Shutting down
[2025-06-22 00:56:03,606] [INFO] uvicorn.error: Waiting for application shutdown.
[2025-06-22 00:56:03,607] [INFO] uvicorn.error: Application shutdown complete.
[2025-06-22 00:56:03,608] [INFO] uvicorn.error: Finished server process [2116]
[2025-06-22 00:56:38,729] [INFO] uvicorn.error: Started server process [1544]
[2025-06-22 00:56:38,729] [INFO] uvicorn.error: Waiting for application startup.
[2025-06-22 00:56:38,730] [INFO] uvicorn.error: Application startup complete.
[2025-06-22 00:57:36,071] [INFO] uvicorn.error: Started server process [2372]
[2025-06-22 00:57:36,072] [INFO] uvicorn.error: Waiting for application startup.
[2025-06-22 00:57:36,072] [INFO] uvicorn.error: Application startup complete.
[2025-06-22 00:58:41,318] [INFO] uvicorn.error: Shutting down
[2025-06-22 00:58:41,422] [INFO] uvicorn.error: Waiting for application shutdown.
[2025-06-22 00:58:41,424] [INFO] uvicorn.error: Application shutdown complete.
[2025-06-22 00:58:41,425] [INFO] uvicorn.error: Finished server process [2372]
[2025-06-22 00:58:43,797] [INFO] uvicorn.error: Started server process [11496]
[2025-06-22 00:58:43,797] [INFO] uvicorn.error: Waiting for application startup.
[2025-06-22 00:58:43,798] [INFO] uvicorn.error: Application startup complete.
[2025-06-22 00:58:45,844] [INFO] uvicorn.error: Shutting down
[2025-06-22 00:58:45,949] [INFO] uvicorn.error: Waiting for application shutdown.
[2025-06-22 00:58:45,950] [INFO] uvicorn.error: Application shutdown complete.
[2025-06-22 00:58:45,951] [INFO] uvicorn.error: Finished server process [11496]
[2025-06-22 00:58:48,150] [INFO] uvicorn.error: Started server process [1452]
[2025-06-22 00:58:48,151] [INFO] uvicorn.error: Waiting for application startup.
[2025-06-22 00:58:48,152] [INFO] uvicorn.error: Application startup complete.
[2025-06-22 00:58:48,913] [INFO] uvicorn.error: Shutting down
[2025-06-22 00:58:49,026] [INFO] uvicorn.error: Waiting for application shutdown.
[2025-06-22 00:58:49,027] [INFO] uvicorn.error: Application shutdown complete.
[2025-06-22 00:58:49,027] [INFO] uvicorn.error: Finished server process [1452]
[2025-06-22 00:58:51,112] [INFO] uvicorn.error: Started server process [11572]
[2025-06-22 00:58:51,112] [INFO] uvicorn.error: Waiting for application startup.
[2025-06-22 00:58:51,113] [INFO] uvicorn.error: Application startup complete.
[2025-06-22 00:58:51,890] [INFO] uvicorn.error: Shutting down
[2025-06-22 00:58:52,005] [INFO] uvicorn.error: Waiting for application shutdown.
[2025-06-22 00:58:52,006] [INFO] uvicorn.error: Application shutdown complete.
[2025-06-22 00:58:52,006] [INFO] uvicorn.error: Finished server process [11572]
[2025-06-22 00:58:54,179] [INFO] uvicorn.error: Started server process [2768]
[2025-06-22 00:58:54,180] [INFO] uvicorn.error: Waiting for application startup.
[2025-06-22 00:58:54,180] [INFO] uvicorn.error: Application startup complete.
[2025-06-22 00:58:56,961] [INFO] app.routes.auth: User found: <app.models.user.User object at 0x0000019CA5D14440>
[2025-06-22 00:58:57,264] [ERROR] uvicorn.error: Exception in ASGI application
Traceback (most recent call last):
  File "C:\Users\pc\AppData\Local\Programs\Python\Python313\Lib\site-packages\uvicorn\protocols\http\h11_impl.py", line 403, in run_asgi
    result = await app(  # type: ignore[func-returns-value]
             ^^^^^^^^^^^^^^^^^^^^^^^^^^^^^^^^^^^^^^^^^^^^^^
        self.scope, self.receive, self.send
        ^^^^^^^^^^^^^^^^^^^^^^^^^^^^^^^^^^^
    )
    ^
  File "C:\Users\pc\AppData\Local\Programs\Python\Python313\Lib\site-packages\uvicorn\middleware\proxy_headers.py", line 60, in __call__
    return await self.app(scope, receive, send)
           ^^^^^^^^^^^^^^^^^^^^^^^^^^^^^^^^^^^^
  File "C:\Users\pc\AppData\Local\Programs\Python\Python313\Lib\site-packages\fastapi\applications.py", line 1054, in __call__
    await super().__call__(scope, receive, send)
  File "C:\Users\pc\AppData\Local\Programs\Python\Python313\Lib\site-packages\starlette\applications.py", line 112, in __call__
    await self.middleware_stack(scope, receive, send)
  File "C:\Users\pc\AppData\Local\Programs\Python\Python313\Lib\site-packages\starlette\middleware\errors.py", line 187, in __call__
    raise exc
  File "C:\Users\pc\AppData\Local\Programs\Python\Python313\Lib\site-packages\starlette\middleware\errors.py", line 165, in __call__
    await self.app(scope, receive, _send)
  File "C:\Users\pc\AppData\Local\Programs\Python\Python313\Lib\site-packages\starlette\middleware\cors.py", line 93, in __call__
    await self.simple_response(scope, receive, send, request_headers=headers)
  File "C:\Users\pc\AppData\Local\Programs\Python\Python313\Lib\site-packages\starlette\middleware\cors.py", line 144, in simple_response
    await self.app(scope, receive, send)
  File "C:\Users\pc\AppData\Local\Programs\Python\Python313\Lib\site-packages\starlette\middleware\exceptions.py", line 62, in __call__
    await wrap_app_handling_exceptions(self.app, conn)(scope, receive, send)
  File "C:\Users\pc\AppData\Local\Programs\Python\Python313\Lib\site-packages\starlette\_exception_handler.py", line 53, in wrapped_app
    raise exc
  File "C:\Users\pc\AppData\Local\Programs\Python\Python313\Lib\site-packages\starlette\_exception_handler.py", line 42, in wrapped_app
    await app(scope, receive, sender)
  File "C:\Users\pc\AppData\Local\Programs\Python\Python313\Lib\site-packages\starlette\routing.py", line 714, in __call__
    await self.middleware_stack(scope, receive, send)
  File "C:\Users\pc\AppData\Local\Programs\Python\Python313\Lib\site-packages\starlette\routing.py", line 734, in app
    await route.handle(scope, receive, send)
  File "C:\Users\pc\AppData\Local\Programs\Python\Python313\Lib\site-packages\starlette\routing.py", line 288, in handle
    await self.app(scope, receive, send)
  File "C:\Users\pc\AppData\Local\Programs\Python\Python313\Lib\site-packages\starlette\routing.py", line 76, in app
    await wrap_app_handling_exceptions(app, request)(scope, receive, send)
  File "C:\Users\pc\AppData\Local\Programs\Python\Python313\Lib\site-packages\starlette\_exception_handler.py", line 53, in wrapped_app
    raise exc
  File "C:\Users\pc\AppData\Local\Programs\Python\Python313\Lib\site-packages\starlette\_exception_handler.py", line 42, in wrapped_app
    await app(scope, receive, sender)
  File "C:\Users\pc\AppData\Local\Programs\Python\Python313\Lib\site-packages\starlette\routing.py", line 73, in app
    response = await f(request)
               ^^^^^^^^^^^^^^^^
  File "C:\Users\pc\AppData\Local\Programs\Python\Python313\Lib\site-packages\fastapi\routing.py", line 301, in app
    raw_response = await run_endpoint_function(
                   ^^^^^^^^^^^^^^^^^^^^^^^^^^^^
    ...<3 lines>...
    )
    ^
  File "C:\Users\pc\AppData\Local\Programs\Python\Python313\Lib\site-packages\fastapi\routing.py", line 214, in run_endpoint_function
    return await run_in_threadpool(dependant.call, **values)
           ^^^^^^^^^^^^^^^^^^^^^^^^^^^^^^^^^^^^^^^^^^^^^^^^^
  File "C:\Users\pc\AppData\Local\Programs\Python\Python313\Lib\site-packages\starlette\concurrency.py", line 37, in run_in_threadpool
    return await anyio.to_thread.run_sync(func)
           ^^^^^^^^^^^^^^^^^^^^^^^^^^^^^^^^^^^^
  File "C:\Users\pc\AppData\Local\Programs\Python\Python313\Lib\site-packages\anyio\to_thread.py", line 56, in run_sync
    return await get_async_backend().run_sync_in_worker_thread(
           ^^^^^^^^^^^^^^^^^^^^^^^^^^^^^^^^^^^^^^^^^^^^^^^^^^^^
        func, args, abandon_on_cancel=abandon_on_cancel, limiter=limiter
        ^^^^^^^^^^^^^^^^^^^^^^^^^^^^^^^^^^^^^^^^^^^^^^^^^^^^^^^^^^^^^^^^
    )
    ^
  File "C:\Users\pc\AppData\Local\Programs\Python\Python313\Lib\site-packages\anyio\_backends\_asyncio.py", line 2470, in run_sync_in_worker_thread
    return await future
           ^^^^^^^^^^^^
  File "C:\Users\pc\AppData\Local\Programs\Python\Python313\Lib\site-packages\anyio\_backends\_asyncio.py", line 967, in run
    result = context.run(func, *args)
  File "D:\Projects\Development\webcore-erp\webcore-erp\wcs-backend\app\routes\auth.py", line 62, in login
    payload = {"sub": user.username, "role_id": user.role_id}
                                                ^^^^^^^^^^^^
AttributeError: 'User' object has no attribute 'role_id'
[2025-06-22 00:59:01,641] [INFO] app.routes.auth: User found: <app.models.user.User object at 0x0000019CA5C63B10>
[2025-06-22 00:59:01,956] [ERROR] uvicorn.error: Exception in ASGI application
Traceback (most recent call last):
  File "C:\Users\pc\AppData\Local\Programs\Python\Python313\Lib\site-packages\uvicorn\protocols\http\h11_impl.py", line 403, in run_asgi
    result = await app(  # type: ignore[func-returns-value]
             ^^^^^^^^^^^^^^^^^^^^^^^^^^^^^^^^^^^^^^^^^^^^^^
        self.scope, self.receive, self.send
        ^^^^^^^^^^^^^^^^^^^^^^^^^^^^^^^^^^^
    )
    ^
  File "C:\Users\pc\AppData\Local\Programs\Python\Python313\Lib\site-packages\uvicorn\middleware\proxy_headers.py", line 60, in __call__
    return await self.app(scope, receive, send)
           ^^^^^^^^^^^^^^^^^^^^^^^^^^^^^^^^^^^^
  File "C:\Users\pc\AppData\Local\Programs\Python\Python313\Lib\site-packages\fastapi\applications.py", line 1054, in __call__
    await super().__call__(scope, receive, send)
  File "C:\Users\pc\AppData\Local\Programs\Python\Python313\Lib\site-packages\starlette\applications.py", line 112, in __call__
    await self.middleware_stack(scope, receive, send)
  File "C:\Users\pc\AppData\Local\Programs\Python\Python313\Lib\site-packages\starlette\middleware\errors.py", line 187, in __call__
    raise exc
  File "C:\Users\pc\AppData\Local\Programs\Python\Python313\Lib\site-packages\starlette\middleware\errors.py", line 165, in __call__
    await self.app(scope, receive, _send)
  File "C:\Users\pc\AppData\Local\Programs\Python\Python313\Lib\site-packages\starlette\middleware\cors.py", line 93, in __call__
    await self.simple_response(scope, receive, send, request_headers=headers)
  File "C:\Users\pc\AppData\Local\Programs\Python\Python313\Lib\site-packages\starlette\middleware\cors.py", line 144, in simple_response
    await self.app(scope, receive, send)
  File "C:\Users\pc\AppData\Local\Programs\Python\Python313\Lib\site-packages\starlette\middleware\exceptions.py", line 62, in __call__
    await wrap_app_handling_exceptions(self.app, conn)(scope, receive, send)
  File "C:\Users\pc\AppData\Local\Programs\Python\Python313\Lib\site-packages\starlette\_exception_handler.py", line 53, in wrapped_app
    raise exc
  File "C:\Users\pc\AppData\Local\Programs\Python\Python313\Lib\site-packages\starlette\_exception_handler.py", line 42, in wrapped_app
    await app(scope, receive, sender)
  File "C:\Users\pc\AppData\Local\Programs\Python\Python313\Lib\site-packages\starlette\routing.py", line 714, in __call__
    await self.middleware_stack(scope, receive, send)
  File "C:\Users\pc\AppData\Local\Programs\Python\Python313\Lib\site-packages\starlette\routing.py", line 734, in app
    await route.handle(scope, receive, send)
  File "C:\Users\pc\AppData\Local\Programs\Python\Python313\Lib\site-packages\starlette\routing.py", line 288, in handle
    await self.app(scope, receive, send)
  File "C:\Users\pc\AppData\Local\Programs\Python\Python313\Lib\site-packages\starlette\routing.py", line 76, in app
    await wrap_app_handling_exceptions(app, request)(scope, receive, send)
  File "C:\Users\pc\AppData\Local\Programs\Python\Python313\Lib\site-packages\starlette\_exception_handler.py", line 53, in wrapped_app
    raise exc
  File "C:\Users\pc\AppData\Local\Programs\Python\Python313\Lib\site-packages\starlette\_exception_handler.py", line 42, in wrapped_app
    await app(scope, receive, sender)
  File "C:\Users\pc\AppData\Local\Programs\Python\Python313\Lib\site-packages\starlette\routing.py", line 73, in app
    response = await f(request)
               ^^^^^^^^^^^^^^^^
  File "C:\Users\pc\AppData\Local\Programs\Python\Python313\Lib\site-packages\fastapi\routing.py", line 301, in app
    raw_response = await run_endpoint_function(
                   ^^^^^^^^^^^^^^^^^^^^^^^^^^^^
    ...<3 lines>...
    )
    ^
  File "C:\Users\pc\AppData\Local\Programs\Python\Python313\Lib\site-packages\fastapi\routing.py", line 214, in run_endpoint_function
    return await run_in_threadpool(dependant.call, **values)
           ^^^^^^^^^^^^^^^^^^^^^^^^^^^^^^^^^^^^^^^^^^^^^^^^^
  File "C:\Users\pc\AppData\Local\Programs\Python\Python313\Lib\site-packages\starlette\concurrency.py", line 37, in run_in_threadpool
    return await anyio.to_thread.run_sync(func)
           ^^^^^^^^^^^^^^^^^^^^^^^^^^^^^^^^^^^^
  File "C:\Users\pc\AppData\Local\Programs\Python\Python313\Lib\site-packages\anyio\to_thread.py", line 56, in run_sync
    return await get_async_backend().run_sync_in_worker_thread(
           ^^^^^^^^^^^^^^^^^^^^^^^^^^^^^^^^^^^^^^^^^^^^^^^^^^^^
        func, args, abandon_on_cancel=abandon_on_cancel, limiter=limiter
        ^^^^^^^^^^^^^^^^^^^^^^^^^^^^^^^^^^^^^^^^^^^^^^^^^^^^^^^^^^^^^^^^
    )
    ^
  File "C:\Users\pc\AppData\Local\Programs\Python\Python313\Lib\site-packages\anyio\_backends\_asyncio.py", line 2470, in run_sync_in_worker_thread
    return await future
           ^^^^^^^^^^^^
  File "C:\Users\pc\AppData\Local\Programs\Python\Python313\Lib\site-packages\anyio\_backends\_asyncio.py", line 967, in run
    result = context.run(func, *args)
  File "D:\Projects\Development\webcore-erp\webcore-erp\wcs-backend\app\routes\auth.py", line 62, in login
    payload = {"sub": user.username, "role_id": user.role_id}
                                                ^^^^^^^^^^^^
AttributeError: 'User' object has no attribute 'role_id'
[2025-06-22 01:00:05,749] [INFO] uvicorn.error: Shutting down
[2025-06-22 01:00:05,855] [INFO] uvicorn.error: Waiting for application shutdown.
[2025-06-22 01:00:05,856] [INFO] uvicorn.error: Application shutdown complete.
[2025-06-22 01:00:05,857] [INFO] uvicorn.error: Finished server process [2768]
[2025-06-22 01:00:08,882] [INFO] uvicorn.error: Started server process [12716]
[2025-06-22 01:00:08,883] [INFO] uvicorn.error: Waiting for application startup.
[2025-06-22 01:00:08,884] [INFO] uvicorn.error: Application startup complete.
[2025-06-22 01:00:08,922] [INFO] app.routes.auth: User found: <app.models.user.User object at 0x0000018ABBEDC590>
[2025-06-22 01:00:09,384] [INFO] app.routes.auth: employee found: <app.models.employee.Employee object at 0x0000018ABBEDC6E0>
[2025-06-22 01:00:09,389] [ERROR] uvicorn.error: Exception in ASGI application
Traceback (most recent call last):
  File "C:\Users\pc\AppData\Local\Programs\Python\Python313\Lib\site-packages\uvicorn\protocols\http\h11_impl.py", line 403, in run_asgi
    result = await app(  # type: ignore[func-returns-value]
             ^^^^^^^^^^^^^^^^^^^^^^^^^^^^^^^^^^^^^^^^^^^^^^
        self.scope, self.receive, self.send
        ^^^^^^^^^^^^^^^^^^^^^^^^^^^^^^^^^^^
    )
    ^
  File "C:\Users\pc\AppData\Local\Programs\Python\Python313\Lib\site-packages\uvicorn\middleware\proxy_headers.py", line 60, in __call__
    return await self.app(scope, receive, send)
           ^^^^^^^^^^^^^^^^^^^^^^^^^^^^^^^^^^^^
  File "C:\Users\pc\AppData\Local\Programs\Python\Python313\Lib\site-packages\fastapi\applications.py", line 1054, in __call__
    await super().__call__(scope, receive, send)
  File "C:\Users\pc\AppData\Local\Programs\Python\Python313\Lib\site-packages\starlette\applications.py", line 112, in __call__
    await self.middleware_stack(scope, receive, send)
  File "C:\Users\pc\AppData\Local\Programs\Python\Python313\Lib\site-packages\starlette\middleware\errors.py", line 187, in __call__
    raise exc
  File "C:\Users\pc\AppData\Local\Programs\Python\Python313\Lib\site-packages\starlette\middleware\errors.py", line 165, in __call__
    await self.app(scope, receive, _send)
  File "C:\Users\pc\AppData\Local\Programs\Python\Python313\Lib\site-packages\starlette\middleware\cors.py", line 93, in __call__
    await self.simple_response(scope, receive, send, request_headers=headers)
  File "C:\Users\pc\AppData\Local\Programs\Python\Python313\Lib\site-packages\starlette\middleware\cors.py", line 144, in simple_response
    await self.app(scope, receive, send)
  File "C:\Users\pc\AppData\Local\Programs\Python\Python313\Lib\site-packages\starlette\middleware\exceptions.py", line 62, in __call__
    await wrap_app_handling_exceptions(self.app, conn)(scope, receive, send)
  File "C:\Users\pc\AppData\Local\Programs\Python\Python313\Lib\site-packages\starlette\_exception_handler.py", line 53, in wrapped_app
    raise exc
  File "C:\Users\pc\AppData\Local\Programs\Python\Python313\Lib\site-packages\starlette\_exception_handler.py", line 42, in wrapped_app
    await app(scope, receive, sender)
  File "C:\Users\pc\AppData\Local\Programs\Python\Python313\Lib\site-packages\starlette\routing.py", line 714, in __call__
    await self.middleware_stack(scope, receive, send)
  File "C:\Users\pc\AppData\Local\Programs\Python\Python313\Lib\site-packages\starlette\routing.py", line 734, in app
    await route.handle(scope, receive, send)
  File "C:\Users\pc\AppData\Local\Programs\Python\Python313\Lib\site-packages\starlette\routing.py", line 288, in handle
    await self.app(scope, receive, send)
  File "C:\Users\pc\AppData\Local\Programs\Python\Python313\Lib\site-packages\starlette\routing.py", line 76, in app
    await wrap_app_handling_exceptions(app, request)(scope, receive, send)
  File "C:\Users\pc\AppData\Local\Programs\Python\Python313\Lib\site-packages\starlette\_exception_handler.py", line 53, in wrapped_app
    raise exc
  File "C:\Users\pc\AppData\Local\Programs\Python\Python313\Lib\site-packages\starlette\_exception_handler.py", line 42, in wrapped_app
    await app(scope, receive, sender)
  File "C:\Users\pc\AppData\Local\Programs\Python\Python313\Lib\site-packages\starlette\routing.py", line 73, in app
    response = await f(request)
               ^^^^^^^^^^^^^^^^
  File "C:\Users\pc\AppData\Local\Programs\Python\Python313\Lib\site-packages\fastapi\routing.py", line 301, in app
    raw_response = await run_endpoint_function(
                   ^^^^^^^^^^^^^^^^^^^^^^^^^^^^
    ...<3 lines>...
    )
    ^
  File "C:\Users\pc\AppData\Local\Programs\Python\Python313\Lib\site-packages\fastapi\routing.py", line 214, in run_endpoint_function
    return await run_in_threadpool(dependant.call, **values)
           ^^^^^^^^^^^^^^^^^^^^^^^^^^^^^^^^^^^^^^^^^^^^^^^^^
  File "C:\Users\pc\AppData\Local\Programs\Python\Python313\Lib\site-packages\starlette\concurrency.py", line 37, in run_in_threadpool
    return await anyio.to_thread.run_sync(func)
           ^^^^^^^^^^^^^^^^^^^^^^^^^^^^^^^^^^^^
  File "C:\Users\pc\AppData\Local\Programs\Python\Python313\Lib\site-packages\anyio\to_thread.py", line 56, in run_sync
    return await get_async_backend().run_sync_in_worker_thread(
           ^^^^^^^^^^^^^^^^^^^^^^^^^^^^^^^^^^^^^^^^^^^^^^^^^^^^
        func, args, abandon_on_cancel=abandon_on_cancel, limiter=limiter
        ^^^^^^^^^^^^^^^^^^^^^^^^^^^^^^^^^^^^^^^^^^^^^^^^^^^^^^^^^^^^^^^^
    )
    ^
  File "C:\Users\pc\AppData\Local\Programs\Python\Python313\Lib\site-packages\anyio\_backends\_asyncio.py", line 2470, in run_sync_in_worker_thread
    return await future
           ^^^^^^^^^^^^
  File "C:\Users\pc\AppData\Local\Programs\Python\Python313\Lib\site-packages\anyio\_backends\_asyncio.py", line 967, in run
    result = context.run(func, *args)
  File "D:\Projects\Development\webcore-erp\webcore-erp\wcs-backend\app\routes\auth.py", line 72, in login
    "role_id": user.role_id,
               ^^^^^^^^^^^^
AttributeError: 'User' object has no attribute 'role_id'
[2025-06-22 01:00:23,381] [INFO] uvicorn.error: Shutting down
[2025-06-22 01:00:23,497] [INFO] uvicorn.error: Waiting for application shutdown.
[2025-06-22 01:00:23,505] [INFO] uvicorn.error: Application shutdown complete.
[2025-06-22 01:00:23,506] [INFO] uvicorn.error: Finished server process [12716]
[2025-06-22 01:00:25,660] [INFO] uvicorn.error: Started server process [10600]
[2025-06-22 01:00:25,660] [INFO] uvicorn.error: Waiting for application startup.
[2025-06-22 01:00:25,661] [INFO] uvicorn.error: Application startup complete.
[2025-06-22 01:00:28,198] [INFO] app.routes.auth: User found: <app.models.user.User object at 0x000002346FD1C590>
[2025-06-22 01:00:28,498] [INFO] app.routes.auth: employee found: <app.models.employee.Employee object at 0x000002346FD1C6E0>
[2025-06-22 01:01:10,369] [INFO] uvicorn.error: Shutting down
[2025-06-22 01:01:10,474] [INFO] uvicorn.error: Waiting for application shutdown.
[2025-06-22 01:01:10,475] [INFO] uvicorn.error: Application shutdown complete.
[2025-06-22 01:01:10,475] [INFO] uvicorn.error: Finished server process [10600]
[2025-06-22 01:01:12,761] [INFO] uvicorn.error: Started server process [13224]
[2025-06-22 01:01:12,761] [INFO] uvicorn.error: Waiting for application startup.
[2025-06-22 01:01:12,762] [INFO] uvicorn.error: Application startup complete.
[2025-06-22 01:01:15,684] [INFO] app.routes.auth: User found: <app.models.user.User object at 0x00000212852BC590>
[2025-06-22 01:01:15,991] [INFO] app.routes.auth: employee found: <app.models.employee.Employee object at 0x00000212852BC6E0>
[2025-06-22 01:01:35,984] [INFO] app.routes.auth: User found: <app.models.user.User object at 0x00000212851FFB10>
[2025-06-22 01:01:36,264] [INFO] app.routes.auth: employee found: <app.models.employee.Employee object at 0x00000212851FF390>
[2025-06-22 01:03:22,158] [INFO] app.routes.auth: User found: <app.models.user.User object at 0x0000021285271A90>
[2025-06-22 01:03:22,453] [INFO] app.routes.auth: employee found: <app.models.employee.Employee object at 0x00000212852720D0>
[2025-06-22 01:03:30,226] [INFO] app.routes.auth: User found: <app.models.user.User object at 0x00000212852DCE90>
[2025-06-22 01:03:30,545] [INFO] app.routes.auth: employee found: <app.models.employee.Employee object at 0x00000212852DD0F0>
[2025-06-22 01:04:40,406] [INFO] app.routes.auth: User found: <app.models.user.User object at 0x00000212852DD0F0>
[2025-06-22 01:04:40,704] [INFO] app.routes.auth: employee found: <app.models.employee.Employee object at 0x00000212852DCE90>
[2025-06-22 01:06:10,091] [INFO] app.routes.auth: User found: <app.models.user.User object at 0x00000212851DF890>
[2025-06-22 01:06:10,397] [INFO] app.routes.auth: employee found: <app.models.employee.Employee object at 0x00000212853603B0>
[2025-06-22 01:18:48,798] [INFO] uvicorn.error: Shutting down
[2025-06-22 01:18:48,901] [INFO] uvicorn.error: Waiting for application shutdown.
[2025-06-22 01:18:48,902] [INFO] uvicorn.error: Application shutdown complete.
[2025-06-22 01:18:48,902] [INFO] uvicorn.error: Finished server process [13224]
[2025-06-22 01:18:51,365] [INFO] uvicorn.error: Started server process [5616]
[2025-06-22 01:18:51,366] [INFO] uvicorn.error: Waiting for application startup.
[2025-06-22 01:18:51,366] [INFO] uvicorn.error: Application startup complete.
[2025-06-22 01:20:49,436] [INFO] uvicorn.error: Shutting down
[2025-06-22 01:20:49,549] [INFO] uvicorn.error: Waiting for application shutdown.
[2025-06-22 01:20:49,549] [INFO] uvicorn.error: Application shutdown complete.
[2025-06-22 01:20:49,550] [INFO] uvicorn.error: Finished server process [5616]
[2025-06-22 01:20:52,419] [INFO] uvicorn.error: Started server process [8420]
[2025-06-22 01:20:52,419] [INFO] uvicorn.error: Waiting for application startup.
[2025-06-22 01:20:52,421] [INFO] uvicorn.error: Application startup complete.
[2025-06-22 01:20:55,006] [INFO] uvicorn.error: Shutting down
[2025-06-22 01:20:55,111] [INFO] uvicorn.error: Waiting for application shutdown.
[2025-06-22 01:20:55,112] [INFO] uvicorn.error: Application shutdown complete.
[2025-06-22 01:20:55,112] [INFO] uvicorn.error: Finished server process [8420]
[2025-06-22 01:20:57,247] [INFO] uvicorn.error: Started server process [8556]
[2025-06-22 01:20:57,247] [INFO] uvicorn.error: Waiting for application startup.
[2025-06-22 01:20:57,248] [INFO] uvicorn.error: Application startup complete.
[2025-06-22 01:22:06,187] [INFO] uvicorn.error: Shutting down
[2025-06-22 01:22:06,301] [INFO] uvicorn.error: Waiting for application shutdown.
[2025-06-22 01:22:06,302] [INFO] uvicorn.error: Application shutdown complete.
[2025-06-22 01:22:06,303] [INFO] uvicorn.error: Finished server process [8556]
[2025-06-22 01:22:08,731] [INFO] uvicorn.error: Started server process [4724]
[2025-06-22 01:22:08,731] [INFO] uvicorn.error: Waiting for application startup.
[2025-06-22 01:22:08,732] [INFO] uvicorn.error: Application startup complete.
[2025-06-22 01:22:15,536] [INFO] uvicorn.error: Shutting down
[2025-06-22 01:22:15,644] [INFO] uvicorn.error: Waiting for application shutdown.
[2025-06-22 01:22:15,645] [INFO] uvicorn.error: Application shutdown complete.
[2025-06-22 01:22:15,645] [INFO] uvicorn.error: Finished server process [4724]
[2025-06-22 01:22:17,812] [INFO] uvicorn.error: Started server process [6496]
[2025-06-22 01:22:17,812] [INFO] uvicorn.error: Waiting for application startup.
[2025-06-22 01:22:17,813] [INFO] uvicorn.error: Application startup complete.
[2025-06-22 01:23:41,688] [INFO] uvicorn.error: Shutting down
[2025-06-22 01:23:41,789] [INFO] uvicorn.error: Waiting for application shutdown.
[2025-06-22 01:23:41,790] [INFO] uvicorn.error: Application shutdown complete.
[2025-06-22 01:23:41,790] [INFO] uvicorn.error: Finished server process [6496]
[2025-06-22 01:23:49,732] [INFO] uvicorn.error: Started server process [12020]
[2025-06-22 01:23:49,733] [INFO] uvicorn.error: Waiting for application startup.
[2025-06-22 01:23:49,733] [INFO] uvicorn.error: Application startup complete.
[2025-06-22 01:24:19,702] [INFO] uvicorn.error: Shutting down
[2025-06-22 01:24:19,818] [INFO] uvicorn.error: Waiting for application shutdown.
[2025-06-22 01:24:19,819] [INFO] uvicorn.error: Application shutdown complete.
[2025-06-22 01:24:19,820] [INFO] uvicorn.error: Finished server process [12020]
[2025-06-22 01:24:22,018] [INFO] uvicorn.error: Started server process [1184]
[2025-06-22 01:24:22,018] [INFO] uvicorn.error: Waiting for application startup.
[2025-06-22 01:24:22,019] [INFO] uvicorn.error: Application startup complete.
[2025-06-22 01:24:41,424] [INFO] uvicorn.error: Shutting down
[2025-06-22 01:24:41,533] [INFO] uvicorn.error: Waiting for application shutdown.
[2025-06-22 01:24:41,534] [INFO] uvicorn.error: Application shutdown complete.
[2025-06-22 01:24:41,535] [INFO] uvicorn.error: Finished server process [1184]
[2025-06-22 01:24:43,757] [INFO] uvicorn.error: Started server process [2956]
[2025-06-22 01:24:43,758] [INFO] uvicorn.error: Waiting for application startup.
[2025-06-22 01:24:43,759] [INFO] uvicorn.error: Application startup complete.
[2025-06-22 01:24:43,825] [ERROR] uvicorn.error: Traceback (most recent call last):
  File "C:\Users\pc\AppData\Local\Programs\Python\Python313\Lib\asyncio\runners.py", line 118, in run
    return self._loop.run_until_complete(task)
           ~~~~~~~~~~~~~~~~~~~~~~~~~~~~~^^^^^^
  File "C:\Users\pc\AppData\Local\Programs\Python\Python313\Lib\asyncio\base_events.py", line 721, in run_until_complete
    return future.result()
           ~~~~~~~~~~~~~^^
asyncio.exceptions.CancelledError

During handling of the above exception, another exception occurred:

Traceback (most recent call last):
  File "C:\Users\pc\AppData\Local\Programs\Python\Python313\Lib\asyncio\runners.py", line 194, in run
    return runner.run(main)
           ~~~~~~~~~~^^^^^^
  File "C:\Users\pc\AppData\Local\Programs\Python\Python313\Lib\asyncio\runners.py", line 123, in run
    raise KeyboardInterrupt()
KeyboardInterrupt

During handling of the above exception, another exception occurred:

Traceback (most recent call last):
  File "C:\Users\pc\AppData\Local\Programs\Python\Python313\Lib\site-packages\starlette\routing.py", line 699, in lifespan
    await receive()
  File "C:\Users\pc\AppData\Local\Programs\Python\Python313\Lib\site-packages\uvicorn\lifespan\on.py", line 137, in receive
    return await self.receive_queue.get()
           ^^^^^^^^^^^^^^^^^^^^^^^^^^^^^^
  File "C:\Users\pc\AppData\Local\Programs\Python\Python313\Lib\asyncio\queues.py", line 186, in get
    await getter
asyncio.exceptions.CancelledError

[2025-06-22 01:24:46,203] [INFO] uvicorn.error: Started server process [6632]
[2025-06-22 01:24:46,203] [INFO] uvicorn.error: Waiting for application startup.
[2025-06-22 01:24:46,204] [INFO] uvicorn.error: Application startup complete.
[2025-06-22 01:25:44,851] [INFO] uvicorn.error: Shutting down
[2025-06-22 01:25:44,954] [INFO] uvicorn.error: Waiting for application shutdown.
[2025-06-22 01:25:44,956] [INFO] uvicorn.error: Application shutdown complete.
[2025-06-22 01:25:44,956] [INFO] uvicorn.error: Finished server process [6632]
[2025-06-22 01:25:47,249] [INFO] uvicorn.error: Started server process [12308]
[2025-06-22 01:25:47,251] [INFO] uvicorn.error: Waiting for application startup.
[2025-06-22 01:25:47,252] [INFO] uvicorn.error: Application startup complete.
[2025-06-22 01:25:49,715] [INFO] uvicorn.error: Shutting down
[2025-06-22 01:25:49,828] [INFO] uvicorn.error: Waiting for application shutdown.
[2025-06-22 01:25:49,829] [INFO] uvicorn.error: Application shutdown complete.
[2025-06-22 01:25:49,829] [INFO] uvicorn.error: Finished server process [12308]
[2025-06-22 01:26:34,801] [INFO] uvicorn.error: Started server process [3380]
[2025-06-22 01:26:34,802] [INFO] uvicorn.error: Waiting for application startup.
[2025-06-22 01:26:34,803] [INFO] uvicorn.error: Application startup complete.
[2025-06-22 01:27:34,162] [INFO] uvicorn.error: Started server process [12808]
[2025-06-22 01:27:34,162] [INFO] uvicorn.error: Waiting for application startup.
[2025-06-22 01:27:34,163] [INFO] uvicorn.error: Application startup complete.
[2025-06-22 01:27:40,260] [INFO] uvicorn.error: Shutting down
[2025-06-22 01:27:40,368] [INFO] uvicorn.error: Waiting for application shutdown.
[2025-06-22 01:27:40,369] [INFO] uvicorn.error: Application shutdown complete.
[2025-06-22 01:27:40,370] [INFO] uvicorn.error: Finished server process [12808]
[2025-06-22 01:28:13,485] [INFO] uvicorn.error: Started server process [4028]
[2025-06-22 01:28:13,485] [INFO] uvicorn.error: Waiting for application startup.
[2025-06-22 01:28:13,486] [INFO] uvicorn.error: Application startup complete.
