[2025-06-24 12:45:07,882] [INFO] app.routes.auth: employee found: <app.models.employee.Employee object at 0x0000020F2A452D50>
[2025-06-24 12:45:33,949] [INFO] uvicorn.error: Shutting down
[2025-06-24 12:45:34,074] [INFO] uvicorn.error: Waiting for application shutdown.
[2025-06-24 12:45:34,075] [INFO] uvicorn.error: Application shutdown complete.
[2025-06-24 12:45:34,076] [INFO] uvicorn.error: Finished server process [4304]
[2025-06-24 12:45:38,978] [INFO] uvicorn.error: Started server process [6412]
[2025-06-24 12:45:38,979] [INFO] uvicorn.error: Waiting for application startup.
[2025-06-24 12:45:38,980] [INFO] uvicorn.error: Application startup complete.
[2025-06-24 12:45:38,981] [INFO] uvicorn.error: Uvicorn running on http://127.0.0.1:8000 (Press CTRL+C to quit)
[2025-06-24 12:45:39,542] [INFO] app.routes.auth: employee found: <app.models.employee.Employee object at 0x000002EA8E541160>
[2025-06-24 12:51:52,790] [INFO] app.routes.auth: employee found: <app.models.employee.Employee object at 0x000002EA8E5F9950>
[2025-06-24 12:55:09,227] [INFO] uvicorn.error: Shutting down
[2025-06-24 12:55:09,333] [INFO] uvicorn.error: Waiting for application shutdown.
[2025-06-24 12:55:09,334] [INFO] uvicorn.error: Application shutdown complete.
[2025-06-24 12:55:09,335] [INFO] uvicorn.error: Finished server process [6412]
[2025-06-24 12:55:14,650] [INFO] uvicorn.error: Started server process [8200]
[2025-06-24 12:55:14,651] [INFO] uvicorn.error: Waiting for application startup.
[2025-06-24 12:55:14,652] [INFO] uvicorn.error: Application startup complete.
[2025-06-24 12:55:14,653] [INFO] uvicorn.error: Uvicorn running on http://127.0.0.1:8000 (Press CTRL+C to quit)
[2025-06-24 12:55:23,398] [INFO] app.routes.employee: Getting employee... 1
[2025-06-24 12:55:23,433] [INFO] app.routes.employee: Getting employee... 1
[2025-06-24 12:55:27,107] [INFO] app.routes.employee: Getting employee... 1
[2025-06-24 12:55:27,125] [INFO] app.routes.employee: Getting employee... 1
[2025-06-24 12:56:30,911] [INFO] uvicorn.error: Shutting down
[2025-06-24 12:56:31,019] [INFO] uvicorn.error: Waiting for application shutdown.
[2025-06-24 12:56:31,020] [INFO] uvicorn.error: Application shutdown complete.
[2025-06-24 12:56:31,021] [INFO] uvicorn.error: Finished server process [8200]
[2025-06-24 12:56:36,625] [INFO] uvicorn.error: Started server process [6996]
[2025-06-24 12:56:36,626] [INFO] uvicorn.error: Waiting for application startup.
[2025-06-24 12:56:36,627] [INFO] uvicorn.error: Application startup complete.
[2025-06-24 12:56:36,629] [INFO] uvicorn.error: Uvicorn running on http://127.0.0.1:8000 (Press CTRL+C to quit)
[2025-06-24 12:57:30,630] [INFO] uvicorn.error: Shutting down
[2025-06-24 12:57:30,733] [INFO] uvicorn.error: Waiting for application shutdown.
[2025-06-24 12:57:30,734] [INFO] uvicorn.error: Application shutdown complete.
[2025-06-24 12:57:30,735] [INFO] uvicorn.error: Finished server process [6996]
[2025-06-24 12:57:37,846] [INFO] uvicorn.error: Started server process [7928]
[2025-06-24 12:57:37,847] [INFO] uvicorn.error: Waiting for application startup.
[2025-06-24 12:57:37,848] [INFO] uvicorn.error: Application startup complete.
[2025-06-24 12:57:37,850] [INFO] uvicorn.error: Uvicorn running on http://127.0.0.1:8000 (Press CTRL+C to quit)
[2025-06-24 12:57:44,375] [INFO] app.routes.auth: employee found: <app.models.employee.Employee object at 0x000001E47F67ABA0>
[2025-06-24 13:14:30,922] [INFO] uvicorn.error: Shutting down
[2025-06-24 13:14:31,028] [INFO] uvicorn.error: Waiting for application shutdown.
[2025-06-24 13:14:31,029] [INFO] uvicorn.error: Application shutdown complete.
[2025-06-24 13:14:31,030] [INFO] uvicorn.error: Finished server process [7928]
[2025-06-24 13:14:36,308] [INFO] uvicorn.error: Started server process [11760]
[2025-06-24 13:14:36,309] [INFO] uvicorn.error: Waiting for application startup.
[2025-06-24 13:14:36,310] [INFO] uvicorn.error: Application startup complete.
[2025-06-24 13:14:36,311] [INFO] uvicorn.error: Uvicorn running on http://127.0.0.1:8000 (Press CTRL+C to quit)
[2025-06-24 13:18:36,966] [INFO] uvicorn.error: Shutting down
[2025-06-24 13:18:37,074] [INFO] uvicorn.error: Waiting for application shutdown.
[2025-06-24 13:18:37,074] [INFO] uvicorn.error: Application shutdown complete.
[2025-06-24 13:18:37,075] [INFO] uvicorn.error: Finished server process [11760]
[2025-06-24 13:18:42,402] [INFO] uvicorn.error: Started server process [7340]
[2025-06-24 13:18:42,403] [INFO] uvicorn.error: Waiting for application startup.
[2025-06-24 13:18:42,404] [INFO] uvicorn.error: Application startup complete.
[2025-06-24 13:18:42,406] [INFO] uvicorn.error: Uvicorn running on http://127.0.0.1:8000 (Press CTRL+C to quit)
[2025-06-24 13:23:43,821] [INFO] uvicorn.error: Shutting down
[2025-06-24 13:23:43,935] [INFO] uvicorn.error: Waiting for application shutdown.
[2025-06-24 13:23:43,936] [INFO] uvicorn.error: Application shutdown complete.
[2025-06-24 13:23:43,937] [INFO] uvicorn.error: Finished server process [7340]
[2025-06-24 13:23:49,242] [INFO] uvicorn.error: Started server process [2472]
[2025-06-24 13:23:49,243] [INFO] uvicorn.error: Waiting for application startup.
[2025-06-24 13:23:49,245] [INFO] uvicorn.error: Application startup complete.
[2025-06-24 13:23:49,246] [INFO] uvicorn.error: Uvicorn running on http://127.0.0.1:8000 (Press CTRL+C to quit)
[2025-06-24 13:25:33,088] [INFO] app.routes.auth: employee found: <app.models.employee.Employee object at 0x00000206CCB6ABA0>
[2025-06-24 13:28:40,422] [INFO] uvicorn.error: Shutting down
[2025-06-24 13:28:40,524] [INFO] uvicorn.error: Waiting for application shutdown.
[2025-06-24 13:28:40,525] [INFO] uvicorn.error: Application shutdown complete.
[2025-06-24 13:28:40,526] [INFO] uvicorn.error: Finished server process [2472]
[2025-06-24 13:28:45,418] [INFO] uvicorn.error: Started server process [13584]
[2025-06-24 13:28:45,419] [INFO] uvicorn.error: Waiting for application startup.
[2025-06-24 13:28:45,430] [INFO] uvicorn.error: Application startup complete.
[2025-06-24 13:28:45,433] [INFO] uvicorn.error: Uvicorn running on http://127.0.0.1:8000 (Press CTRL+C to quit)
[2025-06-24 13:32:17,244] [INFO] uvicorn.error: Shutting down
[2025-06-24 13:32:17,348] [INFO] uvicorn.error: Waiting for application shutdown.
[2025-06-24 13:32:17,350] [INFO] uvicorn.error: Application shutdown complete.
[2025-06-24 13:32:17,351] [INFO] uvicorn.error: Finished server process [13584]
[2025-06-24 13:32:36,228] [INFO] uvicorn.error: Started server process [5608]
[2025-06-24 13:32:36,229] [INFO] uvicorn.error: Waiting for application startup.
[2025-06-24 13:32:36,231] [INFO] uvicorn.error: Application startup complete.
[2025-06-24 13:32:36,233] [INFO] uvicorn.error: Uvicorn running on http://127.0.0.1:8000 (Press CTRL+C to quit)
[2025-06-24 13:32:40,501] [INFO] app.routes.auth: employee found: <app.models.employee.Employee object at 0x000001DCF914E7B0>
[2025-06-24 13:34:07,635] [INFO] uvicorn.error: Shutting down
[2025-06-24 13:34:07,742] [INFO] uvicorn.error: Waiting for application shutdown.
[2025-06-24 13:34:07,743] [INFO] uvicorn.error: Application shutdown complete.
[2025-06-24 13:34:07,744] [INFO] uvicorn.error: Finished server process [5608]
[2025-06-24 13:34:12,800] [INFO] uvicorn.error: Started server process [8916]
[2025-06-24 13:34:12,801] [INFO] uvicorn.error: Waiting for application startup.
[2025-06-24 13:34:12,812] [INFO] uvicorn.error: Application startup complete.
[2025-06-24 13:34:12,813] [INFO] uvicorn.error: Uvicorn running on http://127.0.0.1:8000 (Press CTRL+C to quit)
[2025-06-24 13:34:14,286] [INFO] app.routes.auth: employee found: <app.models.employee.Employee object at 0x000001D1806CD2B0>
[2025-06-24 13:43:38,178] [INFO] app.routes.employee: Getting employee... 1
[2025-06-24 13:43:38,200] [INFO] app.routes.employee: Getting employee... 1
[2025-06-24 13:43:42,312] [INFO] app.routes.employee: Getting employee... 1
[2025-06-24 13:43:42,326] [INFO] app.routes.employee: Getting employee... 1
[2025-06-24 13:43:47,102] [INFO] app.routes.employee: Getting employee... 1
[2025-06-24 13:43:47,121] [INFO] app.routes.employee: Getting employee... 1
[2025-06-24 13:53:38,604] [INFO] app.routes.auth: employee found: <app.models.employee.Employee object at 0x000001D1809D0290>
[2025-06-24 13:53:51,724] [INFO] uvicorn.error: Shutting down
[2025-06-24 13:53:51,826] [INFO] uvicorn.error: Waiting for application shutdown.
[2025-06-24 13:53:51,827] [INFO] uvicorn.error: Application shutdown complete.
[2025-06-24 13:53:51,828] [INFO] uvicorn.error: Finished server process [8916]
[2025-06-24 13:53:57,053] [INFO] uvicorn.error: Started server process [11456]
[2025-06-24 13:53:57,055] [INFO] uvicorn.error: Waiting for application startup.
[2025-06-24 13:53:57,068] [INFO] uvicorn.error: Application startup complete.
[2025-06-24 13:53:57,069] [INFO] uvicorn.error: Uvicorn running on http://127.0.0.1:8000 (Press CTRL+C to quit)
[2025-06-24 13:57:37,945] [INFO] uvicorn.error: Shutting down
[2025-06-24 13:57:38,052] [INFO] uvicorn.error: Waiting for application shutdown.
[2025-06-24 13:57:38,053] [INFO] uvicorn.error: Application shutdown complete.
[2025-06-24 13:57:38,054] [INFO] uvicorn.error: Finished server process [11456]
[2025-06-24 13:57:43,638] [INFO] uvicorn.error: Started server process [10888]
[2025-06-24 13:57:43,639] [INFO] uvicorn.error: Waiting for application startup.
[2025-06-24 13:57:43,649] [INFO] uvicorn.error: Application startup complete.
[2025-06-24 13:57:43,652] [INFO] uvicorn.error: Uvicorn running on http://127.0.0.1:8000 (Press CTRL+C to quit)
[2025-06-24 13:57:50,637] [INFO] app.routes.auth: employee found: <app.models.employee.Employee object at 0x000002166805D2B0>
[2025-06-24 13:57:54,105] [ERROR] uvicorn.error: Exception in ASGI application
Traceback (most recent call last):
  File "C:\Users\pc\AppData\Local\Programs\Python\Python313\Lib\site-packages\uvicorn\protocols\http\h11_impl.py", line 403, in run_asgi
    result = await app(  # type: ignore[func-returns-value]
             ^^^^^^^^^^^^^^^^^^^^^^^^^^^^^^^^^^^^^^^^^^^^^^
        self.scope, self.receive, self.send
        ^^^^^^^^^^^^^^^^^^^^^^^^^^^^^^^^^^^
    )
    ^
  File "C:\Users\pc\AppData\Local\Programs\Python\Python313\Lib\site-packages\uvicorn\middleware\proxy_headers.py", line 60, in __call__
    return await self.app(scope, receive, send)
           ^^^^^^^^^^^^^^^^^^^^^^^^^^^^^^^^^^^^
  File "C:\Users\pc\AppData\Local\Programs\Python\Python313\Lib\site-packages\fastapi\applications.py", line 1054, in __call__
    await super().__call__(scope, receive, send)
  File "C:\Users\pc\AppData\Local\Programs\Python\Python313\Lib\site-packages\starlette\applications.py", line 112, in __call__
    await self.middleware_stack(scope, receive, send)
  File "C:\Users\pc\AppData\Local\Programs\Python\Python313\Lib\site-packages\starlette\middleware\errors.py", line 187, in __call__
    raise exc
  File "C:\Users\pc\AppData\Local\Programs\Python\Python313\Lib\site-packages\starlette\middleware\errors.py", line 165, in __call__
    await self.app(scope, receive, _send)
  File "C:\Users\pc\AppData\Local\Programs\Python\Python313\Lib\site-packages\starlette\middleware\cors.py", line 93, in __call__
    await self.simple_response(scope, receive, send, request_headers=headers)
  File "C:\Users\pc\AppData\Local\Programs\Python\Python313\Lib\site-packages\starlette\middleware\cors.py", line 144, in simple_response
    await self.app(scope, receive, send)
  File "C:\Users\pc\AppData\Local\Programs\Python\Python313\Lib\site-packages\starlette\middleware\exceptions.py", line 62, in __call__
    await wrap_app_handling_exceptions(self.app, conn)(scope, receive, send)
  File "C:\Users\pc\AppData\Local\Programs\Python\Python313\Lib\site-packages\starlette\_exception_handler.py", line 53, in wrapped_app
    raise exc
  File "C:\Users\pc\AppData\Local\Programs\Python\Python313\Lib\site-packages\starlette\_exception_handler.py", line 42, in wrapped_app
    await app(scope, receive, sender)
  File "C:\Users\pc\AppData\Local\Programs\Python\Python313\Lib\site-packages\starlette\routing.py", line 714, in __call__
    await self.middleware_stack(scope, receive, send)
  File "C:\Users\pc\AppData\Local\Programs\Python\Python313\Lib\site-packages\starlette\routing.py", line 734, in app
    await route.handle(scope, receive, send)
  File "C:\Users\pc\AppData\Local\Programs\Python\Python313\Lib\site-packages\starlette\routing.py", line 288, in handle
    await self.app(scope, receive, send)
  File "C:\Users\pc\AppData\Local\Programs\Python\Python313\Lib\site-packages\starlette\routing.py", line 76, in app
    await wrap_app_handling_exceptions(app, request)(scope, receive, send)
  File "C:\Users\pc\AppData\Local\Programs\Python\Python313\Lib\site-packages\starlette\_exception_handler.py", line 53, in wrapped_app
    raise exc
  File "C:\Users\pc\AppData\Local\Programs\Python\Python313\Lib\site-packages\starlette\_exception_handler.py", line 42, in wrapped_app
    await app(scope, receive, sender)
  File "C:\Users\pc\AppData\Local\Programs\Python\Python313\Lib\site-packages\starlette\routing.py", line 73, in app
    response = await f(request)
               ^^^^^^^^^^^^^^^^
  File "C:\Users\pc\AppData\Local\Programs\Python\Python313\Lib\site-packages\fastapi\routing.py", line 301, in app
    raw_response = await run_endpoint_function(
                   ^^^^^^^^^^^^^^^^^^^^^^^^^^^^
    ...<3 lines>...
    )
    ^
  File "C:\Users\pc\AppData\Local\Programs\Python\Python313\Lib\site-packages\fastapi\routing.py", line 214, in run_endpoint_function
    return await run_in_threadpool(dependant.call, **values)
           ^^^^^^^^^^^^^^^^^^^^^^^^^^^^^^^^^^^^^^^^^^^^^^^^^
  File "C:\Users\pc\AppData\Local\Programs\Python\Python313\Lib\site-packages\starlette\concurrency.py", line 37, in run_in_threadpool
    return await anyio.to_thread.run_sync(func)
           ^^^^^^^^^^^^^^^^^^^^^^^^^^^^^^^^^^^^
  File "C:\Users\pc\AppData\Local\Programs\Python\Python313\Lib\site-packages\anyio\to_thread.py", line 56, in run_sync
    return await get_async_backend().run_sync_in_worker_thread(
           ^^^^^^^^^^^^^^^^^^^^^^^^^^^^^^^^^^^^^^^^^^^^^^^^^^^^
        func, args, abandon_on_cancel=abandon_on_cancel, limiter=limiter
        ^^^^^^^^^^^^^^^^^^^^^^^^^^^^^^^^^^^^^^^^^^^^^^^^^^^^^^^^^^^^^^^^
    )
    ^
  File "C:\Users\pc\AppData\Local\Programs\Python\Python313\Lib\site-packages\anyio\_backends\_asyncio.py", line 2470, in run_sync_in_worker_thread
    return await future
           ^^^^^^^^^^^^
  File "C:\Users\pc\AppData\Local\Programs\Python\Python313\Lib\site-packages\anyio\_backends\_asyncio.py", line 967, in run
    result = context.run(func, *args)
  File "D:\Projects\Development\webcore-erp\webcore-erp\wcs-backend\app\routes\user.py", line 40, in get_users
    users = db.query(User).join(Employee).join(Role).filter(User.is_deleted == False).all()
                                                            ^^^^^^^^^^^^^^^
AttributeError: type object 'User' has no attribute 'is_deleted'
[2025-06-24 13:57:54,139] [ERROR] uvicorn.error: Exception in ASGI application
Traceback (most recent call last):
  File "C:\Users\pc\AppData\Local\Programs\Python\Python313\Lib\site-packages\uvicorn\protocols\http\h11_impl.py", line 403, in run_asgi
    result = await app(  # type: ignore[func-returns-value]
             ^^^^^^^^^^^^^^^^^^^^^^^^^^^^^^^^^^^^^^^^^^^^^^
        self.scope, self.receive, self.send
        ^^^^^^^^^^^^^^^^^^^^^^^^^^^^^^^^^^^
    )
    ^
  File "C:\Users\pc\AppData\Local\Programs\Python\Python313\Lib\site-packages\uvicorn\middleware\proxy_headers.py", line 60, in __call__
    return await self.app(scope, receive, send)
           ^^^^^^^^^^^^^^^^^^^^^^^^^^^^^^^^^^^^
  File "C:\Users\pc\AppData\Local\Programs\Python\Python313\Lib\site-packages\fastapi\applications.py", line 1054, in __call__
    await super().__call__(scope, receive, send)
  File "C:\Users\pc\AppData\Local\Programs\Python\Python313\Lib\site-packages\starlette\applications.py", line 112, in __call__
    await self.middleware_stack(scope, receive, send)
  File "C:\Users\pc\AppData\Local\Programs\Python\Python313\Lib\site-packages\starlette\middleware\errors.py", line 187, in __call__
    raise exc
  File "C:\Users\pc\AppData\Local\Programs\Python\Python313\Lib\site-packages\starlette\middleware\errors.py", line 165, in __call__
    await self.app(scope, receive, _send)
  File "C:\Users\pc\AppData\Local\Programs\Python\Python313\Lib\site-packages\starlette\middleware\cors.py", line 93, in __call__
    await self.simple_response(scope, receive, send, request_headers=headers)
  File "C:\Users\pc\AppData\Local\Programs\Python\Python313\Lib\site-packages\starlette\middleware\cors.py", line 144, in simple_response
    await self.app(scope, receive, send)
  File "C:\Users\pc\AppData\Local\Programs\Python\Python313\Lib\site-packages\starlette\middleware\exceptions.py", line 62, in __call__
    await wrap_app_handling_exceptions(self.app, conn)(scope, receive, send)
  File "C:\Users\pc\AppData\Local\Programs\Python\Python313\Lib\site-packages\starlette\_exception_handler.py", line 53, in wrapped_app
    raise exc
  File "C:\Users\pc\AppData\Local\Programs\Python\Python313\Lib\site-packages\starlette\_exception_handler.py", line 42, in wrapped_app
    await app(scope, receive, sender)
  File "C:\Users\pc\AppData\Local\Programs\Python\Python313\Lib\site-packages\starlette\routing.py", line 714, in __call__
    await self.middleware_stack(scope, receive, send)
  File "C:\Users\pc\AppData\Local\Programs\Python\Python313\Lib\site-packages\starlette\routing.py", line 734, in app
    await route.handle(scope, receive, send)
  File "C:\Users\pc\AppData\Local\Programs\Python\Python313\Lib\site-packages\starlette\routing.py", line 288, in handle
    await self.app(scope, receive, send)
  File "C:\Users\pc\AppData\Local\Programs\Python\Python313\Lib\site-packages\starlette\routing.py", line 76, in app
    await wrap_app_handling_exceptions(app, request)(scope, receive, send)
  File "C:\Users\pc\AppData\Local\Programs\Python\Python313\Lib\site-packages\starlette\_exception_handler.py", line 53, in wrapped_app
    raise exc
  File "C:\Users\pc\AppData\Local\Programs\Python\Python313\Lib\site-packages\starlette\_exception_handler.py", line 42, in wrapped_app
    await app(scope, receive, sender)
  File "C:\Users\pc\AppData\Local\Programs\Python\Python313\Lib\site-packages\starlette\routing.py", line 73, in app
    response = await f(request)
               ^^^^^^^^^^^^^^^^
  File "C:\Users\pc\AppData\Local\Programs\Python\Python313\Lib\site-packages\fastapi\routing.py", line 301, in app
    raw_response = await run_endpoint_function(
                   ^^^^^^^^^^^^^^^^^^^^^^^^^^^^
    ...<3 lines>...
    )
    ^
  File "C:\Users\pc\AppData\Local\Programs\Python\Python313\Lib\site-packages\fastapi\routing.py", line 214, in run_endpoint_function
    return await run_in_threadpool(dependant.call, **values)
           ^^^^^^^^^^^^^^^^^^^^^^^^^^^^^^^^^^^^^^^^^^^^^^^^^
  File "C:\Users\pc\AppData\Local\Programs\Python\Python313\Lib\site-packages\starlette\concurrency.py", line 37, in run_in_threadpool
    return await anyio.to_thread.run_sync(func)
           ^^^^^^^^^^^^^^^^^^^^^^^^^^^^^^^^^^^^
  File "C:\Users\pc\AppData\Local\Programs\Python\Python313\Lib\site-packages\anyio\to_thread.py", line 56, in run_sync
    return await get_async_backend().run_sync_in_worker_thread(
           ^^^^^^^^^^^^^^^^^^^^^^^^^^^^^^^^^^^^^^^^^^^^^^^^^^^^
        func, args, abandon_on_cancel=abandon_on_cancel, limiter=limiter
        ^^^^^^^^^^^^^^^^^^^^^^^^^^^^^^^^^^^^^^^^^^^^^^^^^^^^^^^^^^^^^^^^
    )
    ^
  File "C:\Users\pc\AppData\Local\Programs\Python\Python313\Lib\site-packages\anyio\_backends\_asyncio.py", line 2470, in run_sync_in_worker_thread
    return await future
           ^^^^^^^^^^^^
  File "C:\Users\pc\AppData\Local\Programs\Python\Python313\Lib\site-packages\anyio\_backends\_asyncio.py", line 967, in run
    result = context.run(func, *args)
  File "D:\Projects\Development\webcore-erp\webcore-erp\wcs-backend\app\routes\user.py", line 40, in get_users
    users = db.query(User).join(Employee).join(Role).filter(User.is_deleted == False).all()
                                                            ^^^^^^^^^^^^^^^
AttributeError: type object 'User' has no attribute 'is_deleted'
[2025-06-24 13:58:02,621] [ERROR] uvicorn.error: Exception in ASGI application
Traceback (most recent call last):
  File "C:\Users\pc\AppData\Local\Programs\Python\Python313\Lib\site-packages\uvicorn\protocols\http\h11_impl.py", line 403, in run_asgi
    result = await app(  # type: ignore[func-returns-value]
             ^^^^^^^^^^^^^^^^^^^^^^^^^^^^^^^^^^^^^^^^^^^^^^
        self.scope, self.receive, self.send
        ^^^^^^^^^^^^^^^^^^^^^^^^^^^^^^^^^^^
    )
    ^
  File "C:\Users\pc\AppData\Local\Programs\Python\Python313\Lib\site-packages\uvicorn\middleware\proxy_headers.py", line 60, in __call__
    return await self.app(scope, receive, send)
           ^^^^^^^^^^^^^^^^^^^^^^^^^^^^^^^^^^^^
  File "C:\Users\pc\AppData\Local\Programs\Python\Python313\Lib\site-packages\fastapi\applications.py", line 1054, in __call__
    await super().__call__(scope, receive, send)
  File "C:\Users\pc\AppData\Local\Programs\Python\Python313\Lib\site-packages\starlette\applications.py", line 112, in __call__
    await self.middleware_stack(scope, receive, send)
  File "C:\Users\pc\AppData\Local\Programs\Python\Python313\Lib\site-packages\starlette\middleware\errors.py", line 187, in __call__
    raise exc
  File "C:\Users\pc\AppData\Local\Programs\Python\Python313\Lib\site-packages\starlette\middleware\errors.py", line 165, in __call__
    await self.app(scope, receive, _send)
  File "C:\Users\pc\AppData\Local\Programs\Python\Python313\Lib\site-packages\starlette\middleware\cors.py", line 93, in __call__
    await self.simple_response(scope, receive, send, request_headers=headers)
  File "C:\Users\pc\AppData\Local\Programs\Python\Python313\Lib\site-packages\starlette\middleware\cors.py", line 144, in simple_response
    await self.app(scope, receive, send)
  File "C:\Users\pc\AppData\Local\Programs\Python\Python313\Lib\site-packages\starlette\middleware\exceptions.py", line 62, in __call__
    await wrap_app_handling_exceptions(self.app, conn)(scope, receive, send)
  File "C:\Users\pc\AppData\Local\Programs\Python\Python313\Lib\site-packages\starlette\_exception_handler.py", line 53, in wrapped_app
    raise exc
  File "C:\Users\pc\AppData\Local\Programs\Python\Python313\Lib\site-packages\starlette\_exception_handler.py", line 42, in wrapped_app
    await app(scope, receive, sender)
  File "C:\Users\pc\AppData\Local\Programs\Python\Python313\Lib\site-packages\starlette\routing.py", line 714, in __call__
    await self.middleware_stack(scope, receive, send)
  File "C:\Users\pc\AppData\Local\Programs\Python\Python313\Lib\site-packages\starlette\routing.py", line 734, in app
    await route.handle(scope, receive, send)
  File "C:\Users\pc\AppData\Local\Programs\Python\Python313\Lib\site-packages\starlette\routing.py", line 288, in handle
    await self.app(scope, receive, send)
  File "C:\Users\pc\AppData\Local\Programs\Python\Python313\Lib\site-packages\starlette\routing.py", line 76, in app
    await wrap_app_handling_exceptions(app, request)(scope, receive, send)
  File "C:\Users\pc\AppData\Local\Programs\Python\Python313\Lib\site-packages\starlette\_exception_handler.py", line 53, in wrapped_app
    raise exc
  File "C:\Users\pc\AppData\Local\Programs\Python\Python313\Lib\site-packages\starlette\_exception_handler.py", line 42, in wrapped_app
    await app(scope, receive, sender)
  File "C:\Users\pc\AppData\Local\Programs\Python\Python313\Lib\site-packages\starlette\routing.py", line 73, in app
    response = await f(request)
               ^^^^^^^^^^^^^^^^
  File "C:\Users\pc\AppData\Local\Programs\Python\Python313\Lib\site-packages\fastapi\routing.py", line 301, in app
    raw_response = await run_endpoint_function(
                   ^^^^^^^^^^^^^^^^^^^^^^^^^^^^
    ...<3 lines>...
    )
    ^
  File "C:\Users\pc\AppData\Local\Programs\Python\Python313\Lib\site-packages\fastapi\routing.py", line 214, in run_endpoint_function
    return await run_in_threadpool(dependant.call, **values)
           ^^^^^^^^^^^^^^^^^^^^^^^^^^^^^^^^^^^^^^^^^^^^^^^^^
  File "C:\Users\pc\AppData\Local\Programs\Python\Python313\Lib\site-packages\starlette\concurrency.py", line 37, in run_in_threadpool
    return await anyio.to_thread.run_sync(func)
           ^^^^^^^^^^^^^^^^^^^^^^^^^^^^^^^^^^^^
  File "C:\Users\pc\AppData\Local\Programs\Python\Python313\Lib\site-packages\anyio\to_thread.py", line 56, in run_sync
    return await get_async_backend().run_sync_in_worker_thread(
           ^^^^^^^^^^^^^^^^^^^^^^^^^^^^^^^^^^^^^^^^^^^^^^^^^^^^
        func, args, abandon_on_cancel=abandon_on_cancel, limiter=limiter
        ^^^^^^^^^^^^^^^^^^^^^^^^^^^^^^^^^^^^^^^^^^^^^^^^^^^^^^^^^^^^^^^^
    )
    ^
  File "C:\Users\pc\AppData\Local\Programs\Python\Python313\Lib\site-packages\anyio\_backends\_asyncio.py", line 2470, in run_sync_in_worker_thread
    return await future
           ^^^^^^^^^^^^
  File "C:\Users\pc\AppData\Local\Programs\Python\Python313\Lib\site-packages\anyio\_backends\_asyncio.py", line 967, in run
    result = context.run(func, *args)
  File "D:\Projects\Development\webcore-erp\webcore-erp\wcs-backend\app\routes\user.py", line 40, in get_users
    users = db.query(User).join(Employee).join(Role).filter(User.is_deleted == False).all()
                                                            ^^^^^^^^^^^^^^^
AttributeError: type object 'User' has no attribute 'is_deleted'
[2025-06-24 13:58:02,939] [ERROR] uvicorn.error: Exception in ASGI application
Traceback (most recent call last):
  File "C:\Users\pc\AppData\Local\Programs\Python\Python313\Lib\site-packages\uvicorn\protocols\http\h11_impl.py", line 403, in run_asgi
    result = await app(  # type: ignore[func-returns-value]
             ^^^^^^^^^^^^^^^^^^^^^^^^^^^^^^^^^^^^^^^^^^^^^^
        self.scope, self.receive, self.send
        ^^^^^^^^^^^^^^^^^^^^^^^^^^^^^^^^^^^
    )
    ^
  File "C:\Users\pc\AppData\Local\Programs\Python\Python313\Lib\site-packages\uvicorn\middleware\proxy_headers.py", line 60, in __call__
    return await self.app(scope, receive, send)
           ^^^^^^^^^^^^^^^^^^^^^^^^^^^^^^^^^^^^
  File "C:\Users\pc\AppData\Local\Programs\Python\Python313\Lib\site-packages\fastapi\applications.py", line 1054, in __call__
    await super().__call__(scope, receive, send)
  File "C:\Users\pc\AppData\Local\Programs\Python\Python313\Lib\site-packages\starlette\applications.py", line 112, in __call__
    await self.middleware_stack(scope, receive, send)
  File "C:\Users\pc\AppData\Local\Programs\Python\Python313\Lib\site-packages\starlette\middleware\errors.py", line 187, in __call__
    raise exc
  File "C:\Users\pc\AppData\Local\Programs\Python\Python313\Lib\site-packages\starlette\middleware\errors.py", line 165, in __call__
    await self.app(scope, receive, _send)
  File "C:\Users\pc\AppData\Local\Programs\Python\Python313\Lib\site-packages\starlette\middleware\cors.py", line 93, in __call__
    await self.simple_response(scope, receive, send, request_headers=headers)
  File "C:\Users\pc\AppData\Local\Programs\Python\Python313\Lib\site-packages\starlette\middleware\cors.py", line 144, in simple_response
    await self.app(scope, receive, send)
  File "C:\Users\pc\AppData\Local\Programs\Python\Python313\Lib\site-packages\starlette\middleware\exceptions.py", line 62, in __call__
    await wrap_app_handling_exceptions(self.app, conn)(scope, receive, send)
  File "C:\Users\pc\AppData\Local\Programs\Python\Python313\Lib\site-packages\starlette\_exception_handler.py", line 53, in wrapped_app
    raise exc
  File "C:\Users\pc\AppData\Local\Programs\Python\Python313\Lib\site-packages\starlette\_exception_handler.py", line 42, in wrapped_app
    await app(scope, receive, sender)
  File "C:\Users\pc\AppData\Local\Programs\Python\Python313\Lib\site-packages\starlette\routing.py", line 714, in __call__
    await self.middleware_stack(scope, receive, send)
  File "C:\Users\pc\AppData\Local\Programs\Python\Python313\Lib\site-packages\starlette\routing.py", line 734, in app
    await route.handle(scope, receive, send)
  File "C:\Users\pc\AppData\Local\Programs\Python\Python313\Lib\site-packages\starlette\routing.py", line 288, in handle
    await self.app(scope, receive, send)
  File "C:\Users\pc\AppData\Local\Programs\Python\Python313\Lib\site-packages\starlette\routing.py", line 76, in app
    await wrap_app_handling_exceptions(app, request)(scope, receive, send)
  File "C:\Users\pc\AppData\Local\Programs\Python\Python313\Lib\site-packages\starlette\_exception_handler.py", line 53, in wrapped_app
    raise exc
  File "C:\Users\pc\AppData\Local\Programs\Python\Python313\Lib\site-packages\starlette\_exception_handler.py", line 42, in wrapped_app
    await app(scope, receive, sender)
  File "C:\Users\pc\AppData\Local\Programs\Python\Python313\Lib\site-packages\starlette\routing.py", line 73, in app
    response = await f(request)
               ^^^^^^^^^^^^^^^^
  File "C:\Users\pc\AppData\Local\Programs\Python\Python313\Lib\site-packages\fastapi\routing.py", line 301, in app
    raw_response = await run_endpoint_function(
                   ^^^^^^^^^^^^^^^^^^^^^^^^^^^^
    ...<3 lines>...
    )
    ^
  File "C:\Users\pc\AppData\Local\Programs\Python\Python313\Lib\site-packages\fastapi\routing.py", line 214, in run_endpoint_function
    return await run_in_threadpool(dependant.call, **values)
           ^^^^^^^^^^^^^^^^^^^^^^^^^^^^^^^^^^^^^^^^^^^^^^^^^
  File "C:\Users\pc\AppData\Local\Programs\Python\Python313\Lib\site-packages\starlette\concurrency.py", line 37, in run_in_threadpool
    return await anyio.to_thread.run_sync(func)
           ^^^^^^^^^^^^^^^^^^^^^^^^^^^^^^^^^^^^
  File "C:\Users\pc\AppData\Local\Programs\Python\Python313\Lib\site-packages\anyio\to_thread.py", line 56, in run_sync
    return await get_async_backend().run_sync_in_worker_thread(
           ^^^^^^^^^^^^^^^^^^^^^^^^^^^^^^^^^^^^^^^^^^^^^^^^^^^^
        func, args, abandon_on_cancel=abandon_on_cancel, limiter=limiter
        ^^^^^^^^^^^^^^^^^^^^^^^^^^^^^^^^^^^^^^^^^^^^^^^^^^^^^^^^^^^^^^^^
    )
    ^
  File "C:\Users\pc\AppData\Local\Programs\Python\Python313\Lib\site-packages\anyio\_backends\_asyncio.py", line 2470, in run_sync_in_worker_thread
    return await future
           ^^^^^^^^^^^^
  File "C:\Users\pc\AppData\Local\Programs\Python\Python313\Lib\site-packages\anyio\_backends\_asyncio.py", line 967, in run
    result = context.run(func, *args)
  File "D:\Projects\Development\webcore-erp\webcore-erp\wcs-backend\app\routes\user.py", line 40, in get_users
    users = db.query(User).join(Employee).join(Role).filter(User.is_deleted == False).all()
                                                            ^^^^^^^^^^^^^^^
AttributeError: type object 'User' has no attribute 'is_deleted'
[2025-06-24 13:58:46,238] [INFO] uvicorn.error: Shutting down
[2025-06-24 13:58:46,345] [INFO] uvicorn.error: Waiting for application shutdown.
[2025-06-24 13:58:46,346] [INFO] uvicorn.error: Application shutdown complete.
[2025-06-24 13:58:46,347] [INFO] uvicorn.error: Finished server process [10888]
[2025-06-24 13:59:01,649] [INFO] uvicorn.error: Started server process [13792]
[2025-06-24 13:59:01,651] [INFO] uvicorn.error: Waiting for application startup.
[2025-06-24 13:59:01,670] [INFO] uvicorn.error: Application startup complete.
[2025-06-24 13:59:01,674] [INFO] uvicorn.error: Uvicorn running on http://127.0.0.1:8000 (Press CTRL+C to quit)
[2025-06-24 13:59:04,178] [INFO] app.routes.auth: employee found: <app.models.employee.Employee object at 0x000001CF5464CD70>
[2025-06-24 13:59:08,035] [ERROR] uvicorn.error: Exception in ASGI application
Traceback (most recent call last):
  File "C:\Users\pc\AppData\Local\Programs\Python\Python313\Lib\site-packages\uvicorn\protocols\http\h11_impl.py", line 403, in run_asgi
    result = await app(  # type: ignore[func-returns-value]
             ^^^^^^^^^^^^^^^^^^^^^^^^^^^^^^^^^^^^^^^^^^^^^^
        self.scope, self.receive, self.send
        ^^^^^^^^^^^^^^^^^^^^^^^^^^^^^^^^^^^
    )
    ^
  File "C:\Users\pc\AppData\Local\Programs\Python\Python313\Lib\site-packages\uvicorn\middleware\proxy_headers.py", line 60, in __call__
    return await self.app(scope, receive, send)
           ^^^^^^^^^^^^^^^^^^^^^^^^^^^^^^^^^^^^
  File "C:\Users\pc\AppData\Local\Programs\Python\Python313\Lib\site-packages\fastapi\applications.py", line 1054, in __call__
    await super().__call__(scope, receive, send)
  File "C:\Users\pc\AppData\Local\Programs\Python\Python313\Lib\site-packages\starlette\applications.py", line 112, in __call__
    await self.middleware_stack(scope, receive, send)
  File "C:\Users\pc\AppData\Local\Programs\Python\Python313\Lib\site-packages\starlette\middleware\errors.py", line 187, in __call__
    raise exc
  File "C:\Users\pc\AppData\Local\Programs\Python\Python313\Lib\site-packages\starlette\middleware\errors.py", line 165, in __call__
    await self.app(scope, receive, _send)
  File "C:\Users\pc\AppData\Local\Programs\Python\Python313\Lib\site-packages\starlette\middleware\cors.py", line 93, in __call__
    await self.simple_response(scope, receive, send, request_headers=headers)
  File "C:\Users\pc\AppData\Local\Programs\Python\Python313\Lib\site-packages\starlette\middleware\cors.py", line 144, in simple_response
    await self.app(scope, receive, send)
  File "C:\Users\pc\AppData\Local\Programs\Python\Python313\Lib\site-packages\starlette\middleware\exceptions.py", line 62, in __call__
    await wrap_app_handling_exceptions(self.app, conn)(scope, receive, send)
  File "C:\Users\pc\AppData\Local\Programs\Python\Python313\Lib\site-packages\starlette\_exception_handler.py", line 53, in wrapped_app
    raise exc
  File "C:\Users\pc\AppData\Local\Programs\Python\Python313\Lib\site-packages\starlette\_exception_handler.py", line 42, in wrapped_app
    await app(scope, receive, sender)
  File "C:\Users\pc\AppData\Local\Programs\Python\Python313\Lib\site-packages\starlette\routing.py", line 714, in __call__
    await self.middleware_stack(scope, receive, send)
  File "C:\Users\pc\AppData\Local\Programs\Python\Python313\Lib\site-packages\starlette\routing.py", line 734, in app
    await route.handle(scope, receive, send)
  File "C:\Users\pc\AppData\Local\Programs\Python\Python313\Lib\site-packages\starlette\routing.py", line 288, in handle
    await self.app(scope, receive, send)
  File "C:\Users\pc\AppData\Local\Programs\Python\Python313\Lib\site-packages\starlette\routing.py", line 76, in app
    await wrap_app_handling_exceptions(app, request)(scope, receive, send)
  File "C:\Users\pc\AppData\Local\Programs\Python\Python313\Lib\site-packages\starlette\_exception_handler.py", line 53, in wrapped_app
    raise exc
  File "C:\Users\pc\AppData\Local\Programs\Python\Python313\Lib\site-packages\starlette\_exception_handler.py", line 42, in wrapped_app
    await app(scope, receive, sender)
  File "C:\Users\pc\AppData\Local\Programs\Python\Python313\Lib\site-packages\starlette\routing.py", line 73, in app
    response = await f(request)
               ^^^^^^^^^^^^^^^^
  File "C:\Users\pc\AppData\Local\Programs\Python\Python313\Lib\site-packages\fastapi\routing.py", line 301, in app
    raw_response = await run_endpoint_function(
                   ^^^^^^^^^^^^^^^^^^^^^^^^^^^^
    ...<3 lines>...
    )
    ^
  File "C:\Users\pc\AppData\Local\Programs\Python\Python313\Lib\site-packages\fastapi\routing.py", line 214, in run_endpoint_function
    return await run_in_threadpool(dependant.call, **values)
           ^^^^^^^^^^^^^^^^^^^^^^^^^^^^^^^^^^^^^^^^^^^^^^^^^
  File "C:\Users\pc\AppData\Local\Programs\Python\Python313\Lib\site-packages\starlette\concurrency.py", line 37, in run_in_threadpool
    return await anyio.to_thread.run_sync(func)
           ^^^^^^^^^^^^^^^^^^^^^^^^^^^^^^^^^^^^
  File "C:\Users\pc\AppData\Local\Programs\Python\Python313\Lib\site-packages\anyio\to_thread.py", line 56, in run_sync
    return await get_async_backend().run_sync_in_worker_thread(
           ^^^^^^^^^^^^^^^^^^^^^^^^^^^^^^^^^^^^^^^^^^^^^^^^^^^^
        func, args, abandon_on_cancel=abandon_on_cancel, limiter=limiter
        ^^^^^^^^^^^^^^^^^^^^^^^^^^^^^^^^^^^^^^^^^^^^^^^^^^^^^^^^^^^^^^^^
    )
    ^
  File "C:\Users\pc\AppData\Local\Programs\Python\Python313\Lib\site-packages\anyio\_backends\_asyncio.py", line 2470, in run_sync_in_worker_thread
    return await future
           ^^^^^^^^^^^^
  File "C:\Users\pc\AppData\Local\Programs\Python\Python313\Lib\site-packages\anyio\_backends\_asyncio.py", line 967, in run
    result = context.run(func, *args)
  File "D:\Projects\Development\webcore-erp\webcore-erp\wcs-backend\app\routes\user.py", line 40, in get_users
    users = db.query(User).join(Employee).join(Role).filter(User.is_deleted == False).all()
  File "C:\Users\pc\AppData\Local\Programs\Python\Python313\Lib\site-packages\sqlalchemy\orm\query.py", line 2704, in all
    return self._iter().all()  # type: ignore
           ~~~~~~~~~~^^
  File "C:\Users\pc\AppData\Local\Programs\Python\Python313\Lib\site-packages\sqlalchemy\orm\query.py", line 2857, in _iter
    result: Union[ScalarResult[_T], Result[_T]] = self.session.execute(
                                                  ~~~~~~~~~~~~~~~~~~~~^
        statement,
        ^^^^^^^^^^
        params,
        ^^^^^^^
        execution_options={"_sa_orm_load_options": self.load_options},
        ^^^^^^^^^^^^^^^^^^^^^^^^^^^^^^^^^^^^^^^^^^^^^^^^^^^^^^^^^^^^^^
    )
    ^
  File "C:\Users\pc\AppData\Local\Programs\Python\Python313\Lib\site-packages\sqlalchemy\orm\session.py", line 2365, in execute
    return self._execute_internal(
           ~~~~~~~~~~~~~~~~~~~~~~^
        statement,
        ^^^^^^^^^^
    ...<4 lines>...
        _add_event=_add_event,
        ^^^^^^^^^^^^^^^^^^^^^^
    )
    ^
  File "C:\Users\pc\AppData\Local\Programs\Python\Python313\Lib\site-packages\sqlalchemy\orm\session.py", line 2251, in _execute_internal
    result: Result[Any] = compile_state_cls.orm_execute_statement(
                          ~~~~~~~~~~~~~~~~~~~~~~~~~~~~~~~~~~~~~~~^
        self,
        ^^^^^
    ...<4 lines>...
        conn,
        ^^^^^
    )
    ^
  File "C:\Users\pc\AppData\Local\Programs\Python\Python313\Lib\site-packages\sqlalchemy\orm\context.py", line 306, in orm_execute_statement
    result = conn.execute(
        statement, params or {}, execution_options=execution_options
    )
  File "C:\Users\pc\AppData\Local\Programs\Python\Python313\Lib\site-packages\sqlalchemy\engine\base.py", line 1415, in execute
    return meth(
        self,
        distilled_parameters,
        execution_options or NO_OPTIONS,
    )
  File "C:\Users\pc\AppData\Local\Programs\Python\Python313\Lib\site-packages\sqlalchemy\sql\elements.py", line 523, in _execute_on_connection
    return connection._execute_clauseelement(
           ~~~~~~~~~~~~~~~~~~~~~~~~~~~~~~~~~^
        self, distilled_params, execution_options
        ^^^^^^^^^^^^^^^^^^^^^^^^^^^^^^^^^^^^^^^^^
    )
    ^
  File "C:\Users\pc\AppData\Local\Programs\Python\Python313\Lib\site-packages\sqlalchemy\engine\base.py", line 1629, in _execute_clauseelement
    compiled_sql, extracted_params, cache_hit = elem._compile_w_cache(
                                                ~~~~~~~~~~~~~~~~~~~~~^
        dialect=dialect,
        ^^^^^^^^^^^^^^^^
    ...<4 lines>...
        linting=self.dialect.compiler_linting | compiler.WARN_LINTING,
        ^^^^^^^^^^^^^^^^^^^^^^^^^^^^^^^^^^^^^^^^^^^^^^^^^^^^^^^^^^^^^^
    )
    ^
  File "C:\Users\pc\AppData\Local\Programs\Python\Python313\Lib\site-packages\sqlalchemy\sql\elements.py", line 711, in _compile_w_cache
    compiled_sql = self._compiler(
        dialect,
    ...<4 lines>...
        **kw,
    )
  File "C:\Users\pc\AppData\Local\Programs\Python\Python313\Lib\site-packages\sqlalchemy\sql\elements.py", line 320, in _compiler
    return dialect.statement_compiler(dialect, self, **kw)
           ~~~~~~~~~~~~~~~~~~~~~~~~~~^^^^^^^^^^^^^^^^^^^^^
  File "C:\Users\pc\AppData\Local\Programs\Python\Python313\Lib\site-packages\sqlalchemy\sql\compiler.py", line 1446, in __init__
    Compiled.__init__(self, dialect, statement, **kwargs)
    ~~~~~~~~~~~~~~~~~^^^^^^^^^^^^^^^^^^^^^^^^^^^^^^^^^^^^
  File "C:\Users\pc\AppData\Local\Programs\Python\Python313\Lib\site-packages\sqlalchemy\sql\compiler.py", line 886, in __init__
    self.string = self.process(self.statement, **compile_kwargs)
                  ~~~~~~~~~~~~^^^^^^^^^^^^^^^^^^^^^^^^^^^^^^^^^^
  File "C:\Users\pc\AppData\Local\Programs\Python\Python313\Lib\site-packages\sqlalchemy\sql\compiler.py", line 932, in process
    return obj._compiler_dispatch(self, **kwargs)
           ~~~~~~~~~~~~~~~~~~~~~~^^^^^^^^^^^^^^^^
  File "C:\Users\pc\AppData\Local\Programs\Python\Python313\Lib\site-packages\sqlalchemy\sql\visitors.py", line 141, in _compiler_dispatch
    return meth(self, **kw)  # type: ignore  # noqa: E501
  File "C:\Users\pc\AppData\Local\Programs\Python\Python313\Lib\site-packages\sqlalchemy\sql\compiler.py", line 4728, in visit_select
    compile_state = select_stmt._compile_state_factory(
        select_stmt, self, **kwargs
    )
  File "C:\Users\pc\AppData\Local\Programs\Python\Python313\Lib\site-packages\sqlalchemy\sql\base.py", line 687, in create_for_statement
    return klass.create_for_statement(statement, compiler, **kw)
           ~~~~~~~~~~~~~~~~~~~~~~~~~~^^^^^^^^^^^^^^^^^^^^^^^^^^^
  File "C:\Users\pc\AppData\Local\Programs\Python\Python313\Lib\site-packages\sqlalchemy\orm\context.py", line 447, in create_for_statement
    return cls._create_orm_context(
           ~~~~~~~~~~~~~~~~~~~~~~~^
        cast("Union[Select, FromStatement]", statement),
        ^^^^^^^^^^^^^^^^^^^^^^^^^^^^^^^^^^^^^^^^^^^^^^^^
    ...<2 lines>...
        **kw,
        ^^^^^
    )
    ^
  File "C:\Users\pc\AppData\Local\Programs\Python\Python313\Lib\site-packages\sqlalchemy\orm\context.py", line 1246, in _create_orm_context
    self._setup_for_generate()
    ~~~~~~~~~~~~~~~~~~~~~~~~^^
  File "C:\Users\pc\AppData\Local\Programs\Python\Python313\Lib\site-packages\sqlalchemy\orm\context.py", line 1281, in _setup_for_generate
    self._join(query._setup_joins, self._entities)
    ~~~~~~~~~~^^^^^^^^^^^^^^^^^^^^^^^^^^^^^^^^^^^^
  File "C:\Users\pc\AppData\Local\Programs\Python\Python313\Lib\site-packages\sqlalchemy\orm\context.py", line 1922, in _join
    self._join_left_to_right(
    ~~~~~~~~~~~~~~~~~~~~~~~~^
        entities_collection,
        ^^^^^^^^^^^^^^^^^^^^
    ...<5 lines>...
        full,
        ^^^^^
    )
    ^
  File "C:\Users\pc\AppData\Local\Programs\Python\Python313\Lib\site-packages\sqlalchemy\orm\context.py", line 2021, in _join_left_to_right
    _ORMJoin(
    ~~~~~~~~^
        left_clause,
        ^^^^^^^^^^^^
    ...<4 lines>...
        _extra_criteria=extra_criteria,
        ^^^^^^^^^^^^^^^^^^^^^^^^^^^^^^^
    )
    ^
  File "C:\Users\pc\AppData\Local\Programs\Python\Python313\Lib\site-packages\sqlalchemy\orm\util.py", line 1884, in __init__
    expression.Join.__init__(self, left, right, onclause, isouter, full)
    ~~~~~~~~~~~~~~~~~~~~~~~~^^^^^^^^^^^^^^^^^^^^^^^^^^^^^^^^^^^^^^^^^^^^
  File "C:\Users\pc\AppData\Local\Programs\Python\Python313\Lib\site-packages\sqlalchemy\sql\selectable.py", line 1298, in __init__
    self.onclause = self._match_primaries(self.left, self.right)
                    ~~~~~~~~~~~~~~~~~~~~~^^^^^^^^^^^^^^^^^^^^^^^
  File "C:\Users\pc\AppData\Local\Programs\Python\Python313\Lib\site-packages\sqlalchemy\sql\selectable.py", line 1409, in _match_primaries
    return self._join_condition(left, right, a_subset=left_right)
           ~~~~~~~~~~~~~~~~~~~~^^^^^^^^^^^^^^^^^^^^^^^^^^^^^^^^^^
  File "C:\Users\pc\AppData\Local\Programs\Python\Python313\Lib\site-packages\sqlalchemy\sql\selectable.py", line 1432, in _join_condition
    cls._joincond_trim_constraints(
    ~~~~~~~~~~~~~~~~~~~~~~~~~~~~~~^
        a, b, constraints, consider_as_foreign_keys
        ^^^^^^^^^^^^^^^^^^^^^^^^^^^^^^^^^^^^^^^^^^^
    )
    ^
  File "C:\Users\pc\AppData\Local\Programs\Python\Python313\Lib\site-packages\sqlalchemy\sql\selectable.py", line 1577, in _joincond_trim_constraints
    raise exc.AmbiguousForeignKeysError(
    ...<5 lines>...
    )
sqlalchemy.exc.AmbiguousForeignKeysError: Can't determine join between 'users' and 'employees'; tables have more than one foreign key constraint relationship between them. Please specify the 'onclause' of this join explicitly.
[2025-06-24 13:59:08,097] [ERROR] uvicorn.error: Exception in ASGI application
Traceback (most recent call last):
  File "C:\Users\pc\AppData\Local\Programs\Python\Python313\Lib\site-packages\uvicorn\protocols\http\h11_impl.py", line 403, in run_asgi
    result = await app(  # type: ignore[func-returns-value]
             ^^^^^^^^^^^^^^^^^^^^^^^^^^^^^^^^^^^^^^^^^^^^^^
        self.scope, self.receive, self.send
        ^^^^^^^^^^^^^^^^^^^^^^^^^^^^^^^^^^^
    )
    ^
  File "C:\Users\pc\AppData\Local\Programs\Python\Python313\Lib\site-packages\uvicorn\middleware\proxy_headers.py", line 60, in __call__
    return await self.app(scope, receive, send)
           ^^^^^^^^^^^^^^^^^^^^^^^^^^^^^^^^^^^^
  File "C:\Users\pc\AppData\Local\Programs\Python\Python313\Lib\site-packages\fastapi\applications.py", line 1054, in __call__
    await super().__call__(scope, receive, send)
  File "C:\Users\pc\AppData\Local\Programs\Python\Python313\Lib\site-packages\starlette\applications.py", line 112, in __call__
    await self.middleware_stack(scope, receive, send)
  File "C:\Users\pc\AppData\Local\Programs\Python\Python313\Lib\site-packages\starlette\middleware\errors.py", line 187, in __call__
    raise exc
  File "C:\Users\pc\AppData\Local\Programs\Python\Python313\Lib\site-packages\starlette\middleware\errors.py", line 165, in __call__
    await self.app(scope, receive, _send)
  File "C:\Users\pc\AppData\Local\Programs\Python\Python313\Lib\site-packages\starlette\middleware\cors.py", line 93, in __call__
    await self.simple_response(scope, receive, send, request_headers=headers)
  File "C:\Users\pc\AppData\Local\Programs\Python\Python313\Lib\site-packages\starlette\middleware\cors.py", line 144, in simple_response
    await self.app(scope, receive, send)
  File "C:\Users\pc\AppData\Local\Programs\Python\Python313\Lib\site-packages\starlette\middleware\exceptions.py", line 62, in __call__
    await wrap_app_handling_exceptions(self.app, conn)(scope, receive, send)
  File "C:\Users\pc\AppData\Local\Programs\Python\Python313\Lib\site-packages\starlette\_exception_handler.py", line 53, in wrapped_app
    raise exc
  File "C:\Users\pc\AppData\Local\Programs\Python\Python313\Lib\site-packages\starlette\_exception_handler.py", line 42, in wrapped_app
    await app(scope, receive, sender)
  File "C:\Users\pc\AppData\Local\Programs\Python\Python313\Lib\site-packages\starlette\routing.py", line 714, in __call__
    await self.middleware_stack(scope, receive, send)
  File "C:\Users\pc\AppData\Local\Programs\Python\Python313\Lib\site-packages\starlette\routing.py", line 734, in app
    await route.handle(scope, receive, send)
  File "C:\Users\pc\AppData\Local\Programs\Python\Python313\Lib\site-packages\starlette\routing.py", line 288, in handle
    await self.app(scope, receive, send)
  File "C:\Users\pc\AppData\Local\Programs\Python\Python313\Lib\site-packages\starlette\routing.py", line 76, in app
    await wrap_app_handling_exceptions(app, request)(scope, receive, send)
  File "C:\Users\pc\AppData\Local\Programs\Python\Python313\Lib\site-packages\starlette\_exception_handler.py", line 53, in wrapped_app
    raise exc
  File "C:\Users\pc\AppData\Local\Programs\Python\Python313\Lib\site-packages\starlette\_exception_handler.py", line 42, in wrapped_app
    await app(scope, receive, sender)
  File "C:\Users\pc\AppData\Local\Programs\Python\Python313\Lib\site-packages\starlette\routing.py", line 73, in app
    response = await f(request)
               ^^^^^^^^^^^^^^^^
  File "C:\Users\pc\AppData\Local\Programs\Python\Python313\Lib\site-packages\fastapi\routing.py", line 301, in app
    raw_response = await run_endpoint_function(
                   ^^^^^^^^^^^^^^^^^^^^^^^^^^^^
    ...<3 lines>...
    )
    ^
  File "C:\Users\pc\AppData\Local\Programs\Python\Python313\Lib\site-packages\fastapi\routing.py", line 214, in run_endpoint_function
    return await run_in_threadpool(dependant.call, **values)
           ^^^^^^^^^^^^^^^^^^^^^^^^^^^^^^^^^^^^^^^^^^^^^^^^^
  File "C:\Users\pc\AppData\Local\Programs\Python\Python313\Lib\site-packages\starlette\concurrency.py", line 37, in run_in_threadpool
    return await anyio.to_thread.run_sync(func)
           ^^^^^^^^^^^^^^^^^^^^^^^^^^^^^^^^^^^^
  File "C:\Users\pc\AppData\Local\Programs\Python\Python313\Lib\site-packages\anyio\to_thread.py", line 56, in run_sync
    return await get_async_backend().run_sync_in_worker_thread(
           ^^^^^^^^^^^^^^^^^^^^^^^^^^^^^^^^^^^^^^^^^^^^^^^^^^^^
        func, args, abandon_on_cancel=abandon_on_cancel, limiter=limiter
        ^^^^^^^^^^^^^^^^^^^^^^^^^^^^^^^^^^^^^^^^^^^^^^^^^^^^^^^^^^^^^^^^
    )
    ^
  File "C:\Users\pc\AppData\Local\Programs\Python\Python313\Lib\site-packages\anyio\_backends\_asyncio.py", line 2470, in run_sync_in_worker_thread
    return await future
           ^^^^^^^^^^^^
  File "C:\Users\pc\AppData\Local\Programs\Python\Python313\Lib\site-packages\anyio\_backends\_asyncio.py", line 967, in run
    result = context.run(func, *args)
  File "D:\Projects\Development\webcore-erp\webcore-erp\wcs-backend\app\routes\user.py", line 40, in get_users
    users = db.query(User).join(Employee).join(Role).filter(User.is_deleted == False).all()
  File "C:\Users\pc\AppData\Local\Programs\Python\Python313\Lib\site-packages\sqlalchemy\orm\query.py", line 2704, in all
    return self._iter().all()  # type: ignore
           ~~~~~~~~~~^^
  File "C:\Users\pc\AppData\Local\Programs\Python\Python313\Lib\site-packages\sqlalchemy\orm\query.py", line 2857, in _iter
    result: Union[ScalarResult[_T], Result[_T]] = self.session.execute(
                                                  ~~~~~~~~~~~~~~~~~~~~^
        statement,
        ^^^^^^^^^^
        params,
        ^^^^^^^
        execution_options={"_sa_orm_load_options": self.load_options},
        ^^^^^^^^^^^^^^^^^^^^^^^^^^^^^^^^^^^^^^^^^^^^^^^^^^^^^^^^^^^^^^
    )
    ^
  File "C:\Users\pc\AppData\Local\Programs\Python\Python313\Lib\site-packages\sqlalchemy\orm\session.py", line 2365, in execute
    return self._execute_internal(
           ~~~~~~~~~~~~~~~~~~~~~~^
        statement,
        ^^^^^^^^^^
    ...<4 lines>...
        _add_event=_add_event,
        ^^^^^^^^^^^^^^^^^^^^^^
    )
    ^
  File "C:\Users\pc\AppData\Local\Programs\Python\Python313\Lib\site-packages\sqlalchemy\orm\session.py", line 2251, in _execute_internal
    result: Result[Any] = compile_state_cls.orm_execute_statement(
                          ~~~~~~~~~~~~~~~~~~~~~~~~~~~~~~~~~~~~~~~^
        self,
        ^^^^^
    ...<4 lines>...
        conn,
        ^^^^^
    )
    ^
  File "C:\Users\pc\AppData\Local\Programs\Python\Python313\Lib\site-packages\sqlalchemy\orm\context.py", line 306, in orm_execute_statement
    result = conn.execute(
        statement, params or {}, execution_options=execution_options
    )
  File "C:\Users\pc\AppData\Local\Programs\Python\Python313\Lib\site-packages\sqlalchemy\engine\base.py", line 1415, in execute
    return meth(
        self,
        distilled_parameters,
        execution_options or NO_OPTIONS,
    )
  File "C:\Users\pc\AppData\Local\Programs\Python\Python313\Lib\site-packages\sqlalchemy\sql\elements.py", line 523, in _execute_on_connection
    return connection._execute_clauseelement(
           ~~~~~~~~~~~~~~~~~~~~~~~~~~~~~~~~~^
        self, distilled_params, execution_options
        ^^^^^^^^^^^^^^^^^^^^^^^^^^^^^^^^^^^^^^^^^
    )
    ^
  File "C:\Users\pc\AppData\Local\Programs\Python\Python313\Lib\site-packages\sqlalchemy\engine\base.py", line 1629, in _execute_clauseelement
    compiled_sql, extracted_params, cache_hit = elem._compile_w_cache(
                                                ~~~~~~~~~~~~~~~~~~~~~^
        dialect=dialect,
        ^^^^^^^^^^^^^^^^
    ...<4 lines>...
        linting=self.dialect.compiler_linting | compiler.WARN_LINTING,
        ^^^^^^^^^^^^^^^^^^^^^^^^^^^^^^^^^^^^^^^^^^^^^^^^^^^^^^^^^^^^^^
    )
    ^
  File "C:\Users\pc\AppData\Local\Programs\Python\Python313\Lib\site-packages\sqlalchemy\sql\elements.py", line 711, in _compile_w_cache
    compiled_sql = self._compiler(
        dialect,
    ...<4 lines>...
        **kw,
    )
  File "C:\Users\pc\AppData\Local\Programs\Python\Python313\Lib\site-packages\sqlalchemy\sql\elements.py", line 320, in _compiler
    return dialect.statement_compiler(dialect, self, **kw)
           ~~~~~~~~~~~~~~~~~~~~~~~~~~^^^^^^^^^^^^^^^^^^^^^
  File "C:\Users\pc\AppData\Local\Programs\Python\Python313\Lib\site-packages\sqlalchemy\sql\compiler.py", line 1446, in __init__
    Compiled.__init__(self, dialect, statement, **kwargs)
    ~~~~~~~~~~~~~~~~~^^^^^^^^^^^^^^^^^^^^^^^^^^^^^^^^^^^^
  File "C:\Users\pc\AppData\Local\Programs\Python\Python313\Lib\site-packages\sqlalchemy\sql\compiler.py", line 886, in __init__
    self.string = self.process(self.statement, **compile_kwargs)
                  ~~~~~~~~~~~~^^^^^^^^^^^^^^^^^^^^^^^^^^^^^^^^^^
  File "C:\Users\pc\AppData\Local\Programs\Python\Python313\Lib\site-packages\sqlalchemy\sql\compiler.py", line 932, in process
    return obj._compiler_dispatch(self, **kwargs)
           ~~~~~~~~~~~~~~~~~~~~~~^^^^^^^^^^^^^^^^
  File "C:\Users\pc\AppData\Local\Programs\Python\Python313\Lib\site-packages\sqlalchemy\sql\visitors.py", line 141, in _compiler_dispatch
    return meth(self, **kw)  # type: ignore  # noqa: E501
  File "C:\Users\pc\AppData\Local\Programs\Python\Python313\Lib\site-packages\sqlalchemy\sql\compiler.py", line 4728, in visit_select
    compile_state = select_stmt._compile_state_factory(
        select_stmt, self, **kwargs
    )
  File "C:\Users\pc\AppData\Local\Programs\Python\Python313\Lib\site-packages\sqlalchemy\sql\base.py", line 687, in create_for_statement
    return klass.create_for_statement(statement, compiler, **kw)
           ~~~~~~~~~~~~~~~~~~~~~~~~~~^^^^^^^^^^^^^^^^^^^^^^^^^^^
  File "C:\Users\pc\AppData\Local\Programs\Python\Python313\Lib\site-packages\sqlalchemy\orm\context.py", line 447, in create_for_statement
    return cls._create_orm_context(
           ~~~~~~~~~~~~~~~~~~~~~~~^
        cast("Union[Select, FromStatement]", statement),
        ^^^^^^^^^^^^^^^^^^^^^^^^^^^^^^^^^^^^^^^^^^^^^^^^
    ...<2 lines>...
        **kw,
        ^^^^^
    )
    ^
  File "C:\Users\pc\AppData\Local\Programs\Python\Python313\Lib\site-packages\sqlalchemy\orm\context.py", line 1246, in _create_orm_context
    self._setup_for_generate()
    ~~~~~~~~~~~~~~~~~~~~~~~~^^
  File "C:\Users\pc\AppData\Local\Programs\Python\Python313\Lib\site-packages\sqlalchemy\orm\context.py", line 1281, in _setup_for_generate
    self._join(query._setup_joins, self._entities)
    ~~~~~~~~~~^^^^^^^^^^^^^^^^^^^^^^^^^^^^^^^^^^^^
  File "C:\Users\pc\AppData\Local\Programs\Python\Python313\Lib\site-packages\sqlalchemy\orm\context.py", line 1922, in _join
    self._join_left_to_right(
    ~~~~~~~~~~~~~~~~~~~~~~~~^
        entities_collection,
        ^^^^^^^^^^^^^^^^^^^^
    ...<5 lines>...
        full,
        ^^^^^
    )
    ^
  File "C:\Users\pc\AppData\Local\Programs\Python\Python313\Lib\site-packages\sqlalchemy\orm\context.py", line 2021, in _join_left_to_right
    _ORMJoin(
    ~~~~~~~~^
        left_clause,
        ^^^^^^^^^^^^
    ...<4 lines>...
        _extra_criteria=extra_criteria,
        ^^^^^^^^^^^^^^^^^^^^^^^^^^^^^^^
    )
    ^
  File "C:\Users\pc\AppData\Local\Programs\Python\Python313\Lib\site-packages\sqlalchemy\orm\util.py", line 1884, in __init__
    expression.Join.__init__(self, left, right, onclause, isouter, full)
    ~~~~~~~~~~~~~~~~~~~~~~~~^^^^^^^^^^^^^^^^^^^^^^^^^^^^^^^^^^^^^^^^^^^^
  File "C:\Users\pc\AppData\Local\Programs\Python\Python313\Lib\site-packages\sqlalchemy\sql\selectable.py", line 1298, in __init__
    self.onclause = self._match_primaries(self.left, self.right)
                    ~~~~~~~~~~~~~~~~~~~~~^^^^^^^^^^^^^^^^^^^^^^^
  File "C:\Users\pc\AppData\Local\Programs\Python\Python313\Lib\site-packages\sqlalchemy\sql\selectable.py", line 1409, in _match_primaries
    return self._join_condition(left, right, a_subset=left_right)
           ~~~~~~~~~~~~~~~~~~~~^^^^^^^^^^^^^^^^^^^^^^^^^^^^^^^^^^
  File "C:\Users\pc\AppData\Local\Programs\Python\Python313\Lib\site-packages\sqlalchemy\sql\selectable.py", line 1432, in _join_condition
    cls._joincond_trim_constraints(
    ~~~~~~~~~~~~~~~~~~~~~~~~~~~~~~^
        a, b, constraints, consider_as_foreign_keys
        ^^^^^^^^^^^^^^^^^^^^^^^^^^^^^^^^^^^^^^^^^^^
    )
    ^
  File "C:\Users\pc\AppData\Local\Programs\Python\Python313\Lib\site-packages\sqlalchemy\sql\selectable.py", line 1577, in _joincond_trim_constraints
    raise exc.AmbiguousForeignKeysError(
    ...<5 lines>...
    )
sqlalchemy.exc.AmbiguousForeignKeysError: Can't determine join between 'users' and 'employees'; tables have more than one foreign key constraint relationship between them. Please specify the 'onclause' of this join explicitly.
[2025-06-24 13:59:13,320] [ERROR] uvicorn.error: Exception in ASGI application
Traceback (most recent call last):
  File "C:\Users\pc\AppData\Local\Programs\Python\Python313\Lib\site-packages\uvicorn\protocols\http\h11_impl.py", line 403, in run_asgi
    result = await app(  # type: ignore[func-returns-value]
             ^^^^^^^^^^^^^^^^^^^^^^^^^^^^^^^^^^^^^^^^^^^^^^
        self.scope, self.receive, self.send
        ^^^^^^^^^^^^^^^^^^^^^^^^^^^^^^^^^^^
    )
    ^
  File "C:\Users\pc\AppData\Local\Programs\Python\Python313\Lib\site-packages\uvicorn\middleware\proxy_headers.py", line 60, in __call__
    return await self.app(scope, receive, send)
           ^^^^^^^^^^^^^^^^^^^^^^^^^^^^^^^^^^^^
  File "C:\Users\pc\AppData\Local\Programs\Python\Python313\Lib\site-packages\fastapi\applications.py", line 1054, in __call__
    await super().__call__(scope, receive, send)
  File "C:\Users\pc\AppData\Local\Programs\Python\Python313\Lib\site-packages\starlette\applications.py", line 112, in __call__
    await self.middleware_stack(scope, receive, send)
  File "C:\Users\pc\AppData\Local\Programs\Python\Python313\Lib\site-packages\starlette\middleware\errors.py", line 187, in __call__
    raise exc
  File "C:\Users\pc\AppData\Local\Programs\Python\Python313\Lib\site-packages\starlette\middleware\errors.py", line 165, in __call__
    await self.app(scope, receive, _send)
  File "C:\Users\pc\AppData\Local\Programs\Python\Python313\Lib\site-packages\starlette\middleware\cors.py", line 93, in __call__
    await self.simple_response(scope, receive, send, request_headers=headers)
  File "C:\Users\pc\AppData\Local\Programs\Python\Python313\Lib\site-packages\starlette\middleware\cors.py", line 144, in simple_response
    await self.app(scope, receive, send)
  File "C:\Users\pc\AppData\Local\Programs\Python\Python313\Lib\site-packages\starlette\middleware\exceptions.py", line 62, in __call__
    await wrap_app_handling_exceptions(self.app, conn)(scope, receive, send)
  File "C:\Users\pc\AppData\Local\Programs\Python\Python313\Lib\site-packages\starlette\_exception_handler.py", line 53, in wrapped_app
    raise exc
  File "C:\Users\pc\AppData\Local\Programs\Python\Python313\Lib\site-packages\starlette\_exception_handler.py", line 42, in wrapped_app
    await app(scope, receive, sender)
  File "C:\Users\pc\AppData\Local\Programs\Python\Python313\Lib\site-packages\starlette\routing.py", line 714, in __call__
    await self.middleware_stack(scope, receive, send)
  File "C:\Users\pc\AppData\Local\Programs\Python\Python313\Lib\site-packages\starlette\routing.py", line 734, in app
    await route.handle(scope, receive, send)
  File "C:\Users\pc\AppData\Local\Programs\Python\Python313\Lib\site-packages\starlette\routing.py", line 288, in handle
    await self.app(scope, receive, send)
  File "C:\Users\pc\AppData\Local\Programs\Python\Python313\Lib\site-packages\starlette\routing.py", line 76, in app
    await wrap_app_handling_exceptions(app, request)(scope, receive, send)
  File "C:\Users\pc\AppData\Local\Programs\Python\Python313\Lib\site-packages\starlette\_exception_handler.py", line 53, in wrapped_app
    raise exc
  File "C:\Users\pc\AppData\Local\Programs\Python\Python313\Lib\site-packages\starlette\_exception_handler.py", line 42, in wrapped_app
    await app(scope, receive, sender)
  File "C:\Users\pc\AppData\Local\Programs\Python\Python313\Lib\site-packages\starlette\routing.py", line 73, in app
    response = await f(request)
               ^^^^^^^^^^^^^^^^
  File "C:\Users\pc\AppData\Local\Programs\Python\Python313\Lib\site-packages\fastapi\routing.py", line 301, in app
    raw_response = await run_endpoint_function(
                   ^^^^^^^^^^^^^^^^^^^^^^^^^^^^
    ...<3 lines>...
    )
    ^
  File "C:\Users\pc\AppData\Local\Programs\Python\Python313\Lib\site-packages\fastapi\routing.py", line 214, in run_endpoint_function
    return await run_in_threadpool(dependant.call, **values)
           ^^^^^^^^^^^^^^^^^^^^^^^^^^^^^^^^^^^^^^^^^^^^^^^^^
  File "C:\Users\pc\AppData\Local\Programs\Python\Python313\Lib\site-packages\starlette\concurrency.py", line 37, in run_in_threadpool
    return await anyio.to_thread.run_sync(func)
           ^^^^^^^^^^^^^^^^^^^^^^^^^^^^^^^^^^^^
  File "C:\Users\pc\AppData\Local\Programs\Python\Python313\Lib\site-packages\anyio\to_thread.py", line 56, in run_sync
    return await get_async_backend().run_sync_in_worker_thread(
           ^^^^^^^^^^^^^^^^^^^^^^^^^^^^^^^^^^^^^^^^^^^^^^^^^^^^
        func, args, abandon_on_cancel=abandon_on_cancel, limiter=limiter
        ^^^^^^^^^^^^^^^^^^^^^^^^^^^^^^^^^^^^^^^^^^^^^^^^^^^^^^^^^^^^^^^^
    )
    ^
  File "C:\Users\pc\AppData\Local\Programs\Python\Python313\Lib\site-packages\anyio\_backends\_asyncio.py", line 2470, in run_sync_in_worker_thread
    return await future
           ^^^^^^^^^^^^
  File "C:\Users\pc\AppData\Local\Programs\Python\Python313\Lib\site-packages\anyio\_backends\_asyncio.py", line 967, in run
    result = context.run(func, *args)
  File "D:\Projects\Development\webcore-erp\webcore-erp\wcs-backend\app\routes\user.py", line 40, in get_users
    users = db.query(User).join(Employee).join(Role).filter(User.is_deleted == False).all()
  File "C:\Users\pc\AppData\Local\Programs\Python\Python313\Lib\site-packages\sqlalchemy\orm\query.py", line 2704, in all
    return self._iter().all()  # type: ignore
           ~~~~~~~~~~^^
  File "C:\Users\pc\AppData\Local\Programs\Python\Python313\Lib\site-packages\sqlalchemy\orm\query.py", line 2857, in _iter
    result: Union[ScalarResult[_T], Result[_T]] = self.session.execute(
                                                  ~~~~~~~~~~~~~~~~~~~~^
        statement,
        ^^^^^^^^^^
        params,
        ^^^^^^^
        execution_options={"_sa_orm_load_options": self.load_options},
        ^^^^^^^^^^^^^^^^^^^^^^^^^^^^^^^^^^^^^^^^^^^^^^^^^^^^^^^^^^^^^^
    )
    ^
  File "C:\Users\pc\AppData\Local\Programs\Python\Python313\Lib\site-packages\sqlalchemy\orm\session.py", line 2365, in execute
    return self._execute_internal(
           ~~~~~~~~~~~~~~~~~~~~~~^
        statement,
        ^^^^^^^^^^
    ...<4 lines>...
        _add_event=_add_event,
        ^^^^^^^^^^^^^^^^^^^^^^
    )
    ^
  File "C:\Users\pc\AppData\Local\Programs\Python\Python313\Lib\site-packages\sqlalchemy\orm\session.py", line 2251, in _execute_internal
    result: Result[Any] = compile_state_cls.orm_execute_statement(
                          ~~~~~~~~~~~~~~~~~~~~~~~~~~~~~~~~~~~~~~~^
        self,
        ^^^^^
    ...<4 lines>...
        conn,
        ^^^^^
    )
    ^
  File "C:\Users\pc\AppData\Local\Programs\Python\Python313\Lib\site-packages\sqlalchemy\orm\context.py", line 306, in orm_execute_statement
    result = conn.execute(
        statement, params or {}, execution_options=execution_options
    )
  File "C:\Users\pc\AppData\Local\Programs\Python\Python313\Lib\site-packages\sqlalchemy\engine\base.py", line 1415, in execute
    return meth(
        self,
        distilled_parameters,
        execution_options or NO_OPTIONS,
    )
  File "C:\Users\pc\AppData\Local\Programs\Python\Python313\Lib\site-packages\sqlalchemy\sql\elements.py", line 523, in _execute_on_connection
    return connection._execute_clauseelement(
           ~~~~~~~~~~~~~~~~~~~~~~~~~~~~~~~~~^
        self, distilled_params, execution_options
        ^^^^^^^^^^^^^^^^^^^^^^^^^^^^^^^^^^^^^^^^^
    )
    ^
  File "C:\Users\pc\AppData\Local\Programs\Python\Python313\Lib\site-packages\sqlalchemy\engine\base.py", line 1629, in _execute_clauseelement
    compiled_sql, extracted_params, cache_hit = elem._compile_w_cache(
                                                ~~~~~~~~~~~~~~~~~~~~~^
        dialect=dialect,
        ^^^^^^^^^^^^^^^^
    ...<4 lines>...
        linting=self.dialect.compiler_linting | compiler.WARN_LINTING,
        ^^^^^^^^^^^^^^^^^^^^^^^^^^^^^^^^^^^^^^^^^^^^^^^^^^^^^^^^^^^^^^
    )
    ^
  File "C:\Users\pc\AppData\Local\Programs\Python\Python313\Lib\site-packages\sqlalchemy\sql\elements.py", line 711, in _compile_w_cache
    compiled_sql = self._compiler(
        dialect,
    ...<4 lines>...
        **kw,
    )
  File "C:\Users\pc\AppData\Local\Programs\Python\Python313\Lib\site-packages\sqlalchemy\sql\elements.py", line 320, in _compiler
    return dialect.statement_compiler(dialect, self, **kw)
           ~~~~~~~~~~~~~~~~~~~~~~~~~~^^^^^^^^^^^^^^^^^^^^^
  File "C:\Users\pc\AppData\Local\Programs\Python\Python313\Lib\site-packages\sqlalchemy\sql\compiler.py", line 1446, in __init__
    Compiled.__init__(self, dialect, statement, **kwargs)
    ~~~~~~~~~~~~~~~~~^^^^^^^^^^^^^^^^^^^^^^^^^^^^^^^^^^^^
  File "C:\Users\pc\AppData\Local\Programs\Python\Python313\Lib\site-packages\sqlalchemy\sql\compiler.py", line 886, in __init__
    self.string = self.process(self.statement, **compile_kwargs)
                  ~~~~~~~~~~~~^^^^^^^^^^^^^^^^^^^^^^^^^^^^^^^^^^
  File "C:\Users\pc\AppData\Local\Programs\Python\Python313\Lib\site-packages\sqlalchemy\sql\compiler.py", line 932, in process
    return obj._compiler_dispatch(self, **kwargs)
           ~~~~~~~~~~~~~~~~~~~~~~^^^^^^^^^^^^^^^^
  File "C:\Users\pc\AppData\Local\Programs\Python\Python313\Lib\site-packages\sqlalchemy\sql\visitors.py", line 141, in _compiler_dispatch
    return meth(self, **kw)  # type: ignore  # noqa: E501
  File "C:\Users\pc\AppData\Local\Programs\Python\Python313\Lib\site-packages\sqlalchemy\sql\compiler.py", line 4728, in visit_select
    compile_state = select_stmt._compile_state_factory(
        select_stmt, self, **kwargs
    )
  File "C:\Users\pc\AppData\Local\Programs\Python\Python313\Lib\site-packages\sqlalchemy\sql\base.py", line 687, in create_for_statement
    return klass.create_for_statement(statement, compiler, **kw)
           ~~~~~~~~~~~~~~~~~~~~~~~~~~^^^^^^^^^^^^^^^^^^^^^^^^^^^
  File "C:\Users\pc\AppData\Local\Programs\Python\Python313\Lib\site-packages\sqlalchemy\orm\context.py", line 447, in create_for_statement
    return cls._create_orm_context(
           ~~~~~~~~~~~~~~~~~~~~~~~^
        cast("Union[Select, FromStatement]", statement),
        ^^^^^^^^^^^^^^^^^^^^^^^^^^^^^^^^^^^^^^^^^^^^^^^^
    ...<2 lines>...
        **kw,
        ^^^^^
    )
    ^
  File "C:\Users\pc\AppData\Local\Programs\Python\Python313\Lib\site-packages\sqlalchemy\orm\context.py", line 1246, in _create_orm_context
    self._setup_for_generate()
    ~~~~~~~~~~~~~~~~~~~~~~~~^^
  File "C:\Users\pc\AppData\Local\Programs\Python\Python313\Lib\site-packages\sqlalchemy\orm\context.py", line 1281, in _setup_for_generate
    self._join(query._setup_joins, self._entities)
    ~~~~~~~~~~^^^^^^^^^^^^^^^^^^^^^^^^^^^^^^^^^^^^
  File "C:\Users\pc\AppData\Local\Programs\Python\Python313\Lib\site-packages\sqlalchemy\orm\context.py", line 1922, in _join
    self._join_left_to_right(
    ~~~~~~~~~~~~~~~~~~~~~~~~^
        entities_collection,
        ^^^^^^^^^^^^^^^^^^^^
    ...<5 lines>...
        full,
        ^^^^^
    )
    ^
  File "C:\Users\pc\AppData\Local\Programs\Python\Python313\Lib\site-packages\sqlalchemy\orm\context.py", line 2021, in _join_left_to_right
    _ORMJoin(
    ~~~~~~~~^
        left_clause,
        ^^^^^^^^^^^^
    ...<4 lines>...
        _extra_criteria=extra_criteria,
        ^^^^^^^^^^^^^^^^^^^^^^^^^^^^^^^
    )
    ^
  File "C:\Users\pc\AppData\Local\Programs\Python\Python313\Lib\site-packages\sqlalchemy\orm\util.py", line 1884, in __init__
    expression.Join.__init__(self, left, right, onclause, isouter, full)
    ~~~~~~~~~~~~~~~~~~~~~~~~^^^^^^^^^^^^^^^^^^^^^^^^^^^^^^^^^^^^^^^^^^^^
  File "C:\Users\pc\AppData\Local\Programs\Python\Python313\Lib\site-packages\sqlalchemy\sql\selectable.py", line 1298, in __init__
    self.onclause = self._match_primaries(self.left, self.right)
                    ~~~~~~~~~~~~~~~~~~~~~^^^^^^^^^^^^^^^^^^^^^^^
  File "C:\Users\pc\AppData\Local\Programs\Python\Python313\Lib\site-packages\sqlalchemy\sql\selectable.py", line 1409, in _match_primaries
    return self._join_condition(left, right, a_subset=left_right)
           ~~~~~~~~~~~~~~~~~~~~^^^^^^^^^^^^^^^^^^^^^^^^^^^^^^^^^^
  File "C:\Users\pc\AppData\Local\Programs\Python\Python313\Lib\site-packages\sqlalchemy\sql\selectable.py", line 1432, in _join_condition
    cls._joincond_trim_constraints(
    ~~~~~~~~~~~~~~~~~~~~~~~~~~~~~~^
        a, b, constraints, consider_as_foreign_keys
        ^^^^^^^^^^^^^^^^^^^^^^^^^^^^^^^^^^^^^^^^^^^
    )
    ^
  File "C:\Users\pc\AppData\Local\Programs\Python\Python313\Lib\site-packages\sqlalchemy\sql\selectable.py", line 1577, in _joincond_trim_constraints
    raise exc.AmbiguousForeignKeysError(
    ...<5 lines>...
    )
sqlalchemy.exc.AmbiguousForeignKeysError: Can't determine join between 'users' and 'employees'; tables have more than one foreign key constraint relationship between them. Please specify the 'onclause' of this join explicitly.
[2025-06-24 13:59:13,379] [ERROR] uvicorn.error: Exception in ASGI application
Traceback (most recent call last):
  File "C:\Users\pc\AppData\Local\Programs\Python\Python313\Lib\site-packages\uvicorn\protocols\http\h11_impl.py", line 403, in run_asgi
    result = await app(  # type: ignore[func-returns-value]
             ^^^^^^^^^^^^^^^^^^^^^^^^^^^^^^^^^^^^^^^^^^^^^^
        self.scope, self.receive, self.send
        ^^^^^^^^^^^^^^^^^^^^^^^^^^^^^^^^^^^
    )
    ^
  File "C:\Users\pc\AppData\Local\Programs\Python\Python313\Lib\site-packages\uvicorn\middleware\proxy_headers.py", line 60, in __call__
    return await self.app(scope, receive, send)
           ^^^^^^^^^^^^^^^^^^^^^^^^^^^^^^^^^^^^
  File "C:\Users\pc\AppData\Local\Programs\Python\Python313\Lib\site-packages\fastapi\applications.py", line 1054, in __call__
    await super().__call__(scope, receive, send)
  File "C:\Users\pc\AppData\Local\Programs\Python\Python313\Lib\site-packages\starlette\applications.py", line 112, in __call__
    await self.middleware_stack(scope, receive, send)
  File "C:\Users\pc\AppData\Local\Programs\Python\Python313\Lib\site-packages\starlette\middleware\errors.py", line 187, in __call__
    raise exc
  File "C:\Users\pc\AppData\Local\Programs\Python\Python313\Lib\site-packages\starlette\middleware\errors.py", line 165, in __call__
    await self.app(scope, receive, _send)
  File "C:\Users\pc\AppData\Local\Programs\Python\Python313\Lib\site-packages\starlette\middleware\cors.py", line 93, in __call__
    await self.simple_response(scope, receive, send, request_headers=headers)
  File "C:\Users\pc\AppData\Local\Programs\Python\Python313\Lib\site-packages\starlette\middleware\cors.py", line 144, in simple_response
    await self.app(scope, receive, send)
  File "C:\Users\pc\AppData\Local\Programs\Python\Python313\Lib\site-packages\starlette\middleware\exceptions.py", line 62, in __call__
    await wrap_app_handling_exceptions(self.app, conn)(scope, receive, send)
  File "C:\Users\pc\AppData\Local\Programs\Python\Python313\Lib\site-packages\starlette\_exception_handler.py", line 53, in wrapped_app
    raise exc
  File "C:\Users\pc\AppData\Local\Programs\Python\Python313\Lib\site-packages\starlette\_exception_handler.py", line 42, in wrapped_app
    await app(scope, receive, sender)
  File "C:\Users\pc\AppData\Local\Programs\Python\Python313\Lib\site-packages\starlette\routing.py", line 714, in __call__
    await self.middleware_stack(scope, receive, send)
  File "C:\Users\pc\AppData\Local\Programs\Python\Python313\Lib\site-packages\starlette\routing.py", line 734, in app
    await route.handle(scope, receive, send)
  File "C:\Users\pc\AppData\Local\Programs\Python\Python313\Lib\site-packages\starlette\routing.py", line 288, in handle
    await self.app(scope, receive, send)
  File "C:\Users\pc\AppData\Local\Programs\Python\Python313\Lib\site-packages\starlette\routing.py", line 76, in app
    await wrap_app_handling_exceptions(app, request)(scope, receive, send)
  File "C:\Users\pc\AppData\Local\Programs\Python\Python313\Lib\site-packages\starlette\_exception_handler.py", line 53, in wrapped_app
    raise exc
  File "C:\Users\pc\AppData\Local\Programs\Python\Python313\Lib\site-packages\starlette\_exception_handler.py", line 42, in wrapped_app
    await app(scope, receive, sender)
  File "C:\Users\pc\AppData\Local\Programs\Python\Python313\Lib\site-packages\starlette\routing.py", line 73, in app
    response = await f(request)
               ^^^^^^^^^^^^^^^^
  File "C:\Users\pc\AppData\Local\Programs\Python\Python313\Lib\site-packages\fastapi\routing.py", line 301, in app
    raw_response = await run_endpoint_function(
                   ^^^^^^^^^^^^^^^^^^^^^^^^^^^^
    ...<3 lines>...
    )
    ^
  File "C:\Users\pc\AppData\Local\Programs\Python\Python313\Lib\site-packages\fastapi\routing.py", line 214, in run_endpoint_function
    return await run_in_threadpool(dependant.call, **values)
           ^^^^^^^^^^^^^^^^^^^^^^^^^^^^^^^^^^^^^^^^^^^^^^^^^
  File "C:\Users\pc\AppData\Local\Programs\Python\Python313\Lib\site-packages\starlette\concurrency.py", line 37, in run_in_threadpool
    return await anyio.to_thread.run_sync(func)
           ^^^^^^^^^^^^^^^^^^^^^^^^^^^^^^^^^^^^
  File "C:\Users\pc\AppData\Local\Programs\Python\Python313\Lib\site-packages\anyio\to_thread.py", line 56, in run_sync
    return await get_async_backend().run_sync_in_worker_thread(
           ^^^^^^^^^^^^^^^^^^^^^^^^^^^^^^^^^^^^^^^^^^^^^^^^^^^^
        func, args, abandon_on_cancel=abandon_on_cancel, limiter=limiter
        ^^^^^^^^^^^^^^^^^^^^^^^^^^^^^^^^^^^^^^^^^^^^^^^^^^^^^^^^^^^^^^^^
    )
    ^
  File "C:\Users\pc\AppData\Local\Programs\Python\Python313\Lib\site-packages\anyio\_backends\_asyncio.py", line 2470, in run_sync_in_worker_thread
    return await future
           ^^^^^^^^^^^^
  File "C:\Users\pc\AppData\Local\Programs\Python\Python313\Lib\site-packages\anyio\_backends\_asyncio.py", line 967, in run
    result = context.run(func, *args)
  File "D:\Projects\Development\webcore-erp\webcore-erp\wcs-backend\app\routes\user.py", line 40, in get_users
    users = db.query(User).join(Employee).join(Role).filter(User.is_deleted == False).all()
  File "C:\Users\pc\AppData\Local\Programs\Python\Python313\Lib\site-packages\sqlalchemy\orm\query.py", line 2704, in all
    return self._iter().all()  # type: ignore
           ~~~~~~~~~~^^
  File "C:\Users\pc\AppData\Local\Programs\Python\Python313\Lib\site-packages\sqlalchemy\orm\query.py", line 2857, in _iter
    result: Union[ScalarResult[_T], Result[_T]] = self.session.execute(
                                                  ~~~~~~~~~~~~~~~~~~~~^
        statement,
        ^^^^^^^^^^
        params,
        ^^^^^^^
        execution_options={"_sa_orm_load_options": self.load_options},
        ^^^^^^^^^^^^^^^^^^^^^^^^^^^^^^^^^^^^^^^^^^^^^^^^^^^^^^^^^^^^^^
    )
    ^
  File "C:\Users\pc\AppData\Local\Programs\Python\Python313\Lib\site-packages\sqlalchemy\orm\session.py", line 2365, in execute
    return self._execute_internal(
           ~~~~~~~~~~~~~~~~~~~~~~^
        statement,
        ^^^^^^^^^^
    ...<4 lines>...
        _add_event=_add_event,
        ^^^^^^^^^^^^^^^^^^^^^^
    )
    ^
  File "C:\Users\pc\AppData\Local\Programs\Python\Python313\Lib\site-packages\sqlalchemy\orm\session.py", line 2251, in _execute_internal
    result: Result[Any] = compile_state_cls.orm_execute_statement(
                          ~~~~~~~~~~~~~~~~~~~~~~~~~~~~~~~~~~~~~~~^
        self,
        ^^^^^
    ...<4 lines>...
        conn,
        ^^^^^
    )
    ^
  File "C:\Users\pc\AppData\Local\Programs\Python\Python313\Lib\site-packages\sqlalchemy\orm\context.py", line 306, in orm_execute_statement
    result = conn.execute(
        statement, params or {}, execution_options=execution_options
    )
  File "C:\Users\pc\AppData\Local\Programs\Python\Python313\Lib\site-packages\sqlalchemy\engine\base.py", line 1415, in execute
    return meth(
        self,
        distilled_parameters,
        execution_options or NO_OPTIONS,
    )
  File "C:\Users\pc\AppData\Local\Programs\Python\Python313\Lib\site-packages\sqlalchemy\sql\elements.py", line 523, in _execute_on_connection
    return connection._execute_clauseelement(
           ~~~~~~~~~~~~~~~~~~~~~~~~~~~~~~~~~^
        self, distilled_params, execution_options
        ^^^^^^^^^^^^^^^^^^^^^^^^^^^^^^^^^^^^^^^^^
    )
    ^
  File "C:\Users\pc\AppData\Local\Programs\Python\Python313\Lib\site-packages\sqlalchemy\engine\base.py", line 1629, in _execute_clauseelement
    compiled_sql, extracted_params, cache_hit = elem._compile_w_cache(
                                                ~~~~~~~~~~~~~~~~~~~~~^
        dialect=dialect,
        ^^^^^^^^^^^^^^^^
    ...<4 lines>...
        linting=self.dialect.compiler_linting | compiler.WARN_LINTING,
        ^^^^^^^^^^^^^^^^^^^^^^^^^^^^^^^^^^^^^^^^^^^^^^^^^^^^^^^^^^^^^^
    )
    ^
  File "C:\Users\pc\AppData\Local\Programs\Python\Python313\Lib\site-packages\sqlalchemy\sql\elements.py", line 711, in _compile_w_cache
    compiled_sql = self._compiler(
        dialect,
    ...<4 lines>...
        **kw,
    )
  File "C:\Users\pc\AppData\Local\Programs\Python\Python313\Lib\site-packages\sqlalchemy\sql\elements.py", line 320, in _compiler
    return dialect.statement_compiler(dialect, self, **kw)
           ~~~~~~~~~~~~~~~~~~~~~~~~~~^^^^^^^^^^^^^^^^^^^^^
  File "C:\Users\pc\AppData\Local\Programs\Python\Python313\Lib\site-packages\sqlalchemy\sql\compiler.py", line 1446, in __init__
    Compiled.__init__(self, dialect, statement, **kwargs)
    ~~~~~~~~~~~~~~~~~^^^^^^^^^^^^^^^^^^^^^^^^^^^^^^^^^^^^
  File "C:\Users\pc\AppData\Local\Programs\Python\Python313\Lib\site-packages\sqlalchemy\sql\compiler.py", line 886, in __init__
    self.string = self.process(self.statement, **compile_kwargs)
                  ~~~~~~~~~~~~^^^^^^^^^^^^^^^^^^^^^^^^^^^^^^^^^^
  File "C:\Users\pc\AppData\Local\Programs\Python\Python313\Lib\site-packages\sqlalchemy\sql\compiler.py", line 932, in process
    return obj._compiler_dispatch(self, **kwargs)
           ~~~~~~~~~~~~~~~~~~~~~~^^^^^^^^^^^^^^^^
  File "C:\Users\pc\AppData\Local\Programs\Python\Python313\Lib\site-packages\sqlalchemy\sql\visitors.py", line 141, in _compiler_dispatch
    return meth(self, **kw)  # type: ignore  # noqa: E501
  File "C:\Users\pc\AppData\Local\Programs\Python\Python313\Lib\site-packages\sqlalchemy\sql\compiler.py", line 4728, in visit_select
    compile_state = select_stmt._compile_state_factory(
        select_stmt, self, **kwargs
    )
  File "C:\Users\pc\AppData\Local\Programs\Python\Python313\Lib\site-packages\sqlalchemy\sql\base.py", line 687, in create_for_statement
    return klass.create_for_statement(statement, compiler, **kw)
           ~~~~~~~~~~~~~~~~~~~~~~~~~~^^^^^^^^^^^^^^^^^^^^^^^^^^^
  File "C:\Users\pc\AppData\Local\Programs\Python\Python313\Lib\site-packages\sqlalchemy\orm\context.py", line 447, in create_for_statement
    return cls._create_orm_context(
           ~~~~~~~~~~~~~~~~~~~~~~~^
        cast("Union[Select, FromStatement]", statement),
        ^^^^^^^^^^^^^^^^^^^^^^^^^^^^^^^^^^^^^^^^^^^^^^^^
    ...<2 lines>...
        **kw,
        ^^^^^
    )
    ^
  File "C:\Users\pc\AppData\Local\Programs\Python\Python313\Lib\site-packages\sqlalchemy\orm\context.py", line 1246, in _create_orm_context
    self._setup_for_generate()
    ~~~~~~~~~~~~~~~~~~~~~~~~^^
  File "C:\Users\pc\AppData\Local\Programs\Python\Python313\Lib\site-packages\sqlalchemy\orm\context.py", line 1281, in _setup_for_generate
    self._join(query._setup_joins, self._entities)
    ~~~~~~~~~~^^^^^^^^^^^^^^^^^^^^^^^^^^^^^^^^^^^^
  File "C:\Users\pc\AppData\Local\Programs\Python\Python313\Lib\site-packages\sqlalchemy\orm\context.py", line 1922, in _join
    self._join_left_to_right(
    ~~~~~~~~~~~~~~~~~~~~~~~~^
        entities_collection,
        ^^^^^^^^^^^^^^^^^^^^
    ...<5 lines>...
        full,
        ^^^^^
    )
    ^
  File "C:\Users\pc\AppData\Local\Programs\Python\Python313\Lib\site-packages\sqlalchemy\orm\context.py", line 2021, in _join_left_to_right
    _ORMJoin(
    ~~~~~~~~^
        left_clause,
        ^^^^^^^^^^^^
    ...<4 lines>...
        _extra_criteria=extra_criteria,
        ^^^^^^^^^^^^^^^^^^^^^^^^^^^^^^^
    )
    ^
  File "C:\Users\pc\AppData\Local\Programs\Python\Python313\Lib\site-packages\sqlalchemy\orm\util.py", line 1884, in __init__
    expression.Join.__init__(self, left, right, onclause, isouter, full)
    ~~~~~~~~~~~~~~~~~~~~~~~~^^^^^^^^^^^^^^^^^^^^^^^^^^^^^^^^^^^^^^^^^^^^
  File "C:\Users\pc\AppData\Local\Programs\Python\Python313\Lib\site-packages\sqlalchemy\sql\selectable.py", line 1298, in __init__
    self.onclause = self._match_primaries(self.left, self.right)
                    ~~~~~~~~~~~~~~~~~~~~~^^^^^^^^^^^^^^^^^^^^^^^
  File "C:\Users\pc\AppData\Local\Programs\Python\Python313\Lib\site-packages\sqlalchemy\sql\selectable.py", line 1409, in _match_primaries
    return self._join_condition(left, right, a_subset=left_right)
           ~~~~~~~~~~~~~~~~~~~~^^^^^^^^^^^^^^^^^^^^^^^^^^^^^^^^^^
  File "C:\Users\pc\AppData\Local\Programs\Python\Python313\Lib\site-packages\sqlalchemy\sql\selectable.py", line 1432, in _join_condition
    cls._joincond_trim_constraints(
    ~~~~~~~~~~~~~~~~~~~~~~~~~~~~~~^
        a, b, constraints, consider_as_foreign_keys
        ^^^^^^^^^^^^^^^^^^^^^^^^^^^^^^^^^^^^^^^^^^^
    )
    ^
  File "C:\Users\pc\AppData\Local\Programs\Python\Python313\Lib\site-packages\sqlalchemy\sql\selectable.py", line 1577, in _joincond_trim_constraints
    raise exc.AmbiguousForeignKeysError(
    ...<5 lines>...
    )
sqlalchemy.exc.AmbiguousForeignKeysError: Can't determine join between 'users' and 'employees'; tables have more than one foreign key constraint relationship between them. Please specify the 'onclause' of this join explicitly.
[2025-06-24 13:59:34,612] [ERROR] uvicorn.error: Exception in ASGI application
Traceback (most recent call last):
  File "C:\Users\pc\AppData\Local\Programs\Python\Python313\Lib\site-packages\uvicorn\protocols\http\h11_impl.py", line 403, in run_asgi
    result = await app(  # type: ignore[func-returns-value]
             ^^^^^^^^^^^^^^^^^^^^^^^^^^^^^^^^^^^^^^^^^^^^^^
        self.scope, self.receive, self.send
        ^^^^^^^^^^^^^^^^^^^^^^^^^^^^^^^^^^^
    )
    ^
  File "C:\Users\pc\AppData\Local\Programs\Python\Python313\Lib\site-packages\uvicorn\middleware\proxy_headers.py", line 60, in __call__
    return await self.app(scope, receive, send)
           ^^^^^^^^^^^^^^^^^^^^^^^^^^^^^^^^^^^^
  File "C:\Users\pc\AppData\Local\Programs\Python\Python313\Lib\site-packages\fastapi\applications.py", line 1054, in __call__
    await super().__call__(scope, receive, send)
  File "C:\Users\pc\AppData\Local\Programs\Python\Python313\Lib\site-packages\starlette\applications.py", line 112, in __call__
    await self.middleware_stack(scope, receive, send)
  File "C:\Users\pc\AppData\Local\Programs\Python\Python313\Lib\site-packages\starlette\middleware\errors.py", line 187, in __call__
    raise exc
  File "C:\Users\pc\AppData\Local\Programs\Python\Python313\Lib\site-packages\starlette\middleware\errors.py", line 165, in __call__
    await self.app(scope, receive, _send)
  File "C:\Users\pc\AppData\Local\Programs\Python\Python313\Lib\site-packages\starlette\middleware\cors.py", line 85, in __call__
    await self.app(scope, receive, send)
  File "C:\Users\pc\AppData\Local\Programs\Python\Python313\Lib\site-packages\starlette\middleware\exceptions.py", line 62, in __call__
    await wrap_app_handling_exceptions(self.app, conn)(scope, receive, send)
  File "C:\Users\pc\AppData\Local\Programs\Python\Python313\Lib\site-packages\starlette\_exception_handler.py", line 53, in wrapped_app
    raise exc
  File "C:\Users\pc\AppData\Local\Programs\Python\Python313\Lib\site-packages\starlette\_exception_handler.py", line 42, in wrapped_app
    await app(scope, receive, sender)
  File "C:\Users\pc\AppData\Local\Programs\Python\Python313\Lib\site-packages\starlette\routing.py", line 714, in __call__
    await self.middleware_stack(scope, receive, send)
  File "C:\Users\pc\AppData\Local\Programs\Python\Python313\Lib\site-packages\starlette\routing.py", line 734, in app
    await route.handle(scope, receive, send)
  File "C:\Users\pc\AppData\Local\Programs\Python\Python313\Lib\site-packages\starlette\routing.py", line 288, in handle
    await self.app(scope, receive, send)
  File "C:\Users\pc\AppData\Local\Programs\Python\Python313\Lib\site-packages\starlette\routing.py", line 76, in app
    await wrap_app_handling_exceptions(app, request)(scope, receive, send)
  File "C:\Users\pc\AppData\Local\Programs\Python\Python313\Lib\site-packages\starlette\_exception_handler.py", line 53, in wrapped_app
    raise exc
  File "C:\Users\pc\AppData\Local\Programs\Python\Python313\Lib\site-packages\starlette\_exception_handler.py", line 42, in wrapped_app
    await app(scope, receive, sender)
  File "C:\Users\pc\AppData\Local\Programs\Python\Python313\Lib\site-packages\starlette\routing.py", line 73, in app
    response = await f(request)
               ^^^^^^^^^^^^^^^^
  File "C:\Users\pc\AppData\Local\Programs\Python\Python313\Lib\site-packages\fastapi\routing.py", line 301, in app
    raw_response = await run_endpoint_function(
                   ^^^^^^^^^^^^^^^^^^^^^^^^^^^^
    ...<3 lines>...
    )
    ^
  File "C:\Users\pc\AppData\Local\Programs\Python\Python313\Lib\site-packages\fastapi\routing.py", line 214, in run_endpoint_function
    return await run_in_threadpool(dependant.call, **values)
           ^^^^^^^^^^^^^^^^^^^^^^^^^^^^^^^^^^^^^^^^^^^^^^^^^
  File "C:\Users\pc\AppData\Local\Programs\Python\Python313\Lib\site-packages\starlette\concurrency.py", line 37, in run_in_threadpool
    return await anyio.to_thread.run_sync(func)
           ^^^^^^^^^^^^^^^^^^^^^^^^^^^^^^^^^^^^
  File "C:\Users\pc\AppData\Local\Programs\Python\Python313\Lib\site-packages\anyio\to_thread.py", line 56, in run_sync
    return await get_async_backend().run_sync_in_worker_thread(
           ^^^^^^^^^^^^^^^^^^^^^^^^^^^^^^^^^^^^^^^^^^^^^^^^^^^^
        func, args, abandon_on_cancel=abandon_on_cancel, limiter=limiter
        ^^^^^^^^^^^^^^^^^^^^^^^^^^^^^^^^^^^^^^^^^^^^^^^^^^^^^^^^^^^^^^^^
    )
    ^
  File "C:\Users\pc\AppData\Local\Programs\Python\Python313\Lib\site-packages\anyio\_backends\_asyncio.py", line 2470, in run_sync_in_worker_thread
    return await future
           ^^^^^^^^^^^^
  File "C:\Users\pc\AppData\Local\Programs\Python\Python313\Lib\site-packages\anyio\_backends\_asyncio.py", line 967, in run
    result = context.run(func, *args)
  File "D:\Projects\Development\webcore-erp\webcore-erp\wcs-backend\app\routes\user.py", line 40, in get_users
    users = db.query(User).join(Employee).join(Role).filter(User.is_deleted == False).all()
  File "C:\Users\pc\AppData\Local\Programs\Python\Python313\Lib\site-packages\sqlalchemy\orm\query.py", line 2704, in all
    return self._iter().all()  # type: ignore
           ~~~~~~~~~~^^
  File "C:\Users\pc\AppData\Local\Programs\Python\Python313\Lib\site-packages\sqlalchemy\orm\query.py", line 2857, in _iter
    result: Union[ScalarResult[_T], Result[_T]] = self.session.execute(
                                                  ~~~~~~~~~~~~~~~~~~~~^
        statement,
        ^^^^^^^^^^
        params,
        ^^^^^^^
        execution_options={"_sa_orm_load_options": self.load_options},
        ^^^^^^^^^^^^^^^^^^^^^^^^^^^^^^^^^^^^^^^^^^^^^^^^^^^^^^^^^^^^^^
    )
    ^
  File "C:\Users\pc\AppData\Local\Programs\Python\Python313\Lib\site-packages\sqlalchemy\orm\session.py", line 2365, in execute
    return self._execute_internal(
           ~~~~~~~~~~~~~~~~~~~~~~^
        statement,
        ^^^^^^^^^^
    ...<4 lines>...
        _add_event=_add_event,
        ^^^^^^^^^^^^^^^^^^^^^^
    )
    ^
  File "C:\Users\pc\AppData\Local\Programs\Python\Python313\Lib\site-packages\sqlalchemy\orm\session.py", line 2251, in _execute_internal
    result: Result[Any] = compile_state_cls.orm_execute_statement(
                          ~~~~~~~~~~~~~~~~~~~~~~~~~~~~~~~~~~~~~~~^
        self,
        ^^^^^
    ...<4 lines>...
        conn,
        ^^^^^
    )
    ^
  File "C:\Users\pc\AppData\Local\Programs\Python\Python313\Lib\site-packages\sqlalchemy\orm\context.py", line 306, in orm_execute_statement
    result = conn.execute(
        statement, params or {}, execution_options=execution_options
    )
  File "C:\Users\pc\AppData\Local\Programs\Python\Python313\Lib\site-packages\sqlalchemy\engine\base.py", line 1415, in execute
    return meth(
        self,
        distilled_parameters,
        execution_options or NO_OPTIONS,
    )
  File "C:\Users\pc\AppData\Local\Programs\Python\Python313\Lib\site-packages\sqlalchemy\sql\elements.py", line 523, in _execute_on_connection
    return connection._execute_clauseelement(
           ~~~~~~~~~~~~~~~~~~~~~~~~~~~~~~~~~^
        self, distilled_params, execution_options
        ^^^^^^^^^^^^^^^^^^^^^^^^^^^^^^^^^^^^^^^^^
    )
    ^
  File "C:\Users\pc\AppData\Local\Programs\Python\Python313\Lib\site-packages\sqlalchemy\engine\base.py", line 1629, in _execute_clauseelement
    compiled_sql, extracted_params, cache_hit = elem._compile_w_cache(
                                                ~~~~~~~~~~~~~~~~~~~~~^
        dialect=dialect,
        ^^^^^^^^^^^^^^^^
    ...<4 lines>...
        linting=self.dialect.compiler_linting | compiler.WARN_LINTING,
        ^^^^^^^^^^^^^^^^^^^^^^^^^^^^^^^^^^^^^^^^^^^^^^^^^^^^^^^^^^^^^^
    )
    ^
  File "C:\Users\pc\AppData\Local\Programs\Python\Python313\Lib\site-packages\sqlalchemy\sql\elements.py", line 711, in _compile_w_cache
    compiled_sql = self._compiler(
        dialect,
    ...<4 lines>...
        **kw,
    )
  File "C:\Users\pc\AppData\Local\Programs\Python\Python313\Lib\site-packages\sqlalchemy\sql\elements.py", line 320, in _compiler
    return dialect.statement_compiler(dialect, self, **kw)
           ~~~~~~~~~~~~~~~~~~~~~~~~~~^^^^^^^^^^^^^^^^^^^^^
  File "C:\Users\pc\AppData\Local\Programs\Python\Python313\Lib\site-packages\sqlalchemy\sql\compiler.py", line 1446, in __init__
    Compiled.__init__(self, dialect, statement, **kwargs)
    ~~~~~~~~~~~~~~~~~^^^^^^^^^^^^^^^^^^^^^^^^^^^^^^^^^^^^
  File "C:\Users\pc\AppData\Local\Programs\Python\Python313\Lib\site-packages\sqlalchemy\sql\compiler.py", line 886, in __init__
    self.string = self.process(self.statement, **compile_kwargs)
                  ~~~~~~~~~~~~^^^^^^^^^^^^^^^^^^^^^^^^^^^^^^^^^^
  File "C:\Users\pc\AppData\Local\Programs\Python\Python313\Lib\site-packages\sqlalchemy\sql\compiler.py", line 932, in process
    return obj._compiler_dispatch(self, **kwargs)
           ~~~~~~~~~~~~~~~~~~~~~~^^^^^^^^^^^^^^^^
  File "C:\Users\pc\AppData\Local\Programs\Python\Python313\Lib\site-packages\sqlalchemy\sql\visitors.py", line 141, in _compiler_dispatch
    return meth(self, **kw)  # type: ignore  # noqa: E501
  File "C:\Users\pc\AppData\Local\Programs\Python\Python313\Lib\site-packages\sqlalchemy\sql\compiler.py", line 4728, in visit_select
    compile_state = select_stmt._compile_state_factory(
        select_stmt, self, **kwargs
    )
  File "C:\Users\pc\AppData\Local\Programs\Python\Python313\Lib\site-packages\sqlalchemy\sql\base.py", line 687, in create_for_statement
    return klass.create_for_statement(statement, compiler, **kw)
           ~~~~~~~~~~~~~~~~~~~~~~~~~~^^^^^^^^^^^^^^^^^^^^^^^^^^^
  File "C:\Users\pc\AppData\Local\Programs\Python\Python313\Lib\site-packages\sqlalchemy\orm\context.py", line 447, in create_for_statement
    return cls._create_orm_context(
           ~~~~~~~~~~~~~~~~~~~~~~~^
        cast("Union[Select, FromStatement]", statement),
        ^^^^^^^^^^^^^^^^^^^^^^^^^^^^^^^^^^^^^^^^^^^^^^^^
    ...<2 lines>...
        **kw,
        ^^^^^
    )
    ^
  File "C:\Users\pc\AppData\Local\Programs\Python\Python313\Lib\site-packages\sqlalchemy\orm\context.py", line 1246, in _create_orm_context
    self._setup_for_generate()
    ~~~~~~~~~~~~~~~~~~~~~~~~^^
  File "C:\Users\pc\AppData\Local\Programs\Python\Python313\Lib\site-packages\sqlalchemy\orm\context.py", line 1281, in _setup_for_generate
    self._join(query._setup_joins, self._entities)
    ~~~~~~~~~~^^^^^^^^^^^^^^^^^^^^^^^^^^^^^^^^^^^^
  File "C:\Users\pc\AppData\Local\Programs\Python\Python313\Lib\site-packages\sqlalchemy\orm\context.py", line 1922, in _join
    self._join_left_to_right(
    ~~~~~~~~~~~~~~~~~~~~~~~~^
        entities_collection,
        ^^^^^^^^^^^^^^^^^^^^
    ...<5 lines>...
        full,
        ^^^^^
    )
    ^
  File "C:\Users\pc\AppData\Local\Programs\Python\Python313\Lib\site-packages\sqlalchemy\orm\context.py", line 2021, in _join_left_to_right
    _ORMJoin(
    ~~~~~~~~^
        left_clause,
        ^^^^^^^^^^^^
    ...<4 lines>...
        _extra_criteria=extra_criteria,
        ^^^^^^^^^^^^^^^^^^^^^^^^^^^^^^^
    )
    ^
  File "C:\Users\pc\AppData\Local\Programs\Python\Python313\Lib\site-packages\sqlalchemy\orm\util.py", line 1884, in __init__
    expression.Join.__init__(self, left, right, onclause, isouter, full)
    ~~~~~~~~~~~~~~~~~~~~~~~~^^^^^^^^^^^^^^^^^^^^^^^^^^^^^^^^^^^^^^^^^^^^
  File "C:\Users\pc\AppData\Local\Programs\Python\Python313\Lib\site-packages\sqlalchemy\sql\selectable.py", line 1298, in __init__
    self.onclause = self._match_primaries(self.left, self.right)
                    ~~~~~~~~~~~~~~~~~~~~~^^^^^^^^^^^^^^^^^^^^^^^
  File "C:\Users\pc\AppData\Local\Programs\Python\Python313\Lib\site-packages\sqlalchemy\sql\selectable.py", line 1409, in _match_primaries
    return self._join_condition(left, right, a_subset=left_right)
           ~~~~~~~~~~~~~~~~~~~~^^^^^^^^^^^^^^^^^^^^^^^^^^^^^^^^^^
  File "C:\Users\pc\AppData\Local\Programs\Python\Python313\Lib\site-packages\sqlalchemy\sql\selectable.py", line 1432, in _join_condition
    cls._joincond_trim_constraints(
    ~~~~~~~~~~~~~~~~~~~~~~~~~~~~~~^
        a, b, constraints, consider_as_foreign_keys
        ^^^^^^^^^^^^^^^^^^^^^^^^^^^^^^^^^^^^^^^^^^^
    )
    ^
  File "C:\Users\pc\AppData\Local\Programs\Python\Python313\Lib\site-packages\sqlalchemy\sql\selectable.py", line 1577, in _joincond_trim_constraints
    raise exc.AmbiguousForeignKeysError(
    ...<5 lines>...
    )
sqlalchemy.exc.AmbiguousForeignKeysError: Can't determine join between 'users' and 'employees'; tables have more than one foreign key constraint relationship between them. Please specify the 'onclause' of this join explicitly.
[2025-06-24 14:00:23,176] [INFO] uvicorn.error: Shutting down
[2025-06-24 14:00:23,283] [INFO] uvicorn.error: Waiting for application shutdown.
[2025-06-24 14:00:23,284] [INFO] uvicorn.error: Application shutdown complete.
[2025-06-24 14:00:23,284] [INFO] uvicorn.error: Finished server process [13792]
[2025-06-24 14:00:48,112] [INFO] uvicorn.error: Started server process [4152]
[2025-06-24 14:00:48,113] [INFO] uvicorn.error: Waiting for application startup.
[2025-06-24 14:00:48,132] [INFO] uvicorn.error: Application startup complete.
[2025-06-24 14:00:48,134] [INFO] uvicorn.error: Uvicorn running on http://127.0.0.1:8000 (Press CTRL+C to quit)
[2025-06-24 14:00:51,441] [ERROR] uvicorn.error: Exception in ASGI application
Traceback (most recent call last):
  File "C:\Users\pc\AppData\Local\Programs\Python\Python313\Lib\site-packages\uvicorn\protocols\http\h11_impl.py", line 403, in run_asgi
    result = await app(  # type: ignore[func-returns-value]
             ^^^^^^^^^^^^^^^^^^^^^^^^^^^^^^^^^^^^^^^^^^^^^^
        self.scope, self.receive, self.send
        ^^^^^^^^^^^^^^^^^^^^^^^^^^^^^^^^^^^
    )
    ^
  File "C:\Users\pc\AppData\Local\Programs\Python\Python313\Lib\site-packages\uvicorn\middleware\proxy_headers.py", line 60, in __call__
    return await self.app(scope, receive, send)
           ^^^^^^^^^^^^^^^^^^^^^^^^^^^^^^^^^^^^
  File "C:\Users\pc\AppData\Local\Programs\Python\Python313\Lib\site-packages\fastapi\applications.py", line 1054, in __call__
    await super().__call__(scope, receive, send)
  File "C:\Users\pc\AppData\Local\Programs\Python\Python313\Lib\site-packages\starlette\applications.py", line 112, in __call__
    await self.middleware_stack(scope, receive, send)
  File "C:\Users\pc\AppData\Local\Programs\Python\Python313\Lib\site-packages\starlette\middleware\errors.py", line 187, in __call__
    raise exc
  File "C:\Users\pc\AppData\Local\Programs\Python\Python313\Lib\site-packages\starlette\middleware\errors.py", line 165, in __call__
    await self.app(scope, receive, _send)
  File "C:\Users\pc\AppData\Local\Programs\Python\Python313\Lib\site-packages\starlette\middleware\cors.py", line 85, in __call__
    await self.app(scope, receive, send)
  File "C:\Users\pc\AppData\Local\Programs\Python\Python313\Lib\site-packages\starlette\middleware\exceptions.py", line 62, in __call__
    await wrap_app_handling_exceptions(self.app, conn)(scope, receive, send)
  File "C:\Users\pc\AppData\Local\Programs\Python\Python313\Lib\site-packages\starlette\_exception_handler.py", line 53, in wrapped_app
    raise exc
  File "C:\Users\pc\AppData\Local\Programs\Python\Python313\Lib\site-packages\starlette\_exception_handler.py", line 42, in wrapped_app
    await app(scope, receive, sender)
  File "C:\Users\pc\AppData\Local\Programs\Python\Python313\Lib\site-packages\starlette\routing.py", line 714, in __call__
    await self.middleware_stack(scope, receive, send)
  File "C:\Users\pc\AppData\Local\Programs\Python\Python313\Lib\site-packages\starlette\routing.py", line 734, in app
    await route.handle(scope, receive, send)
  File "C:\Users\pc\AppData\Local\Programs\Python\Python313\Lib\site-packages\starlette\routing.py", line 288, in handle
    await self.app(scope, receive, send)
  File "C:\Users\pc\AppData\Local\Programs\Python\Python313\Lib\site-packages\starlette\routing.py", line 76, in app
    await wrap_app_handling_exceptions(app, request)(scope, receive, send)
  File "C:\Users\pc\AppData\Local\Programs\Python\Python313\Lib\site-packages\starlette\_exception_handler.py", line 53, in wrapped_app
    raise exc
  File "C:\Users\pc\AppData\Local\Programs\Python\Python313\Lib\site-packages\starlette\_exception_handler.py", line 42, in wrapped_app
    await app(scope, receive, sender)
  File "C:\Users\pc\AppData\Local\Programs\Python\Python313\Lib\site-packages\starlette\routing.py", line 73, in app
    response = await f(request)
               ^^^^^^^^^^^^^^^^
  File "C:\Users\pc\AppData\Local\Programs\Python\Python313\Lib\site-packages\fastapi\routing.py", line 301, in app
    raw_response = await run_endpoint_function(
                   ^^^^^^^^^^^^^^^^^^^^^^^^^^^^
    ...<3 lines>...
    )
    ^
  File "C:\Users\pc\AppData\Local\Programs\Python\Python313\Lib\site-packages\fastapi\routing.py", line 214, in run_endpoint_function
    return await run_in_threadpool(dependant.call, **values)
           ^^^^^^^^^^^^^^^^^^^^^^^^^^^^^^^^^^^^^^^^^^^^^^^^^
  File "C:\Users\pc\AppData\Local\Programs\Python\Python313\Lib\site-packages\starlette\concurrency.py", line 37, in run_in_threadpool
    return await anyio.to_thread.run_sync(func)
           ^^^^^^^^^^^^^^^^^^^^^^^^^^^^^^^^^^^^
  File "C:\Users\pc\AppData\Local\Programs\Python\Python313\Lib\site-packages\anyio\to_thread.py", line 56, in run_sync
    return await get_async_backend().run_sync_in_worker_thread(
           ^^^^^^^^^^^^^^^^^^^^^^^^^^^^^^^^^^^^^^^^^^^^^^^^^^^^
        func, args, abandon_on_cancel=abandon_on_cancel, limiter=limiter
        ^^^^^^^^^^^^^^^^^^^^^^^^^^^^^^^^^^^^^^^^^^^^^^^^^^^^^^^^^^^^^^^^
    )
    ^
  File "C:\Users\pc\AppData\Local\Programs\Python\Python313\Lib\site-packages\anyio\_backends\_asyncio.py", line 2470, in run_sync_in_worker_thread
    return await future
           ^^^^^^^^^^^^
  File "C:\Users\pc\AppData\Local\Programs\Python\Python313\Lib\site-packages\anyio\_backends\_asyncio.py", line 967, in run
    result = context.run(func, *args)
  File "D:\Projects\Development\webcore-erp\webcore-erp\wcs-backend\app\routes\user.py", line 62, in get_users
    .join(Role, User.role_id == Role.id)              # 👈 Explicit join
                ^^^^^^^^^^^^
AttributeError: type object 'User' has no attribute 'role_id'
[2025-06-24 14:02:56,000] [INFO] uvicorn.error: Shutting down
[2025-06-24 14:02:56,105] [INFO] uvicorn.error: Waiting for application shutdown.
[2025-06-24 14:02:56,106] [INFO] uvicorn.error: Application shutdown complete.
[2025-06-24 14:02:56,107] [INFO] uvicorn.error: Finished server process [4152]
[2025-06-24 14:03:01,050] [INFO] uvicorn.error: Started server process [13992]
[2025-06-24 14:03:01,051] [INFO] uvicorn.error: Waiting for application startup.
[2025-06-24 14:03:01,061] [INFO] uvicorn.error: Application startup complete.
[2025-06-24 14:03:01,063] [INFO] uvicorn.error: Uvicorn running on http://127.0.0.1:8000 (Press CTRL+C to quit)
[2025-06-24 14:03:05,661] [ERROR] uvicorn.error: Exception in ASGI application
Traceback (most recent call last):
  File "C:\Users\pc\AppData\Local\Programs\Python\Python313\Lib\site-packages\sqlalchemy\engine\base.py", line 1963, in _exec_single_context
    self.dialect.do_execute(
    ~~~~~~~~~~~~~~~~~~~~~~~^
        cursor, str_statement, effective_parameters, context
        ^^^^^^^^^^^^^^^^^^^^^^^^^^^^^^^^^^^^^^^^^^^^^^^^^^^^
    )
    ^
  File "C:\Users\pc\AppData\Local\Programs\Python\Python313\Lib\site-packages\sqlalchemy\engine\default.py", line 943, in do_execute
    cursor.execute(statement, parameters)
    ~~~~~~~~~~~~~~^^^^^^^^^^^^^^^^^^^^^^^
sqlite3.OperationalError: ambiguous column name: employees.id

The above exception was the direct cause of the following exception:

Traceback (most recent call last):
  File "C:\Users\pc\AppData\Local\Programs\Python\Python313\Lib\site-packages\uvicorn\protocols\http\h11_impl.py", line 403, in run_asgi
    result = await app(  # type: ignore[func-returns-value]
             ^^^^^^^^^^^^^^^^^^^^^^^^^^^^^^^^^^^^^^^^^^^^^^
        self.scope, self.receive, self.send
        ^^^^^^^^^^^^^^^^^^^^^^^^^^^^^^^^^^^
    )
    ^
  File "C:\Users\pc\AppData\Local\Programs\Python\Python313\Lib\site-packages\uvicorn\middleware\proxy_headers.py", line 60, in __call__
    return await self.app(scope, receive, send)
           ^^^^^^^^^^^^^^^^^^^^^^^^^^^^^^^^^^^^
  File "C:\Users\pc\AppData\Local\Programs\Python\Python313\Lib\site-packages\fastapi\applications.py", line 1054, in __call__
    await super().__call__(scope, receive, send)
  File "C:\Users\pc\AppData\Local\Programs\Python\Python313\Lib\site-packages\starlette\applications.py", line 112, in __call__
    await self.middleware_stack(scope, receive, send)
  File "C:\Users\pc\AppData\Local\Programs\Python\Python313\Lib\site-packages\starlette\middleware\errors.py", line 187, in __call__
    raise exc
  File "C:\Users\pc\AppData\Local\Programs\Python\Python313\Lib\site-packages\starlette\middleware\errors.py", line 165, in __call__
    await self.app(scope, receive, _send)
  File "C:\Users\pc\AppData\Local\Programs\Python\Python313\Lib\site-packages\starlette\middleware\cors.py", line 85, in __call__
    await self.app(scope, receive, send)
  File "C:\Users\pc\AppData\Local\Programs\Python\Python313\Lib\site-packages\starlette\middleware\exceptions.py", line 62, in __call__
    await wrap_app_handling_exceptions(self.app, conn)(scope, receive, send)
  File "C:\Users\pc\AppData\Local\Programs\Python\Python313\Lib\site-packages\starlette\_exception_handler.py", line 53, in wrapped_app
    raise exc
  File "C:\Users\pc\AppData\Local\Programs\Python\Python313\Lib\site-packages\starlette\_exception_handler.py", line 42, in wrapped_app
    await app(scope, receive, sender)
  File "C:\Users\pc\AppData\Local\Programs\Python\Python313\Lib\site-packages\starlette\routing.py", line 714, in __call__
    await self.middleware_stack(scope, receive, send)
  File "C:\Users\pc\AppData\Local\Programs\Python\Python313\Lib\site-packages\starlette\routing.py", line 734, in app
    await route.handle(scope, receive, send)
  File "C:\Users\pc\AppData\Local\Programs\Python\Python313\Lib\site-packages\starlette\routing.py", line 288, in handle
    await self.app(scope, receive, send)
  File "C:\Users\pc\AppData\Local\Programs\Python\Python313\Lib\site-packages\starlette\routing.py", line 76, in app
    await wrap_app_handling_exceptions(app, request)(scope, receive, send)
  File "C:\Users\pc\AppData\Local\Programs\Python\Python313\Lib\site-packages\starlette\_exception_handler.py", line 53, in wrapped_app
    raise exc
  File "C:\Users\pc\AppData\Local\Programs\Python\Python313\Lib\site-packages\starlette\_exception_handler.py", line 42, in wrapped_app
    await app(scope, receive, sender)
  File "C:\Users\pc\AppData\Local\Programs\Python\Python313\Lib\site-packages\starlette\routing.py", line 73, in app
    response = await f(request)
               ^^^^^^^^^^^^^^^^
  File "C:\Users\pc\AppData\Local\Programs\Python\Python313\Lib\site-packages\fastapi\routing.py", line 301, in app
    raw_response = await run_endpoint_function(
                   ^^^^^^^^^^^^^^^^^^^^^^^^^^^^
    ...<3 lines>...
    )
    ^
  File "C:\Users\pc\AppData\Local\Programs\Python\Python313\Lib\site-packages\fastapi\routing.py", line 214, in run_endpoint_function
    return await run_in_threadpool(dependant.call, **values)
           ^^^^^^^^^^^^^^^^^^^^^^^^^^^^^^^^^^^^^^^^^^^^^^^^^
  File "C:\Users\pc\AppData\Local\Programs\Python\Python313\Lib\site-packages\starlette\concurrency.py", line 37, in run_in_threadpool
    return await anyio.to_thread.run_sync(func)
           ^^^^^^^^^^^^^^^^^^^^^^^^^^^^^^^^^^^^
  File "C:\Users\pc\AppData\Local\Programs\Python\Python313\Lib\site-packages\anyio\to_thread.py", line 56, in run_sync
    return await get_async_backend().run_sync_in_worker_thread(
           ^^^^^^^^^^^^^^^^^^^^^^^^^^^^^^^^^^^^^^^^^^^^^^^^^^^^
        func, args, abandon_on_cancel=abandon_on_cancel, limiter=limiter
        ^^^^^^^^^^^^^^^^^^^^^^^^^^^^^^^^^^^^^^^^^^^^^^^^^^^^^^^^^^^^^^^^
    )
    ^
  File "C:\Users\pc\AppData\Local\Programs\Python\Python313\Lib\site-packages\anyio\_backends\_asyncio.py", line 2470, in run_sync_in_worker_thread
    return await future
           ^^^^^^^^^^^^
  File "C:\Users\pc\AppData\Local\Programs\Python\Python313\Lib\site-packages\anyio\_backends\_asyncio.py", line 967, in run
    result = context.run(func, *args)
  File "D:\Projects\Development\webcore-erp\webcore-erp\wcs-backend\app\routes\user.py", line 64, in get_users
    .all()
     ~~~^^
  File "C:\Users\pc\AppData\Local\Programs\Python\Python313\Lib\site-packages\sqlalchemy\orm\query.py", line 2704, in all
    return self._iter().all()  # type: ignore
           ~~~~~~~~~~^^
  File "C:\Users\pc\AppData\Local\Programs\Python\Python313\Lib\site-packages\sqlalchemy\orm\query.py", line 2857, in _iter
    result: Union[ScalarResult[_T], Result[_T]] = self.session.execute(
                                                  ~~~~~~~~~~~~~~~~~~~~^
        statement,
        ^^^^^^^^^^
        params,
        ^^^^^^^
        execution_options={"_sa_orm_load_options": self.load_options},
        ^^^^^^^^^^^^^^^^^^^^^^^^^^^^^^^^^^^^^^^^^^^^^^^^^^^^^^^^^^^^^^
    )
    ^
  File "C:\Users\pc\AppData\Local\Programs\Python\Python313\Lib\site-packages\sqlalchemy\orm\session.py", line 2365, in execute
    return self._execute_internal(
           ~~~~~~~~~~~~~~~~~~~~~~^
        statement,
        ^^^^^^^^^^
    ...<4 lines>...
        _add_event=_add_event,
        ^^^^^^^^^^^^^^^^^^^^^^
    )
    ^
  File "C:\Users\pc\AppData\Local\Programs\Python\Python313\Lib\site-packages\sqlalchemy\orm\session.py", line 2251, in _execute_internal
    result: Result[Any] = compile_state_cls.orm_execute_statement(
                          ~~~~~~~~~~~~~~~~~~~~~~~~~~~~~~~~~~~~~~~^
        self,
        ^^^^^
    ...<4 lines>...
        conn,
        ^^^^^
    )
    ^
  File "C:\Users\pc\AppData\Local\Programs\Python\Python313\Lib\site-packages\sqlalchemy\orm\context.py", line 306, in orm_execute_statement
    result = conn.execute(
        statement, params or {}, execution_options=execution_options
    )
  File "C:\Users\pc\AppData\Local\Programs\Python\Python313\Lib\site-packages\sqlalchemy\engine\base.py", line 1415, in execute
    return meth(
        self,
        distilled_parameters,
        execution_options or NO_OPTIONS,
    )
  File "C:\Users\pc\AppData\Local\Programs\Python\Python313\Lib\site-packages\sqlalchemy\sql\elements.py", line 523, in _execute_on_connection
    return connection._execute_clauseelement(
           ~~~~~~~~~~~~~~~~~~~~~~~~~~~~~~~~~^
        self, distilled_params, execution_options
        ^^^^^^^^^^^^^^^^^^^^^^^^^^^^^^^^^^^^^^^^^
    )
    ^
  File "C:\Users\pc\AppData\Local\Programs\Python\Python313\Lib\site-packages\sqlalchemy\engine\base.py", line 1637, in _execute_clauseelement
    ret = self._execute_context(
        dialect,
    ...<8 lines>...
        cache_hit=cache_hit,
    )
  File "C:\Users\pc\AppData\Local\Programs\Python\Python313\Lib\site-packages\sqlalchemy\engine\base.py", line 1842, in _execute_context
    return self._exec_single_context(
           ~~~~~~~~~~~~~~~~~~~~~~~~~^
        dialect, context, statement, parameters
        ^^^^^^^^^^^^^^^^^^^^^^^^^^^^^^^^^^^^^^^
    )
    ^
  File "C:\Users\pc\AppData\Local\Programs\Python\Python313\Lib\site-packages\sqlalchemy\engine\base.py", line 1982, in _exec_single_context
    self._handle_dbapi_exception(
    ~~~~~~~~~~~~~~~~~~~~~~~~~~~~^
        e, str_statement, effective_parameters, cursor, context
        ^^^^^^^^^^^^^^^^^^^^^^^^^^^^^^^^^^^^^^^^^^^^^^^^^^^^^^^
    )
    ^
  File "C:\Users\pc\AppData\Local\Programs\Python\Python313\Lib\site-packages\sqlalchemy\engine\base.py", line 2351, in _handle_dbapi_exception
    raise sqlalchemy_exception.with_traceback(exc_info[2]) from e
  File "C:\Users\pc\AppData\Local\Programs\Python\Python313\Lib\site-packages\sqlalchemy\engine\base.py", line 1963, in _exec_single_context
    self.dialect.do_execute(
    ~~~~~~~~~~~~~~~~~~~~~~~^
        cursor, str_statement, effective_parameters, context
        ^^^^^^^^^^^^^^^^^^^^^^^^^^^^^^^^^^^^^^^^^^^^^^^^^^^^
    )
    ^
  File "C:\Users\pc\AppData\Local\Programs\Python\Python313\Lib\site-packages\sqlalchemy\engine\default.py", line 943, in do_execute
    cursor.execute(statement, parameters)
    ~~~~~~~~~~~~~~^^^^^^^^^^^^^^^^^^^^^^^
sqlalchemy.exc.OperationalError: (sqlite3.OperationalError) ambiguous column name: employees.id
[SQL: SELECT users.id AS users_id, users.username AS users_username, users.hashed_password AS users_hashed_password, users.employee_id AS users_employee_id, users.is_active AS users_is_active, users.is_first_time_user AS users_is_first_time_user, users.is_deleted AS users_is_deleted, employees.id AS employees_id, employees.user_id AS employees_user_id, employees.first_name AS employees_first_name, employees.middle_name AS employees_middle_name, employees.last_name AS employees_last_name, employees.date_of_joining AS employees_date_of_joining, employees.email AS employees_email, employees.ro_id AS employees_ro_id, employees.role_id AS employees_role_id, employees.department_id AS employees_department_id, employees.status AS employees_status, employees.is_deleted AS employees_is_deleted, roles.id AS roles_id, roles.name AS roles_name, roles.is_deleted AS roles_is_deleted 
FROM users JOIN employees ON users.employee_id = employees.id JOIN employees ON employees.role_id = roles.id, roles 
WHERE users.is_deleted = 0]
(Background on this error at: https://sqlalche.me/e/20/e3q8)
[2025-06-24 14:05:11,767] [INFO] uvicorn.error: Shutting down
[2025-06-24 14:05:11,889] [INFO] uvicorn.error: Waiting for application shutdown.
[2025-06-24 14:05:11,890] [INFO] uvicorn.error: Application shutdown complete.
[2025-06-24 14:05:11,891] [INFO] uvicorn.error: Finished server process [13992]
[2025-06-24 14:05:17,163] [INFO] uvicorn.error: Started server process [11040]
[2025-06-24 14:05:17,164] [INFO] uvicorn.error: Waiting for application startup.
[2025-06-24 14:05:17,178] [INFO] uvicorn.error: Application startup complete.
[2025-06-24 14:05:17,180] [INFO] uvicorn.error: Uvicorn running on http://127.0.0.1:8000 (Press CTRL+C to quit)
[2025-06-24 14:05:17,365] [ERROR] uvicorn.error: Exception in ASGI application
Traceback (most recent call last):
  File "C:\Users\pc\AppData\Local\Programs\Python\Python313\Lib\site-packages\uvicorn\protocols\http\h11_impl.py", line 403, in run_asgi
    result = await app(  # type: ignore[func-returns-value]
             ^^^^^^^^^^^^^^^^^^^^^^^^^^^^^^^^^^^^^^^^^^^^^^
        self.scope, self.receive, self.send
        ^^^^^^^^^^^^^^^^^^^^^^^^^^^^^^^^^^^
    )
    ^
  File "C:\Users\pc\AppData\Local\Programs\Python\Python313\Lib\site-packages\uvicorn\middleware\proxy_headers.py", line 60, in __call__
    return await self.app(scope, receive, send)
           ^^^^^^^^^^^^^^^^^^^^^^^^^^^^^^^^^^^^
  File "C:\Users\pc\AppData\Local\Programs\Python\Python313\Lib\site-packages\fastapi\applications.py", line 1054, in __call__
    await super().__call__(scope, receive, send)
  File "C:\Users\pc\AppData\Local\Programs\Python\Python313\Lib\site-packages\starlette\applications.py", line 112, in __call__
    await self.middleware_stack(scope, receive, send)
  File "C:\Users\pc\AppData\Local\Programs\Python\Python313\Lib\site-packages\starlette\middleware\errors.py", line 187, in __call__
    raise exc
  File "C:\Users\pc\AppData\Local\Programs\Python\Python313\Lib\site-packages\starlette\middleware\errors.py", line 165, in __call__
    await self.app(scope, receive, _send)
  File "C:\Users\pc\AppData\Local\Programs\Python\Python313\Lib\site-packages\starlette\middleware\cors.py", line 85, in __call__
    await self.app(scope, receive, send)
  File "C:\Users\pc\AppData\Local\Programs\Python\Python313\Lib\site-packages\starlette\middleware\exceptions.py", line 62, in __call__
    await wrap_app_handling_exceptions(self.app, conn)(scope, receive, send)
  File "C:\Users\pc\AppData\Local\Programs\Python\Python313\Lib\site-packages\starlette\_exception_handler.py", line 53, in wrapped_app
    raise exc
  File "C:\Users\pc\AppData\Local\Programs\Python\Python313\Lib\site-packages\starlette\_exception_handler.py", line 42, in wrapped_app
    await app(scope, receive, sender)
  File "C:\Users\pc\AppData\Local\Programs\Python\Python313\Lib\site-packages\starlette\routing.py", line 714, in __call__
    await self.middleware_stack(scope, receive, send)
  File "C:\Users\pc\AppData\Local\Programs\Python\Python313\Lib\site-packages\starlette\routing.py", line 734, in app
    await route.handle(scope, receive, send)
  File "C:\Users\pc\AppData\Local\Programs\Python\Python313\Lib\site-packages\starlette\routing.py", line 288, in handle
    await self.app(scope, receive, send)
  File "C:\Users\pc\AppData\Local\Programs\Python\Python313\Lib\site-packages\starlette\routing.py", line 76, in app
    await wrap_app_handling_exceptions(app, request)(scope, receive, send)
  File "C:\Users\pc\AppData\Local\Programs\Python\Python313\Lib\site-packages\starlette\_exception_handler.py", line 53, in wrapped_app
    raise exc
  File "C:\Users\pc\AppData\Local\Programs\Python\Python313\Lib\site-packages\starlette\_exception_handler.py", line 42, in wrapped_app
    await app(scope, receive, sender)
  File "C:\Users\pc\AppData\Local\Programs\Python\Python313\Lib\site-packages\starlette\routing.py", line 73, in app
    response = await f(request)
               ^^^^^^^^^^^^^^^^
  File "C:\Users\pc\AppData\Local\Programs\Python\Python313\Lib\site-packages\fastapi\routing.py", line 327, in app
    content = await serialize_response(
              ^^^^^^^^^^^^^^^^^^^^^^^^^
    ...<9 lines>...
    )
    ^
  File "C:\Users\pc\AppData\Local\Programs\Python\Python313\Lib\site-packages\fastapi\routing.py", line 176, in serialize_response
    raise ResponseValidationError(
        errors=_normalize_errors(errors), body=response_content
    )
fastapi.exceptions.ResponseValidationError: 2 validation errors:
  {'type': 'missing', 'loc': ('response', 0, 'employee_id'), 'msg': 'Field required', 'input': {'id': 1, 'username': 'admin', 'employee_name': 'Amit Kumar Sharma', 'is_active': True, 'role_name': 'Admin'}}
  {'type': 'missing', 'loc': ('response', 1, 'employee_id'), 'msg': 'Field required', 'input': {'id': 2, 'username': 'hr', 'employee_name': 'Priya Rani Verma', 'is_active': True, 'role_name': 'HR'}}

[2025-06-24 14:07:38,616] [INFO] uvicorn.error: Shutting down
[2025-06-24 14:07:38,718] [INFO] uvicorn.error: Waiting for application shutdown.
[2025-06-24 14:07:38,719] [INFO] uvicorn.error: Application shutdown complete.
[2025-06-24 14:07:38,720] [INFO] uvicorn.error: Finished server process [11040]
[2025-06-24 14:07:43,836] [INFO] uvicorn.error: Started server process [12224]
[2025-06-24 14:07:43,837] [INFO] uvicorn.error: Waiting for application startup.
[2025-06-24 14:07:43,849] [INFO] uvicorn.error: Application startup complete.
[2025-06-24 14:07:43,851] [INFO] uvicorn.error: Uvicorn running on http://127.0.0.1:8000 (Press CTRL+C to quit)
[2025-06-24 14:12:56,591] [INFO] app.routes.auth: employee found: <app.models.employee.Employee object at 0x0000011D5E0062D0>
[2025-06-24 14:18:01,265] [INFO] app.routes.auth: employee found: <app.models.employee.Employee object at 0x0000011D5E005250>
[2025-06-24 14:24:36,127] [INFO] uvicorn.error: Shutting down
[2025-06-24 14:24:36,230] [INFO] uvicorn.error: Waiting for application shutdown.
[2025-06-24 14:24:36,231] [INFO] uvicorn.error: Application shutdown complete.
[2025-06-24 14:24:36,233] [INFO] uvicorn.error: Finished server process [12224]
[2025-06-24 14:24:46,022] [INFO] uvicorn.error: Started server process [14180]
[2025-06-24 14:24:46,024] [INFO] uvicorn.error: Waiting for application startup.
[2025-06-24 14:24:46,038] [INFO] uvicorn.error: Application startup complete.
[2025-06-24 14:24:46,041] [INFO] uvicorn.error: Uvicorn running on http://127.0.0.1:8000 (Press CTRL+C to quit)
[2025-06-24 14:33:39,905] [INFO] uvicorn.error: Shutting down
[2025-06-24 14:33:40,007] [INFO] uvicorn.error: Waiting for application shutdown.
[2025-06-24 14:33:40,008] [INFO] uvicorn.error: Application shutdown complete.
[2025-06-24 14:33:40,008] [INFO] uvicorn.error: Finished server process [14180]
[2025-06-24 14:34:40,560] [INFO] uvicorn.error: Started server process [14316]
[2025-06-24 14:34:40,560] [INFO] uvicorn.error: Waiting for application startup.
[2025-06-24 14:34:40,567] [INFO] uvicorn.error: Application startup complete.
[2025-06-24 14:34:40,568] [INFO] uvicorn.error: Uvicorn running on http://127.0.0.1:8000 (Press CTRL+C to quit)
[2025-06-24 14:35:41,877] [INFO] app.routes.auth: employee found: <app.models.employee.Employee object at 0x000002459B4457B0>
[2025-06-24 14:38:36,965] [INFO] app.routes.user: Calling create_user
[2025-06-24 14:38:37,229] [INFO] app.routes.user: Creating user 3_rahul Employee ID: 3 
[2025-06-24 14:38:37,245] [ERROR] uvicorn.error: Exception in ASGI application
Traceback (most recent call last):
  File "C:\Users\pc\AppData\Local\Programs\Python\Python313\Lib\site-packages\uvicorn\protocols\http\h11_impl.py", line 403, in run_asgi
    result = await app(  # type: ignore[func-returns-value]
             ^^^^^^^^^^^^^^^^^^^^^^^^^^^^^^^^^^^^^^^^^^^^^^
        self.scope, self.receive, self.send
        ^^^^^^^^^^^^^^^^^^^^^^^^^^^^^^^^^^^
    )
    ^
  File "C:\Users\pc\AppData\Local\Programs\Python\Python313\Lib\site-packages\uvicorn\middleware\proxy_headers.py", line 60, in __call__
    return await self.app(scope, receive, send)
           ^^^^^^^^^^^^^^^^^^^^^^^^^^^^^^^^^^^^
  File "C:\Users\pc\AppData\Local\Programs\Python\Python313\Lib\site-packages\fastapi\applications.py", line 1054, in __call__
    await super().__call__(scope, receive, send)
  File "C:\Users\pc\AppData\Local\Programs\Python\Python313\Lib\site-packages\starlette\applications.py", line 112, in __call__
    await self.middleware_stack(scope, receive, send)
  File "C:\Users\pc\AppData\Local\Programs\Python\Python313\Lib\site-packages\starlette\middleware\errors.py", line 187, in __call__
    raise exc
  File "C:\Users\pc\AppData\Local\Programs\Python\Python313\Lib\site-packages\starlette\middleware\errors.py", line 165, in __call__
    await self.app(scope, receive, _send)
  File "C:\Users\pc\AppData\Local\Programs\Python\Python313\Lib\site-packages\starlette\middleware\cors.py", line 93, in __call__
    await self.simple_response(scope, receive, send, request_headers=headers)
  File "C:\Users\pc\AppData\Local\Programs\Python\Python313\Lib\site-packages\starlette\middleware\cors.py", line 144, in simple_response
    await self.app(scope, receive, send)
  File "C:\Users\pc\AppData\Local\Programs\Python\Python313\Lib\site-packages\starlette\middleware\exceptions.py", line 62, in __call__
    await wrap_app_handling_exceptions(self.app, conn)(scope, receive, send)
  File "C:\Users\pc\AppData\Local\Programs\Python\Python313\Lib\site-packages\starlette\_exception_handler.py", line 53, in wrapped_app
    raise exc
  File "C:\Users\pc\AppData\Local\Programs\Python\Python313\Lib\site-packages\starlette\_exception_handler.py", line 42, in wrapped_app
    await app(scope, receive, sender)
  File "C:\Users\pc\AppData\Local\Programs\Python\Python313\Lib\site-packages\starlette\routing.py", line 714, in __call__
    await self.middleware_stack(scope, receive, send)
  File "C:\Users\pc\AppData\Local\Programs\Python\Python313\Lib\site-packages\starlette\routing.py", line 734, in app
    await route.handle(scope, receive, send)
  File "C:\Users\pc\AppData\Local\Programs\Python\Python313\Lib\site-packages\starlette\routing.py", line 288, in handle
    await self.app(scope, receive, send)
  File "C:\Users\pc\AppData\Local\Programs\Python\Python313\Lib\site-packages\starlette\routing.py", line 76, in app
    await wrap_app_handling_exceptions(app, request)(scope, receive, send)
  File "C:\Users\pc\AppData\Local\Programs\Python\Python313\Lib\site-packages\starlette\_exception_handler.py", line 53, in wrapped_app
    raise exc
  File "C:\Users\pc\AppData\Local\Programs\Python\Python313\Lib\site-packages\starlette\_exception_handler.py", line 42, in wrapped_app
    await app(scope, receive, sender)
  File "C:\Users\pc\AppData\Local\Programs\Python\Python313\Lib\site-packages\starlette\routing.py", line 73, in app
    response = await f(request)
               ^^^^^^^^^^^^^^^^
  File "C:\Users\pc\AppData\Local\Programs\Python\Python313\Lib\site-packages\fastapi\routing.py", line 301, in app
    raw_response = await run_endpoint_function(
                   ^^^^^^^^^^^^^^^^^^^^^^^^^^^^
    ...<3 lines>...
    )
    ^
  File "C:\Users\pc\AppData\Local\Programs\Python\Python313\Lib\site-packages\fastapi\routing.py", line 214, in run_endpoint_function
    return await run_in_threadpool(dependant.call, **values)
           ^^^^^^^^^^^^^^^^^^^^^^^^^^^^^^^^^^^^^^^^^^^^^^^^^
  File "C:\Users\pc\AppData\Local\Programs\Python\Python313\Lib\site-packages\starlette\concurrency.py", line 37, in run_in_threadpool
    return await anyio.to_thread.run_sync(func)
           ^^^^^^^^^^^^^^^^^^^^^^^^^^^^^^^^^^^^
  File "C:\Users\pc\AppData\Local\Programs\Python\Python313\Lib\site-packages\anyio\to_thread.py", line 56, in run_sync
    return await get_async_backend().run_sync_in_worker_thread(
           ^^^^^^^^^^^^^^^^^^^^^^^^^^^^^^^^^^^^^^^^^^^^^^^^^^^^
        func, args, abandon_on_cancel=abandon_on_cancel, limiter=limiter
        ^^^^^^^^^^^^^^^^^^^^^^^^^^^^^^^^^^^^^^^^^^^^^^^^^^^^^^^^^^^^^^^^
    )
    ^
  File "C:\Users\pc\AppData\Local\Programs\Python\Python313\Lib\site-packages\anyio\_backends\_asyncio.py", line 2470, in run_sync_in_worker_thread
    return await future
           ^^^^^^^^^^^^
  File "C:\Users\pc\AppData\Local\Programs\Python\Python313\Lib\site-packages\anyio\_backends\_asyncio.py", line 967, in run
    result = context.run(func, *args)
  File "D:\Projects\Development\webcore-erp\webcore-erp\wcs-backend\app\routes\user.py", line 109, in create_user
    return UserOut(
        id=new_user.id,
    ...<3 lines>...
        employee_name=full_name.strip()
    )
  File "C:\Users\pc\AppData\Local\Programs\Python\Python313\Lib\site-packages\pydantic\main.py", line 253, in __init__
    validated_self = self.__pydantic_validator__.validate_python(data, self_instance=self)
pydantic_core._pydantic_core.ValidationError: 1 validation error for UserOut
role_name
  Field required [type=missing, input_value={'id': 3, 'username': '3_...e': 'Rahul Singh Yadav'}, input_type=dict]
    For further information visit https://errors.pydantic.dev/2.11/v/missing
[2025-06-24 14:38:42,080] [INFO] app.routes.user: Calling create_user
[2025-06-24 14:38:57,928] [INFO] app.routes.user: Calling create_user
[2025-06-24 14:39:58,828] [INFO] uvicorn.error: Shutting down
[2025-06-24 14:39:58,943] [INFO] uvicorn.error: Waiting for application shutdown.
[2025-06-24 14:39:58,943] [INFO] uvicorn.error: Application shutdown complete.
[2025-06-24 14:39:58,944] [INFO] uvicorn.error: Finished server process [14316]
