dsfds[2025-06-23 06:35:19,377] [INFO] uvicorn.error: Shutting down
[2025-06-23 06:35:19,492] [INFO] uvicorn.error: Waiting for application shutdown.
[2025-06-23 06:35:19,493] [INFO] uvicorn.error: Application shutdown complete.
[2025-06-23 06:35:19,493] [INFO] uvicorn.error: Finished server process [5548]
[2025-06-23 07:24:36,987] [INFO] uvicorn.error: Started server process [12712]
[2025-06-23 07:24:36,988] [INFO] uvicorn.error: Waiting for application startup.
[2025-06-23 07:24:36,989] [INFO] uvicorn.error: Application startup complete.
[2025-06-23 07:24:36,990] [INFO] uvicorn.error: Uvicorn running on http://127.0.0.1:8000 (Press CTRL+C to quit)
[2025-06-23 10:04:43,585] [INFO] app.routes.auth: User found: <app.models.user.User object at 0x000002B54EB61D30>
[2025-06-23 10:04:44,178] [INFO] app.routes.auth: employee found: <app.models.employee.Employee object at 0x000002B54EB61940>
[2025-06-23 10:36:57,161] [INFO] app.routes.auth: User found: <app.models.user.User object at 0x000002B54EBF5BD0>
[2025-06-23 10:36:57,449] [INFO] app.routes.auth: employee found: <app.models.employee.Employee object at 0x000002B54EBF51D0>
[2025-06-23 10:44:03,619] [INFO] uvicorn.error: Shutting down
[2025-06-23 10:44:03,731] [INFO] uvicorn.error: Waiting for application shutdown.
[2025-06-23 10:44:03,731] [INFO] uvicorn.error: Application shutdown complete.
[2025-06-23 10:44:03,732] [INFO] uvicorn.error: Finished server process [12712]
[2025-06-23 10:44:19,478] [INFO] uvicorn.error: Started server process [13784]
[2025-06-23 10:44:19,479] [INFO] uvicorn.error: Waiting for application startup.
[2025-06-23 10:44:19,480] [INFO] uvicorn.error: Application startup complete.
[2025-06-23 10:44:19,481] [INFO] uvicorn.error: Uvicorn running on http://127.0.0.1:8000 (Press CTRL+C to quit)
[2025-06-23 10:44:34,581] [INFO] app.routes.auth: Request.username: admin
[2025-06-23 10:44:34,614] [INFO] app.routes.auth: User found: None
[2025-06-23 10:45:36,526] [INFO] app.routes.auth: Request.username: admin
[2025-06-23 10:45:36,528] [INFO] app.routes.auth: User found: None
[2025-06-23 10:46:28,024] [INFO] uvicorn.error: Shutting down
[2025-06-23 10:46:28,137] [INFO] uvicorn.error: Waiting for application shutdown.
[2025-06-23 10:46:28,137] [INFO] uvicorn.error: Application shutdown complete.
[2025-06-23 10:46:28,138] [INFO] uvicorn.error: Finished server process [13784]
[2025-06-23 10:46:37,221] [INFO] uvicorn.error: Started server process [1012]
[2025-06-23 10:46:37,221] [INFO] uvicorn.error: Waiting for application startup.
[2025-06-23 10:46:37,222] [INFO] uvicorn.error: Application startup complete.
[2025-06-23 10:46:37,224] [INFO] uvicorn.error: Uvicorn running on http://127.0.0.1:8000 (Press CTRL+C to quit)
[2025-06-23 10:46:53,363] [INFO] app.routes.auth: Request.username: admin
[2025-06-23 10:46:53,402] [INFO] app.routes.auth: User found: None
[2025-06-23 10:48:03,646] [INFO] uvicorn.error: Shutting down
[2025-06-23 10:48:03,757] [INFO] uvicorn.error: Waiting for application shutdown.
[2025-06-23 10:48:03,758] [INFO] uvicorn.error: Application shutdown complete.
[2025-06-23 10:48:03,759] [INFO] uvicorn.error: Finished server process [1012]
[2025-06-23 10:48:07,083] [INFO] uvicorn.error: Started server process [6560]
[2025-06-23 10:48:07,083] [INFO] uvicorn.error: Waiting for application startup.
[2025-06-23 10:48:07,084] [INFO] uvicorn.error: Application startup complete.
[2025-06-23 10:48:07,085] [INFO] uvicorn.error: Uvicorn running on http://127.0.0.1:8000 (Press CTRL+C to quit)
[2025-06-23 10:48:13,064] [INFO] app.routes.auth: Request.username: admin
[2025-06-23 10:48:13,096] [WARNING] app.routes.auth: User not found or database is empty
[2025-06-23 10:48:31,212] [INFO] app.routes.auth: Request.username: admin
[2025-06-23 10:48:31,215] [WARNING] app.routes.auth: User not found or database is empty
[2025-06-23 10:48:33,678] [INFO] uvicorn.error: Shutting down
[2025-06-23 10:48:33,779] [INFO] uvicorn.error: Waiting for application shutdown.
[2025-06-23 10:48:33,780] [INFO] uvicorn.error: Application shutdown complete.
[2025-06-23 10:48:33,780] [INFO] uvicorn.error: Finished server process [6560]
[2025-06-23 10:48:36,842] [INFO] uvicorn.error: Started server process [15484]
[2025-06-23 10:48:36,842] [INFO] uvicorn.error: Waiting for application startup.
[2025-06-23 10:48:36,843] [INFO] uvicorn.error: Application startup complete.
[2025-06-23 10:48:36,844] [INFO] uvicorn.error: Uvicorn running on http://127.0.0.1:8000 (Press CTRL+C to quit)
[2025-06-23 10:48:37,523] [INFO] app.routes.auth: Request.username: admin
[2025-06-23 10:48:37,556] [WARNING] app.routes.auth: User not found or database is empty
[2025-06-23 10:49:25,610] [INFO] uvicorn.error: Shutting down
[2025-06-23 10:49:25,718] [INFO] uvicorn.error: Waiting for application shutdown.
[2025-06-23 10:49:25,719] [INFO] uvicorn.error: Application shutdown complete.
[2025-06-23 10:49:25,719] [INFO] uvicorn.error: Finished server process [15484]
[2025-06-23 10:50:10,533] [INFO] uvicorn.error: Started server process [6368]
[2025-06-23 10:50:10,533] [INFO] uvicorn.error: Waiting for application startup.
[2025-06-23 10:50:10,534] [INFO] uvicorn.error: Application startup complete.
[2025-06-23 10:50:10,535] [INFO] uvicorn.error: Uvicorn running on http://127.0.0.1:8000 (Press CTRL+C to quit)
[2025-06-23 10:50:14,492] [INFO] app.routes.auth: Request.username: admin
[2025-06-23 10:50:14,525] [WARNING] app.routes.auth: User not found or database is empty
[2025-06-23 10:51:19,597] [INFO] uvicorn.error: Shutting down
[2025-06-23 10:51:19,712] [INFO] uvicorn.error: Waiting for application shutdown.
[2025-06-23 10:51:19,713] [INFO] uvicorn.error: Application shutdown complete.
[2025-06-23 10:51:19,714] [INFO] uvicorn.error: Finished server process [6368]
[2025-06-23 10:51:23,289] [INFO] uvicorn.error: Started server process [1500]
[2025-06-23 10:51:23,289] [INFO] uvicorn.error: Waiting for application startup.
[2025-06-23 10:51:23,290] [INFO] uvicorn.error: Application startup complete.
[2025-06-23 10:51:23,291] [INFO] uvicorn.error: Uvicorn running on http://127.0.0.1:8000 (Press CTRL+C to quit)
[2025-06-23 10:51:27,370] [INFO] app.routes.auth: Request.username: admin
[2025-06-23 10:51:27,399] [WARNING] app.routes.auth: User not found or database is empty
[2025-06-23 10:51:55,393] [INFO] uvicorn.error: Shutting down
[2025-06-23 10:51:55,495] [INFO] uvicorn.error: Waiting for application shutdown.
[2025-06-23 10:51:55,496] [INFO] uvicorn.error: Application shutdown complete.
[2025-06-23 10:51:55,496] [INFO] uvicorn.error: Finished server process [1500]
[2025-06-23 10:51:58,738] [INFO] uvicorn.error: Started server process [12732]
[2025-06-23 10:51:58,739] [INFO] uvicorn.error: Waiting for application startup.
[2025-06-23 10:51:58,740] [INFO] uvicorn.error: Application startup complete.
[2025-06-23 10:51:58,741] [INFO] uvicorn.error: Uvicorn running on http://127.0.0.1:8000 (Press CTRL+C to quit)
[2025-06-23 10:51:59,455] [INFO] app.database: SQLALCHEMY_DATABASE_URL found: sqlite:///D:\Projects\Development\webcore-erp\webcore-erp\wcs-backend\app\..\erp.db
[2025-06-23 10:51:59,458] [INFO] app.routes.auth: Request.username: admin
[2025-06-23 10:51:59,485] [WARNING] app.routes.auth: User not found or database is empty
[2025-06-23 10:53:22,026] [INFO] uvicorn.error: Shutting down
[2025-06-23 10:53:22,136] [INFO] uvicorn.error: Waiting for application shutdown.
[2025-06-23 10:53:22,137] [INFO] uvicorn.error: Application shutdown complete.
[2025-06-23 10:53:22,137] [INFO] uvicorn.error: Finished server process [12732]
[2025-06-23 11:20:21,617] [INFO] uvicorn.error: Started server process [15616]
[2025-06-23 11:20:21,618] [INFO] uvicorn.error: Waiting for application startup.
[2025-06-23 11:20:21,619] [INFO] uvicorn.error: Application startup complete.
[2025-06-23 11:20:21,620] [INFO] uvicorn.error: Uvicorn running on http://127.0.0.1:8000 (Press CTRL+C to quit)
[2025-06-23 11:20:31,640] [INFO] app.routes.auth: Request.username: string
[2025-06-23 11:20:31,673] [WARNING] app.routes.auth: User not found or database is empty
[2025-06-23 11:20:51,769] [INFO] uvicorn.error: Shutting down
[2025-06-23 11:20:51,871] [INFO] uvicorn.error: Waiting for application shutdown.
[2025-06-23 11:20:51,872] [INFO] uvicorn.error: Application shutdown complete.
[2025-06-23 11:20:51,873] [INFO] uvicorn.error: Finished server process [15616]
[2025-06-23 11:21:04,175] [INFO] uvicorn.error: Started server process [4896]
[2025-06-23 11:21:04,176] [INFO] uvicorn.error: Waiting for application startup.
[2025-06-23 11:21:04,176] [INFO] uvicorn.error: Application startup complete.
[2025-06-23 11:21:04,177] [INFO] uvicorn.error: Uvicorn running on http://127.0.0.1:8000 (Press CTRL+C to quit)
[2025-06-23 11:21:09,534] [INFO] app.routes.auth: Request.username: string
[2025-06-23 11:21:09,563] [WARNING] app.routes.auth: User not found or database is empty
[2025-06-23 11:21:48,914] [INFO] app.routes.auth: Request.username: string
[2025-06-23 11:21:48,916] [WARNING] app.routes.auth: User not found or database is empty
[2025-06-23 11:22:15,442] [INFO] app.routes.auth: Request.username: admin
[2025-06-23 11:22:15,444] [INFO] app.routes.auth: User found: <app.models.user.User object at 0x00000291E2F33CB0>
[2025-06-23 11:22:33,634] [INFO] app.routes.auth: Request.username: admin
[2025-06-23 11:22:33,636] [INFO] app.routes.auth: User found: <app.models.user.User object at 0x00000291E309D310>
[2025-06-23 11:22:33,945] [INFO] app.routes.auth: employee found: <app.models.employee.Employee object at 0x00000291E3024C20>
[2025-06-23 11:22:54,771] [INFO] uvicorn.error: Shutting down
[2025-06-23 11:22:54,881] [INFO] uvicorn.error: Waiting for application shutdown.
[2025-06-23 11:22:54,882] [INFO] uvicorn.error: Application shutdown complete.
[2025-06-23 11:22:54,883] [INFO] uvicorn.error: Finished server process [4896]
[2025-06-23 11:23:01,388] [INFO] uvicorn.error: Started server process [10260]
[2025-06-23 11:23:01,389] [INFO] uvicorn.error: Waiting for application startup.
[2025-06-23 11:23:01,389] [INFO] uvicorn.error: Application startup complete.
[2025-06-23 11:23:01,390] [INFO] uvicorn.error: Uvicorn running on http://127.0.0.1:8000 (Press CTRL+C to quit)
[2025-06-23 11:23:06,767] [INFO] app.routes.auth: Request.username: admin
[2025-06-23 11:23:06,794] [WARNING] app.routes.auth: User not found or database is empty
[2025-06-23 11:23:19,050] [INFO] uvicorn.error: Shutting down
[2025-06-23 11:23:19,158] [INFO] uvicorn.error: Waiting for application shutdown.
[2025-06-23 11:23:19,159] [INFO] uvicorn.error: Application shutdown complete.
[2025-06-23 11:23:19,159] [INFO] uvicorn.error: Finished server process [10260]
[2025-06-23 11:24:15,495] [INFO] uvicorn.error: Started server process [12280]
[2025-06-23 11:24:15,496] [INFO] uvicorn.error: Waiting for application startup.
[2025-06-23 11:24:15,497] [INFO] uvicorn.error: Application startup complete.
[2025-06-23 11:24:15,497] [INFO] uvicorn.error: Uvicorn running on http://127.0.0.1:8000 (Press CTRL+C to quit)
[2025-06-23 11:24:22,458] [INFO] app.routes.auth: Request.username: admin
[2025-06-23 11:24:22,489] [WARNING] app.routes.auth: User not found or database is empty
[2025-06-23 11:26:49,264] [INFO] uvicorn.error: Shutting down
[2025-06-23 11:26:49,366] [INFO] uvicorn.error: Waiting for application shutdown.
[2025-06-23 11:26:49,367] [INFO] uvicorn.error: Application shutdown complete.
[2025-06-23 11:26:49,367] [INFO] uvicorn.error: Finished server process [12280]
[2025-06-23 11:26:52,509] [INFO] uvicorn.error: Started server process [11152]
[2025-06-23 11:26:52,509] [INFO] uvicorn.error: Waiting for application startup.
[2025-06-23 11:26:52,510] [INFO] uvicorn.error: Application startup complete.
[2025-06-23 11:26:52,511] [INFO] uvicorn.error: Uvicorn running on http://127.0.0.1:8000 (Press CTRL+C to quit)
[2025-06-23 11:26:59,603] [INFO] app.routes.auth: Request.username: admin
[2025-06-23 11:26:59,622] [WARNING] app.routes.auth: User  found
[2025-06-23 11:26:59,630] [WARNING] app.routes.auth: User not found or database is empty
[2025-06-23 11:27:31,893] [INFO] uvicorn.error: Shutting down
[2025-06-23 11:27:32,006] [INFO] uvicorn.error: Waiting for application shutdown.
[2025-06-23 11:27:32,007] [INFO] uvicorn.error: Application shutdown complete.
[2025-06-23 11:27:32,008] [INFO] uvicorn.error: Finished server process [11152]
[2025-06-23 11:28:42,320] [INFO] uvicorn.error: Started server process [13920]
[2025-06-23 11:28:42,320] [INFO] uvicorn.error: Waiting for application startup.
[2025-06-23 11:28:42,321] [INFO] uvicorn.error: Application startup complete.
[2025-06-23 11:28:42,322] [INFO] uvicorn.error: Uvicorn running on http://127.0.0.1:8000 (Press CTRL+C to quit)
[2025-06-23 11:28:45,913] [INFO] app.routes.auth: Request.username: admin
[2025-06-23 11:28:45,939] [WARNING] app.routes.auth: User  found
[2025-06-23 11:28:45,944] [WARNING] app.routes.auth: User not found or database is empty
[2025-06-23 11:30:45,193] [INFO] uvicorn.error: Shutting down
[2025-06-23 11:30:45,296] [INFO] uvicorn.error: Waiting for application shutdown.
[2025-06-23 11:30:45,297] [INFO] uvicorn.error: Application shutdown complete.
[2025-06-23 11:30:45,297] [INFO] uvicorn.error: Finished server process [13920]
[2025-06-23 11:30:49,050] [INFO] uvicorn.error: Started server process [15832]
[2025-06-23 11:30:49,051] [INFO] uvicorn.error: Waiting for application startup.
[2025-06-23 11:30:49,052] [INFO] uvicorn.error: Application startup complete.
[2025-06-23 11:30:49,053] [INFO] uvicorn.error: Uvicorn running on http://127.0.0.1:8000 (Press CTRL+C to quit)
[2025-06-23 11:30:52,505] [INFO] app.routes.auth: Request.username: admin
[2025-06-23 11:30:52,537] [ERROR] uvicorn.error: Exception in ASGI application
Traceback (most recent call last):
  File "C:\Users\pc\AppData\Local\Programs\Python\Python313\Lib\site-packages\uvicorn\protocols\http\h11_impl.py", line 403, in run_asgi
    result = await app(  # type: ignore[func-returns-value]
             ^^^^^^^^^^^^^^^^^^^^^^^^^^^^^^^^^^^^^^^^^^^^^^
        self.scope, self.receive, self.send
        ^^^^^^^^^^^^^^^^^^^^^^^^^^^^^^^^^^^
    )
    ^
  File "C:\Users\pc\AppData\Local\Programs\Python\Python313\Lib\site-packages\uvicorn\middleware\proxy_headers.py", line 60, in __call__
    return await self.app(scope, receive, send)
           ^^^^^^^^^^^^^^^^^^^^^^^^^^^^^^^^^^^^
  File "C:\Users\pc\AppData\Local\Programs\Python\Python313\Lib\site-packages\fastapi\applications.py", line 1054, in __call__
    await super().__call__(scope, receive, send)
  File "C:\Users\pc\AppData\Local\Programs\Python\Python313\Lib\site-packages\starlette\applications.py", line 112, in __call__
    await self.middleware_stack(scope, receive, send)
  File "C:\Users\pc\AppData\Local\Programs\Python\Python313\Lib\site-packages\starlette\middleware\errors.py", line 187, in __call__
    raise exc
  File "C:\Users\pc\AppData\Local\Programs\Python\Python313\Lib\site-packages\starlette\middleware\errors.py", line 165, in __call__
    await self.app(scope, receive, _send)
  File "C:\Users\pc\AppData\Local\Programs\Python\Python313\Lib\site-packages\starlette\middleware\cors.py", line 93, in __call__
    await self.simple_response(scope, receive, send, request_headers=headers)
  File "C:\Users\pc\AppData\Local\Programs\Python\Python313\Lib\site-packages\starlette\middleware\cors.py", line 144, in simple_response
    await self.app(scope, receive, send)
  File "C:\Users\pc\AppData\Local\Programs\Python\Python313\Lib\site-packages\starlette\middleware\exceptions.py", line 62, in __call__
    await wrap_app_handling_exceptions(self.app, conn)(scope, receive, send)
  File "C:\Users\pc\AppData\Local\Programs\Python\Python313\Lib\site-packages\starlette\_exception_handler.py", line 53, in wrapped_app
    raise exc
  File "C:\Users\pc\AppData\Local\Programs\Python\Python313\Lib\site-packages\starlette\_exception_handler.py", line 42, in wrapped_app
    await app(scope, receive, sender)
  File "C:\Users\pc\AppData\Local\Programs\Python\Python313\Lib\site-packages\starlette\routing.py", line 714, in __call__
    await self.middleware_stack(scope, receive, send)
  File "C:\Users\pc\AppData\Local\Programs\Python\Python313\Lib\site-packages\starlette\routing.py", line 734, in app
    await route.handle(scope, receive, send)
  File "C:\Users\pc\AppData\Local\Programs\Python\Python313\Lib\site-packages\starlette\routing.py", line 288, in handle
    await self.app(scope, receive, send)
  File "C:\Users\pc\AppData\Local\Programs\Python\Python313\Lib\site-packages\starlette\routing.py", line 76, in app
    await wrap_app_handling_exceptions(app, request)(scope, receive, send)
  File "C:\Users\pc\AppData\Local\Programs\Python\Python313\Lib\site-packages\starlette\_exception_handler.py", line 53, in wrapped_app
    raise exc
  File "C:\Users\pc\AppData\Local\Programs\Python\Python313\Lib\site-packages\starlette\_exception_handler.py", line 42, in wrapped_app
    await app(scope, receive, sender)
  File "C:\Users\pc\AppData\Local\Programs\Python\Python313\Lib\site-packages\starlette\routing.py", line 73, in app
    response = await f(request)
               ^^^^^^^^^^^^^^^^
  File "C:\Users\pc\AppData\Local\Programs\Python\Python313\Lib\site-packages\fastapi\routing.py", line 301, in app
    raw_response = await run_endpoint_function(
                   ^^^^^^^^^^^^^^^^^^^^^^^^^^^^
    ...<3 lines>...
    )
    ^
  File "C:\Users\pc\AppData\Local\Programs\Python\Python313\Lib\site-packages\fastapi\routing.py", line 214, in run_endpoint_function
    return await run_in_threadpool(dependant.call, **values)
           ^^^^^^^^^^^^^^^^^^^^^^^^^^^^^^^^^^^^^^^^^^^^^^^^^
  File "C:\Users\pc\AppData\Local\Programs\Python\Python313\Lib\site-packages\starlette\concurrency.py", line 37, in run_in_threadpool
    return await anyio.to_thread.run_sync(func)
           ^^^^^^^^^^^^^^^^^^^^^^^^^^^^^^^^^^^^
  File "C:\Users\pc\AppData\Local\Programs\Python\Python313\Lib\site-packages\anyio\to_thread.py", line 56, in run_sync
    return await get_async_backend().run_sync_in_worker_thread(
           ^^^^^^^^^^^^^^^^^^^^^^^^^^^^^^^^^^^^^^^^^^^^^^^^^^^^
        func, args, abandon_on_cancel=abandon_on_cancel, limiter=limiter
        ^^^^^^^^^^^^^^^^^^^^^^^^^^^^^^^^^^^^^^^^^^^^^^^^^^^^^^^^^^^^^^^^
    )
    ^
  File "C:\Users\pc\AppData\Local\Programs\Python\Python313\Lib\site-packages\anyio\_backends\_asyncio.py", line 2470, in run_sync_in_worker_thread
    return await future
           ^^^^^^^^^^^^
  File "C:\Users\pc\AppData\Local\Programs\Python\Python313\Lib\site-packages\anyio\_backends\_asyncio.py", line 967, in run
    result = context.run(func, *args)
  File "D:\Projects\Development\webcore-erp\webcore-erp\wcs-backend\app\routes\auth.py", line 64, in login
    user=user.filter(User.username == request.username).first()
         ^^^^
UnboundLocalError: cannot access local variable 'user' where it is not associated with a value
[2025-06-23 11:32:58,104] [INFO] uvicorn.error: Shutting down
[2025-06-23 11:32:58,215] [INFO] uvicorn.error: Waiting for application shutdown.
[2025-06-23 11:32:58,216] [INFO] uvicorn.error: Application shutdown complete.
[2025-06-23 11:32:58,216] [INFO] uvicorn.error: Finished server process [15832]
[2025-06-23 11:33:01,256] [INFO] uvicorn.error: Started server process [15732]
[2025-06-23 11:33:01,257] [INFO] uvicorn.error: Waiting for application startup.
[2025-06-23 11:33:01,258] [INFO] uvicorn.error: Application startup complete.
[2025-06-23 11:33:01,259] [INFO] uvicorn.error: Uvicorn running on http://127.0.0.1:8000 (Press CTRL+C to quit)
[2025-06-23 11:33:06,485] [INFO] app.routes.auth: Request.username: admin
[2025-06-23 11:33:06,518] [WARNING] app.routes.auth: User not found or database is empty
[2025-06-23 11:35:14,500] [INFO] uvicorn.error: Shutting down
[2025-06-23 11:35:14,612] [INFO] uvicorn.error: Waiting for application shutdown.
[2025-06-23 11:35:14,613] [INFO] uvicorn.error: Application shutdown complete.
[2025-06-23 11:35:14,613] [INFO] uvicorn.error: Finished server process [15732]
[2025-06-23 11:35:18,461] [INFO] uvicorn.error: Started server process [10964]
[2025-06-23 11:35:18,461] [INFO] uvicorn.error: Waiting for application startup.
[2025-06-23 11:35:18,462] [INFO] uvicorn.error: Application startup complete.
[2025-06-23 11:35:18,463] [INFO] uvicorn.error: Uvicorn running on http://127.0.0.1:8000 (Press CTRL+C to quit)
[2025-06-23 11:35:21,488] [INFO] app.routes.auth: Request.username: admin
[2025-06-23 11:35:21,514] [WARNING] app.routes.auth: User not found or database is empty
[2025-06-23 11:35:38,229] [INFO] uvicorn.error: Shutting down
[2025-06-23 11:35:38,338] [INFO] uvicorn.error: Waiting for application shutdown.
[2025-06-23 11:35:38,339] [INFO] uvicorn.error: Application shutdown complete.
[2025-06-23 11:35:38,339] [INFO] uvicorn.error: Finished server process [10964]
[2025-06-23 12:09:47,341] [INFO] uvicorn.error: Started server process [10652]
[2025-06-23 12:09:47,341] [INFO] uvicorn.error: Waiting for application startup.
[2025-06-23 12:09:47,342] [INFO] uvicorn.error: Application startup complete.
[2025-06-23 12:09:47,344] [INFO] uvicorn.error: Uvicorn running on http://127.0.0.1:8000 (Press CTRL+C to quit)
[2025-06-23 12:09:49,516] [INFO] app.routes.auth: Request.username: admin
[2025-06-23 12:09:49,557] [WARNING] app.routes.auth: User not found or database is empty
[2025-06-23 12:10:49,855] [INFO] uvicorn.error: Shutting down
[2025-06-23 12:10:49,958] [INFO] uvicorn.error: Waiting for application shutdown.
[2025-06-23 12:10:49,959] [INFO] uvicorn.error: Application shutdown complete.
[2025-06-23 12:10:49,960] [INFO] uvicorn.error: Finished server process [10652]
[2025-06-23 12:10:59,893] [INFO] uvicorn.error: Started server process [15532]
[2025-06-23 12:10:59,894] [INFO] uvicorn.error: Waiting for application startup.
[2025-06-23 12:10:59,895] [INFO] uvicorn.error: Application startup complete.
[2025-06-23 12:10:59,897] [INFO] uvicorn.error: Uvicorn running on http://127.0.0.1:8000 (Press CTRL+C to quit)
[2025-06-23 12:11:03,527] [INFO] app.routes.auth: Request.username: admin
[2025-06-23 12:11:03,572] [WARNING] app.routes.auth: User not found or database is empty
[2025-06-23 12:13:35,649] [INFO] uvicorn.error: Shutting down
[2025-06-23 12:13:35,759] [INFO] uvicorn.error: Waiting for application shutdown.
[2025-06-23 12:13:35,760] [INFO] uvicorn.error: Application shutdown complete.
[2025-06-23 12:13:35,761] [INFO] uvicorn.error: Finished server process [15532]
[2025-06-23 12:14:16,589] [INFO] uvicorn.error: Started server process [9720]
[2025-06-23 12:14:16,590] [INFO] uvicorn.error: Waiting for application startup.
[2025-06-23 12:14:16,591] [INFO] uvicorn.error: Application startup complete.
[2025-06-23 12:14:16,592] [INFO] uvicorn.error: Uvicorn running on http://127.0.0.1:8000 (Press CTRL+C to quit)
[2025-06-23 12:14:22,261] [INFO] app.routes.auth: Request.username: admin
[2025-06-23 12:14:22,307] [INFO] app.routes.auth: Checking user: admin
[2025-06-23 12:14:22,307] [INFO] app.routes.auth: User found
[2025-06-23 12:17:28,830] [INFO] uvicorn.error: Shutting down
[2025-06-23 12:17:28,935] [INFO] uvicorn.error: Waiting for application shutdown.
[2025-06-23 12:17:28,936] [INFO] uvicorn.error: Application shutdown complete.
[2025-06-23 12:17:28,936] [INFO] uvicorn.error: Finished server process [9720]
[2025-06-23 12:17:33,741] [INFO] uvicorn.error: Started server process [3796]
[2025-06-23 12:17:33,741] [INFO] uvicorn.error: Waiting for application startup.
[2025-06-23 12:17:33,742] [INFO] uvicorn.error: Application startup complete.
[2025-06-23 12:17:33,743] [INFO] uvicorn.error: Uvicorn running on http://127.0.0.1:8000 (Press CTRL+C to quit)
[2025-06-23 12:17:39,739] [INFO] app.routes.auth: employee found: <app.models.employee.Employee object at 0x0000027D2BB28D70>
[2025-06-23 12:42:38,359] [INFO] uvicorn.error: Shutting down
[2025-06-23 12:42:38,474] [INFO] uvicorn.error: Waiting for application shutdown.
[2025-06-23 12:42:38,475] [INFO] uvicorn.error: Application shutdown complete.
[2025-06-23 12:42:38,475] [INFO] uvicorn.error: Finished server process [3796]
[2025-06-23 12:42:43,282] [INFO] uvicorn.error: Started server process [9720]
[2025-06-23 12:42:43,283] [INFO] uvicorn.error: Waiting for application startup.
[2025-06-23 12:42:43,285] [INFO] uvicorn.error: Application startup complete.
[2025-06-23 12:42:43,286] [INFO] uvicorn.error: Uvicorn running on http://127.0.0.1:8000 (Press CTRL+C to quit)
[2025-06-23 13:37:29,492] [INFO] uvicorn.error: Shutting down
[2025-06-23 13:37:29,594] [INFO] uvicorn.error: Waiting for application shutdown.
[2025-06-23 13:37:29,596] [INFO] uvicorn.error: Application shutdown complete.
[2025-06-23 13:37:29,597] [INFO] uvicorn.error: Finished server process [9720]
[2025-06-23 14:28:10,784] [INFO] uvicorn.error: Started server process [14432]
[2025-06-23 14:28:10,785] [INFO] uvicorn.error: Waiting for application startup.
[2025-06-23 14:28:10,786] [INFO] uvicorn.error: Application startup complete.
[2025-06-23 14:28:10,786] [INFO] uvicorn.error: Uvicorn running on http://127.0.0.1:8000 (Press CTRL+C to quit)
[2025-06-23 14:28:11,658] [INFO] uvicorn.error: Shutting down
[2025-06-23 14:28:11,773] [INFO] uvicorn.error: Waiting for application shutdown.
[2025-06-23 14:28:11,773] [INFO] uvicorn.error: Application shutdown complete.
[2025-06-23 14:28:11,774] [INFO] uvicorn.error: Finished server process [14432]
[2025-06-23 14:54:07,234] [INFO] uvicorn.error: Started server process [16292]
[2025-06-23 14:54:07,235] [INFO] uvicorn.error: Waiting for application startup.
[2025-06-23 14:54:07,236] [INFO] uvicorn.error: Application startup complete.
[2025-06-23 14:54:07,238] [INFO] uvicorn.error: Uvicorn running on http://127.0.0.1:8000 (Press CTRL+C to quit)
[2025-06-23 14:54:44,536] [ERROR] uvicorn.error: Exception in ASGI application
Traceback (most recent call last):
  File "C:\Users\pc\AppData\Local\Programs\Python\Python313\Lib\site-packages\sqlalchemy\orm\clsregistry.py", line 516, in _resolve_name
    rval = d[token]
           ~^^^^^^^
  File "C:\Users\pc\AppData\Local\Programs\Python\Python313\Lib\site-packages\sqlalchemy\util\_collections.py", line 345, in __missing__
    self[key] = val = self.creator(key)
                      ~~~~~~~~~~~~^^^^^
  File "C:\Users\pc\AppData\Local\Programs\Python\Python313\Lib\site-packages\sqlalchemy\orm\clsregistry.py", line 484, in _access_cls
    return self.fallback[key]
           ~~~~~~~~~~~~~^^^^^
KeyError: 'Sales'

The above exception was the direct cause of the following exception:

Traceback (most recent call last):
  File "C:\Users\pc\AppData\Local\Programs\Python\Python313\Lib\site-packages\uvicorn\protocols\http\h11_impl.py", line 403, in run_asgi
    result = await app(  # type: ignore[func-returns-value]
             ^^^^^^^^^^^^^^^^^^^^^^^^^^^^^^^^^^^^^^^^^^^^^^
        self.scope, self.receive, self.send
        ^^^^^^^^^^^^^^^^^^^^^^^^^^^^^^^^^^^
    )
    ^
  File "C:\Users\pc\AppData\Local\Programs\Python\Python313\Lib\site-packages\uvicorn\middleware\proxy_headers.py", line 60, in __call__
    return await self.app(scope, receive, send)
           ^^^^^^^^^^^^^^^^^^^^^^^^^^^^^^^^^^^^
  File "C:\Users\pc\AppData\Local\Programs\Python\Python313\Lib\site-packages\fastapi\applications.py", line 1054, in __call__
    await super().__call__(scope, receive, send)
  File "C:\Users\pc\AppData\Local\Programs\Python\Python313\Lib\site-packages\starlette\applications.py", line 112, in __call__
    await self.middleware_stack(scope, receive, send)
  File "C:\Users\pc\AppData\Local\Programs\Python\Python313\Lib\site-packages\starlette\middleware\errors.py", line 187, in __call__
    raise exc
  File "C:\Users\pc\AppData\Local\Programs\Python\Python313\Lib\site-packages\starlette\middleware\errors.py", line 165, in __call__
    await self.app(scope, receive, _send)
  File "C:\Users\pc\AppData\Local\Programs\Python\Python313\Lib\site-packages\starlette\middleware\cors.py", line 93, in __call__
    await self.simple_response(scope, receive, send, request_headers=headers)
  File "C:\Users\pc\AppData\Local\Programs\Python\Python313\Lib\site-packages\starlette\middleware\cors.py", line 144, in simple_response
    await self.app(scope, receive, send)
  File "C:\Users\pc\AppData\Local\Programs\Python\Python313\Lib\site-packages\starlette\middleware\exceptions.py", line 62, in __call__
    await wrap_app_handling_exceptions(self.app, conn)(scope, receive, send)
  File "C:\Users\pc\AppData\Local\Programs\Python\Python313\Lib\site-packages\starlette\_exception_handler.py", line 53, in wrapped_app
    raise exc
  File "C:\Users\pc\AppData\Local\Programs\Python\Python313\Lib\site-packages\starlette\_exception_handler.py", line 42, in wrapped_app
    await app(scope, receive, sender)
  File "C:\Users\pc\AppData\Local\Programs\Python\Python313\Lib\site-packages\starlette\routing.py", line 714, in __call__
    await self.middleware_stack(scope, receive, send)
  File "C:\Users\pc\AppData\Local\Programs\Python\Python313\Lib\site-packages\starlette\routing.py", line 734, in app
    await route.handle(scope, receive, send)
  File "C:\Users\pc\AppData\Local\Programs\Python\Python313\Lib\site-packages\starlette\routing.py", line 288, in handle
    await self.app(scope, receive, send)
  File "C:\Users\pc\AppData\Local\Programs\Python\Python313\Lib\site-packages\starlette\routing.py", line 76, in app
    await wrap_app_handling_exceptions(app, request)(scope, receive, send)
  File "C:\Users\pc\AppData\Local\Programs\Python\Python313\Lib\site-packages\starlette\_exception_handler.py", line 53, in wrapped_app
    raise exc
  File "C:\Users\pc\AppData\Local\Programs\Python\Python313\Lib\site-packages\starlette\_exception_handler.py", line 42, in wrapped_app
    await app(scope, receive, sender)
  File "C:\Users\pc\AppData\Local\Programs\Python\Python313\Lib\site-packages\starlette\routing.py", line 73, in app
    response = await f(request)
               ^^^^^^^^^^^^^^^^
  File "C:\Users\pc\AppData\Local\Programs\Python\Python313\Lib\site-packages\fastapi\routing.py", line 301, in app
    raw_response = await run_endpoint_function(
                   ^^^^^^^^^^^^^^^^^^^^^^^^^^^^
    ...<3 lines>...
    )
    ^
  File "C:\Users\pc\AppData\Local\Programs\Python\Python313\Lib\site-packages\fastapi\routing.py", line 214, in run_endpoint_function
    return await run_in_threadpool(dependant.call, **values)
           ^^^^^^^^^^^^^^^^^^^^^^^^^^^^^^^^^^^^^^^^^^^^^^^^^
  File "C:\Users\pc\AppData\Local\Programs\Python\Python313\Lib\site-packages\starlette\concurrency.py", line 37, in run_in_threadpool
    return await anyio.to_thread.run_sync(func)
           ^^^^^^^^^^^^^^^^^^^^^^^^^^^^^^^^^^^^
  File "C:\Users\pc\AppData\Local\Programs\Python\Python313\Lib\site-packages\anyio\to_thread.py", line 56, in run_sync
    return await get_async_backend().run_sync_in_worker_thread(
           ^^^^^^^^^^^^^^^^^^^^^^^^^^^^^^^^^^^^^^^^^^^^^^^^^^^^
        func, args, abandon_on_cancel=abandon_on_cancel, limiter=limiter
        ^^^^^^^^^^^^^^^^^^^^^^^^^^^^^^^^^^^^^^^^^^^^^^^^^^^^^^^^^^^^^^^^
    )
    ^
  File "C:\Users\pc\AppData\Local\Programs\Python\Python313\Lib\site-packages\anyio\_backends\_asyncio.py", line 2470, in run_sync_in_worker_thread
    return await future
           ^^^^^^^^^^^^
  File "C:\Users\pc\AppData\Local\Programs\Python\Python313\Lib\site-packages\anyio\_backends\_asyncio.py", line 967, in run
    result = context.run(func, *args)
  File "D:\Projects\Development\webcore-erp\webcore-erp\wcs-backend\app\routes\auth.py", line 56, in login
    user = db.query(User).filter(User.username == request.username).first()
           ~~~~~~~~^^^^^^
  File "C:\Users\pc\AppData\Local\Programs\Python\Python313\Lib\site-packages\sqlalchemy\orm\session.py", line 2955, in query
    return self._query_cls(entities, self, **kwargs)
           ~~~~~~~~~~~~~~~^^^^^^^^^^^^^^^^^^^^^^^^^^
  File "C:\Users\pc\AppData\Local\Programs\Python\Python313\Lib\site-packages\sqlalchemy\orm\query.py", line 276, in __init__
    self._set_entities(entities)
    ~~~~~~~~~~~~~~~~~~^^^^^^^^^^
  File "C:\Users\pc\AppData\Local\Programs\Python\Python313\Lib\site-packages\sqlalchemy\orm\query.py", line 289, in _set_entities
    coercions.expect(
    ~~~~~~~~~~~~~~~~^
        roles.ColumnsClauseRole,
        ^^^^^^^^^^^^^^^^^^^^^^^^
    ...<2 lines>...
        post_inspect=True,
        ^^^^^^^^^^^^^^^^^^
    )
    ^
  File "C:\Users\pc\AppData\Local\Programs\Python\Python313\Lib\site-packages\sqlalchemy\sql\coercions.py", line 388, in expect
    insp._post_inspect
  File "C:\Users\pc\AppData\Local\Programs\Python\Python313\Lib\site-packages\sqlalchemy\util\langhelpers.py", line 1338, in __get__
    obj.__dict__[self.__name__] = result = self.fget(obj)
                                           ~~~~~~~~~^^^^^
  File "C:\Users\pc\AppData\Local\Programs\Python\Python313\Lib\site-packages\sqlalchemy\orm\mapper.py", line 2724, in _post_inspect
    self._check_configure()
    ~~~~~~~~~~~~~~~~~~~~~^^
  File "C:\Users\pc\AppData\Local\Programs\Python\Python313\Lib\site-packages\sqlalchemy\orm\mapper.py", line 2401, in _check_configure
    _configure_registries({self.registry}, cascade=True)
    ~~~~~~~~~~~~~~~~~~~~~^^^^^^^^^^^^^^^^^^^^^^^^^^^^^^^
  File "C:\Users\pc\AppData\Local\Programs\Python\Python313\Lib\site-packages\sqlalchemy\orm\mapper.py", line 4214, in _configure_registries
    _do_configure_registries(registries, cascade)
    ~~~~~~~~~~~~~~~~~~~~~~~~^^^^^^^^^^^^^^^^^^^^^
  File "C:\Users\pc\AppData\Local\Programs\Python\Python313\Lib\site-packages\sqlalchemy\orm\mapper.py", line 4255, in _do_configure_registries
    mapper._post_configure_properties()
    ~~~~~~~~~~~~~~~~~~~~~~~~~~~~~~~~~^^
  File "C:\Users\pc\AppData\Local\Programs\Python\Python313\Lib\site-packages\sqlalchemy\orm\mapper.py", line 2418, in _post_configure_properties
    prop.init()
    ~~~~~~~~~^^
  File "C:\Users\pc\AppData\Local\Programs\Python\Python313\Lib\site-packages\sqlalchemy\orm\interfaces.py", line 589, in init
    self.do_init()
    ~~~~~~~~~~~~^^
  File "C:\Users\pc\AppData\Local\Programs\Python\Python313\Lib\site-packages\sqlalchemy\orm\relationships.py", line 1656, in do_init
    self._setup_entity()
    ~~~~~~~~~~~~~~~~~~^^
  File "C:\Users\pc\AppData\Local\Programs\Python\Python313\Lib\site-packages\sqlalchemy\orm\relationships.py", line 1866, in _setup_entity
    self._clsregistry_resolve_name(argument)(),
    ~~~~~~~~~~~~~~~~~~~~~~~~~~~~~~~~~~~~~~~~^^
  File "C:\Users\pc\AppData\Local\Programs\Python\Python313\Lib\site-packages\sqlalchemy\orm\clsregistry.py", line 520, in _resolve_name
    self._raise_for_name(name, err)
    ~~~~~~~~~~~~~~~~~~~~^^^^^^^^^^^
  File "C:\Users\pc\AppData\Local\Programs\Python\Python313\Lib\site-packages\sqlalchemy\orm\clsregistry.py", line 501, in _raise_for_name
    raise exc.InvalidRequestError(
    ...<5 lines>...
    ) from err
sqlalchemy.exc.InvalidRequestError: When initializing mapper Mapper[Client(clients)], expression 'Sales' failed to locate a name ('Sales'). If this is a class name, consider adding this relationship() to the <class 'app.models.client.Client'> class after both dependent classes have been defined.
[2025-06-23 16:28:06,164] [INFO] uvicorn.error: Shutting down
[2025-06-23 16:28:06,275] [INFO] uvicorn.error: Waiting for application shutdown.
[2025-06-23 16:28:06,276] [INFO] uvicorn.error: Application shutdown complete.
[2025-06-23 16:28:06,276] [INFO] uvicorn.error: Finished server process [16292]
[2025-06-23 16:28:11,557] [INFO] uvicorn.error: Started server process [7820]
[2025-06-23 16:28:11,558] [INFO] uvicorn.error: Waiting for application startup.
[2025-06-23 16:28:11,559] [INFO] uvicorn.error: Application startup complete.
[2025-06-23 16:28:11,560] [INFO] uvicorn.error: Uvicorn running on http://127.0.0.1:8000 (Press CTRL+C to quit)
[2025-06-23 16:28:24,747] [ERROR] uvicorn.error: Exception in ASGI application
Traceback (most recent call last):
  File "C:\Users\pc\AppData\Local\Programs\Python\Python313\Lib\site-packages\sqlalchemy\orm\clsregistry.py", line 516, in _resolve_name
    rval = d[token]
           ~^^^^^^^
  File "C:\Users\pc\AppData\Local\Programs\Python\Python313\Lib\site-packages\sqlalchemy\util\_collections.py", line 345, in __missing__
    self[key] = val = self.creator(key)
                      ~~~~~~~~~~~~^^^^^
  File "C:\Users\pc\AppData\Local\Programs\Python\Python313\Lib\site-packages\sqlalchemy\orm\clsregistry.py", line 484, in _access_cls
    return self.fallback[key]
           ~~~~~~~~~~~~~^^^^^
KeyError: 'Sales'

The above exception was the direct cause of the following exception:

Traceback (most recent call last):
  File "C:\Users\pc\AppData\Local\Programs\Python\Python313\Lib\site-packages\uvicorn\protocols\http\h11_impl.py", line 403, in run_asgi
    result = await app(  # type: ignore[func-returns-value]
             ^^^^^^^^^^^^^^^^^^^^^^^^^^^^^^^^^^^^^^^^^^^^^^
        self.scope, self.receive, self.send
        ^^^^^^^^^^^^^^^^^^^^^^^^^^^^^^^^^^^
    )
    ^
  File "C:\Users\pc\AppData\Local\Programs\Python\Python313\Lib\site-packages\uvicorn\middleware\proxy_headers.py", line 60, in __call__
    return await self.app(scope, receive, send)
           ^^^^^^^^^^^^^^^^^^^^^^^^^^^^^^^^^^^^
  File "C:\Users\pc\AppData\Local\Programs\Python\Python313\Lib\site-packages\fastapi\applications.py", line 1054, in __call__
    await super().__call__(scope, receive, send)
  File "C:\Users\pc\AppData\Local\Programs\Python\Python313\Lib\site-packages\starlette\applications.py", line 112, in __call__
    await self.middleware_stack(scope, receive, send)
  File "C:\Users\pc\AppData\Local\Programs\Python\Python313\Lib\site-packages\starlette\middleware\errors.py", line 187, in __call__
    raise exc
  File "C:\Users\pc\AppData\Local\Programs\Python\Python313\Lib\site-packages\starlette\middleware\errors.py", line 165, in __call__
    await self.app(scope, receive, _send)
  File "C:\Users\pc\AppData\Local\Programs\Python\Python313\Lib\site-packages\starlette\middleware\cors.py", line 93, in __call__
    await self.simple_response(scope, receive, send, request_headers=headers)
  File "C:\Users\pc\AppData\Local\Programs\Python\Python313\Lib\site-packages\starlette\middleware\cors.py", line 144, in simple_response
    await self.app(scope, receive, send)
  File "C:\Users\pc\AppData\Local\Programs\Python\Python313\Lib\site-packages\starlette\middleware\exceptions.py", line 62, in __call__
    await wrap_app_handling_exceptions(self.app, conn)(scope, receive, send)
  File "C:\Users\pc\AppData\Local\Programs\Python\Python313\Lib\site-packages\starlette\_exception_handler.py", line 53, in wrapped_app
    raise exc
  File "C:\Users\pc\AppData\Local\Programs\Python\Python313\Lib\site-packages\starlette\_exception_handler.py", line 42, in wrapped_app
    await app(scope, receive, sender)
  File "C:\Users\pc\AppData\Local\Programs\Python\Python313\Lib\site-packages\starlette\routing.py", line 714, in __call__
    await self.middleware_stack(scope, receive, send)
  File "C:\Users\pc\AppData\Local\Programs\Python\Python313\Lib\site-packages\starlette\routing.py", line 734, in app
    await route.handle(scope, receive, send)
  File "C:\Users\pc\AppData\Local\Programs\Python\Python313\Lib\site-packages\starlette\routing.py", line 288, in handle
    await self.app(scope, receive, send)
  File "C:\Users\pc\AppData\Local\Programs\Python\Python313\Lib\site-packages\starlette\routing.py", line 76, in app
    await wrap_app_handling_exceptions(app, request)(scope, receive, send)
  File "C:\Users\pc\AppData\Local\Programs\Python\Python313\Lib\site-packages\starlette\_exception_handler.py", line 53, in wrapped_app
    raise exc
  File "C:\Users\pc\AppData\Local\Programs\Python\Python313\Lib\site-packages\starlette\_exception_handler.py", line 42, in wrapped_app
    await app(scope, receive, sender)
  File "C:\Users\pc\AppData\Local\Programs\Python\Python313\Lib\site-packages\starlette\routing.py", line 73, in app
    response = await f(request)
               ^^^^^^^^^^^^^^^^
  File "C:\Users\pc\AppData\Local\Programs\Python\Python313\Lib\site-packages\fastapi\routing.py", line 301, in app
    raw_response = await run_endpoint_function(
                   ^^^^^^^^^^^^^^^^^^^^^^^^^^^^
    ...<3 lines>...
    )
    ^
  File "C:\Users\pc\AppData\Local\Programs\Python\Python313\Lib\site-packages\fastapi\routing.py", line 214, in run_endpoint_function
    return await run_in_threadpool(dependant.call, **values)
           ^^^^^^^^^^^^^^^^^^^^^^^^^^^^^^^^^^^^^^^^^^^^^^^^^
  File "C:\Users\pc\AppData\Local\Programs\Python\Python313\Lib\site-packages\starlette\concurrency.py", line 37, in run_in_threadpool
    return await anyio.to_thread.run_sync(func)
           ^^^^^^^^^^^^^^^^^^^^^^^^^^^^^^^^^^^^
  File "C:\Users\pc\AppData\Local\Programs\Python\Python313\Lib\site-packages\anyio\to_thread.py", line 56, in run_sync
    return await get_async_backend().run_sync_in_worker_thread(
           ^^^^^^^^^^^^^^^^^^^^^^^^^^^^^^^^^^^^^^^^^^^^^^^^^^^^
        func, args, abandon_on_cancel=abandon_on_cancel, limiter=limiter
        ^^^^^^^^^^^^^^^^^^^^^^^^^^^^^^^^^^^^^^^^^^^^^^^^^^^^^^^^^^^^^^^^
    )
    ^
  File "C:\Users\pc\AppData\Local\Programs\Python\Python313\Lib\site-packages\anyio\_backends\_asyncio.py", line 2470, in run_sync_in_worker_thread
    return await future
           ^^^^^^^^^^^^
  File "C:\Users\pc\AppData\Local\Programs\Python\Python313\Lib\site-packages\anyio\_backends\_asyncio.py", line 967, in run
    result = context.run(func, *args)
  File "D:\Projects\Development\webcore-erp\webcore-erp\wcs-backend\app\routes\auth.py", line 56, in login
    user = db.query(User).filter(User.username == request.username).first()
           ~~~~~~~~^^^^^^
  File "C:\Users\pc\AppData\Local\Programs\Python\Python313\Lib\site-packages\sqlalchemy\orm\session.py", line 2955, in query
    return self._query_cls(entities, self, **kwargs)
           ~~~~~~~~~~~~~~~^^^^^^^^^^^^^^^^^^^^^^^^^^
  File "C:\Users\pc\AppData\Local\Programs\Python\Python313\Lib\site-packages\sqlalchemy\orm\query.py", line 276, in __init__
    self._set_entities(entities)
    ~~~~~~~~~~~~~~~~~~^^^^^^^^^^
  File "C:\Users\pc\AppData\Local\Programs\Python\Python313\Lib\site-packages\sqlalchemy\orm\query.py", line 289, in _set_entities
    coercions.expect(
    ~~~~~~~~~~~~~~~~^
        roles.ColumnsClauseRole,
        ^^^^^^^^^^^^^^^^^^^^^^^^
    ...<2 lines>...
        post_inspect=True,
        ^^^^^^^^^^^^^^^^^^
    )
    ^
  File "C:\Users\pc\AppData\Local\Programs\Python\Python313\Lib\site-packages\sqlalchemy\sql\coercions.py", line 388, in expect
    insp._post_inspect
  File "C:\Users\pc\AppData\Local\Programs\Python\Python313\Lib\site-packages\sqlalchemy\util\langhelpers.py", line 1338, in __get__
    obj.__dict__[self.__name__] = result = self.fget(obj)
                                           ~~~~~~~~~^^^^^
  File "C:\Users\pc\AppData\Local\Programs\Python\Python313\Lib\site-packages\sqlalchemy\orm\mapper.py", line 2724, in _post_inspect
    self._check_configure()
    ~~~~~~~~~~~~~~~~~~~~~^^
  File "C:\Users\pc\AppData\Local\Programs\Python\Python313\Lib\site-packages\sqlalchemy\orm\mapper.py", line 2401, in _check_configure
    _configure_registries({self.registry}, cascade=True)
    ~~~~~~~~~~~~~~~~~~~~~^^^^^^^^^^^^^^^^^^^^^^^^^^^^^^^
  File "C:\Users\pc\AppData\Local\Programs\Python\Python313\Lib\site-packages\sqlalchemy\orm\mapper.py", line 4214, in _configure_registries
    _do_configure_registries(registries, cascade)
    ~~~~~~~~~~~~~~~~~~~~~~~~^^^^^^^^^^^^^^^^^^^^^
  File "C:\Users\pc\AppData\Local\Programs\Python\Python313\Lib\site-packages\sqlalchemy\orm\mapper.py", line 4255, in _do_configure_registries
    mapper._post_configure_properties()
    ~~~~~~~~~~~~~~~~~~~~~~~~~~~~~~~~~^^
  File "C:\Users\pc\AppData\Local\Programs\Python\Python313\Lib\site-packages\sqlalchemy\orm\mapper.py", line 2418, in _post_configure_properties
    prop.init()
    ~~~~~~~~~^^
  File "C:\Users\pc\AppData\Local\Programs\Python\Python313\Lib\site-packages\sqlalchemy\orm\interfaces.py", line 589, in init
    self.do_init()
    ~~~~~~~~~~~~^^
  File "C:\Users\pc\AppData\Local\Programs\Python\Python313\Lib\site-packages\sqlalchemy\orm\relationships.py", line 1656, in do_init
    self._setup_entity()
    ~~~~~~~~~~~~~~~~~~^^
  File "C:\Users\pc\AppData\Local\Programs\Python\Python313\Lib\site-packages\sqlalchemy\orm\relationships.py", line 1866, in _setup_entity
    self._clsregistry_resolve_name(argument)(),
    ~~~~~~~~~~~~~~~~~~~~~~~~~~~~~~~~~~~~~~~~^^
  File "C:\Users\pc\AppData\Local\Programs\Python\Python313\Lib\site-packages\sqlalchemy\orm\clsregistry.py", line 520, in _resolve_name
    self._raise_for_name(name, err)
    ~~~~~~~~~~~~~~~~~~~~^^^^^^^^^^^
  File "C:\Users\pc\AppData\Local\Programs\Python\Python313\Lib\site-packages\sqlalchemy\orm\clsregistry.py", line 501, in _raise_for_name
    raise exc.InvalidRequestError(
    ...<5 lines>...
    ) from err
sqlalchemy.exc.InvalidRequestError: When initializing mapper Mapper[Client(clients)], expression 'Sales' failed to locate a name ('Sales'). If this is a class name, consider adding this relationship() to the <class 'app.models.client.Client'> class after both dependent classes have been defined.
[2025-06-23 16:31:11,878] [INFO] uvicorn.error: Shutting down
[2025-06-23 16:31:11,988] [INFO] uvicorn.error: Waiting for application shutdown.
[2025-06-23 16:31:11,989] [INFO] uvicorn.error: Application shutdown complete.
[2025-06-23 16:31:11,989] [INFO] uvicorn.error: Finished server process [7820]
[2025-06-23 16:31:17,695] [INFO] uvicorn.error: Started server process [7240]
[2025-06-23 16:31:17,695] [INFO] uvicorn.error: Waiting for application startup.
[2025-06-23 16:31:17,696] [INFO] uvicorn.error: Application startup complete.
[2025-06-23 16:31:17,698] [INFO] uvicorn.error: Uvicorn running on http://127.0.0.1:8000 (Press CTRL+C to quit)
[2025-06-23 16:31:27,947] [ERROR] uvicorn.error: Exception in ASGI application
Traceback (most recent call last):
  File "C:\Users\pc\AppData\Local\Programs\Python\Python313\Lib\site-packages\sqlalchemy\orm\clsregistry.py", line 516, in _resolve_name
    rval = d[token]
           ~^^^^^^^
  File "C:\Users\pc\AppData\Local\Programs\Python\Python313\Lib\site-packages\sqlalchemy\util\_collections.py", line 345, in __missing__
    self[key] = val = self.creator(key)
                      ~~~~~~~~~~~~^^^^^
  File "C:\Users\pc\AppData\Local\Programs\Python\Python313\Lib\site-packages\sqlalchemy\orm\clsregistry.py", line 484, in _access_cls
    return self.fallback[key]
           ~~~~~~~~~~~~~^^^^^
KeyError: 'Sales'

The above exception was the direct cause of the following exception:

Traceback (most recent call last):
  File "C:\Users\pc\AppData\Local\Programs\Python\Python313\Lib\site-packages\uvicorn\protocols\http\h11_impl.py", line 403, in run_asgi
    result = await app(  # type: ignore[func-returns-value]
             ^^^^^^^^^^^^^^^^^^^^^^^^^^^^^^^^^^^^^^^^^^^^^^
        self.scope, self.receive, self.send
        ^^^^^^^^^^^^^^^^^^^^^^^^^^^^^^^^^^^
    )
    ^
  File "C:\Users\pc\AppData\Local\Programs\Python\Python313\Lib\site-packages\uvicorn\middleware\proxy_headers.py", line 60, in __call__
    return await self.app(scope, receive, send)
           ^^^^^^^^^^^^^^^^^^^^^^^^^^^^^^^^^^^^
  File "C:\Users\pc\AppData\Local\Programs\Python\Python313\Lib\site-packages\fastapi\applications.py", line 1054, in __call__
    await super().__call__(scope, receive, send)
  File "C:\Users\pc\AppData\Local\Programs\Python\Python313\Lib\site-packages\starlette\applications.py", line 112, in __call__
    await self.middleware_stack(scope, receive, send)
  File "C:\Users\pc\AppData\Local\Programs\Python\Python313\Lib\site-packages\starlette\middleware\errors.py", line 187, in __call__
    raise exc
  File "C:\Users\pc\AppData\Local\Programs\Python\Python313\Lib\site-packages\starlette\middleware\errors.py", line 165, in __call__
    await self.app(scope, receive, _send)
  File "C:\Users\pc\AppData\Local\Programs\Python\Python313\Lib\site-packages\starlette\middleware\cors.py", line 93, in __call__
    await self.simple_response(scope, receive, send, request_headers=headers)
  File "C:\Users\pc\AppData\Local\Programs\Python\Python313\Lib\site-packages\starlette\middleware\cors.py", line 144, in simple_response
    await self.app(scope, receive, send)
  File "C:\Users\pc\AppData\Local\Programs\Python\Python313\Lib\site-packages\starlette\middleware\exceptions.py", line 62, in __call__
    await wrap_app_handling_exceptions(self.app, conn)(scope, receive, send)
  File "C:\Users\pc\AppData\Local\Programs\Python\Python313\Lib\site-packages\starlette\_exception_handler.py", line 53, in wrapped_app
    raise exc
  File "C:\Users\pc\AppData\Local\Programs\Python\Python313\Lib\site-packages\starlette\_exception_handler.py", line 42, in wrapped_app
    await app(scope, receive, sender)
  File "C:\Users\pc\AppData\Local\Programs\Python\Python313\Lib\site-packages\starlette\routing.py", line 714, in __call__
    await self.middleware_stack(scope, receive, send)
  File "C:\Users\pc\AppData\Local\Programs\Python\Python313\Lib\site-packages\starlette\routing.py", line 734, in app
    await route.handle(scope, receive, send)
  File "C:\Users\pc\AppData\Local\Programs\Python\Python313\Lib\site-packages\starlette\routing.py", line 288, in handle
    await self.app(scope, receive, send)
  File "C:\Users\pc\AppData\Local\Programs\Python\Python313\Lib\site-packages\starlette\routing.py", line 76, in app
    await wrap_app_handling_exceptions(app, request)(scope, receive, send)
  File "C:\Users\pc\AppData\Local\Programs\Python\Python313\Lib\site-packages\starlette\_exception_handler.py", line 53, in wrapped_app
    raise exc
  File "C:\Users\pc\AppData\Local\Programs\Python\Python313\Lib\site-packages\starlette\_exception_handler.py", line 42, in wrapped_app
    await app(scope, receive, sender)
  File "C:\Users\pc\AppData\Local\Programs\Python\Python313\Lib\site-packages\starlette\routing.py", line 73, in app
    response = await f(request)
               ^^^^^^^^^^^^^^^^
  File "C:\Users\pc\AppData\Local\Programs\Python\Python313\Lib\site-packages\fastapi\routing.py", line 301, in app
    raw_response = await run_endpoint_function(
                   ^^^^^^^^^^^^^^^^^^^^^^^^^^^^
    ...<3 lines>...
    )
    ^
  File "C:\Users\pc\AppData\Local\Programs\Python\Python313\Lib\site-packages\fastapi\routing.py", line 214, in run_endpoint_function
    return await run_in_threadpool(dependant.call, **values)
           ^^^^^^^^^^^^^^^^^^^^^^^^^^^^^^^^^^^^^^^^^^^^^^^^^
  File "C:\Users\pc\AppData\Local\Programs\Python\Python313\Lib\site-packages\starlette\concurrency.py", line 37, in run_in_threadpool
    return await anyio.to_thread.run_sync(func)
           ^^^^^^^^^^^^^^^^^^^^^^^^^^^^^^^^^^^^
  File "C:\Users\pc\AppData\Local\Programs\Python\Python313\Lib\site-packages\anyio\to_thread.py", line 56, in run_sync
    return await get_async_backend().run_sync_in_worker_thread(
           ^^^^^^^^^^^^^^^^^^^^^^^^^^^^^^^^^^^^^^^^^^^^^^^^^^^^
        func, args, abandon_on_cancel=abandon_on_cancel, limiter=limiter
        ^^^^^^^^^^^^^^^^^^^^^^^^^^^^^^^^^^^^^^^^^^^^^^^^^^^^^^^^^^^^^^^^
    )
    ^
  File "C:\Users\pc\AppData\Local\Programs\Python\Python313\Lib\site-packages\anyio\_backends\_asyncio.py", line 2470, in run_sync_in_worker_thread
    return await future
           ^^^^^^^^^^^^
  File "C:\Users\pc\AppData\Local\Programs\Python\Python313\Lib\site-packages\anyio\_backends\_asyncio.py", line 967, in run
    result = context.run(func, *args)
  File "D:\Projects\Development\webcore-erp\webcore-erp\wcs-backend\app\routes\auth.py", line 56, in login
    user = db.query(User).filter(User.username == request.username).first()
           ~~~~~~~~^^^^^^
  File "C:\Users\pc\AppData\Local\Programs\Python\Python313\Lib\site-packages\sqlalchemy\orm\session.py", line 2955, in query
    return self._query_cls(entities, self, **kwargs)
           ~~~~~~~~~~~~~~~^^^^^^^^^^^^^^^^^^^^^^^^^^
  File "C:\Users\pc\AppData\Local\Programs\Python\Python313\Lib\site-packages\sqlalchemy\orm\query.py", line 276, in __init__
    self._set_entities(entities)
    ~~~~~~~~~~~~~~~~~~^^^^^^^^^^
  File "C:\Users\pc\AppData\Local\Programs\Python\Python313\Lib\site-packages\sqlalchemy\orm\query.py", line 289, in _set_entities
    coercions.expect(
    ~~~~~~~~~~~~~~~~^
        roles.ColumnsClauseRole,
        ^^^^^^^^^^^^^^^^^^^^^^^^
    ...<2 lines>...
        post_inspect=True,
        ^^^^^^^^^^^^^^^^^^
    )
    ^
  File "C:\Users\pc\AppData\Local\Programs\Python\Python313\Lib\site-packages\sqlalchemy\sql\coercions.py", line 388, in expect
    insp._post_inspect
  File "C:\Users\pc\AppData\Local\Programs\Python\Python313\Lib\site-packages\sqlalchemy\util\langhelpers.py", line 1338, in __get__
    obj.__dict__[self.__name__] = result = self.fget(obj)
                                           ~~~~~~~~~^^^^^
  File "C:\Users\pc\AppData\Local\Programs\Python\Python313\Lib\site-packages\sqlalchemy\orm\mapper.py", line 2724, in _post_inspect
    self._check_configure()
    ~~~~~~~~~~~~~~~~~~~~~^^
  File "C:\Users\pc\AppData\Local\Programs\Python\Python313\Lib\site-packages\sqlalchemy\orm\mapper.py", line 2401, in _check_configure
    _configure_registries({self.registry}, cascade=True)
    ~~~~~~~~~~~~~~~~~~~~~^^^^^^^^^^^^^^^^^^^^^^^^^^^^^^^
  File "C:\Users\pc\AppData\Local\Programs\Python\Python313\Lib\site-packages\sqlalchemy\orm\mapper.py", line 4214, in _configure_registries
    _do_configure_registries(registries, cascade)
    ~~~~~~~~~~~~~~~~~~~~~~~~^^^^^^^^^^^^^^^^^^^^^
  File "C:\Users\pc\AppData\Local\Programs\Python\Python313\Lib\site-packages\sqlalchemy\orm\mapper.py", line 4255, in _do_configure_registries
    mapper._post_configure_properties()
    ~~~~~~~~~~~~~~~~~~~~~~~~~~~~~~~~~^^
  File "C:\Users\pc\AppData\Local\Programs\Python\Python313\Lib\site-packages\sqlalchemy\orm\mapper.py", line 2418, in _post_configure_properties
    prop.init()
    ~~~~~~~~~^^
  File "C:\Users\pc\AppData\Local\Programs\Python\Python313\Lib\site-packages\sqlalchemy\orm\interfaces.py", line 589, in init
    self.do_init()
    ~~~~~~~~~~~~^^
  File "C:\Users\pc\AppData\Local\Programs\Python\Python313\Lib\site-packages\sqlalchemy\orm\relationships.py", line 1656, in do_init
    self._setup_entity()
    ~~~~~~~~~~~~~~~~~~^^
  File "C:\Users\pc\AppData\Local\Programs\Python\Python313\Lib\site-packages\sqlalchemy\orm\relationships.py", line 1866, in _setup_entity
    self._clsregistry_resolve_name(argument)(),
    ~~~~~~~~~~~~~~~~~~~~~~~~~~~~~~~~~~~~~~~~^^
  File "C:\Users\pc\AppData\Local\Programs\Python\Python313\Lib\site-packages\sqlalchemy\orm\clsregistry.py", line 520, in _resolve_name
    self._raise_for_name(name, err)
    ~~~~~~~~~~~~~~~~~~~~^^^^^^^^^^^
  File "C:\Users\pc\AppData\Local\Programs\Python\Python313\Lib\site-packages\sqlalchemy\orm\clsregistry.py", line 501, in _raise_for_name
    raise exc.InvalidRequestError(
    ...<5 lines>...
    ) from err
sqlalchemy.exc.InvalidRequestError: When initializing mapper Mapper[Client(clients)], expression 'Sales' failed to locate a name ('Sales'). If this is a class name, consider adding this relationship() to the <class 'app.models.client.Client'> class after both dependent classes have been defined.
[2025-06-23 16:36:17,559] [INFO] uvicorn.error: Shutting down
[2025-06-23 16:36:17,665] [INFO] uvicorn.error: Waiting for application shutdown.
[2025-06-23 16:36:17,666] [INFO] uvicorn.error: Application shutdown complete.
[2025-06-23 16:36:17,666] [INFO] uvicorn.error: Finished server process [7240]
[2025-06-23 16:36:22,148] [INFO] uvicorn.error: Started server process [2524]
[2025-06-23 16:36:22,149] [INFO] uvicorn.error: Waiting for application startup.
[2025-06-23 16:36:22,150] [INFO] uvicorn.error: Application startup complete.
[2025-06-23 16:36:22,151] [INFO] uvicorn.error: Uvicorn running on http://127.0.0.1:8000 (Press CTRL+C to quit)
[2025-06-23 16:36:25,037] [ERROR] uvicorn.error: Exception in ASGI application
Traceback (most recent call last):
  File "C:\Users\pc\AppData\Local\Programs\Python\Python313\Lib\site-packages\sqlalchemy\orm\clsregistry.py", line 516, in _resolve_name
    rval = d[token]
           ~^^^^^^^
  File "C:\Users\pc\AppData\Local\Programs\Python\Python313\Lib\site-packages\sqlalchemy\util\_collections.py", line 345, in __missing__
    self[key] = val = self.creator(key)
                      ~~~~~~~~~~~~^^^^^
  File "C:\Users\pc\AppData\Local\Programs\Python\Python313\Lib\site-packages\sqlalchemy\orm\clsregistry.py", line 484, in _access_cls
    return self.fallback[key]
           ~~~~~~~~~~~~~^^^^^
KeyError: 'Sales'

The above exception was the direct cause of the following exception:

Traceback (most recent call last):
  File "C:\Users\pc\AppData\Local\Programs\Python\Python313\Lib\site-packages\uvicorn\protocols\http\h11_impl.py", line 403, in run_asgi
    result = await app(  # type: ignore[func-returns-value]
             ^^^^^^^^^^^^^^^^^^^^^^^^^^^^^^^^^^^^^^^^^^^^^^
        self.scope, self.receive, self.send
        ^^^^^^^^^^^^^^^^^^^^^^^^^^^^^^^^^^^
    )
    ^
  File "C:\Users\pc\AppData\Local\Programs\Python\Python313\Lib\site-packages\uvicorn\middleware\proxy_headers.py", line 60, in __call__
    return await self.app(scope, receive, send)
           ^^^^^^^^^^^^^^^^^^^^^^^^^^^^^^^^^^^^
  File "C:\Users\pc\AppData\Local\Programs\Python\Python313\Lib\site-packages\fastapi\applications.py", line 1054, in __call__
    await super().__call__(scope, receive, send)
  File "C:\Users\pc\AppData\Local\Programs\Python\Python313\Lib\site-packages\starlette\applications.py", line 112, in __call__
    await self.middleware_stack(scope, receive, send)
  File "C:\Users\pc\AppData\Local\Programs\Python\Python313\Lib\site-packages\starlette\middleware\errors.py", line 187, in __call__
    raise exc
  File "C:\Users\pc\AppData\Local\Programs\Python\Python313\Lib\site-packages\starlette\middleware\errors.py", line 165, in __call__
    await self.app(scope, receive, _send)
  File "C:\Users\pc\AppData\Local\Programs\Python\Python313\Lib\site-packages\starlette\middleware\cors.py", line 93, in __call__
    await self.simple_response(scope, receive, send, request_headers=headers)
  File "C:\Users\pc\AppData\Local\Programs\Python\Python313\Lib\site-packages\starlette\middleware\cors.py", line 144, in simple_response
    await self.app(scope, receive, send)
  File "C:\Users\pc\AppData\Local\Programs\Python\Python313\Lib\site-packages\starlette\middleware\exceptions.py", line 62, in __call__
    await wrap_app_handling_exceptions(self.app, conn)(scope, receive, send)
  File "C:\Users\pc\AppData\Local\Programs\Python\Python313\Lib\site-packages\starlette\_exception_handler.py", line 53, in wrapped_app
    raise exc
  File "C:\Users\pc\AppData\Local\Programs\Python\Python313\Lib\site-packages\starlette\_exception_handler.py", line 42, in wrapped_app
    await app(scope, receive, sender)
  File "C:\Users\pc\AppData\Local\Programs\Python\Python313\Lib\site-packages\starlette\routing.py", line 714, in __call__
    await self.middleware_stack(scope, receive, send)
  File "C:\Users\pc\AppData\Local\Programs\Python\Python313\Lib\site-packages\starlette\routing.py", line 734, in app
    await route.handle(scope, receive, send)
  File "C:\Users\pc\AppData\Local\Programs\Python\Python313\Lib\site-packages\starlette\routing.py", line 288, in handle
    await self.app(scope, receive, send)
  File "C:\Users\pc\AppData\Local\Programs\Python\Python313\Lib\site-packages\starlette\routing.py", line 76, in app
    await wrap_app_handling_exceptions(app, request)(scope, receive, send)
  File "C:\Users\pc\AppData\Local\Programs\Python\Python313\Lib\site-packages\starlette\_exception_handler.py", line 53, in wrapped_app
    raise exc
  File "C:\Users\pc\AppData\Local\Programs\Python\Python313\Lib\site-packages\starlette\_exception_handler.py", line 42, in wrapped_app
    await app(scope, receive, sender)
  File "C:\Users\pc\AppData\Local\Programs\Python\Python313\Lib\site-packages\starlette\routing.py", line 73, in app
    response = await f(request)
               ^^^^^^^^^^^^^^^^
  File "C:\Users\pc\AppData\Local\Programs\Python\Python313\Lib\site-packages\fastapi\routing.py", line 301, in app
    raw_response = await run_endpoint_function(
                   ^^^^^^^^^^^^^^^^^^^^^^^^^^^^
    ...<3 lines>...
    )
    ^
  File "C:\Users\pc\AppData\Local\Programs\Python\Python313\Lib\site-packages\fastapi\routing.py", line 214, in run_endpoint_function
    return await run_in_threadpool(dependant.call, **values)
           ^^^^^^^^^^^^^^^^^^^^^^^^^^^^^^^^^^^^^^^^^^^^^^^^^
  File "C:\Users\pc\AppData\Local\Programs\Python\Python313\Lib\site-packages\starlette\concurrency.py", line 37, in run_in_threadpool
    return await anyio.to_thread.run_sync(func)
           ^^^^^^^^^^^^^^^^^^^^^^^^^^^^^^^^^^^^
  File "C:\Users\pc\AppData\Local\Programs\Python\Python313\Lib\site-packages\anyio\to_thread.py", line 56, in run_sync
    return await get_async_backend().run_sync_in_worker_thread(
           ^^^^^^^^^^^^^^^^^^^^^^^^^^^^^^^^^^^^^^^^^^^^^^^^^^^^
        func, args, abandon_on_cancel=abandon_on_cancel, limiter=limiter
        ^^^^^^^^^^^^^^^^^^^^^^^^^^^^^^^^^^^^^^^^^^^^^^^^^^^^^^^^^^^^^^^^
    )
    ^
  File "C:\Users\pc\AppData\Local\Programs\Python\Python313\Lib\site-packages\anyio\_backends\_asyncio.py", line 2470, in run_sync_in_worker_thread
    return await future
           ^^^^^^^^^^^^
  File "C:\Users\pc\AppData\Local\Programs\Python\Python313\Lib\site-packages\anyio\_backends\_asyncio.py", line 967, in run
    result = context.run(func, *args)
  File "D:\Projects\Development\webcore-erp\webcore-erp\wcs-backend\app\routes\auth.py", line 56, in login
    user = db.query(User).filter(User.username == request.username).first()
           ~~~~~~~~^^^^^^
  File "C:\Users\pc\AppData\Local\Programs\Python\Python313\Lib\site-packages\sqlalchemy\orm\session.py", line 2955, in query
    return self._query_cls(entities, self, **kwargs)
           ~~~~~~~~~~~~~~~^^^^^^^^^^^^^^^^^^^^^^^^^^
  File "C:\Users\pc\AppData\Local\Programs\Python\Python313\Lib\site-packages\sqlalchemy\orm\query.py", line 276, in __init__
    self._set_entities(entities)
    ~~~~~~~~~~~~~~~~~~^^^^^^^^^^
  File "C:\Users\pc\AppData\Local\Programs\Python\Python313\Lib\site-packages\sqlalchemy\orm\query.py", line 289, in _set_entities
    coercions.expect(
    ~~~~~~~~~~~~~~~~^
        roles.ColumnsClauseRole,
        ^^^^^^^^^^^^^^^^^^^^^^^^
    ...<2 lines>...
        post_inspect=True,
        ^^^^^^^^^^^^^^^^^^
    )
    ^
  File "C:\Users\pc\AppData\Local\Programs\Python\Python313\Lib\site-packages\sqlalchemy\sql\coercions.py", line 388, in expect
    insp._post_inspect
  File "C:\Users\pc\AppData\Local\Programs\Python\Python313\Lib\site-packages\sqlalchemy\util\langhelpers.py", line 1338, in __get__
    obj.__dict__[self.__name__] = result = self.fget(obj)
                                           ~~~~~~~~~^^^^^
  File "C:\Users\pc\AppData\Local\Programs\Python\Python313\Lib\site-packages\sqlalchemy\orm\mapper.py", line 2724, in _post_inspect
    self._check_configure()
    ~~~~~~~~~~~~~~~~~~~~~^^
  File "C:\Users\pc\AppData\Local\Programs\Python\Python313\Lib\site-packages\sqlalchemy\orm\mapper.py", line 2401, in _check_configure
    _configure_registries({self.registry}, cascade=True)
    ~~~~~~~~~~~~~~~~~~~~~^^^^^^^^^^^^^^^^^^^^^^^^^^^^^^^
  File "C:\Users\pc\AppData\Local\Programs\Python\Python313\Lib\site-packages\sqlalchemy\orm\mapper.py", line 4214, in _configure_registries
    _do_configure_registries(registries, cascade)
    ~~~~~~~~~~~~~~~~~~~~~~~~^^^^^^^^^^^^^^^^^^^^^
  File "C:\Users\pc\AppData\Local\Programs\Python\Python313\Lib\site-packages\sqlalchemy\orm\mapper.py", line 4255, in _do_configure_registries
    mapper._post_configure_properties()
    ~~~~~~~~~~~~~~~~~~~~~~~~~~~~~~~~~^^
  File "C:\Users\pc\AppData\Local\Programs\Python\Python313\Lib\site-packages\sqlalchemy\orm\mapper.py", line 2418, in _post_configure_properties
    prop.init()
    ~~~~~~~~~^^
  File "C:\Users\pc\AppData\Local\Programs\Python\Python313\Lib\site-packages\sqlalchemy\orm\interfaces.py", line 589, in init
    self.do_init()
    ~~~~~~~~~~~~^^
  File "C:\Users\pc\AppData\Local\Programs\Python\Python313\Lib\site-packages\sqlalchemy\orm\relationships.py", line 1656, in do_init
    self._setup_entity()
    ~~~~~~~~~~~~~~~~~~^^
  File "C:\Users\pc\AppData\Local\Programs\Python\Python313\Lib\site-packages\sqlalchemy\orm\relationships.py", line 1866, in _setup_entity
    self._clsregistry_resolve_name(argument)(),
    ~~~~~~~~~~~~~~~~~~~~~~~~~~~~~~~~~~~~~~~~^^
  File "C:\Users\pc\AppData\Local\Programs\Python\Python313\Lib\site-packages\sqlalchemy\orm\clsregistry.py", line 520, in _resolve_name
    self._raise_for_name(name, err)
    ~~~~~~~~~~~~~~~~~~~~^^^^^^^^^^^
  File "C:\Users\pc\AppData\Local\Programs\Python\Python313\Lib\site-packages\sqlalchemy\orm\clsregistry.py", line 501, in _raise_for_name
    raise exc.InvalidRequestError(
    ...<5 lines>...
    ) from err
sqlalchemy.exc.InvalidRequestError: When initializing mapper Mapper[Client(clients)], expression 'Sales' failed to locate a name ('Sales'). If this is a class name, consider adding this relationship() to the <class 'app.models.client.Client'> class after both dependent classes have been defined.
[2025-06-23 16:38:15,081] [INFO] uvicorn.error: Shutting down
[2025-06-23 16:38:15,185] [INFO] uvicorn.error: Waiting for application shutdown.
[2025-06-23 16:38:15,186] [INFO] uvicorn.error: Application shutdown complete.
[2025-06-23 16:38:15,186] [INFO] uvicorn.error: Finished server process [2524]
[2025-06-23 16:38:19,878] [INFO] uvicorn.error: Started server process [13640]
[2025-06-23 16:38:19,879] [INFO] uvicorn.error: Waiting for application startup.
[2025-06-23 16:38:19,880] [INFO] uvicorn.error: Application startup complete.
[2025-06-23 16:38:19,882] [INFO] uvicorn.error: Uvicorn running on http://127.0.0.1:8000 (Press CTRL+C to quit)
[2025-06-23 16:38:21,956] [INFO] app.routes.auth: employee found: <app.models.employee.Employee object at 0x0000027B5E814D70>
[2025-06-23 16:38:30,252] [ERROR] uvicorn.error: Exception in ASGI application
Traceback (most recent call last):
  File "C:\Users\pc\AppData\Local\Programs\Python\Python313\Lib\site-packages\sqlalchemy\engine\base.py", line 1963, in _exec_single_context
    self.dialect.do_execute(
    ~~~~~~~~~~~~~~~~~~~~~~~^
        cursor, str_statement, effective_parameters, context
        ^^^^^^^^^^^^^^^^^^^^^^^^^^^^^^^^^^^^^^^^^^^^^^^^^^^^
    )
    ^
  File "C:\Users\pc\AppData\Local\Programs\Python\Python313\Lib\site-packages\sqlalchemy\engine\default.py", line 943, in do_execute
    cursor.execute(statement, parameters)
    ~~~~~~~~~~~~~~^^^^^^^^^^^^^^^^^^^^^^^
sqlite3.OperationalError: no such column: clients.addressline1

The above exception was the direct cause of the following exception:

Traceback (most recent call last):
  File "C:\Users\pc\AppData\Local\Programs\Python\Python313\Lib\site-packages\uvicorn\protocols\http\h11_impl.py", line 403, in run_asgi
    result = await app(  # type: ignore[func-returns-value]
             ^^^^^^^^^^^^^^^^^^^^^^^^^^^^^^^^^^^^^^^^^^^^^^
        self.scope, self.receive, self.send
        ^^^^^^^^^^^^^^^^^^^^^^^^^^^^^^^^^^^
    )
    ^
  File "C:\Users\pc\AppData\Local\Programs\Python\Python313\Lib\site-packages\uvicorn\middleware\proxy_headers.py", line 60, in __call__
    return await self.app(scope, receive, send)
           ^^^^^^^^^^^^^^^^^^^^^^^^^^^^^^^^^^^^
  File "C:\Users\pc\AppData\Local\Programs\Python\Python313\Lib\site-packages\fastapi\applications.py", line 1054, in __call__
    await super().__call__(scope, receive, send)
  File "C:\Users\pc\AppData\Local\Programs\Python\Python313\Lib\site-packages\starlette\applications.py", line 112, in __call__
    await self.middleware_stack(scope, receive, send)
  File "C:\Users\pc\AppData\Local\Programs\Python\Python313\Lib\site-packages\starlette\middleware\errors.py", line 187, in __call__
    raise exc
  File "C:\Users\pc\AppData\Local\Programs\Python\Python313\Lib\site-packages\starlette\middleware\errors.py", line 165, in __call__
    await self.app(scope, receive, _send)
  File "C:\Users\pc\AppData\Local\Programs\Python\Python313\Lib\site-packages\starlette\middleware\cors.py", line 93, in __call__
    await self.simple_response(scope, receive, send, request_headers=headers)
  File "C:\Users\pc\AppData\Local\Programs\Python\Python313\Lib\site-packages\starlette\middleware\cors.py", line 144, in simple_response
    await self.app(scope, receive, send)
  File "C:\Users\pc\AppData\Local\Programs\Python\Python313\Lib\site-packages\starlette\middleware\exceptions.py", line 62, in __call__
    await wrap_app_handling_exceptions(self.app, conn)(scope, receive, send)
  File "C:\Users\pc\AppData\Local\Programs\Python\Python313\Lib\site-packages\starlette\_exception_handler.py", line 53, in wrapped_app
    raise exc
  File "C:\Users\pc\AppData\Local\Programs\Python\Python313\Lib\site-packages\starlette\_exception_handler.py", line 42, in wrapped_app
    await app(scope, receive, sender)
  File "C:\Users\pc\AppData\Local\Programs\Python\Python313\Lib\site-packages\starlette\routing.py", line 714, in __call__
    await self.middleware_stack(scope, receive, send)
  File "C:\Users\pc\AppData\Local\Programs\Python\Python313\Lib\site-packages\starlette\routing.py", line 734, in app
    await route.handle(scope, receive, send)
  File "C:\Users\pc\AppData\Local\Programs\Python\Python313\Lib\site-packages\starlette\routing.py", line 288, in handle
    await self.app(scope, receive, send)
  File "C:\Users\pc\AppData\Local\Programs\Python\Python313\Lib\site-packages\starlette\routing.py", line 76, in app
    await wrap_app_handling_exceptions(app, request)(scope, receive, send)
  File "C:\Users\pc\AppData\Local\Programs\Python\Python313\Lib\site-packages\starlette\_exception_handler.py", line 53, in wrapped_app
    raise exc
  File "C:\Users\pc\AppData\Local\Programs\Python\Python313\Lib\site-packages\starlette\_exception_handler.py", line 42, in wrapped_app
    await app(scope, receive, sender)
  File "C:\Users\pc\AppData\Local\Programs\Python\Python313\Lib\site-packages\starlette\routing.py", line 73, in app
    response = await f(request)
               ^^^^^^^^^^^^^^^^
  File "C:\Users\pc\AppData\Local\Programs\Python\Python313\Lib\site-packages\fastapi\routing.py", line 301, in app
    raw_response = await run_endpoint_function(
                   ^^^^^^^^^^^^^^^^^^^^^^^^^^^^
    ...<3 lines>...
    )
    ^
  File "C:\Users\pc\AppData\Local\Programs\Python\Python313\Lib\site-packages\fastapi\routing.py", line 214, in run_endpoint_function
    return await run_in_threadpool(dependant.call, **values)
           ^^^^^^^^^^^^^^^^^^^^^^^^^^^^^^^^^^^^^^^^^^^^^^^^^
  File "C:\Users\pc\AppData\Local\Programs\Python\Python313\Lib\site-packages\starlette\concurrency.py", line 37, in run_in_threadpool
    return await anyio.to_thread.run_sync(func)
           ^^^^^^^^^^^^^^^^^^^^^^^^^^^^^^^^^^^^
  File "C:\Users\pc\AppData\Local\Programs\Python\Python313\Lib\site-packages\anyio\to_thread.py", line 56, in run_sync
    return await get_async_backend().run_sync_in_worker_thread(
           ^^^^^^^^^^^^^^^^^^^^^^^^^^^^^^^^^^^^^^^^^^^^^^^^^^^^
        func, args, abandon_on_cancel=abandon_on_cancel, limiter=limiter
        ^^^^^^^^^^^^^^^^^^^^^^^^^^^^^^^^^^^^^^^^^^^^^^^^^^^^^^^^^^^^^^^^
    )
    ^
  File "C:\Users\pc\AppData\Local\Programs\Python\Python313\Lib\site-packages\anyio\_backends\_asyncio.py", line 2470, in run_sync_in_worker_thread
    return await future
           ^^^^^^^^^^^^
  File "C:\Users\pc\AppData\Local\Programs\Python\Python313\Lib\site-packages\anyio\_backends\_asyncio.py", line 967, in run
    result = context.run(func, *args)
  File "D:\Projects\Development\webcore-erp\webcore-erp\wcs-backend\app\routes\client.py", line 35, in get_clients
    return db.query(Client).offset(skip).limit(limit).all()
           ~~~~~~~~~~~~~~~~~~~~~~~~~~~~~~~~~~~~~~~~~~~~~~^^
  File "C:\Users\pc\AppData\Local\Programs\Python\Python313\Lib\site-packages\sqlalchemy\orm\query.py", line 2704, in all
    return self._iter().all()  # type: ignore
           ~~~~~~~~~~^^
  File "C:\Users\pc\AppData\Local\Programs\Python\Python313\Lib\site-packages\sqlalchemy\orm\query.py", line 2857, in _iter
    result: Union[ScalarResult[_T], Result[_T]] = self.session.execute(
                                                  ~~~~~~~~~~~~~~~~~~~~^
        statement,
        ^^^^^^^^^^
        params,
        ^^^^^^^
        execution_options={"_sa_orm_load_options": self.load_options},
        ^^^^^^^^^^^^^^^^^^^^^^^^^^^^^^^^^^^^^^^^^^^^^^^^^^^^^^^^^^^^^^
    )
    ^
  File "C:\Users\pc\AppData\Local\Programs\Python\Python313\Lib\site-packages\sqlalchemy\orm\session.py", line 2365, in execute
    return self._execute_internal(
           ~~~~~~~~~~~~~~~~~~~~~~^
        statement,
        ^^^^^^^^^^
    ...<4 lines>...
        _add_event=_add_event,
        ^^^^^^^^^^^^^^^^^^^^^^
    )
    ^
  File "C:\Users\pc\AppData\Local\Programs\Python\Python313\Lib\site-packages\sqlalchemy\orm\session.py", line 2251, in _execute_internal
    result: Result[Any] = compile_state_cls.orm_execute_statement(
                          ~~~~~~~~~~~~~~~~~~~~~~~~~~~~~~~~~~~~~~~^
        self,
        ^^^^^
    ...<4 lines>...
        conn,
        ^^^^^
    )
    ^
  File "C:\Users\pc\AppData\Local\Programs\Python\Python313\Lib\site-packages\sqlalchemy\orm\context.py", line 306, in orm_execute_statement
    result = conn.execute(
        statement, params or {}, execution_options=execution_options
    )
  File "C:\Users\pc\AppData\Local\Programs\Python\Python313\Lib\site-packages\sqlalchemy\engine\base.py", line 1415, in execute
    return meth(
        self,
        distilled_parameters,
        execution_options or NO_OPTIONS,
    )
  File "C:\Users\pc\AppData\Local\Programs\Python\Python313\Lib\site-packages\sqlalchemy\sql\elements.py", line 523, in _execute_on_connection
    return connection._execute_clauseelement(
           ~~~~~~~~~~~~~~~~~~~~~~~~~~~~~~~~~^
        self, distilled_params, execution_options
        ^^^^^^^^^^^^^^^^^^^^^^^^^^^^^^^^^^^^^^^^^
    )
    ^
  File "C:\Users\pc\AppData\Local\Programs\Python\Python313\Lib\site-packages\sqlalchemy\engine\base.py", line 1637, in _execute_clauseelement
    ret = self._execute_context(
        dialect,
    ...<8 lines>...
        cache_hit=cache_hit,
    )
  File "C:\Users\pc\AppData\Local\Programs\Python\Python313\Lib\site-packages\sqlalchemy\engine\base.py", line 1842, in _execute_context
    return self._exec_single_context(
           ~~~~~~~~~~~~~~~~~~~~~~~~~^
        dialect, context, statement, parameters
        ^^^^^^^^^^^^^^^^^^^^^^^^^^^^^^^^^^^^^^^
    )
    ^
  File "C:\Users\pc\AppData\Local\Programs\Python\Python313\Lib\site-packages\sqlalchemy\engine\base.py", line 1982, in _exec_single_context
    self._handle_dbapi_exception(
    ~~~~~~~~~~~~~~~~~~~~~~~~~~~~^
        e, str_statement, effective_parameters, cursor, context
        ^^^^^^^^^^^^^^^^^^^^^^^^^^^^^^^^^^^^^^^^^^^^^^^^^^^^^^^
    )
    ^
  File "C:\Users\pc\AppData\Local\Programs\Python\Python313\Lib\site-packages\sqlalchemy\engine\base.py", line 2351, in _handle_dbapi_exception
    raise sqlalchemy_exception.with_traceback(exc_info[2]) from e
  File "C:\Users\pc\AppData\Local\Programs\Python\Python313\Lib\site-packages\sqlalchemy\engine\base.py", line 1963, in _exec_single_context
    self.dialect.do_execute(
    ~~~~~~~~~~~~~~~~~~~~~~~^
        cursor, str_statement, effective_parameters, context
        ^^^^^^^^^^^^^^^^^^^^^^^^^^^^^^^^^^^^^^^^^^^^^^^^^^^^
    )
    ^
  File "C:\Users\pc\AppData\Local\Programs\Python\Python313\Lib\site-packages\sqlalchemy\engine\default.py", line 943, in do_execute
    cursor.execute(statement, parameters)
    ~~~~~~~~~~~~~~^^^^^^^^^^^^^^^^^^^^^^^
sqlalchemy.exc.OperationalError: (sqlite3.OperationalError) no such column: clients.addressline1
[SQL: SELECT clients.id AS clients_id, clients.name AS clients_name, clients.client_code AS clients_client_code, clients.contact_person AS clients_contact_person, clients.email AS clients_email, clients.phone AS clients_phone, clients.addressline1 AS clients_addressline1, clients.addressline2 AS clients_addressline2, clients.state AS clients_state, clients.coutry AS clients_coutry, clients.pincode AS clients_pincode, clients.gst_number AS clients_gst_number, clients.is_deleted AS clients_is_deleted 
FROM clients
 LIMIT ? OFFSET ?]
[parameters: (10, 0)]
(Background on this error at: https://sqlalche.me/e/20/e3q8)
[2025-06-23 16:38:30,561] [ERROR] uvicorn.error: Exception in ASGI application
Traceback (most recent call last):
  File "C:\Users\pc\AppData\Local\Programs\Python\Python313\Lib\site-packages\sqlalchemy\engine\base.py", line 1963, in _exec_single_context
    self.dialect.do_execute(
    ~~~~~~~~~~~~~~~~~~~~~~~^
        cursor, str_statement, effective_parameters, context
        ^^^^^^^^^^^^^^^^^^^^^^^^^^^^^^^^^^^^^^^^^^^^^^^^^^^^
    )
    ^
  File "C:\Users\pc\AppData\Local\Programs\Python\Python313\Lib\site-packages\sqlalchemy\engine\default.py", line 943, in do_execute
    cursor.execute(statement, parameters)
    ~~~~~~~~~~~~~~^^^^^^^^^^^^^^^^^^^^^^^
sqlite3.OperationalError: no such column: clients.addressline1

The above exception was the direct cause of the following exception:

Traceback (most recent call last):
  File "C:\Users\pc\AppData\Local\Programs\Python\Python313\Lib\site-packages\uvicorn\protocols\http\h11_impl.py", line 403, in run_asgi
    result = await app(  # type: ignore[func-returns-value]
             ^^^^^^^^^^^^^^^^^^^^^^^^^^^^^^^^^^^^^^^^^^^^^^
        self.scope, self.receive, self.send
        ^^^^^^^^^^^^^^^^^^^^^^^^^^^^^^^^^^^
    )
    ^
  File "C:\Users\pc\AppData\Local\Programs\Python\Python313\Lib\site-packages\uvicorn\middleware\proxy_headers.py", line 60, in __call__
    return await self.app(scope, receive, send)
           ^^^^^^^^^^^^^^^^^^^^^^^^^^^^^^^^^^^^
  File "C:\Users\pc\AppData\Local\Programs\Python\Python313\Lib\site-packages\fastapi\applications.py", line 1054, in __call__
    await super().__call__(scope, receive, send)
  File "C:\Users\pc\AppData\Local\Programs\Python\Python313\Lib\site-packages\starlette\applications.py", line 112, in __call__
    await self.middleware_stack(scope, receive, send)
  File "C:\Users\pc\AppData\Local\Programs\Python\Python313\Lib\site-packages\starlette\middleware\errors.py", line 187, in __call__
    raise exc
  File "C:\Users\pc\AppData\Local\Programs\Python\Python313\Lib\site-packages\starlette\middleware\errors.py", line 165, in __call__
    await self.app(scope, receive, _send)
  File "C:\Users\pc\AppData\Local\Programs\Python\Python313\Lib\site-packages\starlette\middleware\cors.py", line 93, in __call__
    await self.simple_response(scope, receive, send, request_headers=headers)
  File "C:\Users\pc\AppData\Local\Programs\Python\Python313\Lib\site-packages\starlette\middleware\cors.py", line 144, in simple_response
    await self.app(scope, receive, send)
  File "C:\Users\pc\AppData\Local\Programs\Python\Python313\Lib\site-packages\starlette\middleware\exceptions.py", line 62, in __call__
    await wrap_app_handling_exceptions(self.app, conn)(scope, receive, send)
  File "C:\Users\pc\AppData\Local\Programs\Python\Python313\Lib\site-packages\starlette\_exception_handler.py", line 53, in wrapped_app
    raise exc
  File "C:\Users\pc\AppData\Local\Programs\Python\Python313\Lib\site-packages\starlette\_exception_handler.py", line 42, in wrapped_app
    await app(scope, receive, sender)
  File "C:\Users\pc\AppData\Local\Programs\Python\Python313\Lib\site-packages\starlette\routing.py", line 714, in __call__
    await self.middleware_stack(scope, receive, send)
  File "C:\Users\pc\AppData\Local\Programs\Python\Python313\Lib\site-packages\starlette\routing.py", line 734, in app
    await route.handle(scope, receive, send)
  File "C:\Users\pc\AppData\Local\Programs\Python\Python313\Lib\site-packages\starlette\routing.py", line 288, in handle
    await self.app(scope, receive, send)
  File "C:\Users\pc\AppData\Local\Programs\Python\Python313\Lib\site-packages\starlette\routing.py", line 76, in app
    await wrap_app_handling_exceptions(app, request)(scope, receive, send)
  File "C:\Users\pc\AppData\Local\Programs\Python\Python313\Lib\site-packages\starlette\_exception_handler.py", line 53, in wrapped_app
    raise exc
  File "C:\Users\pc\AppData\Local\Programs\Python\Python313\Lib\site-packages\starlette\_exception_handler.py", line 42, in wrapped_app
    await app(scope, receive, sender)
  File "C:\Users\pc\AppData\Local\Programs\Python\Python313\Lib\site-packages\starlette\routing.py", line 73, in app
    response = await f(request)
               ^^^^^^^^^^^^^^^^
  File "C:\Users\pc\AppData\Local\Programs\Python\Python313\Lib\site-packages\fastapi\routing.py", line 301, in app
    raw_response = await run_endpoint_function(
                   ^^^^^^^^^^^^^^^^^^^^^^^^^^^^
    ...<3 lines>...
    )
    ^
  File "C:\Users\pc\AppData\Local\Programs\Python\Python313\Lib\site-packages\fastapi\routing.py", line 214, in run_endpoint_function
    return await run_in_threadpool(dependant.call, **values)
           ^^^^^^^^^^^^^^^^^^^^^^^^^^^^^^^^^^^^^^^^^^^^^^^^^
  File "C:\Users\pc\AppData\Local\Programs\Python\Python313\Lib\site-packages\starlette\concurrency.py", line 37, in run_in_threadpool
    return await anyio.to_thread.run_sync(func)
           ^^^^^^^^^^^^^^^^^^^^^^^^^^^^^^^^^^^^
  File "C:\Users\pc\AppData\Local\Programs\Python\Python313\Lib\site-packages\anyio\to_thread.py", line 56, in run_sync
    return await get_async_backend().run_sync_in_worker_thread(
           ^^^^^^^^^^^^^^^^^^^^^^^^^^^^^^^^^^^^^^^^^^^^^^^^^^^^
        func, args, abandon_on_cancel=abandon_on_cancel, limiter=limiter
        ^^^^^^^^^^^^^^^^^^^^^^^^^^^^^^^^^^^^^^^^^^^^^^^^^^^^^^^^^^^^^^^^
    )
    ^
  File "C:\Users\pc\AppData\Local\Programs\Python\Python313\Lib\site-packages\anyio\_backends\_asyncio.py", line 2470, in run_sync_in_worker_thread
    return await future
           ^^^^^^^^^^^^
  File "C:\Users\pc\AppData\Local\Programs\Python\Python313\Lib\site-packages\anyio\_backends\_asyncio.py", line 967, in run
    result = context.run(func, *args)
  File "D:\Projects\Development\webcore-erp\webcore-erp\wcs-backend\app\routes\client.py", line 35, in get_clients
    return db.query(Client).offset(skip).limit(limit).all()
           ~~~~~~~~~~~~~~~~~~~~~~~~~~~~~~~~~~~~~~~~~~~~~~^^
  File "C:\Users\pc\AppData\Local\Programs\Python\Python313\Lib\site-packages\sqlalchemy\orm\query.py", line 2704, in all
    return self._iter().all()  # type: ignore
           ~~~~~~~~~~^^
  File "C:\Users\pc\AppData\Local\Programs\Python\Python313\Lib\site-packages\sqlalchemy\orm\query.py", line 2857, in _iter
    result: Union[ScalarResult[_T], Result[_T]] = self.session.execute(
                                                  ~~~~~~~~~~~~~~~~~~~~^
        statement,
        ^^^^^^^^^^
        params,
        ^^^^^^^
        execution_options={"_sa_orm_load_options": self.load_options},
        ^^^^^^^^^^^^^^^^^^^^^^^^^^^^^^^^^^^^^^^^^^^^^^^^^^^^^^^^^^^^^^
    )
    ^
  File "C:\Users\pc\AppData\Local\Programs\Python\Python313\Lib\site-packages\sqlalchemy\orm\session.py", line 2365, in execute
    return self._execute_internal(
           ~~~~~~~~~~~~~~~~~~~~~~^
        statement,
        ^^^^^^^^^^
    ...<4 lines>...
        _add_event=_add_event,
        ^^^^^^^^^^^^^^^^^^^^^^
    )
    ^
  File "C:\Users\pc\AppData\Local\Programs\Python\Python313\Lib\site-packages\sqlalchemy\orm\session.py", line 2251, in _execute_internal
    result: Result[Any] = compile_state_cls.orm_execute_statement(
                          ~~~~~~~~~~~~~~~~~~~~~~~~~~~~~~~~~~~~~~~^
        self,
        ^^^^^
    ...<4 lines>...
        conn,
        ^^^^^
    )
    ^
  File "C:\Users\pc\AppData\Local\Programs\Python\Python313\Lib\site-packages\sqlalchemy\orm\context.py", line 306, in orm_execute_statement
    result = conn.execute(
        statement, params or {}, execution_options=execution_options
    )
  File "C:\Users\pc\AppData\Local\Programs\Python\Python313\Lib\site-packages\sqlalchemy\engine\base.py", line 1415, in execute
    return meth(
        self,
        distilled_parameters,
        execution_options or NO_OPTIONS,
    )
  File "C:\Users\pc\AppData\Local\Programs\Python\Python313\Lib\site-packages\sqlalchemy\sql\elements.py", line 523, in _execute_on_connection
    return connection._execute_clauseelement(
           ~~~~~~~~~~~~~~~~~~~~~~~~~~~~~~~~~^
        self, distilled_params, execution_options
        ^^^^^^^^^^^^^^^^^^^^^^^^^^^^^^^^^^^^^^^^^
    )
    ^
  File "C:\Users\pc\AppData\Local\Programs\Python\Python313\Lib\site-packages\sqlalchemy\engine\base.py", line 1637, in _execute_clauseelement
    ret = self._execute_context(
        dialect,
    ...<8 lines>...
        cache_hit=cache_hit,
    )
  File "C:\Users\pc\AppData\Local\Programs\Python\Python313\Lib\site-packages\sqlalchemy\engine\base.py", line 1842, in _execute_context
    return self._exec_single_context(
           ~~~~~~~~~~~~~~~~~~~~~~~~~^
        dialect, context, statement, parameters
        ^^^^^^^^^^^^^^^^^^^^^^^^^^^^^^^^^^^^^^^
    )
    ^
  File "C:\Users\pc\AppData\Local\Programs\Python\Python313\Lib\site-packages\sqlalchemy\engine\base.py", line 1982, in _exec_single_context
    self._handle_dbapi_exception(
    ~~~~~~~~~~~~~~~~~~~~~~~~~~~~^
        e, str_statement, effective_parameters, cursor, context
        ^^^^^^^^^^^^^^^^^^^^^^^^^^^^^^^^^^^^^^^^^^^^^^^^^^^^^^^
    )
    ^
  File "C:\Users\pc\AppData\Local\Programs\Python\Python313\Lib\site-packages\sqlalchemy\engine\base.py", line 2351, in _handle_dbapi_exception
    raise sqlalchemy_exception.with_traceback(exc_info[2]) from e
  File "C:\Users\pc\AppData\Local\Programs\Python\Python313\Lib\site-packages\sqlalchemy\engine\base.py", line 1963, in _exec_single_context
    self.dialect.do_execute(
    ~~~~~~~~~~~~~~~~~~~~~~~^
        cursor, str_statement, effective_parameters, context
        ^^^^^^^^^^^^^^^^^^^^^^^^^^^^^^^^^^^^^^^^^^^^^^^^^^^^
    )
    ^
  File "C:\Users\pc\AppData\Local\Programs\Python\Python313\Lib\site-packages\sqlalchemy\engine\default.py", line 943, in do_execute
    cursor.execute(statement, parameters)
    ~~~~~~~~~~~~~~^^^^^^^^^^^^^^^^^^^^^^^
sqlalchemy.exc.OperationalError: (sqlite3.OperationalError) no such column: clients.addressline1
[SQL: SELECT clients.id AS clients_id, clients.name AS clients_name, clients.client_code AS clients_client_code, clients.contact_person AS clients_contact_person, clients.email AS clients_email, clients.phone AS clients_phone, clients.addressline1 AS clients_addressline1, clients.addressline2 AS clients_addressline2, clients.state AS clients_state, clients.coutry AS clients_coutry, clients.pincode AS clients_pincode, clients.gst_number AS clients_gst_number, clients.is_deleted AS clients_is_deleted 
FROM clients
 LIMIT ? OFFSET ?]
[parameters: (10, 0)]
(Background on this error at: https://sqlalche.me/e/20/e3q8)
[2025-06-23 16:38:41,226] [ERROR] uvicorn.error: Exception in ASGI application
Traceback (most recent call last):
  File "C:\Users\pc\AppData\Local\Programs\Python\Python313\Lib\site-packages\sqlalchemy\engine\base.py", line 1963, in _exec_single_context
    self.dialect.do_execute(
    ~~~~~~~~~~~~~~~~~~~~~~~^
        cursor, str_statement, effective_parameters, context
        ^^^^^^^^^^^^^^^^^^^^^^^^^^^^^^^^^^^^^^^^^^^^^^^^^^^^
    )
    ^
  File "C:\Users\pc\AppData\Local\Programs\Python\Python313\Lib\site-packages\sqlalchemy\engine\default.py", line 943, in do_execute
    cursor.execute(statement, parameters)
    ~~~~~~~~~~~~~~^^^^^^^^^^^^^^^^^^^^^^^
sqlite3.OperationalError: no such column: clients.addressline1

The above exception was the direct cause of the following exception:

Traceback (most recent call last):
  File "C:\Users\pc\AppData\Local\Programs\Python\Python313\Lib\site-packages\uvicorn\protocols\http\h11_impl.py", line 403, in run_asgi
    result = await app(  # type: ignore[func-returns-value]
             ^^^^^^^^^^^^^^^^^^^^^^^^^^^^^^^^^^^^^^^^^^^^^^
        self.scope, self.receive, self.send
        ^^^^^^^^^^^^^^^^^^^^^^^^^^^^^^^^^^^
    )
    ^
  File "C:\Users\pc\AppData\Local\Programs\Python\Python313\Lib\site-packages\uvicorn\middleware\proxy_headers.py", line 60, in __call__
    return await self.app(scope, receive, send)
           ^^^^^^^^^^^^^^^^^^^^^^^^^^^^^^^^^^^^
  File "C:\Users\pc\AppData\Local\Programs\Python\Python313\Lib\site-packages\fastapi\applications.py", line 1054, in __call__
    await super().__call__(scope, receive, send)
  File "C:\Users\pc\AppData\Local\Programs\Python\Python313\Lib\site-packages\starlette\applications.py", line 112, in __call__
    await self.middleware_stack(scope, receive, send)
  File "C:\Users\pc\AppData\Local\Programs\Python\Python313\Lib\site-packages\starlette\middleware\errors.py", line 187, in __call__
    raise exc
  File "C:\Users\pc\AppData\Local\Programs\Python\Python313\Lib\site-packages\starlette\middleware\errors.py", line 165, in __call__
    await self.app(scope, receive, _send)
  File "C:\Users\pc\AppData\Local\Programs\Python\Python313\Lib\site-packages\starlette\middleware\cors.py", line 93, in __call__
    await self.simple_response(scope, receive, send, request_headers=headers)
  File "C:\Users\pc\AppData\Local\Programs\Python\Python313\Lib\site-packages\starlette\middleware\cors.py", line 144, in simple_response
    await self.app(scope, receive, send)
  File "C:\Users\pc\AppData\Local\Programs\Python\Python313\Lib\site-packages\starlette\middleware\exceptions.py", line 62, in __call__
    await wrap_app_handling_exceptions(self.app, conn)(scope, receive, send)
  File "C:\Users\pc\AppData\Local\Programs\Python\Python313\Lib\site-packages\starlette\_exception_handler.py", line 53, in wrapped_app
    raise exc
  File "C:\Users\pc\AppData\Local\Programs\Python\Python313\Lib\site-packages\starlette\_exception_handler.py", line 42, in wrapped_app
    await app(scope, receive, sender)
  File "C:\Users\pc\AppData\Local\Programs\Python\Python313\Lib\site-packages\starlette\routing.py", line 714, in __call__
    await self.middleware_stack(scope, receive, send)
  File "C:\Users\pc\AppData\Local\Programs\Python\Python313\Lib\site-packages\starlette\routing.py", line 734, in app
    await route.handle(scope, receive, send)
  File "C:\Users\pc\AppData\Local\Programs\Python\Python313\Lib\site-packages\starlette\routing.py", line 288, in handle
    await self.app(scope, receive, send)
  File "C:\Users\pc\AppData\Local\Programs\Python\Python313\Lib\site-packages\starlette\routing.py", line 76, in app
    await wrap_app_handling_exceptions(app, request)(scope, receive, send)
  File "C:\Users\pc\AppData\Local\Programs\Python\Python313\Lib\site-packages\starlette\_exception_handler.py", line 53, in wrapped_app
    raise exc
  File "C:\Users\pc\AppData\Local\Programs\Python\Python313\Lib\site-packages\starlette\_exception_handler.py", line 42, in wrapped_app
    await app(scope, receive, sender)
  File "C:\Users\pc\AppData\Local\Programs\Python\Python313\Lib\site-packages\starlette\routing.py", line 73, in app
    response = await f(request)
               ^^^^^^^^^^^^^^^^
  File "C:\Users\pc\AppData\Local\Programs\Python\Python313\Lib\site-packages\fastapi\routing.py", line 301, in app
    raw_response = await run_endpoint_function(
                   ^^^^^^^^^^^^^^^^^^^^^^^^^^^^
    ...<3 lines>...
    )
    ^
  File "C:\Users\pc\AppData\Local\Programs\Python\Python313\Lib\site-packages\fastapi\routing.py", line 214, in run_endpoint_function
    return await run_in_threadpool(dependant.call, **values)
           ^^^^^^^^^^^^^^^^^^^^^^^^^^^^^^^^^^^^^^^^^^^^^^^^^
  File "C:\Users\pc\AppData\Local\Programs\Python\Python313\Lib\site-packages\starlette\concurrency.py", line 37, in run_in_threadpool
    return await anyio.to_thread.run_sync(func)
           ^^^^^^^^^^^^^^^^^^^^^^^^^^^^^^^^^^^^
  File "C:\Users\pc\AppData\Local\Programs\Python\Python313\Lib\site-packages\anyio\to_thread.py", line 56, in run_sync
    return await get_async_backend().run_sync_in_worker_thread(
           ^^^^^^^^^^^^^^^^^^^^^^^^^^^^^^^^^^^^^^^^^^^^^^^^^^^^
        func, args, abandon_on_cancel=abandon_on_cancel, limiter=limiter
        ^^^^^^^^^^^^^^^^^^^^^^^^^^^^^^^^^^^^^^^^^^^^^^^^^^^^^^^^^^^^^^^^
    )
    ^
  File "C:\Users\pc\AppData\Local\Programs\Python\Python313\Lib\site-packages\anyio\_backends\_asyncio.py", line 2470, in run_sync_in_worker_thread
    return await future
           ^^^^^^^^^^^^
  File "C:\Users\pc\AppData\Local\Programs\Python\Python313\Lib\site-packages\anyio\_backends\_asyncio.py", line 967, in run
    result = context.run(func, *args)
  File "D:\Projects\Development\webcore-erp\webcore-erp\wcs-backend\app\routes\client.py", line 35, in get_clients
    return db.query(Client).offset(skip).limit(limit).all()
           ~~~~~~~~~~~~~~~~~~~~~~~~~~~~~~~~~~~~~~~~~~~~~~^^
  File "C:\Users\pc\AppData\Local\Programs\Python\Python313\Lib\site-packages\sqlalchemy\orm\query.py", line 2704, in all
    return self._iter().all()  # type: ignore
           ~~~~~~~~~~^^
  File "C:\Users\pc\AppData\Local\Programs\Python\Python313\Lib\site-packages\sqlalchemy\orm\query.py", line 2857, in _iter
    result: Union[ScalarResult[_T], Result[_T]] = self.session.execute(
                                                  ~~~~~~~~~~~~~~~~~~~~^
        statement,
        ^^^^^^^^^^
        params,
        ^^^^^^^
        execution_options={"_sa_orm_load_options": self.load_options},
        ^^^^^^^^^^^^^^^^^^^^^^^^^^^^^^^^^^^^^^^^^^^^^^^^^^^^^^^^^^^^^^
    )
    ^
  File "C:\Users\pc\AppData\Local\Programs\Python\Python313\Lib\site-packages\sqlalchemy\orm\session.py", line 2365, in execute
    return self._execute_internal(
           ~~~~~~~~~~~~~~~~~~~~~~^
        statement,
        ^^^^^^^^^^
    ...<4 lines>...
        _add_event=_add_event,
        ^^^^^^^^^^^^^^^^^^^^^^
    )
    ^
  File "C:\Users\pc\AppData\Local\Programs\Python\Python313\Lib\site-packages\sqlalchemy\orm\session.py", line 2251, in _execute_internal
    result: Result[Any] = compile_state_cls.orm_execute_statement(
                          ~~~~~~~~~~~~~~~~~~~~~~~~~~~~~~~~~~~~~~~^
        self,
        ^^^^^
    ...<4 lines>...
        conn,
        ^^^^^
    )
    ^
  File "C:\Users\pc\AppData\Local\Programs\Python\Python313\Lib\site-packages\sqlalchemy\orm\context.py", line 306, in orm_execute_statement
    result = conn.execute(
        statement, params or {}, execution_options=execution_options
    )
  File "C:\Users\pc\AppData\Local\Programs\Python\Python313\Lib\site-packages\sqlalchemy\engine\base.py", line 1415, in execute
    return meth(
        self,
        distilled_parameters,
        execution_options or NO_OPTIONS,
    )
  File "C:\Users\pc\AppData\Local\Programs\Python\Python313\Lib\site-packages\sqlalchemy\sql\elements.py", line 523, in _execute_on_connection
    return connection._execute_clauseelement(
           ~~~~~~~~~~~~~~~~~~~~~~~~~~~~~~~~~^
        self, distilled_params, execution_options
        ^^^^^^^^^^^^^^^^^^^^^^^^^^^^^^^^^^^^^^^^^
    )
    ^
  File "C:\Users\pc\AppData\Local\Programs\Python\Python313\Lib\site-packages\sqlalchemy\engine\base.py", line 1637, in _execute_clauseelement
    ret = self._execute_context(
        dialect,
    ...<8 lines>...
        cache_hit=cache_hit,
    )
  File "C:\Users\pc\AppData\Local\Programs\Python\Python313\Lib\site-packages\sqlalchemy\engine\base.py", line 1842, in _execute_context
    return self._exec_single_context(
           ~~~~~~~~~~~~~~~~~~~~~~~~~^
        dialect, context, statement, parameters
        ^^^^^^^^^^^^^^^^^^^^^^^^^^^^^^^^^^^^^^^
    )
    ^
  File "C:\Users\pc\AppData\Local\Programs\Python\Python313\Lib\site-packages\sqlalchemy\engine\base.py", line 1982, in _exec_single_context
    self._handle_dbapi_exception(
    ~~~~~~~~~~~~~~~~~~~~~~~~~~~~^
        e, str_statement, effective_parameters, cursor, context
        ^^^^^^^^^^^^^^^^^^^^^^^^^^^^^^^^^^^^^^^^^^^^^^^^^^^^^^^
    )
    ^
  File "C:\Users\pc\AppData\Local\Programs\Python\Python313\Lib\site-packages\sqlalchemy\engine\base.py", line 2351, in _handle_dbapi_exception
    raise sqlalchemy_exception.with_traceback(exc_info[2]) from e
  File "C:\Users\pc\AppData\Local\Programs\Python\Python313\Lib\site-packages\sqlalchemy\engine\base.py", line 1963, in _exec_single_context
    self.dialect.do_execute(
    ~~~~~~~~~~~~~~~~~~~~~~~^
        cursor, str_statement, effective_parameters, context
        ^^^^^^^^^^^^^^^^^^^^^^^^^^^^^^^^^^^^^^^^^^^^^^^^^^^^
    )
    ^
  File "C:\Users\pc\AppData\Local\Programs\Python\Python313\Lib\site-packages\sqlalchemy\engine\default.py", line 943, in do_execute
    cursor.execute(statement, parameters)
    ~~~~~~~~~~~~~~^^^^^^^^^^^^^^^^^^^^^^^
sqlalchemy.exc.OperationalError: (sqlite3.OperationalError) no such column: clients.addressline1
[SQL: SELECT clients.id AS clients_id, clients.name AS clients_name, clients.client_code AS clients_client_code, clients.contact_person AS clients_contact_person, clients.email AS clients_email, clients.phone AS clients_phone, clients.addressline1 AS clients_addressline1, clients.addressline2 AS clients_addressline2, clients.state AS clients_state, clients.coutry AS clients_coutry, clients.pincode AS clients_pincode, clients.gst_number AS clients_gst_number, clients.is_deleted AS clients_is_deleted 
FROM clients
 LIMIT ? OFFSET ?]
[parameters: (10, 0)]
(Background on this error at: https://sqlalche.me/e/20/e3q8)
[2025-06-23 16:38:41,475] [ERROR] uvicorn.error: Exception in ASGI application
Traceback (most recent call last):
  File "C:\Users\pc\AppData\Local\Programs\Python\Python313\Lib\site-packages\sqlalchemy\engine\base.py", line 1963, in _exec_single_context
    self.dialect.do_execute(
    ~~~~~~~~~~~~~~~~~~~~~~~^
        cursor, str_statement, effective_parameters, context
        ^^^^^^^^^^^^^^^^^^^^^^^^^^^^^^^^^^^^^^^^^^^^^^^^^^^^
    )
    ^
  File "C:\Users\pc\AppData\Local\Programs\Python\Python313\Lib\site-packages\sqlalchemy\engine\default.py", line 943, in do_execute
    cursor.execute(statement, parameters)
    ~~~~~~~~~~~~~~^^^^^^^^^^^^^^^^^^^^^^^
sqlite3.OperationalError: no such column: clients.addressline1

The above exception was the direct cause of the following exception:

Traceback (most recent call last):
  File "C:\Users\pc\AppData\Local\Programs\Python\Python313\Lib\site-packages\uvicorn\protocols\http\h11_impl.py", line 403, in run_asgi
    result = await app(  # type: ignore[func-returns-value]
             ^^^^^^^^^^^^^^^^^^^^^^^^^^^^^^^^^^^^^^^^^^^^^^
        self.scope, self.receive, self.send
        ^^^^^^^^^^^^^^^^^^^^^^^^^^^^^^^^^^^
    )
    ^
  File "C:\Users\pc\AppData\Local\Programs\Python\Python313\Lib\site-packages\uvicorn\middleware\proxy_headers.py", line 60, in __call__
    return await self.app(scope, receive, send)
           ^^^^^^^^^^^^^^^^^^^^^^^^^^^^^^^^^^^^
  File "C:\Users\pc\AppData\Local\Programs\Python\Python313\Lib\site-packages\fastapi\applications.py", line 1054, in __call__
    await super().__call__(scope, receive, send)
  File "C:\Users\pc\AppData\Local\Programs\Python\Python313\Lib\site-packages\starlette\applications.py", line 112, in __call__
    await self.middleware_stack(scope, receive, send)
  File "C:\Users\pc\AppData\Local\Programs\Python\Python313\Lib\site-packages\starlette\middleware\errors.py", line 187, in __call__
    raise exc
  File "C:\Users\pc\AppData\Local\Programs\Python\Python313\Lib\site-packages\starlette\middleware\errors.py", line 165, in __call__
    await self.app(scope, receive, _send)
  File "C:\Users\pc\AppData\Local\Programs\Python\Python313\Lib\site-packages\starlette\middleware\cors.py", line 93, in __call__
    await self.simple_response(scope, receive, send, request_headers=headers)
  File "C:\Users\pc\AppData\Local\Programs\Python\Python313\Lib\site-packages\starlette\middleware\cors.py", line 144, in simple_response
    await self.app(scope, receive, send)
  File "C:\Users\pc\AppData\Local\Programs\Python\Python313\Lib\site-packages\starlette\middleware\exceptions.py", line 62, in __call__
    await wrap_app_handling_exceptions(self.app, conn)(scope, receive, send)
  File "C:\Users\pc\AppData\Local\Programs\Python\Python313\Lib\site-packages\starlette\_exception_handler.py", line 53, in wrapped_app
    raise exc
  File "C:\Users\pc\AppData\Local\Programs\Python\Python313\Lib\site-packages\starlette\_exception_handler.py", line 42, in wrapped_app
    await app(scope, receive, sender)
  File "C:\Users\pc\AppData\Local\Programs\Python\Python313\Lib\site-packages\starlette\routing.py", line 714, in __call__
    await self.middleware_stack(scope, receive, send)
  File "C:\Users\pc\AppData\Local\Programs\Python\Python313\Lib\site-packages\starlette\routing.py", line 734, in app
    await route.handle(scope, receive, send)
  File "C:\Users\pc\AppData\Local\Programs\Python\Python313\Lib\site-packages\starlette\routing.py", line 288, in handle
    await self.app(scope, receive, send)
  File "C:\Users\pc\AppData\Local\Programs\Python\Python313\Lib\site-packages\starlette\routing.py", line 76, in app
    await wrap_app_handling_exceptions(app, request)(scope, receive, send)
  File "C:\Users\pc\AppData\Local\Programs\Python\Python313\Lib\site-packages\starlette\_exception_handler.py", line 53, in wrapped_app
    raise exc
  File "C:\Users\pc\AppData\Local\Programs\Python\Python313\Lib\site-packages\starlette\_exception_handler.py", line 42, in wrapped_app
    await app(scope, receive, sender)
  File "C:\Users\pc\AppData\Local\Programs\Python\Python313\Lib\site-packages\starlette\routing.py", line 73, in app
    response = await f(request)
               ^^^^^^^^^^^^^^^^
  File "C:\Users\pc\AppData\Local\Programs\Python\Python313\Lib\site-packages\fastapi\routing.py", line 301, in app
    raw_response = await run_endpoint_function(
                   ^^^^^^^^^^^^^^^^^^^^^^^^^^^^
    ...<3 lines>...
    )
    ^
  File "C:\Users\pc\AppData\Local\Programs\Python\Python313\Lib\site-packages\fastapi\routing.py", line 214, in run_endpoint_function
    return await run_in_threadpool(dependant.call, **values)
           ^^^^^^^^^^^^^^^^^^^^^^^^^^^^^^^^^^^^^^^^^^^^^^^^^
  File "C:\Users\pc\AppData\Local\Programs\Python\Python313\Lib\site-packages\starlette\concurrency.py", line 37, in run_in_threadpool
    return await anyio.to_thread.run_sync(func)
           ^^^^^^^^^^^^^^^^^^^^^^^^^^^^^^^^^^^^
  File "C:\Users\pc\AppData\Local\Programs\Python\Python313\Lib\site-packages\anyio\to_thread.py", line 56, in run_sync
    return await get_async_backend().run_sync_in_worker_thread(
           ^^^^^^^^^^^^^^^^^^^^^^^^^^^^^^^^^^^^^^^^^^^^^^^^^^^^
        func, args, abandon_on_cancel=abandon_on_cancel, limiter=limiter
        ^^^^^^^^^^^^^^^^^^^^^^^^^^^^^^^^^^^^^^^^^^^^^^^^^^^^^^^^^^^^^^^^
    )
    ^
  File "C:\Users\pc\AppData\Local\Programs\Python\Python313\Lib\site-packages\anyio\_backends\_asyncio.py", line 2470, in run_sync_in_worker_thread
    return await future
           ^^^^^^^^^^^^
  File "C:\Users\pc\AppData\Local\Programs\Python\Python313\Lib\site-packages\anyio\_backends\_asyncio.py", line 967, in run
    result = context.run(func, *args)
  File "D:\Projects\Development\webcore-erp\webcore-erp\wcs-backend\app\routes\client.py", line 35, in get_clients
    return db.query(Client).offset(skip).limit(limit).all()
           ~~~~~~~~~~~~~~~~~~~~~~~~~~~~~~~~~~~~~~~~~~~~~~^^
  File "C:\Users\pc\AppData\Local\Programs\Python\Python313\Lib\site-packages\sqlalchemy\orm\query.py", line 2704, in all
    return self._iter().all()  # type: ignore
           ~~~~~~~~~~^^
  File "C:\Users\pc\AppData\Local\Programs\Python\Python313\Lib\site-packages\sqlalchemy\orm\query.py", line 2857, in _iter
    result: Union[ScalarResult[_T], Result[_T]] = self.session.execute(
                                                  ~~~~~~~~~~~~~~~~~~~~^
        statement,
        ^^^^^^^^^^
        params,
        ^^^^^^^
        execution_options={"_sa_orm_load_options": self.load_options},
        ^^^^^^^^^^^^^^^^^^^^^^^^^^^^^^^^^^^^^^^^^^^^^^^^^^^^^^^^^^^^^^
    )
    ^
  File "C:\Users\pc\AppData\Local\Programs\Python\Python313\Lib\site-packages\sqlalchemy\orm\session.py", line 2365, in execute
    return self._execute_internal(
           ~~~~~~~~~~~~~~~~~~~~~~^
        statement,
        ^^^^^^^^^^
    ...<4 lines>...
        _add_event=_add_event,
        ^^^^^^^^^^^^^^^^^^^^^^
    )
    ^
  File "C:\Users\pc\AppData\Local\Programs\Python\Python313\Lib\site-packages\sqlalchemy\orm\session.py", line 2251, in _execute_internal
    result: Result[Any] = compile_state_cls.orm_execute_statement(
                          ~~~~~~~~~~~~~~~~~~~~~~~~~~~~~~~~~~~~~~~^
        self,
        ^^^^^
    ...<4 lines>...
        conn,
        ^^^^^
    )
    ^
  File "C:\Users\pc\AppData\Local\Programs\Python\Python313\Lib\site-packages\sqlalchemy\orm\context.py", line 306, in orm_execute_statement
    result = conn.execute(
        statement, params or {}, execution_options=execution_options
    )
  File "C:\Users\pc\AppData\Local\Programs\Python\Python313\Lib\site-packages\sqlalchemy\engine\base.py", line 1415, in execute
    return meth(
        self,
        distilled_parameters,
        execution_options or NO_OPTIONS,
    )
  File "C:\Users\pc\AppData\Local\Programs\Python\Python313\Lib\site-packages\sqlalchemy\sql\elements.py", line 523, in _execute_on_connection
    return connection._execute_clauseelement(
           ~~~~~~~~~~~~~~~~~~~~~~~~~~~~~~~~~^
        self, distilled_params, execution_options
        ^^^^^^^^^^^^^^^^^^^^^^^^^^^^^^^^^^^^^^^^^
    )
    ^
  File "C:\Users\pc\AppData\Local\Programs\Python\Python313\Lib\site-packages\sqlalchemy\engine\base.py", line 1637, in _execute_clauseelement
    ret = self._execute_context(
        dialect,
    ...<8 lines>...
        cache_hit=cache_hit,
    )
  File "C:\Users\pc\AppData\Local\Programs\Python\Python313\Lib\site-packages\sqlalchemy\engine\base.py", line 1842, in _execute_context
    return self._exec_single_context(
           ~~~~~~~~~~~~~~~~~~~~~~~~~^
        dialect, context, statement, parameters
        ^^^^^^^^^^^^^^^^^^^^^^^^^^^^^^^^^^^^^^^
    )
    ^
  File "C:\Users\pc\AppData\Local\Programs\Python\Python313\Lib\site-packages\sqlalchemy\engine\base.py", line 1982, in _exec_single_context
    self._handle_dbapi_exception(
    ~~~~~~~~~~~~~~~~~~~~~~~~~~~~^
        e, str_statement, effective_parameters, cursor, context
        ^^^^^^^^^^^^^^^^^^^^^^^^^^^^^^^^^^^^^^^^^^^^^^^^^^^^^^^
    )
    ^
  File "C:\Users\pc\AppData\Local\Programs\Python\Python313\Lib\site-packages\sqlalchemy\engine\base.py", line 2351, in _handle_dbapi_exception
    raise sqlalchemy_exception.with_traceback(exc_info[2]) from e
  File "C:\Users\pc\AppData\Local\Programs\Python\Python313\Lib\site-packages\sqlalchemy\engine\base.py", line 1963, in _exec_single_context
    self.dialect.do_execute(
    ~~~~~~~~~~~~~~~~~~~~~~~^
        cursor, str_statement, effective_parameters, context
        ^^^^^^^^^^^^^^^^^^^^^^^^^^^^^^^^^^^^^^^^^^^^^^^^^^^^
    )
    ^
  File "C:\Users\pc\AppData\Local\Programs\Python\Python313\Lib\site-packages\sqlalchemy\engine\default.py", line 943, in do_execute
    cursor.execute(statement, parameters)
    ~~~~~~~~~~~~~~^^^^^^^^^^^^^^^^^^^^^^^
sqlalchemy.exc.OperationalError: (sqlite3.OperationalError) no such column: clients.addressline1
[SQL: SELECT clients.id AS clients_id, clients.name AS clients_name, clients.client_code AS clients_client_code, clients.contact_person AS clients_contact_person, clients.email AS clients_email, clients.phone AS clients_phone, clients.addressline1 AS clients_addressline1, clients.addressline2 AS clients_addressline2, clients.state AS clients_state, clients.coutry AS clients_coutry, clients.pincode AS clients_pincode, clients.gst_number AS clients_gst_number, clients.is_deleted AS clients_is_deleted 
FROM clients
 LIMIT ? OFFSET ?]
[parameters: (10, 0)]
(Background on this error at: https://sqlalche.me/e/20/e3q8)
[2025-06-23 16:38:43,592] [INFO] app.routes.auth: employee found: <app.models.employee.Employee object at 0x0000027B5E88D950>
[2025-06-23 16:38:51,542] [ERROR] uvicorn.error: Exception in ASGI application
Traceback (most recent call last):
  File "C:\Users\pc\AppData\Local\Programs\Python\Python313\Lib\site-packages\sqlalchemy\engine\base.py", line 1963, in _exec_single_context
    self.dialect.do_execute(
    ~~~~~~~~~~~~~~~~~~~~~~~^
        cursor, str_statement, effective_parameters, context
        ^^^^^^^^^^^^^^^^^^^^^^^^^^^^^^^^^^^^^^^^^^^^^^^^^^^^
    )
    ^
  File "C:\Users\pc\AppData\Local\Programs\Python\Python313\Lib\site-packages\sqlalchemy\engine\default.py", line 943, in do_execute
    cursor.execute(statement, parameters)
    ~~~~~~~~~~~~~~^^^^^^^^^^^^^^^^^^^^^^^
sqlite3.OperationalError: no such column: clients.addressline1

The above exception was the direct cause of the following exception:

Traceback (most recent call last):
  File "C:\Users\pc\AppData\Local\Programs\Python\Python313\Lib\site-packages\uvicorn\protocols\http\h11_impl.py", line 403, in run_asgi
    result = await app(  # type: ignore[func-returns-value]
             ^^^^^^^^^^^^^^^^^^^^^^^^^^^^^^^^^^^^^^^^^^^^^^
        self.scope, self.receive, self.send
        ^^^^^^^^^^^^^^^^^^^^^^^^^^^^^^^^^^^
    )
    ^
  File "C:\Users\pc\AppData\Local\Programs\Python\Python313\Lib\site-packages\uvicorn\middleware\proxy_headers.py", line 60, in __call__
    return await self.app(scope, receive, send)
           ^^^^^^^^^^^^^^^^^^^^^^^^^^^^^^^^^^^^
  File "C:\Users\pc\AppData\Local\Programs\Python\Python313\Lib\site-packages\fastapi\applications.py", line 1054, in __call__
    await super().__call__(scope, receive, send)
  File "C:\Users\pc\AppData\Local\Programs\Python\Python313\Lib\site-packages\starlette\applications.py", line 112, in __call__
    await self.middleware_stack(scope, receive, send)
  File "C:\Users\pc\AppData\Local\Programs\Python\Python313\Lib\site-packages\starlette\middleware\errors.py", line 187, in __call__
    raise exc
  File "C:\Users\pc\AppData\Local\Programs\Python\Python313\Lib\site-packages\starlette\middleware\errors.py", line 165, in __call__
    await self.app(scope, receive, _send)
  File "C:\Users\pc\AppData\Local\Programs\Python\Python313\Lib\site-packages\starlette\middleware\cors.py", line 93, in __call__
    await self.simple_response(scope, receive, send, request_headers=headers)
  File "C:\Users\pc\AppData\Local\Programs\Python\Python313\Lib\site-packages\starlette\middleware\cors.py", line 144, in simple_response
    await self.app(scope, receive, send)
  File "C:\Users\pc\AppData\Local\Programs\Python\Python313\Lib\site-packages\starlette\middleware\exceptions.py", line 62, in __call__
    await wrap_app_handling_exceptions(self.app, conn)(scope, receive, send)
  File "C:\Users\pc\AppData\Local\Programs\Python\Python313\Lib\site-packages\starlette\_exception_handler.py", line 53, in wrapped_app
    raise exc
  File "C:\Users\pc\AppData\Local\Programs\Python\Python313\Lib\site-packages\starlette\_exception_handler.py", line 42, in wrapped_app
    await app(scope, receive, sender)
  File "C:\Users\pc\AppData\Local\Programs\Python\Python313\Lib\site-packages\starlette\routing.py", line 714, in __call__
    await self.middleware_stack(scope, receive, send)
  File "C:\Users\pc\AppData\Local\Programs\Python\Python313\Lib\site-packages\starlette\routing.py", line 734, in app
    await route.handle(scope, receive, send)
  File "C:\Users\pc\AppData\Local\Programs\Python\Python313\Lib\site-packages\starlette\routing.py", line 288, in handle
    await self.app(scope, receive, send)
  File "C:\Users\pc\AppData\Local\Programs\Python\Python313\Lib\site-packages\starlette\routing.py", line 76, in app
    await wrap_app_handling_exceptions(app, request)(scope, receive, send)
  File "C:\Users\pc\AppData\Local\Programs\Python\Python313\Lib\site-packages\starlette\_exception_handler.py", line 53, in wrapped_app
    raise exc
  File "C:\Users\pc\AppData\Local\Programs\Python\Python313\Lib\site-packages\starlette\_exception_handler.py", line 42, in wrapped_app
    await app(scope, receive, sender)
  File "C:\Users\pc\AppData\Local\Programs\Python\Python313\Lib\site-packages\starlette\routing.py", line 73, in app
    response = await f(request)
               ^^^^^^^^^^^^^^^^
  File "C:\Users\pc\AppData\Local\Programs\Python\Python313\Lib\site-packages\fastapi\routing.py", line 301, in app
    raw_response = await run_endpoint_function(
                   ^^^^^^^^^^^^^^^^^^^^^^^^^^^^
    ...<3 lines>...
    )
    ^
  File "C:\Users\pc\AppData\Local\Programs\Python\Python313\Lib\site-packages\fastapi\routing.py", line 214, in run_endpoint_function
    return await run_in_threadpool(dependant.call, **values)
           ^^^^^^^^^^^^^^^^^^^^^^^^^^^^^^^^^^^^^^^^^^^^^^^^^
  File "C:\Users\pc\AppData\Local\Programs\Python\Python313\Lib\site-packages\starlette\concurrency.py", line 37, in run_in_threadpool
    return await anyio.to_thread.run_sync(func)
           ^^^^^^^^^^^^^^^^^^^^^^^^^^^^^^^^^^^^
  File "C:\Users\pc\AppData\Local\Programs\Python\Python313\Lib\site-packages\anyio\to_thread.py", line 56, in run_sync
    return await get_async_backend().run_sync_in_worker_thread(
           ^^^^^^^^^^^^^^^^^^^^^^^^^^^^^^^^^^^^^^^^^^^^^^^^^^^^
        func, args, abandon_on_cancel=abandon_on_cancel, limiter=limiter
        ^^^^^^^^^^^^^^^^^^^^^^^^^^^^^^^^^^^^^^^^^^^^^^^^^^^^^^^^^^^^^^^^
    )
    ^
  File "C:\Users\pc\AppData\Local\Programs\Python\Python313\Lib\site-packages\anyio\_backends\_asyncio.py", line 2470, in run_sync_in_worker_thread
    return await future
           ^^^^^^^^^^^^
  File "C:\Users\pc\AppData\Local\Programs\Python\Python313\Lib\site-packages\anyio\_backends\_asyncio.py", line 967, in run
    result = context.run(func, *args)
  File "D:\Projects\Development\webcore-erp\webcore-erp\wcs-backend\app\routes\client.py", line 35, in get_clients
    return db.query(Client).offset(skip).limit(limit).all()
           ~~~~~~~~~~~~~~~~~~~~~~~~~~~~~~~~~~~~~~~~~~~~~~^^
  File "C:\Users\pc\AppData\Local\Programs\Python\Python313\Lib\site-packages\sqlalchemy\orm\query.py", line 2704, in all
    return self._iter().all()  # type: ignore
           ~~~~~~~~~~^^
  File "C:\Users\pc\AppData\Local\Programs\Python\Python313\Lib\site-packages\sqlalchemy\orm\query.py", line 2857, in _iter
    result: Union[ScalarResult[_T], Result[_T]] = self.session.execute(
                                                  ~~~~~~~~~~~~~~~~~~~~^
        statement,
        ^^^^^^^^^^
        params,
        ^^^^^^^
        execution_options={"_sa_orm_load_options": self.load_options},
        ^^^^^^^^^^^^^^^^^^^^^^^^^^^^^^^^^^^^^^^^^^^^^^^^^^^^^^^^^^^^^^
    )
    ^
  File "C:\Users\pc\AppData\Local\Programs\Python\Python313\Lib\site-packages\sqlalchemy\orm\session.py", line 2365, in execute
    return self._execute_internal(
           ~~~~~~~~~~~~~~~~~~~~~~^
        statement,
        ^^^^^^^^^^
    ...<4 lines>...
        _add_event=_add_event,
        ^^^^^^^^^^^^^^^^^^^^^^
    )
    ^
  File "C:\Users\pc\AppData\Local\Programs\Python\Python313\Lib\site-packages\sqlalchemy\orm\session.py", line 2251, in _execute_internal
    result: Result[Any] = compile_state_cls.orm_execute_statement(
                          ~~~~~~~~~~~~~~~~~~~~~~~~~~~~~~~~~~~~~~~^
        self,
        ^^^^^
    ...<4 lines>...
        conn,
        ^^^^^
    )
    ^
  File "C:\Users\pc\AppData\Local\Programs\Python\Python313\Lib\site-packages\sqlalchemy\orm\context.py", line 306, in orm_execute_statement
    result = conn.execute(
        statement, params or {}, execution_options=execution_options
    )
  File "C:\Users\pc\AppData\Local\Programs\Python\Python313\Lib\site-packages\sqlalchemy\engine\base.py", line 1415, in execute
    return meth(
        self,
        distilled_parameters,
        execution_options or NO_OPTIONS,
    )
  File "C:\Users\pc\AppData\Local\Programs\Python\Python313\Lib\site-packages\sqlalchemy\sql\elements.py", line 523, in _execute_on_connection
    return connection._execute_clauseelement(
           ~~~~~~~~~~~~~~~~~~~~~~~~~~~~~~~~~^
        self, distilled_params, execution_options
        ^^^^^^^^^^^^^^^^^^^^^^^^^^^^^^^^^^^^^^^^^
    )
    ^
  File "C:\Users\pc\AppData\Local\Programs\Python\Python313\Lib\site-packages\sqlalchemy\engine\base.py", line 1637, in _execute_clauseelement
    ret = self._execute_context(
        dialect,
    ...<8 lines>...
        cache_hit=cache_hit,
    )
  File "C:\Users\pc\AppData\Local\Programs\Python\Python313\Lib\site-packages\sqlalchemy\engine\base.py", line 1842, in _execute_context
    return self._exec_single_context(
           ~~~~~~~~~~~~~~~~~~~~~~~~~^
        dialect, context, statement, parameters
        ^^^^^^^^^^^^^^^^^^^^^^^^^^^^^^^^^^^^^^^
    )
    ^
  File "C:\Users\pc\AppData\Local\Programs\Python\Python313\Lib\site-packages\sqlalchemy\engine\base.py", line 1982, in _exec_single_context
    self._handle_dbapi_exception(
    ~~~~~~~~~~~~~~~~~~~~~~~~~~~~^
        e, str_statement, effective_parameters, cursor, context
        ^^^^^^^^^^^^^^^^^^^^^^^^^^^^^^^^^^^^^^^^^^^^^^^^^^^^^^^
    )
    ^
  File "C:\Users\pc\AppData\Local\Programs\Python\Python313\Lib\site-packages\sqlalchemy\engine\base.py", line 2351, in _handle_dbapi_exception
    raise sqlalchemy_exception.with_traceback(exc_info[2]) from e
  File "C:\Users\pc\AppData\Local\Programs\Python\Python313\Lib\site-packages\sqlalchemy\engine\base.py", line 1963, in _exec_single_context
    self.dialect.do_execute(
    ~~~~~~~~~~~~~~~~~~~~~~~^
        cursor, str_statement, effective_parameters, context
        ^^^^^^^^^^^^^^^^^^^^^^^^^^^^^^^^^^^^^^^^^^^^^^^^^^^^
    )
    ^
  File "C:\Users\pc\AppData\Local\Programs\Python\Python313\Lib\site-packages\sqlalchemy\engine\default.py", line 943, in do_execute
    cursor.execute(statement, parameters)
    ~~~~~~~~~~~~~~^^^^^^^^^^^^^^^^^^^^^^^
sqlalchemy.exc.OperationalError: (sqlite3.OperationalError) no such column: clients.addressline1
[SQL: SELECT clients.id AS clients_id, clients.name AS clients_name, clients.client_code AS clients_client_code, clients.contact_person AS clients_contact_person, clients.email AS clients_email, clients.phone AS clients_phone, clients.addressline1 AS clients_addressline1, clients.addressline2 AS clients_addressline2, clients.state AS clients_state, clients.coutry AS clients_coutry, clients.pincode AS clients_pincode, clients.gst_number AS clients_gst_number, clients.is_deleted AS clients_is_deleted 
FROM clients
 LIMIT ? OFFSET ?]
[parameters: (10, 0)]
(Background on this error at: https://sqlalche.me/e/20/e3q8)
[2025-06-23 16:38:51,803] [ERROR] uvicorn.error: Exception in ASGI application
Traceback (most recent call last):
  File "C:\Users\pc\AppData\Local\Programs\Python\Python313\Lib\site-packages\sqlalchemy\engine\base.py", line 1963, in _exec_single_context
    self.dialect.do_execute(
    ~~~~~~~~~~~~~~~~~~~~~~~^
        cursor, str_statement, effective_parameters, context
        ^^^^^^^^^^^^^^^^^^^^^^^^^^^^^^^^^^^^^^^^^^^^^^^^^^^^
    )
    ^
  File "C:\Users\pc\AppData\Local\Programs\Python\Python313\Lib\site-packages\sqlalchemy\engine\default.py", line 943, in do_execute
    cursor.execute(statement, parameters)
    ~~~~~~~~~~~~~~^^^^^^^^^^^^^^^^^^^^^^^
sqlite3.OperationalError: no such column: clients.addressline1

The above exception was the direct cause of the following exception:

Traceback (most recent call last):
  File "C:\Users\pc\AppData\Local\Programs\Python\Python313\Lib\site-packages\uvicorn\protocols\http\h11_impl.py", line 403, in run_asgi
    result = await app(  # type: ignore[func-returns-value]
             ^^^^^^^^^^^^^^^^^^^^^^^^^^^^^^^^^^^^^^^^^^^^^^
        self.scope, self.receive, self.send
        ^^^^^^^^^^^^^^^^^^^^^^^^^^^^^^^^^^^
    )
    ^
  File "C:\Users\pc\AppData\Local\Programs\Python\Python313\Lib\site-packages\uvicorn\middleware\proxy_headers.py", line 60, in __call__
    return await self.app(scope, receive, send)
           ^^^^^^^^^^^^^^^^^^^^^^^^^^^^^^^^^^^^
  File "C:\Users\pc\AppData\Local\Programs\Python\Python313\Lib\site-packages\fastapi\applications.py", line 1054, in __call__
    await super().__call__(scope, receive, send)
  File "C:\Users\pc\AppData\Local\Programs\Python\Python313\Lib\site-packages\starlette\applications.py", line 112, in __call__
    await self.middleware_stack(scope, receive, send)
  File "C:\Users\pc\AppData\Local\Programs\Python\Python313\Lib\site-packages\starlette\middleware\errors.py", line 187, in __call__
    raise exc
  File "C:\Users\pc\AppData\Local\Programs\Python\Python313\Lib\site-packages\starlette\middleware\errors.py", line 165, in __call__
    await self.app(scope, receive, _send)
  File "C:\Users\pc\AppData\Local\Programs\Python\Python313\Lib\site-packages\starlette\middleware\cors.py", line 93, in __call__
    await self.simple_response(scope, receive, send, request_headers=headers)
  File "C:\Users\pc\AppData\Local\Programs\Python\Python313\Lib\site-packages\starlette\middleware\cors.py", line 144, in simple_response
    await self.app(scope, receive, send)
  File "C:\Users\pc\AppData\Local\Programs\Python\Python313\Lib\site-packages\starlette\middleware\exceptions.py", line 62, in __call__
    await wrap_app_handling_exceptions(self.app, conn)(scope, receive, send)
  File "C:\Users\pc\AppData\Local\Programs\Python\Python313\Lib\site-packages\starlette\_exception_handler.py", line 53, in wrapped_app
    raise exc
  File "C:\Users\pc\AppData\Local\Programs\Python\Python313\Lib\site-packages\starlette\_exception_handler.py", line 42, in wrapped_app
    await app(scope, receive, sender)
  File "C:\Users\pc\AppData\Local\Programs\Python\Python313\Lib\site-packages\starlette\routing.py", line 714, in __call__
    await self.middleware_stack(scope, receive, send)
  File "C:\Users\pc\AppData\Local\Programs\Python\Python313\Lib\site-packages\starlette\routing.py", line 734, in app
    await route.handle(scope, receive, send)
  File "C:\Users\pc\AppData\Local\Programs\Python\Python313\Lib\site-packages\starlette\routing.py", line 288, in handle
    await self.app(scope, receive, send)
  File "C:\Users\pc\AppData\Local\Programs\Python\Python313\Lib\site-packages\starlette\routing.py", line 76, in app
    await wrap_app_handling_exceptions(app, request)(scope, receive, send)
  File "C:\Users\pc\AppData\Local\Programs\Python\Python313\Lib\site-packages\starlette\_exception_handler.py", line 53, in wrapped_app
    raise exc
  File "C:\Users\pc\AppData\Local\Programs\Python\Python313\Lib\site-packages\starlette\_exception_handler.py", line 42, in wrapped_app
    await app(scope, receive, sender)
  File "C:\Users\pc\AppData\Local\Programs\Python\Python313\Lib\site-packages\starlette\routing.py", line 73, in app
    response = await f(request)
               ^^^^^^^^^^^^^^^^
  File "C:\Users\pc\AppData\Local\Programs\Python\Python313\Lib\site-packages\fastapi\routing.py", line 301, in app
    raw_response = await run_endpoint_function(
                   ^^^^^^^^^^^^^^^^^^^^^^^^^^^^
    ...<3 lines>...
    )
    ^
  File "C:\Users\pc\AppData\Local\Programs\Python\Python313\Lib\site-packages\fastapi\routing.py", line 214, in run_endpoint_function
    return await run_in_threadpool(dependant.call, **values)
           ^^^^^^^^^^^^^^^^^^^^^^^^^^^^^^^^^^^^^^^^^^^^^^^^^
  File "C:\Users\pc\AppData\Local\Programs\Python\Python313\Lib\site-packages\starlette\concurrency.py", line 37, in run_in_threadpool
    return await anyio.to_thread.run_sync(func)
           ^^^^^^^^^^^^^^^^^^^^^^^^^^^^^^^^^^^^
  File "C:\Users\pc\AppData\Local\Programs\Python\Python313\Lib\site-packages\anyio\to_thread.py", line 56, in run_sync
    return await get_async_backend().run_sync_in_worker_thread(
           ^^^^^^^^^^^^^^^^^^^^^^^^^^^^^^^^^^^^^^^^^^^^^^^^^^^^
        func, args, abandon_on_cancel=abandon_on_cancel, limiter=limiter
        ^^^^^^^^^^^^^^^^^^^^^^^^^^^^^^^^^^^^^^^^^^^^^^^^^^^^^^^^^^^^^^^^
    )
    ^
  File "C:\Users\pc\AppData\Local\Programs\Python\Python313\Lib\site-packages\anyio\_backends\_asyncio.py", line 2470, in run_sync_in_worker_thread
    return await future
           ^^^^^^^^^^^^
  File "C:\Users\pc\AppData\Local\Programs\Python\Python313\Lib\site-packages\anyio\_backends\_asyncio.py", line 967, in run
    result = context.run(func, *args)
  File "D:\Projects\Development\webcore-erp\webcore-erp\wcs-backend\app\routes\client.py", line 35, in get_clients
    return db.query(Client).offset(skip).limit(limit).all()
           ~~~~~~~~~~~~~~~~~~~~~~~~~~~~~~~~~~~~~~~~~~~~~~^^
  File "C:\Users\pc\AppData\Local\Programs\Python\Python313\Lib\site-packages\sqlalchemy\orm\query.py", line 2704, in all
    return self._iter().all()  # type: ignore
           ~~~~~~~~~~^^
  File "C:\Users\pc\AppData\Local\Programs\Python\Python313\Lib\site-packages\sqlalchemy\orm\query.py", line 2857, in _iter
    result: Union[ScalarResult[_T], Result[_T]] = self.session.execute(
                                                  ~~~~~~~~~~~~~~~~~~~~^
        statement,
        ^^^^^^^^^^
        params,
        ^^^^^^^
        execution_options={"_sa_orm_load_options": self.load_options},
        ^^^^^^^^^^^^^^^^^^^^^^^^^^^^^^^^^^^^^^^^^^^^^^^^^^^^^^^^^^^^^^
    )
    ^
  File "C:\Users\pc\AppData\Local\Programs\Python\Python313\Lib\site-packages\sqlalchemy\orm\session.py", line 2365, in execute
    return self._execute_internal(
           ~~~~~~~~~~~~~~~~~~~~~~^
        statement,
        ^^^^^^^^^^
    ...<4 lines>...
        _add_event=_add_event,
        ^^^^^^^^^^^^^^^^^^^^^^
    )
    ^
  File "C:\Users\pc\AppData\Local\Programs\Python\Python313\Lib\site-packages\sqlalchemy\orm\session.py", line 2251, in _execute_internal
    result: Result[Any] = compile_state_cls.orm_execute_statement(
                          ~~~~~~~~~~~~~~~~~~~~~~~~~~~~~~~~~~~~~~~^
        self,
        ^^^^^
    ...<4 lines>...
        conn,
        ^^^^^
    )
    ^
  File "C:\Users\pc\AppData\Local\Programs\Python\Python313\Lib\site-packages\sqlalchemy\orm\context.py", line 306, in orm_execute_statement
    result = conn.execute(
        statement, params or {}, execution_options=execution_options
    )
  File "C:\Users\pc\AppData\Local\Programs\Python\Python313\Lib\site-packages\sqlalchemy\engine\base.py", line 1415, in execute
    return meth(
        self,
        distilled_parameters,
        execution_options or NO_OPTIONS,
    )
  File "C:\Users\pc\AppData\Local\Programs\Python\Python313\Lib\site-packages\sqlalchemy\sql\elements.py", line 523, in _execute_on_connection
    return connection._execute_clauseelement(
           ~~~~~~~~~~~~~~~~~~~~~~~~~~~~~~~~~^
        self, distilled_params, execution_options
        ^^^^^^^^^^^^^^^^^^^^^^^^^^^^^^^^^^^^^^^^^
    )
    ^
  File "C:\Users\pc\AppData\Local\Programs\Python\Python313\Lib\site-packages\sqlalchemy\engine\base.py", line 1637, in _execute_clauseelement
    ret = self._execute_context(
        dialect,
    ...<8 lines>...
        cache_hit=cache_hit,
    )
  File "C:\Users\pc\AppData\Local\Programs\Python\Python313\Lib\site-packages\sqlalchemy\engine\base.py", line 1842, in _execute_context
    return self._exec_single_context(
           ~~~~~~~~~~~~~~~~~~~~~~~~~^
        dialect, context, statement, parameters
        ^^^^^^^^^^^^^^^^^^^^^^^^^^^^^^^^^^^^^^^
    )
    ^
  File "C:\Users\pc\AppData\Local\Programs\Python\Python313\Lib\site-packages\sqlalchemy\engine\base.py", line 1982, in _exec_single_context
    self._handle_dbapi_exception(
    ~~~~~~~~~~~~~~~~~~~~~~~~~~~~^
        e, str_statement, effective_parameters, cursor, context
        ^^^^^^^^^^^^^^^^^^^^^^^^^^^^^^^^^^^^^^^^^^^^^^^^^^^^^^^
    )
    ^
  File "C:\Users\pc\AppData\Local\Programs\Python\Python313\Lib\site-packages\sqlalchemy\engine\base.py", line 2351, in _handle_dbapi_exception
    raise sqlalchemy_exception.with_traceback(exc_info[2]) from e
  File "C:\Users\pc\AppData\Local\Programs\Python\Python313\Lib\site-packages\sqlalchemy\engine\base.py", line 1963, in _exec_single_context
    self.dialect.do_execute(
    ~~~~~~~~~~~~~~~~~~~~~~~^
        cursor, str_statement, effective_parameters, context
        ^^^^^^^^^^^^^^^^^^^^^^^^^^^^^^^^^^^^^^^^^^^^^^^^^^^^
    )
    ^
  File "C:\Users\pc\AppData\Local\Programs\Python\Python313\Lib\site-packages\sqlalchemy\engine\default.py", line 943, in do_execute
    cursor.execute(statement, parameters)
    ~~~~~~~~~~~~~~^^^^^^^^^^^^^^^^^^^^^^^
sqlalchemy.exc.OperationalError: (sqlite3.OperationalError) no such column: clients.addressline1
[SQL: SELECT clients.id AS clients_id, clients.name AS clients_name, clients.client_code AS clients_client_code, clients.contact_person AS clients_contact_person, clients.email AS clients_email, clients.phone AS clients_phone, clients.addressline1 AS clients_addressline1, clients.addressline2 AS clients_addressline2, clients.state AS clients_state, clients.coutry AS clients_coutry, clients.pincode AS clients_pincode, clients.gst_number AS clients_gst_number, clients.is_deleted AS clients_is_deleted 
FROM clients
 LIMIT ? OFFSET ?]
[parameters: (10, 0)]
(Background on this error at: https://sqlalche.me/e/20/e3q8)
[2025-06-23 16:39:00,577] [ERROR] uvicorn.error: Exception in ASGI application
Traceback (most recent call last):
  File "C:\Users\pc\AppData\Local\Programs\Python\Python313\Lib\site-packages\sqlalchemy\engine\base.py", line 1963, in _exec_single_context
    self.dialect.do_execute(
    ~~~~~~~~~~~~~~~~~~~~~~~^
        cursor, str_statement, effective_parameters, context
        ^^^^^^^^^^^^^^^^^^^^^^^^^^^^^^^^^^^^^^^^^^^^^^^^^^^^
    )
    ^
  File "C:\Users\pc\AppData\Local\Programs\Python\Python313\Lib\site-packages\sqlalchemy\engine\default.py", line 943, in do_execute
    cursor.execute(statement, parameters)
    ~~~~~~~~~~~~~~^^^^^^^^^^^^^^^^^^^^^^^
sqlite3.OperationalError: no such column: clients.addressline1

The above exception was the direct cause of the following exception:

Traceback (most recent call last):
  File "C:\Users\pc\AppData\Local\Programs\Python\Python313\Lib\site-packages\uvicorn\protocols\http\h11_impl.py", line 403, in run_asgi
    result = await app(  # type: ignore[func-returns-value]
             ^^^^^^^^^^^^^^^^^^^^^^^^^^^^^^^^^^^^^^^^^^^^^^
        self.scope, self.receive, self.send
        ^^^^^^^^^^^^^^^^^^^^^^^^^^^^^^^^^^^
    )
    ^
  File "C:\Users\pc\AppData\Local\Programs\Python\Python313\Lib\site-packages\uvicorn\middleware\proxy_headers.py", line 60, in __call__
    return await self.app(scope, receive, send)
           ^^^^^^^^^^^^^^^^^^^^^^^^^^^^^^^^^^^^
  File "C:\Users\pc\AppData\Local\Programs\Python\Python313\Lib\site-packages\fastapi\applications.py", line 1054, in __call__
    await super().__call__(scope, receive, send)
  File "C:\Users\pc\AppData\Local\Programs\Python\Python313\Lib\site-packages\starlette\applications.py", line 112, in __call__
    await self.middleware_stack(scope, receive, send)
  File "C:\Users\pc\AppData\Local\Programs\Python\Python313\Lib\site-packages\starlette\middleware\errors.py", line 187, in __call__
    raise exc
  File "C:\Users\pc\AppData\Local\Programs\Python\Python313\Lib\site-packages\starlette\middleware\errors.py", line 165, in __call__
    await self.app(scope, receive, _send)
  File "C:\Users\pc\AppData\Local\Programs\Python\Python313\Lib\site-packages\starlette\middleware\cors.py", line 93, in __call__
    await self.simple_response(scope, receive, send, request_headers=headers)
  File "C:\Users\pc\AppData\Local\Programs\Python\Python313\Lib\site-packages\starlette\middleware\cors.py", line 144, in simple_response
    await self.app(scope, receive, send)
  File "C:\Users\pc\AppData\Local\Programs\Python\Python313\Lib\site-packages\starlette\middleware\exceptions.py", line 62, in __call__
    await wrap_app_handling_exceptions(self.app, conn)(scope, receive, send)
  File "C:\Users\pc\AppData\Local\Programs\Python\Python313\Lib\site-packages\starlette\_exception_handler.py", line 53, in wrapped_app
    raise exc
  File "C:\Users\pc\AppData\Local\Programs\Python\Python313\Lib\site-packages\starlette\_exception_handler.py", line 42, in wrapped_app
    await app(scope, receive, sender)
  File "C:\Users\pc\AppData\Local\Programs\Python\Python313\Lib\site-packages\starlette\routing.py", line 714, in __call__
    await self.middleware_stack(scope, receive, send)
  File "C:\Users\pc\AppData\Local\Programs\Python\Python313\Lib\site-packages\starlette\routing.py", line 734, in app
    await route.handle(scope, receive, send)
  File "C:\Users\pc\AppData\Local\Programs\Python\Python313\Lib\site-packages\starlette\routing.py", line 288, in handle
    await self.app(scope, receive, send)
  File "C:\Users\pc\AppData\Local\Programs\Python\Python313\Lib\site-packages\starlette\routing.py", line 76, in app
    await wrap_app_handling_exceptions(app, request)(scope, receive, send)
  File "C:\Users\pc\AppData\Local\Programs\Python\Python313\Lib\site-packages\starlette\_exception_handler.py", line 53, in wrapped_app
    raise exc
  File "C:\Users\pc\AppData\Local\Programs\Python\Python313\Lib\site-packages\starlette\_exception_handler.py", line 42, in wrapped_app
    await app(scope, receive, sender)
  File "C:\Users\pc\AppData\Local\Programs\Python\Python313\Lib\site-packages\starlette\routing.py", line 73, in app
    response = await f(request)
               ^^^^^^^^^^^^^^^^
  File "C:\Users\pc\AppData\Local\Programs\Python\Python313\Lib\site-packages\fastapi\routing.py", line 301, in app
    raw_response = await run_endpoint_function(
                   ^^^^^^^^^^^^^^^^^^^^^^^^^^^^
    ...<3 lines>...
    )
    ^
  File "C:\Users\pc\AppData\Local\Programs\Python\Python313\Lib\site-packages\fastapi\routing.py", line 214, in run_endpoint_function
    return await run_in_threadpool(dependant.call, **values)
           ^^^^^^^^^^^^^^^^^^^^^^^^^^^^^^^^^^^^^^^^^^^^^^^^^
  File "C:\Users\pc\AppData\Local\Programs\Python\Python313\Lib\site-packages\starlette\concurrency.py", line 37, in run_in_threadpool
    return await anyio.to_thread.run_sync(func)
           ^^^^^^^^^^^^^^^^^^^^^^^^^^^^^^^^^^^^
  File "C:\Users\pc\AppData\Local\Programs\Python\Python313\Lib\site-packages\anyio\to_thread.py", line 56, in run_sync
    return await get_async_backend().run_sync_in_worker_thread(
           ^^^^^^^^^^^^^^^^^^^^^^^^^^^^^^^^^^^^^^^^^^^^^^^^^^^^
        func, args, abandon_on_cancel=abandon_on_cancel, limiter=limiter
        ^^^^^^^^^^^^^^^^^^^^^^^^^^^^^^^^^^^^^^^^^^^^^^^^^^^^^^^^^^^^^^^^
    )
    ^
  File "C:\Users\pc\AppData\Local\Programs\Python\Python313\Lib\site-packages\anyio\_backends\_asyncio.py", line 2470, in run_sync_in_worker_thread
    return await future
           ^^^^^^^^^^^^
  File "C:\Users\pc\AppData\Local\Programs\Python\Python313\Lib\site-packages\anyio\_backends\_asyncio.py", line 967, in run
    result = context.run(func, *args)
  File "D:\Projects\Development\webcore-erp\webcore-erp\wcs-backend\app\routes\client.py", line 35, in get_clients
    return db.query(Client).offset(skip).limit(limit).all()
           ~~~~~~~~~~~~~~~~~~~~~~~~~~~~~~~~~~~~~~~~~~~~~~^^
  File "C:\Users\pc\AppData\Local\Programs\Python\Python313\Lib\site-packages\sqlalchemy\orm\query.py", line 2704, in all
    return self._iter().all()  # type: ignore
           ~~~~~~~~~~^^
  File "C:\Users\pc\AppData\Local\Programs\Python\Python313\Lib\site-packages\sqlalchemy\orm\query.py", line 2857, in _iter
    result: Union[ScalarResult[_T], Result[_T]] = self.session.execute(
                                                  ~~~~~~~~~~~~~~~~~~~~^
        statement,
        ^^^^^^^^^^
        params,
        ^^^^^^^
        execution_options={"_sa_orm_load_options": self.load_options},
        ^^^^^^^^^^^^^^^^^^^^^^^^^^^^^^^^^^^^^^^^^^^^^^^^^^^^^^^^^^^^^^
    )
    ^
  File "C:\Users\pc\AppData\Local\Programs\Python\Python313\Lib\site-packages\sqlalchemy\orm\session.py", line 2365, in execute
    return self._execute_internal(
           ~~~~~~~~~~~~~~~~~~~~~~^
        statement,
        ^^^^^^^^^^
    ...<4 lines>...
        _add_event=_add_event,
        ^^^^^^^^^^^^^^^^^^^^^^
    )
    ^
  File "C:\Users\pc\AppData\Local\Programs\Python\Python313\Lib\site-packages\sqlalchemy\orm\session.py", line 2251, in _execute_internal
    result: Result[Any] = compile_state_cls.orm_execute_statement(
                          ~~~~~~~~~~~~~~~~~~~~~~~~~~~~~~~~~~~~~~~^
        self,
        ^^^^^
    ...<4 lines>...
        conn,
        ^^^^^
    )
    ^
  File "C:\Users\pc\AppData\Local\Programs\Python\Python313\Lib\site-packages\sqlalchemy\orm\context.py", line 306, in orm_execute_statement
    result = conn.execute(
        statement, params or {}, execution_options=execution_options
    )
  File "C:\Users\pc\AppData\Local\Programs\Python\Python313\Lib\site-packages\sqlalchemy\engine\base.py", line 1415, in execute
    return meth(
        self,
        distilled_parameters,
        execution_options or NO_OPTIONS,
    )
  File "C:\Users\pc\AppData\Local\Programs\Python\Python313\Lib\site-packages\sqlalchemy\sql\elements.py", line 523, in _execute_on_connection
    return connection._execute_clauseelement(
           ~~~~~~~~~~~~~~~~~~~~~~~~~~~~~~~~~^
        self, distilled_params, execution_options
        ^^^^^^^^^^^^^^^^^^^^^^^^^^^^^^^^^^^^^^^^^
    )
    ^
  File "C:\Users\pc\AppData\Local\Programs\Python\Python313\Lib\site-packages\sqlalchemy\engine\base.py", line 1637, in _execute_clauseelement
    ret = self._execute_context(
        dialect,
    ...<8 lines>...
        cache_hit=cache_hit,
    )
  File "C:\Users\pc\AppData\Local\Programs\Python\Python313\Lib\site-packages\sqlalchemy\engine\base.py", line 1842, in _execute_context
    return self._exec_single_context(
           ~~~~~~~~~~~~~~~~~~~~~~~~~^
        dialect, context, statement, parameters
        ^^^^^^^^^^^^^^^^^^^^^^^^^^^^^^^^^^^^^^^
    )
    ^
  File "C:\Users\pc\AppData\Local\Programs\Python\Python313\Lib\site-packages\sqlalchemy\engine\base.py", line 1982, in _exec_single_context
    self._handle_dbapi_exception(
    ~~~~~~~~~~~~~~~~~~~~~~~~~~~~^
        e, str_statement, effective_parameters, cursor, context
        ^^^^^^^^^^^^^^^^^^^^^^^^^^^^^^^^^^^^^^^^^^^^^^^^^^^^^^^
    )
    ^
  File "C:\Users\pc\AppData\Local\Programs\Python\Python313\Lib\site-packages\sqlalchemy\engine\base.py", line 2351, in _handle_dbapi_exception
    raise sqlalchemy_exception.with_traceback(exc_info[2]) from e
  File "C:\Users\pc\AppData\Local\Programs\Python\Python313\Lib\site-packages\sqlalchemy\engine\base.py", line 1963, in _exec_single_context
    self.dialect.do_execute(
    ~~~~~~~~~~~~~~~~~~~~~~~^
        cursor, str_statement, effective_parameters, context
        ^^^^^^^^^^^^^^^^^^^^^^^^^^^^^^^^^^^^^^^^^^^^^^^^^^^^
    )
    ^
  File "C:\Users\pc\AppData\Local\Programs\Python\Python313\Lib\site-packages\sqlalchemy\engine\default.py", line 943, in do_execute
    cursor.execute(statement, parameters)
    ~~~~~~~~~~~~~~^^^^^^^^^^^^^^^^^^^^^^^
sqlalchemy.exc.OperationalError: (sqlite3.OperationalError) no such column: clients.addressline1
[SQL: SELECT clients.id AS clients_id, clients.name AS clients_name, clients.client_code AS clients_client_code, clients.contact_person AS clients_contact_person, clients.email AS clients_email, clients.phone AS clients_phone, clients.addressline1 AS clients_addressline1, clients.addressline2 AS clients_addressline2, clients.state AS clients_state, clients.coutry AS clients_coutry, clients.pincode AS clients_pincode, clients.gst_number AS clients_gst_number, clients.is_deleted AS clients_is_deleted 
FROM clients
 LIMIT ? OFFSET ?]
[parameters: (10, 0)]
(Background on this error at: https://sqlalche.me/e/20/e3q8)
[2025-06-23 16:39:00,898] [ERROR] uvicorn.error: Exception in ASGI application
Traceback (most recent call last):
  File "C:\Users\pc\AppData\Local\Programs\Python\Python313\Lib\site-packages\sqlalchemy\engine\base.py", line 1963, in _exec_single_context
    self.dialect.do_execute(
    ~~~~~~~~~~~~~~~~~~~~~~~^
        cursor, str_statement, effective_parameters, context
        ^^^^^^^^^^^^^^^^^^^^^^^^^^^^^^^^^^^^^^^^^^^^^^^^^^^^
    )
    ^
  File "C:\Users\pc\AppData\Local\Programs\Python\Python313\Lib\site-packages\sqlalchemy\engine\default.py", line 943, in do_execute
    cursor.execute(statement, parameters)
    ~~~~~~~~~~~~~~^^^^^^^^^^^^^^^^^^^^^^^
sqlite3.OperationalError: no such column: clients.addressline1

The above exception was the direct cause of the following exception:

Traceback (most recent call last):
  File "C:\Users\pc\AppData\Local\Programs\Python\Python313\Lib\site-packages\uvicorn\protocols\http\h11_impl.py", line 403, in run_asgi
    result = await app(  # type: ignore[func-returns-value]
             ^^^^^^^^^^^^^^^^^^^^^^^^^^^^^^^^^^^^^^^^^^^^^^
        self.scope, self.receive, self.send
        ^^^^^^^^^^^^^^^^^^^^^^^^^^^^^^^^^^^
    )
    ^
  File "C:\Users\pc\AppData\Local\Programs\Python\Python313\Lib\site-packages\uvicorn\middleware\proxy_headers.py", line 60, in __call__
    return await self.app(scope, receive, send)
           ^^^^^^^^^^^^^^^^^^^^^^^^^^^^^^^^^^^^
  File "C:\Users\pc\AppData\Local\Programs\Python\Python313\Lib\site-packages\fastapi\applications.py", line 1054, in __call__
    await super().__call__(scope, receive, send)
  File "C:\Users\pc\AppData\Local\Programs\Python\Python313\Lib\site-packages\starlette\applications.py", line 112, in __call__
    await self.middleware_stack(scope, receive, send)
  File "C:\Users\pc\AppData\Local\Programs\Python\Python313\Lib\site-packages\starlette\middleware\errors.py", line 187, in __call__
    raise exc
  File "C:\Users\pc\AppData\Local\Programs\Python\Python313\Lib\site-packages\starlette\middleware\errors.py", line 165, in __call__
    await self.app(scope, receive, _send)
  File "C:\Users\pc\AppData\Local\Programs\Python\Python313\Lib\site-packages\starlette\middleware\cors.py", line 93, in __call__
    await self.simple_response(scope, receive, send, request_headers=headers)
  File "C:\Users\pc\AppData\Local\Programs\Python\Python313\Lib\site-packages\starlette\middleware\cors.py", line 144, in simple_response
    await self.app(scope, receive, send)
  File "C:\Users\pc\AppData\Local\Programs\Python\Python313\Lib\site-packages\starlette\middleware\exceptions.py", line 62, in __call__
    await wrap_app_handling_exceptions(self.app, conn)(scope, receive, send)
  File "C:\Users\pc\AppData\Local\Programs\Python\Python313\Lib\site-packages\starlette\_exception_handler.py", line 53, in wrapped_app
    raise exc
  File "C:\Users\pc\AppData\Local\Programs\Python\Python313\Lib\site-packages\starlette\_exception_handler.py", line 42, in wrapped_app
    await app(scope, receive, sender)
  File "C:\Users\pc\AppData\Local\Programs\Python\Python313\Lib\site-packages\starlette\routing.py", line 714, in __call__
    await self.middleware_stack(scope, receive, send)
  File "C:\Users\pc\AppData\Local\Programs\Python\Python313\Lib\site-packages\starlette\routing.py", line 734, in app
    await route.handle(scope, receive, send)
  File "C:\Users\pc\AppData\Local\Programs\Python\Python313\Lib\site-packages\starlette\routing.py", line 288, in handle
    await self.app(scope, receive, send)
  File "C:\Users\pc\AppData\Local\Programs\Python\Python313\Lib\site-packages\starlette\routing.py", line 76, in app
    await wrap_app_handling_exceptions(app, request)(scope, receive, send)
  File "C:\Users\pc\AppData\Local\Programs\Python\Python313\Lib\site-packages\starlette\_exception_handler.py", line 53, in wrapped_app
    raise exc
  File "C:\Users\pc\AppData\Local\Programs\Python\Python313\Lib\site-packages\starlette\_exception_handler.py", line 42, in wrapped_app
    await app(scope, receive, sender)
  File "C:\Users\pc\AppData\Local\Programs\Python\Python313\Lib\site-packages\starlette\routing.py", line 73, in app
    response = await f(request)
               ^^^^^^^^^^^^^^^^
  File "C:\Users\pc\AppData\Local\Programs\Python\Python313\Lib\site-packages\fastapi\routing.py", line 301, in app
    raw_response = await run_endpoint_function(
                   ^^^^^^^^^^^^^^^^^^^^^^^^^^^^
    ...<3 lines>...
    )
    ^
  File "C:\Users\pc\AppData\Local\Programs\Python\Python313\Lib\site-packages\fastapi\routing.py", line 214, in run_endpoint_function
    return await run_in_threadpool(dependant.call, **values)
           ^^^^^^^^^^^^^^^^^^^^^^^^^^^^^^^^^^^^^^^^^^^^^^^^^
  File "C:\Users\pc\AppData\Local\Programs\Python\Python313\Lib\site-packages\starlette\concurrency.py", line 37, in run_in_threadpool
    return await anyio.to_thread.run_sync(func)
           ^^^^^^^^^^^^^^^^^^^^^^^^^^^^^^^^^^^^
  File "C:\Users\pc\AppData\Local\Programs\Python\Python313\Lib\site-packages\anyio\to_thread.py", line 56, in run_sync
    return await get_async_backend().run_sync_in_worker_thread(
           ^^^^^^^^^^^^^^^^^^^^^^^^^^^^^^^^^^^^^^^^^^^^^^^^^^^^
        func, args, abandon_on_cancel=abandon_on_cancel, limiter=limiter
        ^^^^^^^^^^^^^^^^^^^^^^^^^^^^^^^^^^^^^^^^^^^^^^^^^^^^^^^^^^^^^^^^
    )
    ^
  File "C:\Users\pc\AppData\Local\Programs\Python\Python313\Lib\site-packages\anyio\_backends\_asyncio.py", line 2470, in run_sync_in_worker_thread
    return await future
           ^^^^^^^^^^^^
  File "C:\Users\pc\AppData\Local\Programs\Python\Python313\Lib\site-packages\anyio\_backends\_asyncio.py", line 967, in run
    result = context.run(func, *args)
  File "D:\Projects\Development\webcore-erp\webcore-erp\wcs-backend\app\routes\client.py", line 35, in get_clients
    return db.query(Client).offset(skip).limit(limit).all()
           ~~~~~~~~~~~~~~~~~~~~~~~~~~~~~~~~~~~~~~~~~~~~~~^^
  File "C:\Users\pc\AppData\Local\Programs\Python\Python313\Lib\site-packages\sqlalchemy\orm\query.py", line 2704, in all
    return self._iter().all()  # type: ignore
           ~~~~~~~~~~^^
  File "C:\Users\pc\AppData\Local\Programs\Python\Python313\Lib\site-packages\sqlalchemy\orm\query.py", line 2857, in _iter
    result: Union[ScalarResult[_T], Result[_T]] = self.session.execute(
                                                  ~~~~~~~~~~~~~~~~~~~~^
        statement,
        ^^^^^^^^^^
        params,
        ^^^^^^^
        execution_options={"_sa_orm_load_options": self.load_options},
        ^^^^^^^^^^^^^^^^^^^^^^^^^^^^^^^^^^^^^^^^^^^^^^^^^^^^^^^^^^^^^^
    )
    ^
  File "C:\Users\pc\AppData\Local\Programs\Python\Python313\Lib\site-packages\sqlalchemy\orm\session.py", line 2365, in execute
    return self._execute_internal(
           ~~~~~~~~~~~~~~~~~~~~~~^
        statement,
        ^^^^^^^^^^
    ...<4 lines>...
        _add_event=_add_event,
        ^^^^^^^^^^^^^^^^^^^^^^
    )
    ^
  File "C:\Users\pc\AppData\Local\Programs\Python\Python313\Lib\site-packages\sqlalchemy\orm\session.py", line 2251, in _execute_internal
    result: Result[Any] = compile_state_cls.orm_execute_statement(
                          ~~~~~~~~~~~~~~~~~~~~~~~~~~~~~~~~~~~~~~~^
        self,
        ^^^^^
    ...<4 lines>...
        conn,
        ^^^^^
    )
    ^
  File "C:\Users\pc\AppData\Local\Programs\Python\Python313\Lib\site-packages\sqlalchemy\orm\context.py", line 306, in orm_execute_statement
    result = conn.execute(
        statement, params or {}, execution_options=execution_options
    )
  File "C:\Users\pc\AppData\Local\Programs\Python\Python313\Lib\site-packages\sqlalchemy\engine\base.py", line 1415, in execute
    return meth(
        self,
        distilled_parameters,
        execution_options or NO_OPTIONS,
    )
  File "C:\Users\pc\AppData\Local\Programs\Python\Python313\Lib\site-packages\sqlalchemy\sql\elements.py", line 523, in _execute_on_connection
    return connection._execute_clauseelement(
           ~~~~~~~~~~~~~~~~~~~~~~~~~~~~~~~~~^
        self, distilled_params, execution_options
        ^^^^^^^^^^^^^^^^^^^^^^^^^^^^^^^^^^^^^^^^^
    )
    ^
  File "C:\Users\pc\AppData\Local\Programs\Python\Python313\Lib\site-packages\sqlalchemy\engine\base.py", line 1637, in _execute_clauseelement
    ret = self._execute_context(
        dialect,
    ...<8 lines>...
        cache_hit=cache_hit,
    )
  File "C:\Users\pc\AppData\Local\Programs\Python\Python313\Lib\site-packages\sqlalchemy\engine\base.py", line 1842, in _execute_context
    return self._exec_single_context(
           ~~~~~~~~~~~~~~~~~~~~~~~~~^
        dialect, context, statement, parameters
        ^^^^^^^^^^^^^^^^^^^^^^^^^^^^^^^^^^^^^^^
    )
    ^
  File "C:\Users\pc\AppData\Local\Programs\Python\Python313\Lib\site-packages\sqlalchemy\engine\base.py", line 1982, in _exec_single_context
    self._handle_dbapi_exception(
    ~~~~~~~~~~~~~~~~~~~~~~~~~~~~^
        e, str_statement, effective_parameters, cursor, context
        ^^^^^^^^^^^^^^^^^^^^^^^^^^^^^^^^^^^^^^^^^^^^^^^^^^^^^^^
    )
    ^
  File "C:\Users\pc\AppData\Local\Programs\Python\Python313\Lib\site-packages\sqlalchemy\engine\base.py", line 2351, in _handle_dbapi_exception
    raise sqlalchemy_exception.with_traceback(exc_info[2]) from e
  File "C:\Users\pc\AppData\Local\Programs\Python\Python313\Lib\site-packages\sqlalchemy\engine\base.py", line 1963, in _exec_single_context
    self.dialect.do_execute(
    ~~~~~~~~~~~~~~~~~~~~~~~^
        cursor, str_statement, effective_parameters, context
        ^^^^^^^^^^^^^^^^^^^^^^^^^^^^^^^^^^^^^^^^^^^^^^^^^^^^
    )
    ^
  File "C:\Users\pc\AppData\Local\Programs\Python\Python313\Lib\site-packages\sqlalchemy\engine\default.py", line 943, in do_execute
    cursor.execute(statement, parameters)
    ~~~~~~~~~~~~~~^^^^^^^^^^^^^^^^^^^^^^^
sqlalchemy.exc.OperationalError: (sqlite3.OperationalError) no such column: clients.addressline1
[SQL: SELECT clients.id AS clients_id, clients.name AS clients_name, clients.client_code AS clients_client_code, clients.contact_person AS clients_contact_person, clients.email AS clients_email, clients.phone AS clients_phone, clients.addressline1 AS clients_addressline1, clients.addressline2 AS clients_addressline2, clients.state AS clients_state, clients.coutry AS clients_coutry, clients.pincode AS clients_pincode, clients.gst_number AS clients_gst_number, clients.is_deleted AS clients_is_deleted 
FROM clients
 LIMIT ? OFFSET ?]
[parameters: (10, 0)]
(Background on this error at: https://sqlalche.me/e/20/e3q8)
[2025-06-23 16:42:47,804] [ERROR] uvicorn.error: Exception in ASGI application
Traceback (most recent call last):
  File "C:\Users\pc\AppData\Local\Programs\Python\Python313\Lib\site-packages\uvicorn\protocols\http\h11_impl.py", line 403, in run_asgi
    result = await app(  # type: ignore[func-returns-value]
             ^^^^^^^^^^^^^^^^^^^^^^^^^^^^^^^^^^^^^^^^^^^^^^
        self.scope, self.receive, self.send
        ^^^^^^^^^^^^^^^^^^^^^^^^^^^^^^^^^^^
    )
    ^
  File "C:\Users\pc\AppData\Local\Programs\Python\Python313\Lib\site-packages\uvicorn\middleware\proxy_headers.py", line 60, in __call__
    return await self.app(scope, receive, send)
           ^^^^^^^^^^^^^^^^^^^^^^^^^^^^^^^^^^^^
  File "C:\Users\pc\AppData\Local\Programs\Python\Python313\Lib\site-packages\fastapi\applications.py", line 1054, in __call__
    await super().__call__(scope, receive, send)
  File "C:\Users\pc\AppData\Local\Programs\Python\Python313\Lib\site-packages\starlette\applications.py", line 112, in __call__
    await self.middleware_stack(scope, receive, send)
  File "C:\Users\pc\AppData\Local\Programs\Python\Python313\Lib\site-packages\starlette\middleware\errors.py", line 187, in __call__
    raise exc
  File "C:\Users\pc\AppData\Local\Programs\Python\Python313\Lib\site-packages\starlette\middleware\errors.py", line 165, in __call__
    await self.app(scope, receive, _send)
  File "C:\Users\pc\AppData\Local\Programs\Python\Python313\Lib\site-packages\starlette\middleware\cors.py", line 93, in __call__
    await self.simple_response(scope, receive, send, request_headers=headers)
  File "C:\Users\pc\AppData\Local\Programs\Python\Python313\Lib\site-packages\starlette\middleware\cors.py", line 144, in simple_response
    await self.app(scope, receive, send)
  File "C:\Users\pc\AppData\Local\Programs\Python\Python313\Lib\site-packages\starlette\middleware\exceptions.py", line 62, in __call__
    await wrap_app_handling_exceptions(self.app, conn)(scope, receive, send)
  File "C:\Users\pc\AppData\Local\Programs\Python\Python313\Lib\site-packages\starlette\_exception_handler.py", line 53, in wrapped_app
    raise exc
  File "C:\Users\pc\AppData\Local\Programs\Python\Python313\Lib\site-packages\starlette\_exception_handler.py", line 42, in wrapped_app
    await app(scope, receive, sender)
  File "C:\Users\pc\AppData\Local\Programs\Python\Python313\Lib\site-packages\starlette\routing.py", line 714, in __call__
    await self.middleware_stack(scope, receive, send)
  File "C:\Users\pc\AppData\Local\Programs\Python\Python313\Lib\site-packages\starlette\routing.py", line 734, in app
    await route.handle(scope, receive, send)
  File "C:\Users\pc\AppData\Local\Programs\Python\Python313\Lib\site-packages\starlette\routing.py", line 288, in handle
    await self.app(scope, receive, send)
  File "C:\Users\pc\AppData\Local\Programs\Python\Python313\Lib\site-packages\starlette\routing.py", line 76, in app
    await wrap_app_handling_exceptions(app, request)(scope, receive, send)
  File "C:\Users\pc\AppData\Local\Programs\Python\Python313\Lib\site-packages\starlette\_exception_handler.py", line 53, in wrapped_app
    raise exc
  File "C:\Users\pc\AppData\Local\Programs\Python\Python313\Lib\site-packages\starlette\_exception_handler.py", line 42, in wrapped_app
    await app(scope, receive, sender)
  File "C:\Users\pc\AppData\Local\Programs\Python\Python313\Lib\site-packages\starlette\routing.py", line 73, in app
    response = await f(request)
               ^^^^^^^^^^^^^^^^
  File "C:\Users\pc\AppData\Local\Programs\Python\Python313\Lib\site-packages\fastapi\routing.py", line 327, in app
    content = await serialize_response(
              ^^^^^^^^^^^^^^^^^^^^^^^^^
    ...<9 lines>...
    )
    ^
  File "C:\Users\pc\AppData\Local\Programs\Python\Python313\Lib\site-packages\fastapi\routing.py", line 176, in serialize_response
    raise ResponseValidationError(
        errors=_normalize_errors(errors), body=response_content
    )
fastapi.exceptions.ResponseValidationError: 5 validation errors:
  {'type': 'missing', 'loc': ('response', 0, 'address'), 'msg': 'Field required', 'input': <app.models.client.Client object at 0x0000027B5E726660>}
  {'type': 'missing', 'loc': ('response', 1, 'address'), 'msg': 'Field required', 'input': <app.models.client.Client object at 0x0000027B5E7B7B10>}
  {'type': 'missing', 'loc': ('response', 2, 'address'), 'msg': 'Field required', 'input': <app.models.client.Client object at 0x0000027B5E7B79D0>}
  {'type': 'missing', 'loc': ('response', 3, 'address'), 'msg': 'Field required', 'input': <app.models.client.Client object at 0x0000027B5E8B6EA0>}
  {'type': 'missing', 'loc': ('response', 4, 'address'), 'msg': 'Field required', 'input': <app.models.client.Client object at 0x0000027B5E8B6B10>}

[2025-06-23 16:42:48,044] [ERROR] uvicorn.error: Exception in ASGI application
Traceback (most recent call last):
  File "C:\Users\pc\AppData\Local\Programs\Python\Python313\Lib\site-packages\uvicorn\protocols\http\h11_impl.py", line 403, in run_asgi
    result = await app(  # type: ignore[func-returns-value]
             ^^^^^^^^^^^^^^^^^^^^^^^^^^^^^^^^^^^^^^^^^^^^^^
        self.scope, self.receive, self.send
        ^^^^^^^^^^^^^^^^^^^^^^^^^^^^^^^^^^^
    )
    ^
  File "C:\Users\pc\AppData\Local\Programs\Python\Python313\Lib\site-packages\uvicorn\middleware\proxy_headers.py", line 60, in __call__
    return await self.app(scope, receive, send)
           ^^^^^^^^^^^^^^^^^^^^^^^^^^^^^^^^^^^^
  File "C:\Users\pc\AppData\Local\Programs\Python\Python313\Lib\site-packages\fastapi\applications.py", line 1054, in __call__
    await super().__call__(scope, receive, send)
  File "C:\Users\pc\AppData\Local\Programs\Python\Python313\Lib\site-packages\starlette\applications.py", line 112, in __call__
    await self.middleware_stack(scope, receive, send)
  File "C:\Users\pc\AppData\Local\Programs\Python\Python313\Lib\site-packages\starlette\middleware\errors.py", line 187, in __call__
    raise exc
  File "C:\Users\pc\AppData\Local\Programs\Python\Python313\Lib\site-packages\starlette\middleware\errors.py", line 165, in __call__
    await self.app(scope, receive, _send)
  File "C:\Users\pc\AppData\Local\Programs\Python\Python313\Lib\site-packages\starlette\middleware\cors.py", line 93, in __call__
    await self.simple_response(scope, receive, send, request_headers=headers)
  File "C:\Users\pc\AppData\Local\Programs\Python\Python313\Lib\site-packages\starlette\middleware\cors.py", line 144, in simple_response
    await self.app(scope, receive, send)
  File "C:\Users\pc\AppData\Local\Programs\Python\Python313\Lib\site-packages\starlette\middleware\exceptions.py", line 62, in __call__
    await wrap_app_handling_exceptions(self.app, conn)(scope, receive, send)
  File "C:\Users\pc\AppData\Local\Programs\Python\Python313\Lib\site-packages\starlette\_exception_handler.py", line 53, in wrapped_app
    raise exc
  File "C:\Users\pc\AppData\Local\Programs\Python\Python313\Lib\site-packages\starlette\_exception_handler.py", line 42, in wrapped_app
    await app(scope, receive, sender)
  File "C:\Users\pc\AppData\Local\Programs\Python\Python313\Lib\site-packages\starlette\routing.py", line 714, in __call__
    await self.middleware_stack(scope, receive, send)
  File "C:\Users\pc\AppData\Local\Programs\Python\Python313\Lib\site-packages\starlette\routing.py", line 734, in app
    await route.handle(scope, receive, send)
  File "C:\Users\pc\AppData\Local\Programs\Python\Python313\Lib\site-packages\starlette\routing.py", line 288, in handle
    await self.app(scope, receive, send)
  File "C:\Users\pc\AppData\Local\Programs\Python\Python313\Lib\site-packages\starlette\routing.py", line 76, in app
    await wrap_app_handling_exceptions(app, request)(scope, receive, send)
  File "C:\Users\pc\AppData\Local\Programs\Python\Python313\Lib\site-packages\starlette\_exception_handler.py", line 53, in wrapped_app
    raise exc
  File "C:\Users\pc\AppData\Local\Programs\Python\Python313\Lib\site-packages\starlette\_exception_handler.py", line 42, in wrapped_app
    await app(scope, receive, sender)
  File "C:\Users\pc\AppData\Local\Programs\Python\Python313\Lib\site-packages\starlette\routing.py", line 73, in app
    response = await f(request)
               ^^^^^^^^^^^^^^^^
  File "C:\Users\pc\AppData\Local\Programs\Python\Python313\Lib\site-packages\fastapi\routing.py", line 327, in app
    content = await serialize_response(
              ^^^^^^^^^^^^^^^^^^^^^^^^^
    ...<9 lines>...
    )
    ^
  File "C:\Users\pc\AppData\Local\Programs\Python\Python313\Lib\site-packages\fastapi\routing.py", line 176, in serialize_response
    raise ResponseValidationError(
        errors=_normalize_errors(errors), body=response_content
    )
fastapi.exceptions.ResponseValidationError: 5 validation errors:
  {'type': 'missing', 'loc': ('response', 0, 'address'), 'msg': 'Field required', 'input': <app.models.client.Client object at 0x0000027B5E892570>}
  {'type': 'missing', 'loc': ('response', 1, 'address'), 'msg': 'Field required', 'input': <app.models.client.Client object at 0x0000027B5E7AF460>}
  {'type': 'missing', 'loc': ('response', 2, 'address'), 'msg': 'Field required', 'input': <app.models.client.Client object at 0x0000027B5E7AF350>}
  {'type': 'missing', 'loc': ('response', 3, 'address'), 'msg': 'Field required', 'input': <app.models.client.Client object at 0x0000027B5E8CED50>}
  {'type': 'missing', 'loc': ('response', 4, 'address'), 'msg': 'Field required', 'input': <app.models.client.Client object at 0x0000027B5E8CF750>}

[2025-06-23 16:42:48,997] [INFO] app.routes.auth: employee found: <app.models.employee.Employee object at 0x0000027B5E7B6210>
[2025-06-23 16:42:56,379] [ERROR] uvicorn.error: Exception in ASGI application
Traceback (most recent call last):
  File "C:\Users\pc\AppData\Local\Programs\Python\Python313\Lib\site-packages\uvicorn\protocols\http\h11_impl.py", line 403, in run_asgi
    result = await app(  # type: ignore[func-returns-value]
             ^^^^^^^^^^^^^^^^^^^^^^^^^^^^^^^^^^^^^^^^^^^^^^
        self.scope, self.receive, self.send
        ^^^^^^^^^^^^^^^^^^^^^^^^^^^^^^^^^^^
    )
    ^
  File "C:\Users\pc\AppData\Local\Programs\Python\Python313\Lib\site-packages\uvicorn\middleware\proxy_headers.py", line 60, in __call__
    return await self.app(scope, receive, send)
           ^^^^^^^^^^^^^^^^^^^^^^^^^^^^^^^^^^^^
  File "C:\Users\pc\AppData\Local\Programs\Python\Python313\Lib\site-packages\fastapi\applications.py", line 1054, in __call__
    await super().__call__(scope, receive, send)
  File "C:\Users\pc\AppData\Local\Programs\Python\Python313\Lib\site-packages\starlette\applications.py", line 112, in __call__
    await self.middleware_stack(scope, receive, send)
  File "C:\Users\pc\AppData\Local\Programs\Python\Python313\Lib\site-packages\starlette\middleware\errors.py", line 187, in __call__
    raise exc
  File "C:\Users\pc\AppData\Local\Programs\Python\Python313\Lib\site-packages\starlette\middleware\errors.py", line 165, in __call__
    await self.app(scope, receive, _send)
  File "C:\Users\pc\AppData\Local\Programs\Python\Python313\Lib\site-packages\starlette\middleware\cors.py", line 93, in __call__
    await self.simple_response(scope, receive, send, request_headers=headers)
  File "C:\Users\pc\AppData\Local\Programs\Python\Python313\Lib\site-packages\starlette\middleware\cors.py", line 144, in simple_response
    await self.app(scope, receive, send)
  File "C:\Users\pc\AppData\Local\Programs\Python\Python313\Lib\site-packages\starlette\middleware\exceptions.py", line 62, in __call__
    await wrap_app_handling_exceptions(self.app, conn)(scope, receive, send)
  File "C:\Users\pc\AppData\Local\Programs\Python\Python313\Lib\site-packages\starlette\_exception_handler.py", line 53, in wrapped_app
    raise exc
  File "C:\Users\pc\AppData\Local\Programs\Python\Python313\Lib\site-packages\starlette\_exception_handler.py", line 42, in wrapped_app
    await app(scope, receive, sender)
  File "C:\Users\pc\AppData\Local\Programs\Python\Python313\Lib\site-packages\starlette\routing.py", line 714, in __call__
    await self.middleware_stack(scope, receive, send)
  File "C:\Users\pc\AppData\Local\Programs\Python\Python313\Lib\site-packages\starlette\routing.py", line 734, in app
    await route.handle(scope, receive, send)
  File "C:\Users\pc\AppData\Local\Programs\Python\Python313\Lib\site-packages\starlette\routing.py", line 288, in handle
    await self.app(scope, receive, send)
  File "C:\Users\pc\AppData\Local\Programs\Python\Python313\Lib\site-packages\starlette\routing.py", line 76, in app
    await wrap_app_handling_exceptions(app, request)(scope, receive, send)
  File "C:\Users\pc\AppData\Local\Programs\Python\Python313\Lib\site-packages\starlette\_exception_handler.py", line 53, in wrapped_app
    raise exc
  File "C:\Users\pc\AppData\Local\Programs\Python\Python313\Lib\site-packages\starlette\_exception_handler.py", line 42, in wrapped_app
    await app(scope, receive, sender)
  File "C:\Users\pc\AppData\Local\Programs\Python\Python313\Lib\site-packages\starlette\routing.py", line 73, in app
    response = await f(request)
               ^^^^^^^^^^^^^^^^
  File "C:\Users\pc\AppData\Local\Programs\Python\Python313\Lib\site-packages\fastapi\routing.py", line 327, in app
    content = await serialize_response(
              ^^^^^^^^^^^^^^^^^^^^^^^^^
    ...<9 lines>...
    )
    ^
  File "C:\Users\pc\AppData\Local\Programs\Python\Python313\Lib\site-packages\fastapi\routing.py", line 176, in serialize_response
    raise ResponseValidationError(
        errors=_normalize_errors(errors), body=response_content
    )
fastapi.exceptions.ResponseValidationError: 5 validation errors:
  {'type': 'missing', 'loc': ('response', 0, 'address'), 'msg': 'Field required', 'input': <app.models.client.Client object at 0x0000027B5E915E50>}
  {'type': 'missing', 'loc': ('response', 1, 'address'), 'msg': 'Field required', 'input': <app.models.client.Client object at 0x0000027B5E915F40>}
  {'type': 'missing', 'loc': ('response', 2, 'address'), 'msg': 'Field required', 'input': <app.models.client.Client object at 0x0000027B5E943770>}
  {'type': 'missing', 'loc': ('response', 3, 'address'), 'msg': 'Field required', 'input': <app.models.client.Client object at 0x0000027B5E9434D0>}
  {'type': 'missing', 'loc': ('response', 4, 'address'), 'msg': 'Field required', 'input': <app.models.client.Client object at 0x0000027B5E881BF0>}

[2025-06-23 16:42:56,643] [ERROR] uvicorn.error: Exception in ASGI application
Traceback (most recent call last):
  File "C:\Users\pc\AppData\Local\Programs\Python\Python313\Lib\site-packages\uvicorn\protocols\http\h11_impl.py", line 403, in run_asgi
    result = await app(  # type: ignore[func-returns-value]
             ^^^^^^^^^^^^^^^^^^^^^^^^^^^^^^^^^^^^^^^^^^^^^^
        self.scope, self.receive, self.send
        ^^^^^^^^^^^^^^^^^^^^^^^^^^^^^^^^^^^
    )
    ^
  File "C:\Users\pc\AppData\Local\Programs\Python\Python313\Lib\site-packages\uvicorn\middleware\proxy_headers.py", line 60, in __call__
    return await self.app(scope, receive, send)
           ^^^^^^^^^^^^^^^^^^^^^^^^^^^^^^^^^^^^
  File "C:\Users\pc\AppData\Local\Programs\Python\Python313\Lib\site-packages\fastapi\applications.py", line 1054, in __call__
    await super().__call__(scope, receive, send)
  File "C:\Users\pc\AppData\Local\Programs\Python\Python313\Lib\site-packages\starlette\applications.py", line 112, in __call__
    await self.middleware_stack(scope, receive, send)
  File "C:\Users\pc\AppData\Local\Programs\Python\Python313\Lib\site-packages\starlette\middleware\errors.py", line 187, in __call__
    raise exc
  File "C:\Users\pc\AppData\Local\Programs\Python\Python313\Lib\site-packages\starlette\middleware\errors.py", line 165, in __call__
    await self.app(scope, receive, _send)
  File "C:\Users\pc\AppData\Local\Programs\Python\Python313\Lib\site-packages\starlette\middleware\cors.py", line 93, in __call__
    await self.simple_response(scope, receive, send, request_headers=headers)
  File "C:\Users\pc\AppData\Local\Programs\Python\Python313\Lib\site-packages\starlette\middleware\cors.py", line 144, in simple_response
    await self.app(scope, receive, send)
  File "C:\Users\pc\AppData\Local\Programs\Python\Python313\Lib\site-packages\starlette\middleware\exceptions.py", line 62, in __call__
    await wrap_app_handling_exceptions(self.app, conn)(scope, receive, send)
  File "C:\Users\pc\AppData\Local\Programs\Python\Python313\Lib\site-packages\starlette\_exception_handler.py", line 53, in wrapped_app
    raise exc
  File "C:\Users\pc\AppData\Local\Programs\Python\Python313\Lib\site-packages\starlette\_exception_handler.py", line 42, in wrapped_app
    await app(scope, receive, sender)
  File "C:\Users\pc\AppData\Local\Programs\Python\Python313\Lib\site-packages\starlette\routing.py", line 714, in __call__
    await self.middleware_stack(scope, receive, send)
  File "C:\Users\pc\AppData\Local\Programs\Python\Python313\Lib\site-packages\starlette\routing.py", line 734, in app
    await route.handle(scope, receive, send)
  File "C:\Users\pc\AppData\Local\Programs\Python\Python313\Lib\site-packages\starlette\routing.py", line 288, in handle
    await self.app(scope, receive, send)
  File "C:\Users\pc\AppData\Local\Programs\Python\Python313\Lib\site-packages\starlette\routing.py", line 76, in app
    await wrap_app_handling_exceptions(app, request)(scope, receive, send)
  File "C:\Users\pc\AppData\Local\Programs\Python\Python313\Lib\site-packages\starlette\_exception_handler.py", line 53, in wrapped_app
    raise exc
  File "C:\Users\pc\AppData\Local\Programs\Python\Python313\Lib\site-packages\starlette\_exception_handler.py", line 42, in wrapped_app
    await app(scope, receive, sender)
  File "C:\Users\pc\AppData\Local\Programs\Python\Python313\Lib\site-packages\starlette\routing.py", line 73, in app
    response = await f(request)
               ^^^^^^^^^^^^^^^^
  File "C:\Users\pc\AppData\Local\Programs\Python\Python313\Lib\site-packages\fastapi\routing.py", line 327, in app
    content = await serialize_response(
              ^^^^^^^^^^^^^^^^^^^^^^^^^
    ...<9 lines>...
    )
    ^
  File "C:\Users\pc\AppData\Local\Programs\Python\Python313\Lib\site-packages\fastapi\routing.py", line 176, in serialize_response
    raise ResponseValidationError(
        errors=_normalize_errors(errors), body=response_content
    )
fastapi.exceptions.ResponseValidationError: 5 validation errors:
  {'type': 'missing', 'loc': ('response', 0, 'address'), 'msg': 'Field required', 'input': <app.models.client.Client object at 0x0000027B5E88A450>}
  {'type': 'missing', 'loc': ('response', 1, 'address'), 'msg': 'Field required', 'input': <app.models.client.Client object at 0x0000027B5E88A2D0>}
  {'type': 'missing', 'loc': ('response', 2, 'address'), 'msg': 'Field required', 'input': <app.models.client.Client object at 0x0000027B5E889D90>}
  {'type': 'missing', 'loc': ('response', 3, 'address'), 'msg': 'Field required', 'input': <app.models.client.Client object at 0x0000027B5E88A150>}
  {'type': 'missing', 'loc': ('response', 4, 'address'), 'msg': 'Field required', 'input': <app.models.client.Client object at 0x0000027B5E88A5D0>}

[2025-06-23 16:43:16,793] [ERROR] uvicorn.error: Exception in ASGI application
Traceback (most recent call last):
  File "C:\Users\pc\AppData\Local\Programs\Python\Python313\Lib\site-packages\uvicorn\protocols\http\h11_impl.py", line 403, in run_asgi
    result = await app(  # type: ignore[func-returns-value]
             ^^^^^^^^^^^^^^^^^^^^^^^^^^^^^^^^^^^^^^^^^^^^^^
        self.scope, self.receive, self.send
        ^^^^^^^^^^^^^^^^^^^^^^^^^^^^^^^^^^^
    )
    ^
  File "C:\Users\pc\AppData\Local\Programs\Python\Python313\Lib\site-packages\uvicorn\middleware\proxy_headers.py", line 60, in __call__
    return await self.app(scope, receive, send)
           ^^^^^^^^^^^^^^^^^^^^^^^^^^^^^^^^^^^^
  File "C:\Users\pc\AppData\Local\Programs\Python\Python313\Lib\site-packages\fastapi\applications.py", line 1054, in __call__
    await super().__call__(scope, receive, send)
  File "C:\Users\pc\AppData\Local\Programs\Python\Python313\Lib\site-packages\starlette\applications.py", line 112, in __call__
    await self.middleware_stack(scope, receive, send)
  File "C:\Users\pc\AppData\Local\Programs\Python\Python313\Lib\site-packages\starlette\middleware\errors.py", line 187, in __call__
    raise exc
  File "C:\Users\pc\AppData\Local\Programs\Python\Python313\Lib\site-packages\starlette\middleware\errors.py", line 165, in __call__
    await self.app(scope, receive, _send)
  File "C:\Users\pc\AppData\Local\Programs\Python\Python313\Lib\site-packages\starlette\middleware\cors.py", line 85, in __call__
    await self.app(scope, receive, send)
  File "C:\Users\pc\AppData\Local\Programs\Python\Python313\Lib\site-packages\starlette\middleware\exceptions.py", line 62, in __call__
    await wrap_app_handling_exceptions(self.app, conn)(scope, receive, send)
  File "C:\Users\pc\AppData\Local\Programs\Python\Python313\Lib\site-packages\starlette\_exception_handler.py", line 53, in wrapped_app
    raise exc
  File "C:\Users\pc\AppData\Local\Programs\Python\Python313\Lib\site-packages\starlette\_exception_handler.py", line 42, in wrapped_app
    await app(scope, receive, sender)
  File "C:\Users\pc\AppData\Local\Programs\Python\Python313\Lib\site-packages\starlette\routing.py", line 714, in __call__
    await self.middleware_stack(scope, receive, send)
  File "C:\Users\pc\AppData\Local\Programs\Python\Python313\Lib\site-packages\starlette\routing.py", line 734, in app
    await route.handle(scope, receive, send)
  File "C:\Users\pc\AppData\Local\Programs\Python\Python313\Lib\site-packages\starlette\routing.py", line 288, in handle
    await self.app(scope, receive, send)
  File "C:\Users\pc\AppData\Local\Programs\Python\Python313\Lib\site-packages\starlette\routing.py", line 76, in app
    await wrap_app_handling_exceptions(app, request)(scope, receive, send)
  File "C:\Users\pc\AppData\Local\Programs\Python\Python313\Lib\site-packages\starlette\_exception_handler.py", line 53, in wrapped_app
    raise exc
  File "C:\Users\pc\AppData\Local\Programs\Python\Python313\Lib\site-packages\starlette\_exception_handler.py", line 42, in wrapped_app
    await app(scope, receive, sender)
  File "C:\Users\pc\AppData\Local\Programs\Python\Python313\Lib\site-packages\starlette\routing.py", line 73, in app
    response = await f(request)
               ^^^^^^^^^^^^^^^^
  File "C:\Users\pc\AppData\Local\Programs\Python\Python313\Lib\site-packages\fastapi\routing.py", line 327, in app
    content = await serialize_response(
              ^^^^^^^^^^^^^^^^^^^^^^^^^
    ...<9 lines>...
    )
    ^
  File "C:\Users\pc\AppData\Local\Programs\Python\Python313\Lib\site-packages\fastapi\routing.py", line 176, in serialize_response
    raise ResponseValidationError(
        errors=_normalize_errors(errors), body=response_content
    )
fastapi.exceptions.ResponseValidationError: 5 validation errors:
  {'type': 'missing', 'loc': ('response', 0, 'address'), 'msg': 'Field required', 'input': <app.models.client.Client object at 0x0000027B5E59AC90>}
  {'type': 'missing', 'loc': ('response', 1, 'address'), 'msg': 'Field required', 'input': <app.models.client.Client object at 0x0000027B5E88A390>}
  {'type': 'missing', 'loc': ('response', 2, 'address'), 'msg': 'Field required', 'input': <app.models.client.Client object at 0x0000027B5E88A090>}
  {'type': 'missing', 'loc': ('response', 3, 'address'), 'msg': 'Field required', 'input': <app.models.client.Client object at 0x0000027B5E889FD0>}
  {'type': 'missing', 'loc': ('response', 4, 'address'), 'msg': 'Field required', 'input': <app.models.client.Client object at 0x0000027B5E88A210>}

[2025-06-23 16:45:42,194] [INFO] uvicorn.error: Shutting down
[2025-06-23 16:45:42,307] [INFO] uvicorn.error: Waiting for application shutdown.
[2025-06-23 16:45:42,308] [INFO] uvicorn.error: Application shutdown complete.
[2025-06-23 16:45:42,308] [INFO] uvicorn.error: Finished server process [13640]
[2025-06-23 16:48:46,075] [INFO] uvicorn.error: Started server process [8496]
[2025-06-23 16:48:46,076] [INFO] uvicorn.error: Waiting for application startup.
[2025-06-23 16:48:46,077] [INFO] uvicorn.error: Application startup complete.
[2025-06-23 16:48:46,078] [INFO] uvicorn.error: Uvicorn running on http://127.0.0.1:8000 (Press CTRL+C to quit)
[2025-06-23 16:48:59,105] [INFO] app.routes.auth: employee found: <app.models.employee.Employee object at 0x000001CFD35067B0>
[2025-06-23 16:49:14,263] [INFO] app.routes.auth: employee found: <app.models.employee.Employee object at 0x000001CFD378D310>
[2025-06-23 16:51:15,257] [INFO] uvicorn.error: Shutting down
[2025-06-23 16:51:15,363] [INFO] uvicorn.error: Waiting for application shutdown.
[2025-06-23 16:51:15,364] [INFO] uvicorn.error: Application shutdown complete.
[2025-06-23 16:51:15,364] [INFO] uvicorn.error: Finished server process [8496]
[2025-06-23 16:51:19,799] [INFO] uvicorn.error: Started server process [14848]
[2025-06-23 16:51:19,800] [INFO] uvicorn.error: Waiting for application startup.
[2025-06-23 16:51:19,801] [INFO] uvicorn.error: Application startup complete.
[2025-06-23 16:51:19,802] [INFO] uvicorn.error: Uvicorn running on http://127.0.0.1:8000 (Press CTRL+C to quit)
[2025-06-23 16:51:29,289] [ERROR] uvicorn.error: Exception in ASGI application
Traceback (most recent call last):
  File "C:\Users\pc\AppData\Local\Programs\Python\Python313\Lib\site-packages\sqlalchemy\orm\mapper.py", line 2522, in get_property
    return self._props[key]
           ~~~~~~~~~~~^^^^^
KeyError: 'states'

The above exception was the direct cause of the following exception:

Traceback (most recent call last):
  File "C:\Users\pc\AppData\Local\Programs\Python\Python313\Lib\site-packages\uvicorn\protocols\http\h11_impl.py", line 403, in run_asgi
    result = await app(  # type: ignore[func-returns-value]
             ^^^^^^^^^^^^^^^^^^^^^^^^^^^^^^^^^^^^^^^^^^^^^^
        self.scope, self.receive, self.send
        ^^^^^^^^^^^^^^^^^^^^^^^^^^^^^^^^^^^
    )
    ^
  File "C:\Users\pc\AppData\Local\Programs\Python\Python313\Lib\site-packages\uvicorn\middleware\proxy_headers.py", line 60, in __call__
    return await self.app(scope, receive, send)
           ^^^^^^^^^^^^^^^^^^^^^^^^^^^^^^^^^^^^
  File "C:\Users\pc\AppData\Local\Programs\Python\Python313\Lib\site-packages\fastapi\applications.py", line 1054, in __call__
    await super().__call__(scope, receive, send)
  File "C:\Users\pc\AppData\Local\Programs\Python\Python313\Lib\site-packages\starlette\applications.py", line 112, in __call__
    await self.middleware_stack(scope, receive, send)
  File "C:\Users\pc\AppData\Local\Programs\Python\Python313\Lib\site-packages\starlette\middleware\errors.py", line 187, in __call__
    raise exc
  File "C:\Users\pc\AppData\Local\Programs\Python\Python313\Lib\site-packages\starlette\middleware\errors.py", line 165, in __call__
    await self.app(scope, receive, _send)
  File "C:\Users\pc\AppData\Local\Programs\Python\Python313\Lib\site-packages\starlette\middleware\cors.py", line 85, in __call__
    await self.app(scope, receive, send)
  File "C:\Users\pc\AppData\Local\Programs\Python\Python313\Lib\site-packages\starlette\middleware\exceptions.py", line 62, in __call__
    await wrap_app_handling_exceptions(self.app, conn)(scope, receive, send)
  File "C:\Users\pc\AppData\Local\Programs\Python\Python313\Lib\site-packages\starlette\_exception_handler.py", line 53, in wrapped_app
    raise exc
  File "C:\Users\pc\AppData\Local\Programs\Python\Python313\Lib\site-packages\starlette\_exception_handler.py", line 42, in wrapped_app
    await app(scope, receive, sender)
  File "C:\Users\pc\AppData\Local\Programs\Python\Python313\Lib\site-packages\starlette\routing.py", line 714, in __call__
    await self.middleware_stack(scope, receive, send)
  File "C:\Users\pc\AppData\Local\Programs\Python\Python313\Lib\site-packages\starlette\routing.py", line 734, in app
    await route.handle(scope, receive, send)
  File "C:\Users\pc\AppData\Local\Programs\Python\Python313\Lib\site-packages\starlette\routing.py", line 288, in handle
    await self.app(scope, receive, send)
  File "C:\Users\pc\AppData\Local\Programs\Python\Python313\Lib\site-packages\starlette\routing.py", line 76, in app
    await wrap_app_handling_exceptions(app, request)(scope, receive, send)
  File "C:\Users\pc\AppData\Local\Programs\Python\Python313\Lib\site-packages\starlette\_exception_handler.py", line 53, in wrapped_app
    raise exc
  File "C:\Users\pc\AppData\Local\Programs\Python\Python313\Lib\site-packages\starlette\_exception_handler.py", line 42, in wrapped_app
    await app(scope, receive, sender)
  File "C:\Users\pc\AppData\Local\Programs\Python\Python313\Lib\site-packages\starlette\routing.py", line 73, in app
    response = await f(request)
               ^^^^^^^^^^^^^^^^
  File "C:\Users\pc\AppData\Local\Programs\Python\Python313\Lib\site-packages\fastapi\routing.py", line 301, in app
    raw_response = await run_endpoint_function(
                   ^^^^^^^^^^^^^^^^^^^^^^^^^^^^
    ...<3 lines>...
    )
    ^
  File "C:\Users\pc\AppData\Local\Programs\Python\Python313\Lib\site-packages\fastapi\routing.py", line 214, in run_endpoint_function
    return await run_in_threadpool(dependant.call, **values)
           ^^^^^^^^^^^^^^^^^^^^^^^^^^^^^^^^^^^^^^^^^^^^^^^^^
  File "C:\Users\pc\AppData\Local\Programs\Python\Python313\Lib\site-packages\starlette\concurrency.py", line 37, in run_in_threadpool
    return await anyio.to_thread.run_sync(func)
           ^^^^^^^^^^^^^^^^^^^^^^^^^^^^^^^^^^^^
  File "C:\Users\pc\AppData\Local\Programs\Python\Python313\Lib\site-packages\anyio\to_thread.py", line 56, in run_sync
    return await get_async_backend().run_sync_in_worker_thread(
           ^^^^^^^^^^^^^^^^^^^^^^^^^^^^^^^^^^^^^^^^^^^^^^^^^^^^
        func, args, abandon_on_cancel=abandon_on_cancel, limiter=limiter
        ^^^^^^^^^^^^^^^^^^^^^^^^^^^^^^^^^^^^^^^^^^^^^^^^^^^^^^^^^^^^^^^^
    )
    ^
  File "C:\Users\pc\AppData\Local\Programs\Python\Python313\Lib\site-packages\anyio\_backends\_asyncio.py", line 2470, in run_sync_in_worker_thread
    return await future
           ^^^^^^^^^^^^
  File "C:\Users\pc\AppData\Local\Programs\Python\Python313\Lib\site-packages\anyio\_backends\_asyncio.py", line 967, in run
    result = context.run(func, *args)
  File "D:\Projects\Development\webcore-erp\webcore-erp\wcs-backend\app\routes\client.py", line 35, in get_clients
    return db.query(Client).offset(skip).limit(limit).all()
           ~~~~~~~~^^^^^^^^
  File "C:\Users\pc\AppData\Local\Programs\Python\Python313\Lib\site-packages\sqlalchemy\orm\session.py", line 2955, in query
    return self._query_cls(entities, self, **kwargs)
           ~~~~~~~~~~~~~~~^^^^^^^^^^^^^^^^^^^^^^^^^^
  File "C:\Users\pc\AppData\Local\Programs\Python\Python313\Lib\site-packages\sqlalchemy\orm\query.py", line 276, in __init__
    self._set_entities(entities)
    ~~~~~~~~~~~~~~~~~~^^^^^^^^^^
  File "C:\Users\pc\AppData\Local\Programs\Python\Python313\Lib\site-packages\sqlalchemy\orm\query.py", line 289, in _set_entities
    coercions.expect(
    ~~~~~~~~~~~~~~~~^
        roles.ColumnsClauseRole,
        ^^^^^^^^^^^^^^^^^^^^^^^^
    ...<2 lines>...
        post_inspect=True,
        ^^^^^^^^^^^^^^^^^^
    )
    ^
  File "C:\Users\pc\AppData\Local\Programs\Python\Python313\Lib\site-packages\sqlalchemy\sql\coercions.py", line 388, in expect
    insp._post_inspect
  File "C:\Users\pc\AppData\Local\Programs\Python\Python313\Lib\site-packages\sqlalchemy\util\langhelpers.py", line 1338, in __get__
    obj.__dict__[self.__name__] = result = self.fget(obj)
                                           ~~~~~~~~~^^^^^
  File "C:\Users\pc\AppData\Local\Programs\Python\Python313\Lib\site-packages\sqlalchemy\orm\mapper.py", line 2724, in _post_inspect
    self._check_configure()
    ~~~~~~~~~~~~~~~~~~~~~^^
  File "C:\Users\pc\AppData\Local\Programs\Python\Python313\Lib\site-packages\sqlalchemy\orm\mapper.py", line 2401, in _check_configure
    _configure_registries({self.registry}, cascade=True)
    ~~~~~~~~~~~~~~~~~~~~~^^^^^^^^^^^^^^^^^^^^^^^^^^^^^^^
  File "C:\Users\pc\AppData\Local\Programs\Python\Python313\Lib\site-packages\sqlalchemy\orm\mapper.py", line 4214, in _configure_registries
    _do_configure_registries(registries, cascade)
    ~~~~~~~~~~~~~~~~~~~~~~~~^^^^^^^^^^^^^^^^^^^^^
  File "C:\Users\pc\AppData\Local\Programs\Python\Python313\Lib\site-packages\sqlalchemy\orm\mapper.py", line 4255, in _do_configure_registries
    mapper._post_configure_properties()
    ~~~~~~~~~~~~~~~~~~~~~~~~~~~~~~~~~^^
  File "C:\Users\pc\AppData\Local\Programs\Python\Python313\Lib\site-packages\sqlalchemy\orm\mapper.py", line 2418, in _post_configure_properties
    prop.init()
    ~~~~~~~~~^^
  File "C:\Users\pc\AppData\Local\Programs\Python\Python313\Lib\site-packages\sqlalchemy\orm\interfaces.py", line 589, in init
    self.do_init()
    ~~~~~~~~~~~~^^
  File "C:\Users\pc\AppData\Local\Programs\Python\Python313\Lib\site-packages\sqlalchemy\orm\relationships.py", line 1661, in do_init
    self._generate_backref()
    ~~~~~~~~~~~~~~~~~~~~~~^^
  File "C:\Users\pc\AppData\Local\Programs\Python\Python313\Lib\site-packages\sqlalchemy\orm\relationships.py", line 2145, in _generate_backref
    self._add_reverse_property(self.back_populates)
    ~~~~~~~~~~~~~~~~~~~~~~~~~~^^^^^^^^^^^^^^^^^^^^^
  File "C:\Users\pc\AppData\Local\Programs\Python\Python313\Lib\site-packages\sqlalchemy\orm\relationships.py", line 1592, in _add_reverse_property
    other = self.mapper.get_property(key, _configure_mappers=False)
  File "C:\Users\pc\AppData\Local\Programs\Python\Python313\Lib\site-packages\sqlalchemy\orm\mapper.py", line 2524, in get_property
    raise sa_exc.InvalidRequestError(
    ...<3 lines>...
    ) from err
sqlalchemy.exc.InvalidRequestError: Mapper 'Mapper[Country(countries)]' has no property 'states'.  If this property was indicated from other mappers or configure events, ensure registry.configure() has been called.
[2025-06-23 16:52:40,313] [INFO] uvicorn.error: Shutting down
[2025-06-23 16:52:40,416] [INFO] uvicorn.error: Waiting for application shutdown.
[2025-06-23 16:52:40,417] [INFO] uvicorn.error: Application shutdown complete.
[2025-06-23 16:52:40,417] [INFO] uvicorn.error: Finished server process [14848]
[2025-06-23 16:52:45,154] [INFO] uvicorn.error: Started server process [15864]
[2025-06-23 16:52:45,155] [INFO] uvicorn.error: Waiting for application startup.
[2025-06-23 16:52:45,156] [INFO] uvicorn.error: Application startup complete.
[2025-06-23 16:52:45,157] [INFO] uvicorn.error: Uvicorn running on http://127.0.0.1:8000 (Press CTRL+C to quit)
[2025-06-23 16:54:40,727] [INFO] uvicorn.error: Shutting down
[2025-06-23 16:54:40,844] [INFO] uvicorn.error: Waiting for application shutdown.
[2025-06-23 16:54:40,845] [INFO] uvicorn.error: Application shutdown complete.
[2025-06-23 16:54:40,845] [INFO] uvicorn.error: Finished server process [15864]
[2025-06-23 16:54:45,385] [INFO] uvicorn.error: Started server process [2648]
[2025-06-23 16:54:45,386] [INFO] uvicorn.error: Waiting for application startup.
[2025-06-23 16:54:45,387] [INFO] uvicorn.error: Application startup complete.
[2025-06-23 16:54:45,388] [INFO] uvicorn.error: Uvicorn running on http://127.0.0.1:8000 (Press CTRL+C to quit)
[2025-06-23 17:01:31,418] [INFO] uvicorn.error: Shutting down
[2025-06-23 17:01:31,522] [INFO] uvicorn.error: Waiting for application shutdown.
[2025-06-23 17:01:31,523] [INFO] uvicorn.error: Application shutdown complete.
[2025-06-23 17:01:31,523] [INFO] uvicorn.error: Finished server process [2648]
[2025-06-23 17:01:36,177] [INFO] uvicorn.error: Started server process [4828]
[2025-06-23 17:01:36,178] [INFO] uvicorn.error: Waiting for application startup.
[2025-06-23 17:01:36,180] [INFO] uvicorn.error: Application startup complete.
[2025-06-23 17:01:36,181] [INFO] uvicorn.error: Uvicorn running on http://127.0.0.1:8000 (Press CTRL+C to quit)
[2025-06-23 17:02:19,113] [INFO] uvicorn.error: Shutting down
[2025-06-23 17:02:19,215] [INFO] uvicorn.error: Waiting for application shutdown.
[2025-06-23 17:02:19,216] [INFO] uvicorn.error: Application shutdown complete.
[2025-06-23 17:02:19,217] [INFO] uvicorn.error: Finished server process [4828]
[2025-06-23 17:02:23,765] [INFO] uvicorn.error: Started server process [13324]
[2025-06-23 17:02:23,766] [INFO] uvicorn.error: Waiting for application startup.
[2025-06-23 17:02:23,767] [INFO] uvicorn.error: Application startup complete.
[2025-06-23 17:02:23,768] [INFO] uvicorn.error: Uvicorn running on http://127.0.0.1:8000 (Press CTRL+C to quit)
[2025-06-23 17:02:52,684] [INFO] app.routes.auth: employee found: <app.models.employee.Employee object at 0x0000017F3915A3C0>
[2025-06-23 17:03:15,250] [INFO] app.routes.auth: employee found: <app.models.employee.Employee object at 0x0000017F39246710>
[2025-06-23 17:09:35,513] [INFO] app.routes.auth: employee found: <app.models.employee.Employee object at 0x0000017F39246850>
[2025-06-23 17:23:21,140] [INFO] uvicorn.error: Shutting down
[2025-06-23 17:23:21,256] [INFO] uvicorn.error: Waiting for application shutdown.
[2025-06-23 17:23:21,257] [INFO] uvicorn.error: Application shutdown complete.
[2025-06-23 17:23:21,257] [INFO] uvicorn.error: Finished server process [13324]
[2025-06-23 17:23:26,046] [INFO] uvicorn.error: Started server process [8760]
[2025-06-23 17:23:26,047] [INFO] uvicorn.error: Waiting for application startup.
[2025-06-23 17:23:26,048] [INFO] uvicorn.error: Application startup complete.
[2025-06-23 17:23:26,049] [INFO] uvicorn.error: Uvicorn running on http://127.0.0.1:8000 (Press CTRL+C to quit)
[2025-06-23 17:24:16,990] [INFO] app.routes.auth: employee found: <app.models.employee.Employee object at 0x000001C9A934E7B0>
[2025-06-23 17:24:43,051] [INFO] app.routes.auth: employee found: <app.models.employee.Employee object at 0x000001C9A94ECE10>
[2025-06-23 17:24:59,826] [INFO] app.routes.auth: employee found: <app.models.employee.Employee object at 0x000001C9A94ECE10>
[2025-06-23 17:25:55,502] [INFO] app.routes.auth: employee found: <app.models.employee.Employee object at 0x000001C9A94DA9E0>
[2025-06-23 17:28:46,143] [INFO] app.routes.auth: employee found: <app.models.employee.Employee object at 0x000001C9A94DAB10>
[2025-06-23 17:29:06,564] [INFO] app.routes.auth: employee found: <app.models.employee.Employee object at 0x000001C9A9663E30>
[2025-06-23 17:29:28,234] [INFO] app.routes.auth: employee found: <app.models.employee.Employee object at 0x000001C9A95117B0>
[2025-06-23 17:31:53,339] [INFO] app.routes.auth: employee found: <app.models.employee.Employee object at 0x000001C9A9511590>
[2025-06-23 17:34:42,849] [INFO] app.routes.auth: employee found: <app.models.employee.Employee object at 0x000001C9A9433050>
[2025-06-23 17:38:05,148] [INFO] app.routes.auth: employee found: <app.models.employee.Employee object at 0x000001C9A9433050>
[2025-06-23 17:38:18,822] [INFO] app.routes.auth: employee found: <app.models.employee.Employee object at 0x000001C9A9685130>
[2025-06-23 19:09:06,552] [INFO] uvicorn.error: Shutting down
[2025-06-23 19:09:06,656] [INFO] uvicorn.error: Waiting for application shutdown.
[2025-06-23 19:09:06,657] [INFO] uvicorn.error: Application shutdown complete.
[2025-06-23 19:09:06,657] [INFO] uvicorn.error: Finished server process [8760]
